2023-01-09T04:48:27.258750014Z I0109 04:48:27.258651       1 flags.go:64] FLAG: --add-dir-header="false"
2023-01-09T04:48:27.258750014Z I0109 04:48:27.258721       1 flags.go:64] FLAG: --allow-metric-labels="[]"
2023-01-09T04:48:27.258750014Z I0109 04:48:27.258729       1 flags.go:64] FLAG: --alsologtostderr="false"
2023-01-09T04:48:27.258750014Z I0109 04:48:27.258732       1 flags.go:64] FLAG: --authentication-kubeconfig="/etc/kubernetes/static-pod-resources/configmaps/scheduler-kubeconfig/kubeconfig"
2023-01-09T04:48:27.258865063Z I0109 04:48:27.258737       1 flags.go:64] FLAG: --authentication-skip-lookup="false"
2023-01-09T04:48:27.258865063Z I0109 04:48:27.258742       1 flags.go:64] FLAG: --authentication-token-webhook-cache-ttl="10s"
2023-01-09T04:48:27.258865063Z I0109 04:48:27.258748       1 flags.go:64] FLAG: --authentication-tolerate-lookup-failure="true"
2023-01-09T04:48:27.258865063Z I0109 04:48:27.258753       1 flags.go:64] FLAG: --authorization-always-allow-paths="[/healthz,/readyz,/livez]"
2023-01-09T04:48:27.258865063Z I0109 04:48:27.258762       1 flags.go:64] FLAG: --authorization-kubeconfig="/etc/kubernetes/static-pod-resources/configmaps/scheduler-kubeconfig/kubeconfig"
2023-01-09T04:48:27.258865063Z I0109 04:48:27.258768       1 flags.go:64] FLAG: --authorization-webhook-cache-authorized-ttl="10s"
2023-01-09T04:48:27.258865063Z I0109 04:48:27.258773       1 flags.go:64] FLAG: --authorization-webhook-cache-unauthorized-ttl="10s"
2023-01-09T04:48:27.258865063Z I0109 04:48:27.258778       1 flags.go:64] FLAG: --bind-address="0.0.0.0"
2023-01-09T04:48:27.258865063Z I0109 04:48:27.258782       1 flags.go:64] FLAG: --cert-dir="/var/run/kubernetes"
2023-01-09T04:48:27.258865063Z I0109 04:48:27.258785       1 flags.go:64] FLAG: --client-ca-file=""
2023-01-09T04:48:27.258865063Z I0109 04:48:27.258788       1 flags.go:64] FLAG: --config="/etc/kubernetes/static-pod-resources/configmaps/config/config.yaml"
2023-01-09T04:48:27.258865063Z I0109 04:48:27.258791       1 flags.go:64] FLAG: --contention-profiling="true"
2023-01-09T04:48:27.258865063Z I0109 04:48:27.258795       1 flags.go:64] FLAG: --disabled-metrics="[]"
2023-01-09T04:48:27.258865063Z I0109 04:48:27.258800       1 flags.go:64] FLAG: --feature-gates="APIPriorityAndFairness=true,CSIMigrationAzureFile=false,CSIMigrationvSphere=false,DownwardAPIHugePages=true,RotateKubeletServerCertificate=true"
2023-01-09T04:48:27.258865063Z I0109 04:48:27.258819       1 flags.go:64] FLAG: --help="false"
2023-01-09T04:48:27.258865063Z I0109 04:48:27.258824       1 flags.go:64] FLAG: --http2-max-streams-per-connection="0"
2023-01-09T04:48:27.258865063Z I0109 04:48:27.258829       1 flags.go:64] FLAG: --kube-api-burst="100"
2023-01-09T04:48:27.258865063Z I0109 04:48:27.258834       1 flags.go:64] FLAG: --kube-api-content-type="application/vnd.kubernetes.protobuf"
2023-01-09T04:48:27.258865063Z I0109 04:48:27.258837       1 flags.go:64] FLAG: --kube-api-qps="50"
2023-01-09T04:48:27.258865063Z I0109 04:48:27.258841       1 flags.go:64] FLAG: --kubeconfig=""
2023-01-09T04:48:27.258865063Z I0109 04:48:27.258844       1 flags.go:64] FLAG: --leader-elect="true"
2023-01-09T04:48:27.258865063Z I0109 04:48:27.258847       1 flags.go:64] FLAG: --leader-elect-lease-duration="15s"
2023-01-09T04:48:27.258865063Z I0109 04:48:27.258850       1 flags.go:64] FLAG: --leader-elect-renew-deadline="10s"
2023-01-09T04:48:27.258865063Z I0109 04:48:27.258853       1 flags.go:64] FLAG: --leader-elect-resource-lock="leases"
2023-01-09T04:48:27.258865063Z I0109 04:48:27.258857       1 flags.go:64] FLAG: --leader-elect-resource-name="kube-scheduler"
2023-01-09T04:48:27.258882942Z I0109 04:48:27.258861       1 flags.go:64] FLAG: --leader-elect-resource-namespace="kube-system"
2023-01-09T04:48:27.258882942Z I0109 04:48:27.258866       1 flags.go:64] FLAG: --leader-elect-retry-period="2s"
2023-01-09T04:48:27.258882942Z I0109 04:48:27.258870       1 flags.go:64] FLAG: --lock-object-name="kube-scheduler"
2023-01-09T04:48:27.258882942Z I0109 04:48:27.258875       1 flags.go:64] FLAG: --lock-object-namespace="kube-system"
2023-01-09T04:48:27.258882942Z I0109 04:48:27.258879       1 flags.go:64] FLAG: --log-backtrace-at=":0"
2023-01-09T04:48:27.258897867Z I0109 04:48:27.258884       1 flags.go:64] FLAG: --log-dir=""
2023-01-09T04:48:27.258897867Z I0109 04:48:27.258889       1 flags.go:64] FLAG: --log-file=""
2023-01-09T04:48:27.258897867Z I0109 04:48:27.258893       1 flags.go:64] FLAG: --log-file-max-size="1800"
2023-01-09T04:48:27.258909162Z I0109 04:48:27.258898       1 flags.go:64] FLAG: --log-flush-frequency="5s"
2023-01-09T04:48:27.258909162Z I0109 04:48:27.258902       1 flags.go:64] FLAG: --log-json-info-buffer-size="0"
2023-01-09T04:48:27.258918255Z I0109 04:48:27.258911       1 flags.go:64] FLAG: --log-json-split-stream="false"
2023-01-09T04:48:27.258918255Z I0109 04:48:27.258915       1 flags.go:64] FLAG: --logging-format="text"
2023-01-09T04:48:27.258928610Z I0109 04:48:27.258919       1 flags.go:64] FLAG: --logtostderr="true"
2023-01-09T04:48:27.258928610Z I0109 04:48:27.258923       1 flags.go:64] FLAG: --master=""
2023-01-09T04:48:27.258938361Z I0109 04:48:27.258928       1 flags.go:64] FLAG: --one-output="false"
2023-01-09T04:48:27.258938361Z I0109 04:48:27.258933       1 flags.go:64] FLAG: --permit-address-sharing="false"
2023-01-09T04:48:27.258948199Z I0109 04:48:27.258937       1 flags.go:64] FLAG: --permit-port-sharing="false"
2023-01-09T04:48:27.258948199Z I0109 04:48:27.258941       1 flags.go:64] FLAG: --pod-max-in-unschedulable-pods-duration="5m0s"
2023-01-09T04:48:27.258957955Z I0109 04:48:27.258946       1 flags.go:64] FLAG: --profiling="true"
2023-01-09T04:48:27.258957955Z I0109 04:48:27.258950       1 flags.go:64] FLAG: --requestheader-allowed-names="[]"
2023-01-09T04:48:27.258967854Z I0109 04:48:27.258956       1 flags.go:64] FLAG: --requestheader-client-ca-file=""
2023-01-09T04:48:27.258967854Z I0109 04:48:27.258960       1 flags.go:64] FLAG: --requestheader-extra-headers-prefix="[x-remote-extra-]"
2023-01-09T04:48:27.258978219Z I0109 04:48:27.258964       1 flags.go:64] FLAG: --requestheader-group-headers="[x-remote-group]"
2023-01-09T04:48:27.258978219Z I0109 04:48:27.258969       1 flags.go:64] FLAG: --requestheader-username-headers="[x-remote-user]"
2023-01-09T04:48:27.258978219Z I0109 04:48:27.258973       1 flags.go:64] FLAG: --secure-port="10259"
2023-01-09T04:48:27.258995371Z I0109 04:48:27.258977       1 flags.go:64] FLAG: --show-hidden-metrics-for-version=""
2023-01-09T04:48:27.258995371Z I0109 04:48:27.258979       1 flags.go:64] FLAG: --skip-headers="false"
2023-01-09T04:48:27.258995371Z I0109 04:48:27.258982       1 flags.go:64] FLAG: --skip-log-headers="false"
2023-01-09T04:48:27.258995371Z I0109 04:48:27.258985       1 flags.go:64] FLAG: --stderrthreshold="2"
2023-01-09T04:48:27.258995371Z I0109 04:48:27.258988       1 flags.go:64] FLAG: --tls-cert-file="/etc/kubernetes/static-pod-resources/secrets/serving-cert/tls.crt"
2023-01-09T04:48:27.259006842Z I0109 04:48:27.258992       1 flags.go:64] FLAG: --tls-cipher-suites="[TLS_ECDHE_ECDSA_WITH_AES_128_GCM_SHA256,TLS_ECDHE_RSA_WITH_AES_128_GCM_SHA256,TLS_ECDHE_ECDSA_WITH_AES_256_GCM_SHA384,TLS_ECDHE_RSA_WITH_AES_256_GCM_SHA384,TLS_ECDHE_ECDSA_WITH_CHACHA20_POLY1305_SHA256,TLS_ECDHE_RSA_WITH_CHACHA20_POLY1305_SHA256]"
2023-01-09T04:48:27.259021101Z I0109 04:48:27.259004       1 flags.go:64] FLAG: --tls-min-version="VersionTLS12"
2023-01-09T04:48:27.259021101Z I0109 04:48:27.259008       1 flags.go:64] FLAG: --tls-private-key-file="/etc/kubernetes/static-pod-resources/secrets/serving-cert/tls.key"
2023-01-09T04:48:27.259021101Z I0109 04:48:27.259012       1 flags.go:64] FLAG: --tls-sni-cert-key="[]"
2023-01-09T04:48:27.259021101Z I0109 04:48:27.259016       1 flags.go:64] FLAG: --unsupported-kube-api-over-localhost="false"
2023-01-09T04:48:27.259041761Z I0109 04:48:27.259021       1 flags.go:64] FLAG: --v="2"
2023-01-09T04:48:27.259041761Z I0109 04:48:27.259037       1 flags.go:64] FLAG: --version="false"
2023-01-09T04:48:27.259050346Z I0109 04:48:27.259042       1 flags.go:64] FLAG: --vmodule=""
2023-01-09T04:48:27.259050346Z I0109 04:48:27.259046       1 flags.go:64] FLAG: --write-config-to=""
2023-01-09T04:48:27.260217268Z I0109 04:48:27.260179       1 dynamic_serving_content.go:113] "Loaded a new cert/key pair" name="serving-cert::/etc/kubernetes/static-pod-resources/secrets/serving-cert/tls.crt::/etc/kubernetes/static-pod-resources/secrets/serving-cert/tls.key"
2023-01-09T04:48:27.827715364Z I0109 04:48:27.827674       1 requestheader_controller.go:244] Loaded a new request header values for RequestHeaderAuthRequestController
2023-01-09T04:48:27.861967083Z I0109 04:48:27.861923       1 configfile.go:102] "Using component config" config=<
2023-01-09T04:48:27.861967083Z 	apiVersion: kubescheduler.config.k8s.io/v1beta3
2023-01-09T04:48:27.861967083Z 	clientConnection:
2023-01-09T04:48:27.861967083Z 	  acceptContentTypes: ""
2023-01-09T04:48:27.861967083Z 	  burst: 100
2023-01-09T04:48:27.861967083Z 	  contentType: application/vnd.kubernetes.protobuf
2023-01-09T04:48:27.861967083Z 	  kubeconfig: /etc/kubernetes/static-pod-resources/configmaps/scheduler-kubeconfig/kubeconfig
2023-01-09T04:48:27.861967083Z 	  qps: 50
2023-01-09T04:48:27.861967083Z 	enableContentionProfiling: true
2023-01-09T04:48:27.861967083Z 	enableProfiling: true
2023-01-09T04:48:27.861967083Z 	kind: KubeSchedulerConfiguration
2023-01-09T04:48:27.861967083Z 	leaderElection:
2023-01-09T04:48:27.861967083Z 	  leaderElect: true
2023-01-09T04:48:27.861967083Z 	  leaseDuration: 2m17s
2023-01-09T04:48:27.861967083Z 	  renewDeadline: 1m47s
2023-01-09T04:48:27.861967083Z 	  resourceLock: configmapsleases
2023-01-09T04:48:27.861967083Z 	  resourceName: kube-scheduler
2023-01-09T04:48:27.861967083Z 	  resourceNamespace: openshift-kube-scheduler
2023-01-09T04:48:27.861967083Z 	  retryPeriod: 26s
2023-01-09T04:48:27.861967083Z 	parallelism: 16
2023-01-09T04:48:27.861967083Z 	percentageOfNodesToScore: 0
2023-01-09T04:48:27.861967083Z 	podInitialBackoffSeconds: 1
2023-01-09T04:48:27.861967083Z 	podMaxBackoffSeconds: 10
2023-01-09T04:48:27.861967083Z 	profiles:
2023-01-09T04:48:27.861967083Z 	- pluginConfig:
2023-01-09T04:48:27.861967083Z 	  - args:
2023-01-09T04:48:27.861967083Z 	      apiVersion: kubescheduler.config.k8s.io/v1beta3
2023-01-09T04:48:27.861967083Z 	      kind: DefaultPreemptionArgs
2023-01-09T04:48:27.861967083Z 	      minCandidateNodesAbsolute: 100
2023-01-09T04:48:27.861967083Z 	      minCandidateNodesPercentage: 10
2023-01-09T04:48:27.861967083Z 	    name: DefaultPreemption
2023-01-09T04:48:27.861967083Z 	  - args:
2023-01-09T04:48:27.861967083Z 	      apiVersion: kubescheduler.config.k8s.io/v1beta3
2023-01-09T04:48:27.861967083Z 	      hardPodAffinityWeight: 1
2023-01-09T04:48:27.861967083Z 	      kind: InterPodAffinityArgs
2023-01-09T04:48:27.861967083Z 	    name: InterPodAffinity
2023-01-09T04:48:27.861967083Z 	  - args:
2023-01-09T04:48:27.861967083Z 	      apiVersion: kubescheduler.config.k8s.io/v1beta3
2023-01-09T04:48:27.861967083Z 	      kind: NodeAffinityArgs
2023-01-09T04:48:27.861967083Z 	    name: NodeAffinity
2023-01-09T04:48:27.861967083Z 	  - args:
2023-01-09T04:48:27.861967083Z 	      apiVersion: kubescheduler.config.k8s.io/v1beta3
2023-01-09T04:48:27.861967083Z 	      kind: NodeResourcesBalancedAllocationArgs
2023-01-09T04:48:27.861967083Z 	      resources:
2023-01-09T04:48:27.861967083Z 	      - name: cpu
2023-01-09T04:48:27.861967083Z 	        weight: 1
2023-01-09T04:48:27.861967083Z 	      - name: memory
2023-01-09T04:48:27.861967083Z 	        weight: 1
2023-01-09T04:48:27.861967083Z 	    name: NodeResourcesBalancedAllocation
2023-01-09T04:48:27.861967083Z 	  - args:
2023-01-09T04:48:27.861967083Z 	      apiVersion: kubescheduler.config.k8s.io/v1beta3
2023-01-09T04:48:27.861967083Z 	      kind: NodeResourcesFitArgs
2023-01-09T04:48:27.861967083Z 	      scoringStrategy:
2023-01-09T04:48:27.861967083Z 	        resources:
2023-01-09T04:48:27.861967083Z 	        - name: cpu
2023-01-09T04:48:27.861967083Z 	          weight: 1
2023-01-09T04:48:27.861967083Z 	        - name: memory
2023-01-09T04:48:27.861967083Z 	          weight: 1
2023-01-09T04:48:27.861967083Z 	        type: LeastAllocated
2023-01-09T04:48:27.861967083Z 	    name: NodeResourcesFit
2023-01-09T04:48:27.861967083Z 	  - args:
2023-01-09T04:48:27.861967083Z 	      apiVersion: kubescheduler.config.k8s.io/v1beta3
2023-01-09T04:48:27.861967083Z 	      defaultingType: System
2023-01-09T04:48:27.861967083Z 	      kind: PodTopologySpreadArgs
2023-01-09T04:48:27.861967083Z 	    name: PodTopologySpread
2023-01-09T04:48:27.861967083Z 	  - args:
2023-01-09T04:48:27.861967083Z 	      apiVersion: kubescheduler.config.k8s.io/v1beta3
2023-01-09T04:48:27.861967083Z 	      bindTimeoutSeconds: 600
2023-01-09T04:48:27.861967083Z 	      kind: VolumeBindingArgs
2023-01-09T04:48:27.861967083Z 	    name: VolumeBinding
2023-01-09T04:48:27.861967083Z 	  plugins:
2023-01-09T04:48:27.861967083Z 	    bind: {}
2023-01-09T04:48:27.861967083Z 	    filter: {}
2023-01-09T04:48:27.861967083Z 	    multiPoint:
2023-01-09T04:48:27.861967083Z 	      enabled:
2023-01-09T04:48:27.861967083Z 	      - name: PrioritySort
2023-01-09T04:48:27.861967083Z 	        weight: 0
2023-01-09T04:48:27.861967083Z 	      - name: NodeUnschedulable
2023-01-09T04:48:27.861967083Z 	        weight: 0
2023-01-09T04:48:27.861967083Z 	      - name: NodeName
2023-01-09T04:48:27.861967083Z 	        weight: 0
2023-01-09T04:48:27.861967083Z 	      - name: TaintToleration
2023-01-09T04:48:27.861967083Z 	        weight: 3
2023-01-09T04:48:27.861967083Z 	      - name: NodeAffinity
2023-01-09T04:48:27.861967083Z 	        weight: 2
2023-01-09T04:48:27.861967083Z 	      - name: NodePorts
2023-01-09T04:48:27.861967083Z 	        weight: 0
2023-01-09T04:48:27.861967083Z 	      - name: NodeResourcesFit
2023-01-09T04:48:27.861967083Z 	        weight: 1
2023-01-09T04:48:27.861967083Z 	      - name: VolumeRestrictions
2023-01-09T04:48:27.861967083Z 	        weight: 0
2023-01-09T04:48:27.861967083Z 	      - name: EBSLimits
2023-01-09T04:48:27.861967083Z 	        weight: 0
2023-01-09T04:48:27.861967083Z 	      - name: GCEPDLimits
2023-01-09T04:48:27.861967083Z 	        weight: 0
2023-01-09T04:48:27.861967083Z 	      - name: NodeVolumeLimits
2023-01-09T04:48:27.861967083Z 	        weight: 0
2023-01-09T04:48:27.861967083Z 	      - name: AzureDiskLimits
2023-01-09T04:48:27.861967083Z 	        weight: 0
2023-01-09T04:48:27.861967083Z 	      - name: VolumeBinding
2023-01-09T04:48:27.861967083Z 	        weight: 0
2023-01-09T04:48:27.861967083Z 	      - name: VolumeZone
2023-01-09T04:48:27.861967083Z 	        weight: 0
2023-01-09T04:48:27.861967083Z 	      - name: PodTopologySpread
2023-01-09T04:48:27.861967083Z 	        weight: 2
2023-01-09T04:48:27.861967083Z 	      - name: InterPodAffinity
2023-01-09T04:48:27.861967083Z 	        weight: 2
2023-01-09T04:48:27.861967083Z 	      - name: DefaultPreemption
2023-01-09T04:48:27.861967083Z 	        weight: 0
2023-01-09T04:48:27.861967083Z 	      - name: NodeResourcesBalancedAllocation
2023-01-09T04:48:27.861967083Z 	        weight: 1
2023-01-09T04:48:27.861967083Z 	      - name: ImageLocality
2023-01-09T04:48:27.861967083Z 	        weight: 1
2023-01-09T04:48:27.861967083Z 	      - name: DefaultBinder
2023-01-09T04:48:27.861967083Z 	        weight: 0
2023-01-09T04:48:27.861967083Z 	    permit: {}
2023-01-09T04:48:27.861967083Z 	    postBind: {}
2023-01-09T04:48:27.861967083Z 	    postFilter: {}
2023-01-09T04:48:27.861967083Z 	    preBind: {}
2023-01-09T04:48:27.861967083Z 	    preFilter: {}
2023-01-09T04:48:27.861967083Z 	    preScore: {}
2023-01-09T04:48:27.861967083Z 	    queueSort: {}
2023-01-09T04:48:27.861967083Z 	    reserve: {}
2023-01-09T04:48:27.861967083Z 	    score: {}
2023-01-09T04:48:27.861967083Z 	  schedulerName: default-scheduler
2023-01-09T04:48:27.861967083Z  >
2023-01-09T04:48:27.862036045Z I0109 04:48:27.861963       1 server.go:152] "Starting Kubernetes Scheduler" version="v1.25.4+77bec7a"
2023-01-09T04:48:27.862036045Z I0109 04:48:27.861973       1 server.go:154] "Golang settings" GOGC="" GOMAXPROCS="" GOTRACEBACK=""
2023-01-09T04:48:27.870531055Z I0109 04:48:27.870500       1 requestheader_controller.go:169] Starting RequestHeaderAuthRequestController
2023-01-09T04:48:27.870594617Z I0109 04:48:27.870582       1 shared_informer.go:255] Waiting for caches to sync for RequestHeaderAuthRequestController
2023-01-09T04:48:27.870646221Z I0109 04:48:27.870512       1 configmap_cafile_content.go:202] "Starting controller" name="client-ca::kube-system::extension-apiserver-authentication::requestheader-client-ca-file"
2023-01-09T04:48:27.870675904Z I0109 04:48:27.870664       1 shared_informer.go:255] Waiting for caches to sync for client-ca::kube-system::extension-apiserver-authentication::requestheader-client-ca-file
2023-01-09T04:48:27.870710906Z I0109 04:48:27.870519       1 configmap_cafile_content.go:202] "Starting controller" name="client-ca::kube-system::extension-apiserver-authentication::client-ca-file"
2023-01-09T04:48:27.870738631Z I0109 04:48:27.870729       1 shared_informer.go:255] Waiting for caches to sync for client-ca::kube-system::extension-apiserver-authentication::client-ca-file
2023-01-09T04:48:27.870887466Z I0109 04:48:27.870857       1 tlsconfig.go:200] "Loaded serving cert" certName="serving-cert::/etc/kubernetes/static-pod-resources/secrets/serving-cert/tls.crt::/etc/kubernetes/static-pod-resources/secrets/serving-cert/tls.key" certDetail="\"scheduler.openshift-kube-scheduler.svc\" [serving] validServingFor=[scheduler.openshift-kube-scheduler.svc,scheduler.openshift-kube-scheduler.svc.cluster.local] issuer=\"openshift-service-serving-signer@1673239264\" (2023-01-09 04:41:11 +0000 UTC to 2025-01-08 04:41:12 +0000 UTC (now=2023-01-09 04:48:27.870823819 +0000 UTC))"
2023-01-09T04:48:27.871108219Z I0109 04:48:27.871079       1 named_certificates.go:53] "Loaded SNI cert" index=0 certName="self-signed loopback" certDetail="\"apiserver-loopback-client@1673239707\" [serving] validServingFor=[apiserver-loopback-client] issuer=\"apiserver-loopback-client-ca@1673239707\" (2023-01-09 03:48:27 +0000 UTC to 2024-01-09 03:48:27 +0000 UTC (now=2023-01-09 04:48:27.871039459 +0000 UTC))"
2023-01-09T04:48:27.871163467Z I0109 04:48:27.871150       1 secure_serving.go:210] Serving securely on [::]:10259
2023-01-09T04:48:27.871282356Z I0109 04:48:27.871118       1 dynamic_serving_content.go:132] "Starting controller" name="serving-cert::/etc/kubernetes/static-pod-resources/secrets/serving-cert/tls.crt::/etc/kubernetes/static-pod-resources/secrets/serving-cert/tls.key"
2023-01-09T04:48:27.872917858Z I0109 04:48:27.872894       1 tlsconfig.go:240] "Starting DynamicServingCertificateController"
2023-01-09T04:48:27.907620926Z I0109 04:48:27.907575       1 node_tree.go:65] "Added node in listed group to NodeTree" node="ip-10-0-145-4.us-east-2.compute.internal" zone="us-east-2:\x00:us-east-2a"
2023-01-09T04:48:27.907814053Z I0109 04:48:27.907785       1 node_tree.go:65] "Added node in listed group to NodeTree" node="ip-10-0-160-211.us-east-2.compute.internal" zone="us-east-2:\x00:us-east-2b"
2023-01-09T04:48:27.907926883Z I0109 04:48:27.907913       1 node_tree.go:65] "Added node in listed group to NodeTree" node="ip-10-0-199-219.us-east-2.compute.internal" zone="us-east-2:\x00:us-east-2c"
2023-01-09T04:48:27.908005244Z I0109 04:48:27.907986       1 node_tree.go:65] "Added node in listed group to NodeTree" node="ip-10-0-200-52.us-east-2.compute.internal" zone="us-east-2:\x00:us-east-2c"
2023-01-09T04:48:27.908120094Z I0109 04:48:27.908095       1 node_tree.go:65] "Added node in listed group to NodeTree" node="ip-10-0-130-201.us-east-2.compute.internal" zone="us-east-2:\x00:us-east-2a"
2023-01-09T04:48:27.908192631Z I0109 04:48:27.908172       1 node_tree.go:65] "Added node in listed group to NodeTree" node="ip-10-0-144-137.us-east-2.compute.internal" zone="us-east-2:\x00:us-east-2a"
2023-01-09T04:48:27.908271677Z I0109 04:48:27.908259       1 node_tree.go:65] "Added node in listed group to NodeTree" node="ip-10-0-162-201.us-east-2.compute.internal" zone="us-east-2:\x00:us-east-2b"
2023-01-09T04:48:27.991781698Z I0109 04:48:27.991742       1 shared_informer.go:262] Caches are synced for client-ca::kube-system::extension-apiserver-authentication::client-ca-file
2023-01-09T04:48:27.999500336Z I0109 04:48:27.999386       1 shared_informer.go:262] Caches are synced for RequestHeaderAuthRequestController
2023-01-09T04:48:28.000064262Z I0109 04:48:28.000037       1 tlsconfig.go:178] "Loaded client CA" index=0 certName="client-ca::kube-system::extension-apiserver-authentication::client-ca-file,client-ca::kube-system::extension-apiserver-authentication::requestheader-client-ca-file" certDetail="\"admin-kubeconfig-signer\" [] issuer=\"<self>\" (2023-01-09 04:28:21 +0000 UTC to 2033-01-06 04:28:21 +0000 UTC (now=2023-01-09 04:48:28.000005626 +0000 UTC))"
2023-01-09T04:48:28.000139428Z I0109 04:48:28.000126       1 tlsconfig.go:178] "Loaded client CA" index=1 certName="client-ca::kube-system::extension-apiserver-authentication::client-ca-file,client-ca::kube-system::extension-apiserver-authentication::requestheader-client-ca-file" certDetail="\"kubelet-signer\" [] issuer=\"<self>\" (2023-01-09 04:28:24 +0000 UTC to 2023-01-10 04:28:24 +0000 UTC (now=2023-01-09 04:48:28.000095507 +0000 UTC))"
2023-01-09T04:48:28.000198976Z I0109 04:48:28.000188       1 tlsconfig.go:178] "Loaded client CA" index=2 certName="client-ca::kube-system::extension-apiserver-authentication::client-ca-file,client-ca::kube-system::extension-apiserver-authentication::requestheader-client-ca-file" certDetail="\"kube-control-plane-signer\" [] issuer=\"<self>\" (2023-01-09 04:28:24 +0000 UTC to 2024-01-09 04:28:24 +0000 UTC (now=2023-01-09 04:48:28.000170647 +0000 UTC))"
2023-01-09T04:48:28.000244848Z I0109 04:48:28.000236       1 tlsconfig.go:178] "Loaded client CA" index=3 certName="client-ca::kube-system::extension-apiserver-authentication::client-ca-file,client-ca::kube-system::extension-apiserver-authentication::requestheader-client-ca-file" certDetail="\"kube-apiserver-to-kubelet-signer\" [] issuer=\"<self>\" (2023-01-09 04:28:24 +0000 UTC to 2024-01-09 04:28:24 +0000 UTC (now=2023-01-09 04:48:28.000219306 +0000 UTC))"
2023-01-09T04:48:28.000290495Z I0109 04:48:28.000280       1 tlsconfig.go:178] "Loaded client CA" index=4 certName="client-ca::kube-system::extension-apiserver-authentication::client-ca-file,client-ca::kube-system::extension-apiserver-authentication::requestheader-client-ca-file" certDetail="\"kubelet-bootstrap-kubeconfig-signer\" [] issuer=\"<self>\" (2023-01-09 04:28:22 +0000 UTC to 2033-01-06 04:28:22 +0000 UTC (now=2023-01-09 04:48:28.000263823 +0000 UTC))"
2023-01-09T04:48:28.000358644Z I0109 04:48:28.000325       1 tlsconfig.go:178] "Loaded client CA" index=5 certName="client-ca::kube-system::extension-apiserver-authentication::client-ca-file,client-ca::kube-system::extension-apiserver-authentication::requestheader-client-ca-file" certDetail="\"kube-csr-signer_@1673239265\" [] issuer=\"kubelet-signer\" (2023-01-09 04:41:04 +0000 UTC to 2023-01-10 04:28:24 +0000 UTC (now=2023-01-09 04:48:28.000309166 +0000 UTC))"
2023-01-09T04:48:28.000415600Z I0109 04:48:28.000405       1 tlsconfig.go:178] "Loaded client CA" index=6 certName="client-ca::kube-system::extension-apiserver-authentication::client-ca-file,client-ca::kube-system::extension-apiserver-authentication::requestheader-client-ca-file" certDetail="\"openshift-kube-apiserver-operator_node-system-admin-signer@1673239266\" [] issuer=\"<self>\" (2023-01-09 04:41:06 +0000 UTC to 2024-01-09 04:41:07 +0000 UTC (now=2023-01-09 04:48:28.000385131 +0000 UTC))"
2023-01-09T04:48:28.000621611Z I0109 04:48:28.000609       1 tlsconfig.go:200] "Loaded serving cert" certName="serving-cert::/etc/kubernetes/static-pod-resources/secrets/serving-cert/tls.crt::/etc/kubernetes/static-pod-resources/secrets/serving-cert/tls.key" certDetail="\"scheduler.openshift-kube-scheduler.svc\" [serving] validServingFor=[scheduler.openshift-kube-scheduler.svc,scheduler.openshift-kube-scheduler.svc.cluster.local] issuer=\"openshift-service-serving-signer@1673239264\" (2023-01-09 04:41:11 +0000 UTC to 2025-01-08 04:41:12 +0000 UTC (now=2023-01-09 04:48:28.000584172 +0000 UTC))"
2023-01-09T04:48:28.000776370Z I0109 04:48:28.000764       1 named_certificates.go:53] "Loaded SNI cert" index=0 certName="self-signed loopback" certDetail="\"apiserver-loopback-client@1673239707\" [serving] validServingFor=[apiserver-loopback-client] issuer=\"apiserver-loopback-client-ca@1673239707\" (2023-01-09 03:48:27 +0000 UTC to 2024-01-09 03:48:27 +0000 UTC (now=2023-01-09 04:48:28.000744686 +0000 UTC))"
2023-01-09T04:48:28.000827547Z I0109 04:48:27.999394       1 shared_informer.go:262] Caches are synced for client-ca::kube-system::extension-apiserver-authentication::requestheader-client-ca-file
2023-01-09T04:48:28.001129086Z I0109 04:48:28.001113       1 tlsconfig.go:178] "Loaded client CA" index=0 certName="client-ca::kube-system::extension-apiserver-authentication::client-ca-file,client-ca::kube-system::extension-apiserver-authentication::requestheader-client-ca-file" certDetail="\"admin-kubeconfig-signer\" [] issuer=\"<self>\" (2023-01-09 04:28:21 +0000 UTC to 2033-01-06 04:28:21 +0000 UTC (now=2023-01-09 04:48:28.00109232 +0000 UTC))"
2023-01-09T04:48:28.001189268Z I0109 04:48:28.001178       1 tlsconfig.go:178] "Loaded client CA" index=1 certName="client-ca::kube-system::extension-apiserver-authentication::client-ca-file,client-ca::kube-system::extension-apiserver-authentication::requestheader-client-ca-file" certDetail="\"kubelet-signer\" [] issuer=\"<self>\" (2023-01-09 04:28:24 +0000 UTC to 2023-01-10 04:28:24 +0000 UTC (now=2023-01-09 04:48:28.001160312 +0000 UTC))"
2023-01-09T04:48:28.001233201Z I0109 04:48:28.001224       1 tlsconfig.go:178] "Loaded client CA" index=2 certName="client-ca::kube-system::extension-apiserver-authentication::client-ca-file,client-ca::kube-system::extension-apiserver-authentication::requestheader-client-ca-file" certDetail="\"kube-control-plane-signer\" [] issuer=\"<self>\" (2023-01-09 04:28:24 +0000 UTC to 2024-01-09 04:28:24 +0000 UTC (now=2023-01-09 04:48:28.001208106 +0000 UTC))"
2023-01-09T04:48:28.001279356Z I0109 04:48:28.001269       1 tlsconfig.go:178] "Loaded client CA" index=3 certName="client-ca::kube-system::extension-apiserver-authentication::client-ca-file,client-ca::kube-system::extension-apiserver-authentication::requestheader-client-ca-file" certDetail="\"kube-apiserver-to-kubelet-signer\" [] issuer=\"<self>\" (2023-01-09 04:28:24 +0000 UTC to 2024-01-09 04:28:24 +0000 UTC (now=2023-01-09 04:48:28.001251871 +0000 UTC))"
2023-01-09T04:48:28.001323353Z I0109 04:48:28.001314       1 tlsconfig.go:178] "Loaded client CA" index=4 certName="client-ca::kube-system::extension-apiserver-authentication::client-ca-file,client-ca::kube-system::extension-apiserver-authentication::requestheader-client-ca-file" certDetail="\"kubelet-bootstrap-kubeconfig-signer\" [] issuer=\"<self>\" (2023-01-09 04:28:22 +0000 UTC to 2033-01-06 04:28:22 +0000 UTC (now=2023-01-09 04:48:28.001296881 +0000 UTC))"
2023-01-09T04:48:28.001425982Z I0109 04:48:28.001404       1 tlsconfig.go:178] "Loaded client CA" index=5 certName="client-ca::kube-system::extension-apiserver-authentication::client-ca-file,client-ca::kube-system::extension-apiserver-authentication::requestheader-client-ca-file" certDetail="\"kube-csr-signer_@1673239265\" [] issuer=\"kubelet-signer\" (2023-01-09 04:41:04 +0000 UTC to 2023-01-10 04:28:24 +0000 UTC (now=2023-01-09 04:48:28.001384901 +0000 UTC))"
2023-01-09T04:48:28.001477979Z I0109 04:48:28.001468       1 tlsconfig.go:178] "Loaded client CA" index=6 certName="client-ca::kube-system::extension-apiserver-authentication::client-ca-file,client-ca::kube-system::extension-apiserver-authentication::requestheader-client-ca-file" certDetail="\"openshift-kube-apiserver-operator_node-system-admin-signer@1673239266\" [] issuer=\"<self>\" (2023-01-09 04:41:06 +0000 UTC to 2024-01-09 04:41:07 +0000 UTC (now=2023-01-09 04:48:28.001449961 +0000 UTC))"
2023-01-09T04:48:28.001521812Z I0109 04:48:28.001512       1 tlsconfig.go:178] "Loaded client CA" index=7 certName="client-ca::kube-system::extension-apiserver-authentication::client-ca-file,client-ca::kube-system::extension-apiserver-authentication::requestheader-client-ca-file" certDetail="\"aggregator-signer\" [] issuer=\"<self>\" (2023-01-09 04:28:22 +0000 UTC to 2023-01-10 04:28:22 +0000 UTC (now=2023-01-09 04:48:28.001496726 +0000 UTC))"
2023-01-09T04:48:28.001695480Z I0109 04:48:28.001682       1 tlsconfig.go:200] "Loaded serving cert" certName="serving-cert::/etc/kubernetes/static-pod-resources/secrets/serving-cert/tls.crt::/etc/kubernetes/static-pod-resources/secrets/serving-cert/tls.key" certDetail="\"scheduler.openshift-kube-scheduler.svc\" [serving] validServingFor=[scheduler.openshift-kube-scheduler.svc,scheduler.openshift-kube-scheduler.svc.cluster.local] issuer=\"openshift-service-serving-signer@1673239264\" (2023-01-09 04:41:11 +0000 UTC to 2025-01-08 04:41:12 +0000 UTC (now=2023-01-09 04:48:28.001659426 +0000 UTC))"
2023-01-09T04:48:28.001850133Z I0109 04:48:28.001838       1 named_certificates.go:53] "Loaded SNI cert" index=0 certName="self-signed loopback" certDetail="\"apiserver-loopback-client@1673239707\" [serving] validServingFor=[apiserver-loopback-client] issuer=\"apiserver-loopback-client-ca@1673239707\" (2023-01-09 03:48:27 +0000 UTC to 2024-01-09 03:48:27 +0000 UTC (now=2023-01-09 04:48:28.001813167 +0000 UTC))"
2023-01-09T04:48:28.083107723Z I0109 04:48:28.083071       1 leaderelection.go:248] attempting to acquire leader lease openshift-kube-scheduler/kube-scheduler...
2023-01-09T04:48:38.058899466Z E0109 04:48:38.058832       1 webhook.go:223] Failed to make webhook authorizer request: Post "https://api-int.sn-loggvls-jsm.qe.devcluster.openshift.com:6443/apis/authorization.k8s.io/v1/subjectaccessreviews?timeout=10s": dial tcp 10.0.196.87:6443: connect: connection refused
2023-01-09T04:48:38.058962265Z E0109 04:48:38.058890       1 errors.go:77] Post "https://api-int.sn-loggvls-jsm.qe.devcluster.openshift.com:6443/apis/authorization.k8s.io/v1/subjectaccessreviews?timeout=10s": dial tcp 10.0.196.87:6443: connect: connection refused
2023-01-09T04:48:41.737964549Z E0109 04:48:41.737915       1 webhook.go:223] Failed to make webhook authorizer request: Post "https://api-int.sn-loggvls-jsm.qe.devcluster.openshift.com:6443/apis/authorization.k8s.io/v1/subjectaccessreviews?timeout=10s": dial tcp 10.0.131.80:6443: connect: connection refused
2023-01-09T04:48:41.737964549Z E0109 04:48:41.737953       1 errors.go:77] Post "https://api-int.sn-loggvls-jsm.qe.devcluster.openshift.com:6443/apis/authorization.k8s.io/v1/subjectaccessreviews?timeout=10s": dial tcp 10.0.131.80:6443: connect: connection refused
2023-01-09T04:50:04.053733664Z I0109 04:50:04.053681       1 leaderelection.go:258] successfully acquired lease openshift-kube-scheduler/kube-scheduler
2023-01-09T04:50:04.054459158Z I0109 04:50:04.054419       1 schedule_one.go:826] "Unable to schedule pod; no fit; waiting" pod="openshift-oauth-apiserver/apiserver-545598cc79-stls7" err="0/7 nodes are available: 3 node(s) didn't match pod anti-affinity rules, 4 node(s) didn't match Pod's node affinity/selector. preemption: 0/7 nodes are available: 3 node(s) didn't match pod anti-affinity rules, 4 Preemption is not helpful for scheduling."
2023-01-09T04:50:04.055054454Z I0109 04:50:04.055022       1 schedule_one.go:826] "Unable to schedule pod; no fit; waiting" pod="openshift-apiserver/apiserver-86b6d848c8-9mtm9" err="0/7 nodes are available: 3 node(s) didn't match pod anti-affinity rules, 4 node(s) didn't match Pod's node affinity/selector. preemption: 0/7 nodes are available: 3 node(s) didn't match pod anti-affinity rules, 4 Preemption is not helpful for scheduling."
2023-01-09T04:50:04.055639569Z I0109 04:50:04.055557       1 schedule_one.go:826] "Unable to schedule pod; no fit; waiting" pod="openshift-authentication/oauth-openshift-7b6d7d47d4-2524q" err="0/7 nodes are available: 3 node(s) didn't match pod anti-affinity rules, 4 node(s) didn't match Pod's node affinity/selector. preemption: 0/7 nodes are available: 3 node(s) didn't match pod anti-affinity rules, 4 Preemption is not helpful for scheduling."
2023-01-09T04:50:04.056133003Z I0109 04:50:04.056095       1 schedule_one.go:826] "Unable to schedule pod; no fit; waiting" pod="openshift-console/console-6cbb95b566-zblmm" err="0/7 nodes are available: 3 node(s) didn't match pod anti-affinity rules, 4 node(s) didn't match Pod's node affinity/selector. preemption: 0/7 nodes are available: 3 node(s) didn't match pod anti-affinity rules, 4 Preemption is not helpful for scheduling."
2023-01-09T04:50:04.069159997Z I0109 04:50:04.069127       1 schedule_one.go:826] "Unable to schedule pod; no fit; waiting" pod="openshift-console/console-6cbb95b566-blr5w" err="0/7 nodes are available: 3 node(s) didn't match pod anti-affinity rules, 4 node(s) didn't match Pod's node affinity/selector. preemption: 0/7 nodes are available: 3 node(s) didn't match pod anti-affinity rules, 4 Preemption is not helpful for scheduling."
2023-01-09T04:50:09.349190140Z I0109 04:50:09.349143       1 schedule_one.go:826] "Unable to schedule pod; no fit; waiting" pod="openshift-oauth-apiserver/apiserver-545598cc79-stls7" err="0/7 nodes are available: 3 node(s) didn't match pod anti-affinity rules, 4 node(s) didn't match Pod's node affinity/selector. preemption: 0/7 nodes are available: 3 node(s) didn't match pod anti-affinity rules, 4 Preemption is not helpful for scheduling."
2023-01-09T04:50:09.349857399Z I0109 04:50:09.349822       1 schedule_one.go:826] "Unable to schedule pod; no fit; waiting" pod="openshift-apiserver/apiserver-86b6d848c8-9mtm9" err="0/7 nodes are available: 3 node(s) didn't match pod anti-affinity rules, 4 node(s) didn't match Pod's node affinity/selector. preemption: 0/7 nodes are available: 3 node(s) didn't match pod anti-affinity rules, 4 Preemption is not helpful for scheduling."
2023-01-09T04:50:09.350406986Z I0109 04:50:09.350374       1 schedule_one.go:826] "Unable to schedule pod; no fit; waiting" pod="openshift-authentication/oauth-openshift-7b6d7d47d4-2524q" err="0/7 nodes are available: 3 node(s) didn't match pod anti-affinity rules, 4 node(s) didn't match Pod's node affinity/selector. preemption: 0/7 nodes are available: 3 node(s) didn't match pod anti-affinity rules, 4 Preemption is not helpful for scheduling."
2023-01-09T04:50:09.350779690Z I0109 04:50:09.350759       1 schedule_one.go:826] "Unable to schedule pod; no fit; waiting" pod="openshift-console/console-6cbb95b566-zblmm" err="0/7 nodes are available: 3 node(s) didn't match pod anti-affinity rules, 4 node(s) didn't match Pod's node affinity/selector. preemption: 0/7 nodes are available: 3 node(s) didn't match pod anti-affinity rules, 4 Preemption is not helpful for scheduling."
2023-01-09T04:50:09.351209958Z I0109 04:50:09.351182       1 schedule_one.go:826] "Unable to schedule pod; no fit; waiting" pod="openshift-console/console-6cbb95b566-blr5w" err="0/7 nodes are available: 3 node(s) didn't match pod anti-affinity rules, 4 node(s) didn't match Pod's node affinity/selector. preemption: 0/7 nodes are available: 3 node(s) didn't match pod anti-affinity rules, 4 Preemption is not helpful for scheduling."
2023-01-09T04:50:09.357282819Z E0109 04:50:09.357182       1 event_broadcaster.go:253] Server rejected event '&v1.Event{TypeMeta:v1.TypeMeta{Kind:"", APIVersion:""}, ObjectMeta:v1.ObjectMeta{Name:"apiserver-86b6d848c8-9mtm9.17388abc90bf7a86", GenerateName:"", Namespace:"openshift-apiserver", SelfLink:"", UID:"a583c129-c805-47ce-9e13-81eff4ab6451", ResourceVersion:"25193", Generation:0, CreationTimestamp:time.Date(2023, time.January, 9, 4, 50, 4, 0, time.Local), DeletionTimestamp:<nil>, DeletionGracePeriodSeconds:(*int64)(nil), Labels:map[string]string(nil), Annotations:map[string]string(nil), OwnerReferences:[]v1.OwnerReference(nil), Finalizers:[]string(nil), ManagedFields:[]v1.ManagedFieldsEntry{v1.ManagedFieldsEntry{Manager:"kube-scheduler", Operation:"Update", APIVersion:"events.k8s.io/v1", Time:time.Date(2023, time.January, 9, 4, 50, 4, 0, time.Local), FieldsType:"FieldsV1", FieldsV1:(*v1.FieldsV1)(0xc0027acae0), Subresource:""}}}, EventTime:time.Date(2023, time.January, 9, 4, 50, 4, 55089000, time.Local), Series:(*v1.EventSeries)(0xc002730da0), ReportingController:"default-scheduler", ReportingInstance:"default-scheduler-ip-10-0-199-219", Action:"Scheduling", Reason:"FailedScheduling", Regarding:v1.ObjectReference{Kind:"Pod", Namespace:"openshift-apiserver", Name:"apiserver-86b6d848c8-9mtm9", UID:"24b04715-1c91-439c-9e4f-a86f7f6705a5", APIVersion:"v1", ResourceVersion:"24593", FieldPath:""}, Related:(*v1.ObjectReference)(nil), Note:"0/7 nodes are available: 3 node(s) didn't match pod anti-affinity rules, 4 node(s) didn't match Pod's node affinity/selector. preemption: 0/7 nodes are available: 3 node(s) didn't match pod anti-affinity rules, 4 Preemption is not helpful for scheduling.", Type:"Warning", DeprecatedSource:v1.EventSource{Component:"", Host:""}, DeprecatedFirstTimestamp:time.Date(1, time.January, 1, 0, 0, 0, 0, time.UTC), DeprecatedLastTimestamp:time.Date(1, time.January, 1, 0, 0, 0, 0, time.UTC), DeprecatedCount:0}': 'Event "apiserver-86b6d848c8-9mtm9.17388abc90bf7a86" is invalid: series.count: Invalid value: "": should be at least 2' (will not retry!)
2023-01-09T04:50:09.358957795Z E0109 04:50:09.358874       1 event_broadcaster.go:253] Server rejected event '&v1.Event{TypeMeta:v1.TypeMeta{Kind:"", APIVersion:""}, ObjectMeta:v1.ObjectMeta{Name:"oauth-openshift-7b6d7d47d4-2524q.17388abc90c7f633", GenerateName:"", Namespace:"openshift-authentication", SelfLink:"", UID:"f4580ae5-4ba9-49ce-be0a-f3cea8fb98ba", ResourceVersion:"25192", Generation:0, CreationTimestamp:time.Date(2023, time.January, 9, 4, 50, 4, 0, time.Local), DeletionTimestamp:<nil>, DeletionGracePeriodSeconds:(*int64)(nil), Labels:map[string]string(nil), Annotations:map[string]string(nil), OwnerReferences:[]v1.OwnerReference(nil), Finalizers:[]string(nil), ManagedFields:[]v1.ManagedFieldsEntry{v1.ManagedFieldsEntry{Manager:"kube-scheduler", Operation:"Update", APIVersion:"events.k8s.io/v1", Time:time.Date(2023, time.January, 9, 4, 50, 4, 0, time.Local), FieldsType:"FieldsV1", FieldsV1:(*v1.FieldsV1)(0xc00227bdd0), Subresource:""}}}, EventTime:time.Date(2023, time.January, 9, 4, 50, 4, 55645000, time.Local), Series:(*v1.EventSeries)(0xc00074e020), ReportingController:"default-scheduler", ReportingInstance:"default-scheduler-ip-10-0-199-219", Action:"Scheduling", Reason:"FailedScheduling", Regarding:v1.ObjectReference{Kind:"Pod", Namespace:"openshift-authentication", Name:"oauth-openshift-7b6d7d47d4-2524q", UID:"d6873009-6911-4d60-86dc-840908d4fdc3", APIVersion:"v1", ResourceVersion:"25011", FieldPath:""}, Related:(*v1.ObjectReference)(nil), Note:"0/7 nodes are available: 3 node(s) didn't match pod anti-affinity rules, 4 node(s) didn't match Pod's node affinity/selector. preemption: 0/7 nodes are available: 3 node(s) didn't match pod anti-affinity rules, 4 Preemption is not helpful for scheduling.", Type:"Warning", DeprecatedSource:v1.EventSource{Component:"", Host:""}, DeprecatedFirstTimestamp:time.Date(1, time.January, 1, 0, 0, 0, 0, time.UTC), DeprecatedLastTimestamp:time.Date(1, time.January, 1, 0, 0, 0, 0, time.UTC), DeprecatedCount:0}': 'Event "oauth-openshift-7b6d7d47d4-2524q.17388abc90c7f633" is invalid: series.count: Invalid value: "": should be at least 2' (will not retry!)
2023-01-09T04:50:09.359039703Z E0109 04:50:09.358960       1 event_broadcaster.go:253] Server rejected event '&v1.Event{TypeMeta:v1.TypeMeta{Kind:"", APIVersion:""}, ObjectMeta:v1.ObjectMeta{Name:"apiserver-545598cc79-stls7.17388abc90b73009", GenerateName:"", Namespace:"openshift-oauth-apiserver", SelfLink:"", UID:"64208d18-2bf1-4547-8d8e-0eeab41e2ef4", ResourceVersion:"25191", Generation:0, CreationTimestamp:time.Date(2023, time.January, 9, 4, 50, 4, 0, time.Local), DeletionTimestamp:<nil>, DeletionGracePeriodSeconds:(*int64)(nil), Labels:map[string]string(nil), Annotations:map[string]string(nil), OwnerReferences:[]v1.OwnerReference(nil), Finalizers:[]string(nil), ManagedFields:[]v1.ManagedFieldsEntry{v1.ManagedFieldsEntry{Manager:"kube-scheduler", Operation:"Update", APIVersion:"events.k8s.io/v1", Time:time.Date(2023, time.January, 9, 4, 50, 4, 0, time.Local), FieldsType:"FieldsV1", FieldsV1:(*v1.FieldsV1)(0xc00227bd10), Subresource:""}}}, EventTime:time.Date(2023, time.January, 9, 4, 50, 4, 54542000, time.Local), Series:(*v1.EventSeries)(0xc002919ac0), ReportingController:"default-scheduler", ReportingInstance:"default-scheduler-ip-10-0-199-219", Action:"Scheduling", Reason:"FailedScheduling", Regarding:v1.ObjectReference{Kind:"Pod", Namespace:"openshift-oauth-apiserver", Name:"apiserver-545598cc79-stls7", UID:"0afa8bb3-8bee-42c1-a629-bce612df275c", APIVersion:"v1", ResourceVersion:"24284", FieldPath:""}, Related:(*v1.ObjectReference)(nil), Note:"0/7 nodes are available: 3 node(s) didn't match pod anti-affinity rules, 4 node(s) didn't match Pod's node affinity/selector. preemption: 0/7 nodes are available: 3 node(s) didn't match pod anti-affinity rules, 4 Preemption is not helpful for scheduling.", Type:"Warning", DeprecatedSource:v1.EventSource{Component:"", Host:""}, DeprecatedFirstTimestamp:time.Date(1, time.January, 1, 0, 0, 0, 0, time.UTC), DeprecatedLastTimestamp:time.Date(1, time.January, 1, 0, 0, 0, 0, time.UTC), DeprecatedCount:0}': 'Event "apiserver-545598cc79-stls7.17388abc90b73009" is invalid: series.count: Invalid value: "": should be at least 2' (will not retry!)
2023-01-09T04:50:20.576997335Z I0109 04:50:20.576960       1 schedule_one.go:826] "Unable to schedule pod; no fit; waiting" pod="openshift-apiserver/apiserver-86b6d848c8-9mtm9" err="0/7 nodes are available: 3 node(s) didn't match pod anti-affinity rules, 4 node(s) didn't match Pod's node affinity/selector. preemption: 0/7 nodes are available: 3 node(s) didn't match pod anti-affinity rules, 4 Preemption is not helpful for scheduling."
2023-01-09T04:50:20.577526339Z I0109 04:50:20.577496       1 schedule_one.go:826] "Unable to schedule pod; no fit; waiting" pod="openshift-authentication/oauth-openshift-7b6d7d47d4-2524q" err="0/7 nodes are available: 3 node(s) didn't match pod anti-affinity rules, 4 node(s) didn't match Pod's node affinity/selector. preemption: 0/7 nodes are available: 3 node(s) didn't match pod anti-affinity rules, 4 Preemption is not helpful for scheduling."
2023-01-09T04:50:20.578137689Z I0109 04:50:20.578094       1 schedule_one.go:826] "Unable to schedule pod; no fit; waiting" pod="openshift-console/console-6cbb95b566-zblmm" err="0/7 nodes are available: 3 node(s) didn't match pod anti-affinity rules, 4 node(s) didn't match Pod's node affinity/selector. preemption: 0/7 nodes are available: 3 node(s) didn't match pod anti-affinity rules, 4 Preemption is not helpful for scheduling."
2023-01-09T04:50:20.578643249Z I0109 04:50:20.578614       1 schedule_one.go:826] "Unable to schedule pod; no fit; waiting" pod="openshift-console/console-6cbb95b566-blr5w" err="0/7 nodes are available: 3 node(s) didn't match pod anti-affinity rules, 4 node(s) didn't match Pod's node affinity/selector. preemption: 0/7 nodes are available: 3 node(s) didn't match pod anti-affinity rules, 4 Preemption is not helpful for scheduling."
2023-01-09T04:50:20.585644642Z I0109 04:50:20.585614       1 schedule_one.go:266] "Successfully bound pod to node" pod="openshift-oauth-apiserver/apiserver-545598cc79-stls7" node="ip-10-0-199-219.us-east-2.compute.internal" evaluatedNodes=7 feasibleNodes=1
2023-01-09T04:50:20.586441173Z E0109 04:50:20.586297       1 event_broadcaster.go:253] Server rejected event '&v1.Event{TypeMeta:v1.TypeMeta{Kind:"", APIVersion:""}, ObjectMeta:v1.ObjectMeta{Name:"console-6cbb95b566-zblmm.17388abdcc65dc4e", GenerateName:"", Namespace:"openshift-console", SelfLink:"", UID:"2c217720-df12-4515-ae23-ab2a04f38ac5", ResourceVersion:"25229", Generation:0, CreationTimestamp:time.Date(2023, time.January, 9, 4, 50, 9, 0, time.Local), DeletionTimestamp:<nil>, DeletionGracePeriodSeconds:(*int64)(nil), Labels:map[string]string(nil), Annotations:map[string]string(nil), OwnerReferences:[]v1.OwnerReference(nil), Finalizers:[]string(nil), ManagedFields:[]v1.ManagedFieldsEntry{v1.ManagedFieldsEntry{Manager:"kube-scheduler", Operation:"Update", APIVersion:"events.k8s.io/v1", Time:time.Date(2023, time.January, 9, 4, 50, 9, 0, time.Local), FieldsType:"FieldsV1", FieldsV1:(*v1.FieldsV1)(0xc0014ebed8), Subresource:""}}}, EventTime:time.Date(2023, time.January, 9, 4, 50, 9, 350816000, time.Local), Series:(*v1.EventSeries)(0xc002731740), ReportingController:"default-scheduler", ReportingInstance:"default-scheduler-ip-10-0-199-219", Action:"Scheduling", Reason:"FailedScheduling", Regarding:v1.ObjectReference{Kind:"Pod", Namespace:"openshift-console", Name:"console-6cbb95b566-zblmm", UID:"47bf5dbf-20c2-4d90-a121-22d0dc55d1f6", APIVersion:"v1", ResourceVersion:"25197", FieldPath:""}, Related:(*v1.ObjectReference)(nil), Note:"0/7 nodes are available: 3 node(s) didn't match pod anti-affinity rules, 4 node(s) didn't match Pod's node affinity/selector. preemption: 0/7 nodes are available: 3 node(s) didn't match pod anti-affinity rules, 4 Preemption is not helpful for scheduling.", Type:"Warning", DeprecatedSource:v1.EventSource{Component:"", Host:""}, DeprecatedFirstTimestamp:time.Date(1, time.January, 1, 0, 0, 0, 0, time.UTC), DeprecatedLastTimestamp:time.Date(1, time.January, 1, 0, 0, 0, 0, time.UTC), DeprecatedCount:0}': 'Event "console-6cbb95b566-zblmm.17388abdcc65dc4e" is invalid: series.count: Invalid value: "": should be at least 2' (will not retry!)
2023-01-09T04:50:20.587098799Z E0109 04:50:20.587007       1 event_broadcaster.go:253] Server rejected event '&v1.Event{TypeMeta:v1.TypeMeta{Kind:"", APIVersion:""}, ObjectMeta:v1.ObjectMeta{Name:"console-6cbb95b566-blr5w.17388abdcc6c6272", GenerateName:"", Namespace:"openshift-console", SelfLink:"", UID:"9c4f14fd-9260-49b7-8624-fbd0ff09f7b4", ResourceVersion:"25230", Generation:0, CreationTimestamp:time.Date(2023, time.January, 9, 4, 50, 9, 0, time.Local), DeletionTimestamp:<nil>, DeletionGracePeriodSeconds:(*int64)(nil), Labels:map[string]string(nil), Annotations:map[string]string(nil), OwnerReferences:[]v1.OwnerReference(nil), Finalizers:[]string(nil), ManagedFields:[]v1.ManagedFieldsEntry{v1.ManagedFieldsEntry{Manager:"kube-scheduler", Operation:"Update", APIVersion:"events.k8s.io/v1", Time:time.Date(2023, time.January, 9, 4, 50, 9, 0, time.Local), FieldsType:"FieldsV1", FieldsV1:(*v1.FieldsV1)(0xc000012af8), Subresource:""}}}, EventTime:time.Date(2023, time.January, 9, 4, 50, 9, 351244000, time.Local), Series:(*v1.EventSeries)(0xc002341f60), ReportingController:"default-scheduler", ReportingInstance:"default-scheduler-ip-10-0-199-219", Action:"Scheduling", Reason:"FailedScheduling", Regarding:v1.ObjectReference{Kind:"Pod", Namespace:"openshift-console", Name:"console-6cbb95b566-blr5w", UID:"2ecab2fa-f13b-4619-97f3-b7cccb9762eb", APIVersion:"v1", ResourceVersion:"25199", FieldPath:""}, Related:(*v1.ObjectReference)(nil), Note:"0/7 nodes are available: 3 node(s) didn't match pod anti-affinity rules, 4 node(s) didn't match Pod's node affinity/selector. preemption: 0/7 nodes are available: 3 node(s) didn't match pod anti-affinity rules, 4 Preemption is not helpful for scheduling.", Type:"Warning", DeprecatedSource:v1.EventSource{Component:"", Host:""}, DeprecatedFirstTimestamp:time.Date(1, time.January, 1, 0, 0, 0, 0, time.UTC), DeprecatedLastTimestamp:time.Date(1, time.January, 1, 0, 0, 0, 0, time.UTC), DeprecatedCount:0}': 'Event "console-6cbb95b566-blr5w.17388abdcc6c6272" is invalid: series.count: Invalid value: "": should be at least 2' (will not retry!)
2023-01-09T04:50:25.067444152Z I0109 04:50:25.067400       1 schedule_one.go:826] "Unable to schedule pod; no fit; waiting" pod="openshift-apiserver/apiserver-86b6d848c8-9mtm9" err="0/7 nodes are available: 3 node(s) didn't match pod anti-affinity rules, 4 node(s) didn't match Pod's node affinity/selector. preemption: 0/7 nodes are available: 3 node(s) didn't match pod anti-affinity rules, 4 Preemption is not helpful for scheduling."
2023-01-09T04:50:25.068101485Z I0109 04:50:25.068075       1 schedule_one.go:826] "Unable to schedule pod; no fit; waiting" pod="openshift-console/console-6cbb95b566-zblmm" err="0/7 nodes are available: 3 node(s) didn't match pod anti-affinity rules, 4 node(s) didn't match Pod's node affinity/selector. preemption: 0/7 nodes are available: 3 node(s) didn't match pod anti-affinity rules, 4 Preemption is not helpful for scheduling."
2023-01-09T04:50:25.068487961Z I0109 04:50:25.068464       1 schedule_one.go:826] "Unable to schedule pod; no fit; waiting" pod="openshift-console/console-6cbb95b566-blr5w" err="0/7 nodes are available: 3 node(s) didn't match pod anti-affinity rules, 4 node(s) didn't match Pod's node affinity/selector. preemption: 0/7 nodes are available: 3 node(s) didn't match pod anti-affinity rules, 4 Preemption is not helpful for scheduling."
2023-01-09T04:50:25.075260860Z I0109 04:50:25.075225       1 schedule_one.go:266] "Successfully bound pod to node" pod="openshift-authentication/oauth-openshift-7b6d7d47d4-2524q" node="ip-10-0-160-211.us-east-2.compute.internal" evaluatedNodes=7 feasibleNodes=1
2023-01-09T04:50:26.695104345Z I0109 04:50:26.695060       1 schedule_one.go:826] "Unable to schedule pod; no fit; waiting" pod="openshift-oauth-apiserver/apiserver-545598cc79-ztrmn" err="0/7 nodes are available: 3 node(s) didn't match pod anti-affinity rules, 4 node(s) didn't match Pod's node affinity/selector. preemption: 0/7 nodes are available: 3 node(s) didn't match pod anti-affinity rules, 4 Preemption is not helpful for scheduling."
2023-01-09T04:50:28.068932399Z I0109 04:50:28.068892       1 schedule_one.go:826] "Unable to schedule pod; no fit; waiting" pod="openshift-oauth-apiserver/apiserver-545598cc79-ztrmn" err="0/7 nodes are available: 3 node(s) didn't match pod anti-affinity rules, 4 node(s) didn't match Pod's node affinity/selector. preemption: 0/7 nodes are available: 3 node(s) didn't match pod anti-affinity rules, 4 Preemption is not helpful for scheduling."
2023-01-09T04:50:33.071906721Z I0109 04:50:33.071865       1 schedule_one.go:826] "Unable to schedule pod; no fit; waiting" pod="openshift-apiserver/apiserver-86b6d848c8-9mtm9" err="0/7 nodes are available: 3 node(s) didn't match pod anti-affinity rules, 4 node(s) didn't match Pod's node affinity/selector. preemption: 0/7 nodes are available: 3 node(s) didn't match pod anti-affinity rules, 4 Preemption is not helpful for scheduling."
2023-01-09T04:50:33.072542544Z I0109 04:50:33.072517       1 schedule_one.go:826] "Unable to schedule pod; no fit; waiting" pod="openshift-console/console-6cbb95b566-blr5w" err="0/7 nodes are available: 3 node(s) didn't match pod anti-affinity rules, 4 node(s) didn't match Pod's node affinity/selector. preemption: 0/7 nodes are available: 3 node(s) didn't match pod anti-affinity rules, 4 Preemption is not helpful for scheduling."
2023-01-09T04:50:33.079144707Z I0109 04:50:33.079107       1 schedule_one.go:266] "Successfully bound pod to node" pod="openshift-console/console-6cbb95b566-zblmm" node="ip-10-0-199-219.us-east-2.compute.internal" evaluatedNodes=7 feasibleNodes=1
2023-01-09T04:50:36.062423625Z I0109 04:50:36.062383       1 schedule_one.go:826] "Unable to schedule pod; no fit; waiting" pod="openshift-oauth-apiserver/apiserver-545598cc79-ztrmn" err="0/7 nodes are available: 3 node(s) didn't match pod anti-affinity rules, 4 node(s) didn't match Pod's node affinity/selector. preemption: 0/7 nodes are available: 3 node(s) didn't match pod anti-affinity rules, 4 Preemption is not helpful for scheduling."
2023-01-09T04:50:36.069483788Z E0109 04:50:36.069385       1 event_broadcaster.go:253] Server rejected event '&v1.Event{TypeMeta:v1.TypeMeta{Kind:"", APIVersion:""}, ObjectMeta:v1.ObjectMeta{Name:"apiserver-545598cc79-ztrmn.17388ac228164849", GenerateName:"", Namespace:"openshift-oauth-apiserver", SelfLink:"", UID:"d26a0412-b662-418e-a0f3-4309364850d8", ResourceVersion:"25472", Generation:0, CreationTimestamp:time.Date(2023, time.January, 9, 4, 50, 28, 0, time.Local), DeletionTimestamp:<nil>, DeletionGracePeriodSeconds:(*int64)(nil), Labels:map[string]string(nil), Annotations:map[string]string(nil), OwnerReferences:[]v1.OwnerReference(nil), Finalizers:[]string(nil), ManagedFields:[]v1.ManagedFieldsEntry{v1.ManagedFieldsEntry{Manager:"kube-scheduler", Operation:"Update", APIVersion:"events.k8s.io/v1", Time:time.Date(2023, time.January, 9, 4, 50, 28, 0, time.Local), FieldsType:"FieldsV1", FieldsV1:(*v1.FieldsV1)(0xc00184c7b0), Subresource:""}}}, EventTime:time.Date(2023, time.January, 9, 4, 50, 28, 68973000, time.Local), Series:(*v1.EventSeries)(0xc00049d1c0), ReportingController:"default-scheduler", ReportingInstance:"default-scheduler-ip-10-0-199-219", Action:"Scheduling", Reason:"FailedScheduling", Regarding:v1.ObjectReference{Kind:"Pod", Namespace:"openshift-oauth-apiserver", Name:"apiserver-545598cc79-ztrmn", UID:"e6dfa4d3-5c82-40d2-aa1e-97cedf46fb41", APIVersion:"v1", ResourceVersion:"25443", FieldPath:""}, Related:(*v1.ObjectReference)(nil), Note:"0/7 nodes are available: 3 node(s) didn't match pod anti-affinity rules, 4 node(s) didn't match Pod's node affinity/selector. preemption: 0/7 nodes are available: 3 node(s) didn't match pod anti-affinity rules, 4 Preemption is not helpful for scheduling.", Type:"Warning", DeprecatedSource:v1.EventSource{Component:"", Host:""}, DeprecatedFirstTimestamp:time.Date(1, time.January, 1, 0, 0, 0, 0, time.UTC), DeprecatedLastTimestamp:time.Date(1, time.January, 1, 0, 0, 0, 0, time.UTC), DeprecatedCount:0}': 'Event "apiserver-545598cc79-ztrmn.17388ac228164849" is invalid: series.count: Invalid value: "": should be at least 2' (will not retry!)
2023-01-09T04:50:40.076459825Z I0109 04:50:40.076415       1 schedule_one.go:826] "Unable to schedule pod; no fit; waiting" pod="openshift-oauth-apiserver/apiserver-545598cc79-ztrmn" err="0/7 nodes are available: 3 node(s) didn't match pod anti-affinity rules, 4 node(s) didn't match Pod's node affinity/selector. preemption: 0/7 nodes are available: 3 node(s) didn't match pod anti-affinity rules, 4 Preemption is not helpful for scheduling."
2023-01-09T04:50:43.085603390Z I0109 04:50:43.085545       1 schedule_one.go:266] "Successfully bound pod to node" pod="openshift-console/console-6cbb95b566-blr5w" node="ip-10-0-160-211.us-east-2.compute.internal" evaluatedNodes=7 feasibleNodes=1
2023-01-09T04:50:43.087173244Z I0109 04:50:43.087116       1 schedule_one.go:266] "Successfully bound pod to node" pod="openshift-apiserver/apiserver-86b6d848c8-9mtm9" node="ip-10-0-199-219.us-east-2.compute.internal" evaluatedNodes=7 feasibleNodes=1
2023-01-09T04:50:48.079969648Z I0109 04:50:48.079927       1 schedule_one.go:826] "Unable to schedule pod; no fit; waiting" pod="openshift-oauth-apiserver/apiserver-545598cc79-ztrmn" err="0/7 nodes are available: 3 node(s) didn't match pod anti-affinity rules, 4 node(s) didn't match Pod's node affinity/selector. preemption: 0/7 nodes are available: 3 node(s) didn't match pod anti-affinity rules, 4 Preemption is not helpful for scheduling."
2023-01-09T04:50:48.786108474Z I0109 04:50:48.786040       1 schedule_one.go:826] "Unable to schedule pod; no fit; waiting" pod="openshift-apiserver/apiserver-86b6d848c8-8ns9s" err="0/7 nodes are available: 3 node(s) didn't match pod anti-affinity rules, 4 node(s) didn't match Pod's node affinity/selector. preemption: 0/7 nodes are available: 3 node(s) didn't match pod anti-affinity rules, 4 Preemption is not helpful for scheduling."
2023-01-09T04:50:56.148447440Z I0109 04:50:56.148404       1 schedule_one.go:826] "Unable to schedule pod; no fit; waiting" pod="openshift-apiserver/apiserver-86b6d848c8-8ns9s" err="0/7 nodes are available: 3 node(s) didn't match pod anti-affinity rules, 4 node(s) didn't match Pod's node affinity/selector. preemption: 0/7 nodes are available: 3 node(s) didn't match pod anti-affinity rules, 4 Preemption is not helpful for scheduling."
2023-01-09T04:50:58.087215038Z I0109 04:50:58.087173       1 schedule_one.go:826] "Unable to schedule pod; no fit; waiting" pod="openshift-oauth-apiserver/apiserver-545598cc79-ztrmn" err="0/7 nodes are available: 3 node(s) didn't match pod anti-affinity rules, 4 node(s) didn't match Pod's node affinity/selector. preemption: 0/7 nodes are available: 3 node(s) didn't match pod anti-affinity rules, 4 Preemption is not helpful for scheduling."
2023-01-09T04:51:00.136653178Z I0109 04:51:00.136611       1 schedule_one.go:826] "Unable to schedule pod; no fit; waiting" pod="openshift-apiserver/apiserver-86b6d848c8-8ns9s" err="0/7 nodes are available: 3 node(s) didn't match pod anti-affinity rules, 4 node(s) didn't match Pod's node affinity/selector. preemption: 0/7 nodes are available: 3 node(s) didn't match pod anti-affinity rules, 4 Preemption is not helpful for scheduling."
2023-01-09T04:51:00.141839814Z E0109 04:51:00.141743       1 event_broadcaster.go:253] Server rejected event '&v1.Event{TypeMeta:v1.TypeMeta{Kind:"", APIVersion:""}, ObjectMeta:v1.ObjectMeta{Name:"apiserver-86b6d848c8-8ns9s.17388ac8b1c23965", GenerateName:"", Namespace:"openshift-apiserver", SelfLink:"", UID:"05816c09-73a4-4ce8-bd52-e14e6d2318d3", ResourceVersion:"25840", Generation:0, CreationTimestamp:time.Date(2023, time.January, 9, 4, 50, 56, 0, time.Local), DeletionTimestamp:<nil>, DeletionGracePeriodSeconds:(*int64)(nil), Labels:map[string]string(nil), Annotations:map[string]string(nil), OwnerReferences:[]v1.OwnerReference(nil), Finalizers:[]string(nil), ManagedFields:[]v1.ManagedFieldsEntry{v1.ManagedFieldsEntry{Manager:"kube-scheduler", Operation:"Update", APIVersion:"events.k8s.io/v1", Time:time.Date(2023, time.January, 9, 4, 50, 56, 0, time.Local), FieldsType:"FieldsV1", FieldsV1:(*v1.FieldsV1)(0xc00227bbd8), Subresource:""}}}, EventTime:time.Date(2023, time.January, 9, 4, 50, 56, 148524000, time.Local), Series:(*v1.EventSeries)(0xc001e71740), ReportingController:"default-scheduler", ReportingInstance:"default-scheduler-ip-10-0-199-219", Action:"Scheduling", Reason:"FailedScheduling", Regarding:v1.ObjectReference{Kind:"Pod", Namespace:"openshift-apiserver", Name:"apiserver-86b6d848c8-8ns9s", UID:"08b7cba0-9ee3-4805-96f7-0aeec3cf57bf", APIVersion:"v1", ResourceVersion:"25762", FieldPath:""}, Related:(*v1.ObjectReference)(nil), Note:"0/7 nodes are available: 3 node(s) didn't match pod anti-affinity rules, 4 node(s) didn't match Pod's node affinity/selector. preemption: 0/7 nodes are available: 3 node(s) didn't match pod anti-affinity rules, 4 Preemption is not helpful for scheduling.", Type:"Warning", DeprecatedSource:v1.EventSource{Component:"", Host:""}, DeprecatedFirstTimestamp:time.Date(1, time.January, 1, 0, 0, 0, 0, time.UTC), DeprecatedLastTimestamp:time.Date(1, time.January, 1, 0, 0, 0, 0, time.UTC), DeprecatedCount:0}': 'Event "apiserver-86b6d848c8-8ns9s.17388ac8b1c23965" is invalid: series.count: Invalid value: "": should be at least 2' (will not retry!)
2023-01-09T04:51:05.091839151Z I0109 04:51:05.091792       1 schedule_one.go:826] "Unable to schedule pod; no fit; waiting" pod="openshift-apiserver/apiserver-86b6d848c8-8ns9s" err="0/7 nodes are available: 3 node(s) didn't match pod anti-affinity rules, 4 node(s) didn't match Pod's node affinity/selector. preemption: 0/7 nodes are available: 3 node(s) didn't match pod anti-affinity rules, 4 Preemption is not helpful for scheduling."
2023-01-09T04:51:08.093134806Z I0109 04:51:08.093087       1 schedule_one.go:826] "Unable to schedule pod; no fit; waiting" pod="openshift-oauth-apiserver/apiserver-545598cc79-ztrmn" err="0/7 nodes are available: 3 node(s) didn't match pod anti-affinity rules, 4 node(s) didn't match Pod's node affinity/selector. preemption: 0/7 nodes are available: 3 node(s) didn't match pod anti-affinity rules, 4 Preemption is not helpful for scheduling."
2023-01-09T04:51:13.096733945Z I0109 04:51:13.096692       1 schedule_one.go:826] "Unable to schedule pod; no fit; waiting" pod="openshift-apiserver/apiserver-86b6d848c8-8ns9s" err="0/7 nodes are available: 3 node(s) didn't match pod anti-affinity rules, 4 node(s) didn't match Pod's node affinity/selector. preemption: 0/7 nodes are available: 3 node(s) didn't match pod anti-affinity rules, 4 Preemption is not helpful for scheduling."
2023-01-09T04:51:18.100942758Z I0109 04:51:18.100894       1 schedule_one.go:826] "Unable to schedule pod; no fit; waiting" pod="openshift-oauth-apiserver/apiserver-545598cc79-ztrmn" err="0/7 nodes are available: 3 node(s) didn't match pod anti-affinity rules, 4 node(s) didn't match Pod's node affinity/selector. preemption: 0/7 nodes are available: 3 node(s) didn't match pod anti-affinity rules, 4 Preemption is not helpful for scheduling."
2023-01-09T04:51:23.104382937Z I0109 04:51:23.104322       1 schedule_one.go:826] "Unable to schedule pod; no fit; waiting" pod="openshift-apiserver/apiserver-86b6d848c8-8ns9s" err="0/7 nodes are available: 3 node(s) didn't match pod anti-affinity rules, 4 node(s) didn't match Pod's node affinity/selector. preemption: 0/7 nodes are available: 3 node(s) didn't match pod anti-affinity rules, 4 Preemption is not helpful for scheduling."
2023-01-09T04:51:28.106781294Z I0109 04:51:28.106737       1 schedule_one.go:826] "Unable to schedule pod; no fit; waiting" pod="openshift-oauth-apiserver/apiserver-545598cc79-ztrmn" err="0/7 nodes are available: 3 node(s) didn't match pod anti-affinity rules, 4 node(s) didn't match Pod's node affinity/selector. preemption: 0/7 nodes are available: 3 node(s) didn't match pod anti-affinity rules, 4 Preemption is not helpful for scheduling."
2023-01-09T04:51:33.110762378Z I0109 04:51:33.110709       1 schedule_one.go:826] "Unable to schedule pod; no fit; waiting" pod="openshift-apiserver/apiserver-86b6d848c8-8ns9s" err="0/7 nodes are available: 3 node(s) didn't match pod anti-affinity rules, 4 node(s) didn't match Pod's node affinity/selector. preemption: 0/7 nodes are available: 3 node(s) didn't match pod anti-affinity rules, 4 Preemption is not helpful for scheduling."
2023-01-09T04:51:38.120645195Z I0109 04:51:38.120599       1 schedule_one.go:266] "Successfully bound pod to node" pod="openshift-oauth-apiserver/apiserver-545598cc79-ztrmn" node="ip-10-0-160-211.us-east-2.compute.internal" evaluatedNodes=7 feasibleNodes=1
2023-01-09T04:51:43.117702933Z I0109 04:51:43.117655       1 schedule_one.go:826] "Unable to schedule pod; no fit; waiting" pod="openshift-apiserver/apiserver-86b6d848c8-8ns9s" err="0/7 nodes are available: 3 node(s) didn't match pod anti-affinity rules, 4 node(s) didn't match Pod's node affinity/selector. preemption: 0/7 nodes are available: 3 node(s) didn't match pod anti-affinity rules, 4 Preemption is not helpful for scheduling."
2023-01-09T04:51:44.403463810Z I0109 04:51:44.403372       1 schedule_one.go:826] "Unable to schedule pod; no fit; waiting" pod="openshift-oauth-apiserver/apiserver-545598cc79-zjm2r" err="0/7 nodes are available: 3 node(s) didn't match pod anti-affinity rules, 4 node(s) didn't match Pod's node affinity/selector. preemption: 0/7 nodes are available: 3 node(s) didn't match pod anti-affinity rules, 4 Preemption is not helpful for scheduling."
2023-01-09T04:52:04.398547649Z I0109 04:52:04.398497       1 schedule_one.go:826] "Unable to schedule pod; no fit; waiting" pod="openshift-apiserver/apiserver-86b6d848c8-8ns9s" err="0/7 nodes are available: 3 node(s) didn't match pod anti-affinity rules, 4 node(s) didn't match Pod's node affinity/selector. preemption: 0/7 nodes are available: 3 node(s) didn't match pod anti-affinity rules, 4 Preemption is not helpful for scheduling."
2023-01-09T04:52:04.399258729Z I0109 04:52:04.399229       1 schedule_one.go:826] "Unable to schedule pod; no fit; waiting" pod="openshift-oauth-apiserver/apiserver-545598cc79-zjm2r" err="0/7 nodes are available: 3 node(s) didn't match pod anti-affinity rules, 4 node(s) didn't match Pod's node affinity/selector. preemption: 0/7 nodes are available: 3 node(s) didn't match pod anti-affinity rules, 4 Preemption is not helpful for scheduling."
2023-01-09T04:52:06.146329225Z I0109 04:52:06.146286       1 schedule_one.go:266] "Successfully bound pod to node" pod="openshift-marketplace/certified-operators-mt996" node="ip-10-0-199-219.us-east-2.compute.internal" evaluatedNodes=7 feasibleNodes=3
2023-01-09T04:52:07.134517994Z I0109 04:52:07.134451       1 schedule_one.go:826] "Unable to schedule pod; no fit; waiting" pod="openshift-oauth-apiserver/apiserver-545598cc79-zjm2r" err="0/7 nodes are available: 3 node(s) didn't match pod anti-affinity rules, 4 node(s) didn't match Pod's node affinity/selector. preemption: 0/7 nodes are available: 3 node(s) didn't match pod anti-affinity rules, 4 Preemption is not helpful for scheduling."
2023-01-09T04:52:07.181097667Z E0109 04:52:07.180966       1 event_broadcaster.go:253] Server rejected event '&v1.Event{TypeMeta:v1.TypeMeta{Kind:"", APIVersion:""}, ObjectMeta:v1.ObjectMeta{Name:"apiserver-545598cc79-zjm2r.17388ad895d27eb1", GenerateName:"", Namespace:"openshift-oauth-apiserver", SelfLink:"", UID:"1f477002-1a46-4478-a1eb-ff1c4d15be1a", ResourceVersion:"26518", Generation:0, CreationTimestamp:time.Date(2023, time.January, 9, 4, 52, 4, 0, time.Local), DeletionTimestamp:<nil>, DeletionGracePeriodSeconds:(*int64)(nil), Labels:map[string]string(nil), Annotations:map[string]string(nil), OwnerReferences:[]v1.OwnerReference(nil), Finalizers:[]string(nil), ManagedFields:[]v1.ManagedFieldsEntry{v1.ManagedFieldsEntry{Manager:"kube-scheduler", Operation:"Update", APIVersion:"events.k8s.io/v1", Time:time.Date(2023, time.January, 9, 4, 52, 4, 0, time.Local), FieldsType:"FieldsV1", FieldsV1:(*v1.FieldsV1)(0xc00290bc08), Subresource:""}}}, EventTime:time.Date(2023, time.January, 9, 4, 52, 4, 399305000, time.Local), Series:(*v1.EventSeries)(0xc001e70020), ReportingController:"default-scheduler", ReportingInstance:"default-scheduler-ip-10-0-199-219", Action:"Scheduling", Reason:"FailedScheduling", Regarding:v1.ObjectReference{Kind:"Pod", Namespace:"openshift-oauth-apiserver", Name:"apiserver-545598cc79-zjm2r", UID:"d195666d-8b18-4ceb-87d2-d857b3f46b00", APIVersion:"v1", ResourceVersion:"26384", FieldPath:""}, Related:(*v1.ObjectReference)(nil), Note:"0/7 nodes are available: 3 node(s) didn't match pod anti-affinity rules, 4 node(s) didn't match Pod's node affinity/selector. preemption: 0/7 nodes are available: 3 node(s) didn't match pod anti-affinity rules, 4 Preemption is not helpful for scheduling.", Type:"Warning", DeprecatedSource:v1.EventSource{Component:"", Host:""}, DeprecatedFirstTimestamp:time.Date(1, time.January, 1, 0, 0, 0, 0, time.UTC), DeprecatedLastTimestamp:time.Date(1, time.January, 1, 0, 0, 0, 0, time.UTC), DeprecatedCount:0}': 'Event "apiserver-545598cc79-zjm2r.17388ad895d27eb1" is invalid: series.count: Invalid value: "": should be at least 2' (will not retry!)
2023-01-09T04:52:11.135622321Z I0109 04:52:11.135579       1 schedule_one.go:826] "Unable to schedule pod; no fit; waiting" pod="openshift-oauth-apiserver/apiserver-545598cc79-zjm2r" err="0/7 nodes are available: 3 node(s) didn't match pod anti-affinity rules, 4 node(s) didn't match Pod's node affinity/selector. preemption: 0/7 nodes are available: 3 node(s) didn't match pod anti-affinity rules, 4 Preemption is not helpful for scheduling."
2023-01-09T04:52:15.146970921Z I0109 04:52:15.146933       1 schedule_one.go:266] "Successfully bound pod to node" pod="openshift-apiserver/apiserver-86b6d848c8-8ns9s" node="ip-10-0-160-211.us-east-2.compute.internal" evaluatedNodes=7 feasibleNodes=1
2023-01-09T04:52:19.141160567Z I0109 04:52:19.141124       1 schedule_one.go:826] "Unable to schedule pod; no fit; waiting" pod="openshift-oauth-apiserver/apiserver-545598cc79-zjm2r" err="0/7 nodes are available: 3 node(s) didn't match pod anti-affinity rules, 4 node(s) didn't match Pod's node affinity/selector. preemption: 0/7 nodes are available: 3 node(s) didn't match pod anti-affinity rules, 4 Preemption is not helpful for scheduling."
2023-01-09T04:52:29.146734211Z I0109 04:52:29.146690       1 schedule_one.go:826] "Unable to schedule pod; no fit; waiting" pod="openshift-oauth-apiserver/apiserver-545598cc79-zjm2r" err="0/7 nodes are available: 3 node(s) didn't match pod anti-affinity rules, 4 node(s) didn't match Pod's node affinity/selector. preemption: 0/7 nodes are available: 3 node(s) didn't match pod anti-affinity rules, 4 Preemption is not helpful for scheduling."
2023-01-09T04:52:43.366412088Z I0109 04:52:43.366373       1 schedule_one.go:826] "Unable to schedule pod; no fit; waiting" pod="openshift-oauth-apiserver/apiserver-545598cc79-zjm2r" err="0/7 nodes are available: 3 node(s) didn't match pod anti-affinity rules, 4 node(s) didn't match Pod's node affinity/selector. preemption: 0/7 nodes are available: 3 node(s) didn't match pod anti-affinity rules, 4 Preemption is not helpful for scheduling."
2023-01-09T04:52:53.934534036Z E0109 04:52:53.934477       1 webhook.go:154] Failed to make webhook authenticator request: Post "https://api-int.sn-loggvls-jsm.qe.devcluster.openshift.com:6443/apis/authentication.k8s.io/v1/tokenreviews": dial tcp 10.0.196.87:6443: connect: connection refused
2023-01-09T04:52:53.934588217Z E0109 04:52:53.934573       1 authentication.go:63] "Unable to authenticate the request" err="[invalid bearer token, Post \"https://api-int.sn-loggvls-jsm.qe.devcluster.openshift.com:6443/apis/authentication.k8s.io/v1/tokenreviews\": dial tcp 10.0.196.87:6443: connect: connection refused]"
2023-01-09T04:52:55.127016451Z E0109 04:52:55.126828       1 reflector.go:140] vendor/k8s.io/client-go/informers/factory.go:134: Failed to watch *v1.PersistentVolume: unknown (get persistentvolumes)
2023-01-09T04:52:55.127016451Z E0109 04:52:55.126949       1 framework.go:1039] "Failed running Bind plugin" err="pods \"apiserver-545598cc79-zjm2r\" is forbidden: User \"system:kube-scheduler\" cannot create resource \"pods/binding\" in API group \"\" in the namespace \"openshift-oauth-apiserver\"" plugin="DefaultBinder" pod="openshift-oauth-apiserver/apiserver-545598cc79-zjm2r"
2023-01-09T04:52:55.127016451Z I0109 04:52:55.126984       1 schedule_one.go:797] "Failed to bind pod" pod="openshift-oauth-apiserver/apiserver-545598cc79-zjm2r"
2023-01-09T04:52:55.127075792Z E0109 04:52:55.127055       1 schedule_one.go:842] "Error scheduling pod; retrying" err="binding rejected: running Bind plugin \"DefaultBinder\": pods \"apiserver-545598cc79-zjm2r\" is forbidden: User \"system:kube-scheduler\" cannot create resource \"pods/binding\" in API group \"\" in the namespace \"openshift-oauth-apiserver\"" pod="openshift-oauth-apiserver/apiserver-545598cc79-zjm2r"
2023-01-09T04:52:55.127465482Z E0109 04:52:55.127432       1 reflector.go:140] vendor/k8s.io/client-go/informers/factory.go:134: Failed to watch *v1.ReplicaSet: unknown (get replicasets.apps)
2023-01-09T04:53:03.385951234Z I0109 04:53:03.382460       1 schedule_one.go:266] "Successfully bound pod to node" pod="openshift-marketplace/community-operators-9c2tv" node="ip-10-0-145-4.us-east-2.compute.internal" evaluatedNodes=7 feasibleNodes=3
2023-01-09T04:53:03.407220555Z I0109 04:53:03.407171       1 schedule_one.go:266] "Successfully bound pod to node" pod="openshift-marketplace/redhat-operators-9ndg6" node="ip-10-0-145-4.us-east-2.compute.internal" evaluatedNodes=7 feasibleNodes=3
2023-01-09T04:53:03.849506304Z I0109 04:53:03.849457       1 schedule_one.go:266] "Successfully bound pod to node" pod="openshift-marketplace/redhat-marketplace-w5vj9" node="ip-10-0-199-219.us-east-2.compute.internal" evaluatedNodes=7 feasibleNodes=3
2023-01-09T04:53:05.192873011Z I0109 04:53:05.190969       1 schedule_one.go:266] "Successfully bound pod to node" pod="openshift-oauth-apiserver/apiserver-545598cc79-zjm2r" node="ip-10-0-145-4.us-east-2.compute.internal" evaluatedNodes=7 feasibleNodes=1
2023-01-09T04:54:14.113600241Z I0109 04:54:14.113558       1 schedule_one.go:266] "Successfully bound pod to node" pod="openshift-multus/cni-sysctl-allowlist-ds-qptrc" node="ip-10-0-144-137.us-east-2.compute.internal" evaluatedNodes=1 feasibleNodes=1
2023-01-09T04:54:14.119780086Z I0109 04:54:14.119742       1 schedule_one.go:266] "Successfully bound pod to node" pod="openshift-multus/cni-sysctl-allowlist-ds-8bvl5" node="ip-10-0-162-201.us-east-2.compute.internal" evaluatedNodes=1 feasibleNodes=1
2023-01-09T04:54:14.123794381Z I0109 04:54:14.123750       1 schedule_one.go:266] "Successfully bound pod to node" pod="openshift-multus/cni-sysctl-allowlist-ds-wf7k9" node="ip-10-0-200-52.us-east-2.compute.internal" evaluatedNodes=1 feasibleNodes=1
2023-01-09T04:54:14.130033010Z I0109 04:54:14.129989       1 schedule_one.go:266] "Successfully bound pod to node" pod="openshift-multus/cni-sysctl-allowlist-ds-ghl8d" node="ip-10-0-130-201.us-east-2.compute.internal" evaluatedNodes=1 feasibleNodes=1
2023-01-09T04:59:48.951593189Z I0109 04:59:48.951534       1 schedule_one.go:826] "Unable to schedule pod; no fit; waiting" pod="openshift-authentication/oauth-openshift-7db4769fc7-2f2q7" err="0/7 nodes are available: 3 node(s) didn't match pod anti-affinity rules, 4 node(s) didn't match Pod's node affinity/selector. preemption: 0/7 nodes are available: 3 node(s) didn't match pod anti-affinity rules, 4 Preemption is not helpful for scheduling."
2023-01-09T05:00:00.198654034Z I0109 05:00:00.198574       1 schedule_one.go:266] "Successfully bound pod to node" pod="openshift-operator-lifecycle-manager/collect-profiles-27887340-jqx2b" node="ip-10-0-144-137.us-east-2.compute.internal" evaluatedNodes=7 feasibleNodes=4
2023-01-09T05:00:04.630704606Z I0109 05:00:04.630665       1 schedule_one.go:826] "Unable to schedule pod; no fit; waiting" pod="openshift-authentication/oauth-openshift-7db4769fc7-2f2q7" err="0/7 nodes are available: 3 node(s) didn't match pod anti-affinity rules, 4 node(s) didn't match Pod's node affinity/selector. preemption: 0/7 nodes are available: 3 node(s) didn't match pod anti-affinity rules, 4 Preemption is not helpful for scheduling."
2023-01-09T05:00:07.441002053Z I0109 05:00:07.440962       1 schedule_one.go:826] "Unable to schedule pod; no fit; waiting" pod="openshift-authentication/oauth-openshift-7db4769fc7-2f2q7" err="0/7 nodes are available: 3 node(s) didn't match pod anti-affinity rules, 4 node(s) didn't match Pod's node affinity/selector. preemption: 0/7 nodes are available: 3 node(s) didn't match pod anti-affinity rules, 4 Preemption is not helpful for scheduling."
2023-01-09T05:00:07.448904925Z E0109 05:00:07.448808       1 event_broadcaster.go:253] Server rejected event '&v1.Event{TypeMeta:v1.TypeMeta{Kind:"", APIVersion:""}, ObjectMeta:v1.ObjectMeta{Name:"oauth-openshift-7db4769fc7-2f2q7.17388b4865d8e830", GenerateName:"", Namespace:"openshift-authentication", SelfLink:"", UID:"4e47b046-9232-4e87-a882-7d04838e695f", ResourceVersion:"30775", Generation:0, CreationTimestamp:time.Date(2023, time.January, 9, 5, 0, 4, 0, time.Local), DeletionTimestamp:<nil>, DeletionGracePeriodSeconds:(*int64)(nil), Labels:map[string]string(nil), Annotations:map[string]string(nil), OwnerReferences:[]v1.OwnerReference(nil), Finalizers:[]string(nil), ManagedFields:[]v1.ManagedFieldsEntry{v1.ManagedFieldsEntry{Manager:"kube-scheduler", Operation:"Update", APIVersion:"events.k8s.io/v1", Time:time.Date(2023, time.January, 9, 5, 0, 4, 0, time.Local), FieldsType:"FieldsV1", FieldsV1:(*v1.FieldsV1)(0xc000515cc8), Subresource:""}}}, EventTime:time.Date(2023, time.January, 9, 5, 0, 4, 630754000, time.Local), Series:(*v1.EventSeries)(0xc001bcc740), ReportingController:"default-scheduler", ReportingInstance:"default-scheduler-ip-10-0-199-219", Action:"Scheduling", Reason:"FailedScheduling", Regarding:v1.ObjectReference{Kind:"Pod", Namespace:"openshift-authentication", Name:"oauth-openshift-7db4769fc7-2f2q7", UID:"79f26195-985c-40c7-b734-544517c7ee58", APIVersion:"v1", ResourceVersion:"30635", FieldPath:""}, Related:(*v1.ObjectReference)(nil), Note:"0/7 nodes are available: 3 node(s) didn't match pod anti-affinity rules, 4 node(s) didn't match Pod's node affinity/selector. preemption: 0/7 nodes are available: 3 node(s) didn't match pod anti-affinity rules, 4 Preemption is not helpful for scheduling.", Type:"Warning", DeprecatedSource:v1.EventSource{Component:"", Host:""}, DeprecatedFirstTimestamp:time.Date(1, time.January, 1, 0, 0, 0, 0, time.UTC), DeprecatedLastTimestamp:time.Date(1, time.January, 1, 0, 0, 0, 0, time.UTC), DeprecatedCount:0}': 'Event "oauth-openshift-7db4769fc7-2f2q7.17388b4865d8e830" is invalid: series.count: Invalid value: "": should be at least 2' (will not retry!)
2023-01-09T05:00:15.497005757Z I0109 05:00:15.496961       1 schedule_one.go:266] "Successfully bound pod to node" pod="openshift-authentication/oauth-openshift-7db4769fc7-2f2q7" node="ip-10-0-199-219.us-east-2.compute.internal" evaluatedNodes=7 feasibleNodes=1
2023-01-09T05:00:17.559061373Z I0109 05:00:17.559015       1 schedule_one.go:826] "Unable to schedule pod; no fit; waiting" pod="openshift-authentication/oauth-openshift-7db4769fc7-xknq2" err="0/7 nodes are available: 3 node(s) didn't match pod anti-affinity rules, 4 node(s) didn't match Pod's node affinity/selector. preemption: 0/7 nodes are available: 3 node(s) didn't match pod anti-affinity rules, 4 Preemption is not helpful for scheduling."
2023-01-09T05:00:27.875910328Z E0109 05:00:27.875808       1 event_broadcaster.go:253] Server rejected event '&v1.Event{TypeMeta:v1.TypeMeta{Kind:"", APIVersion:""}, ObjectMeta:v1.ObjectMeta{Name:"apiserver-545598cc79-stls7.17388abc90b73009", GenerateName:"", Namespace:"openshift-oauth-apiserver", SelfLink:"", UID:"64208d18-2bf1-4547-8d8e-0eeab41e2ef4", ResourceVersion:"25191", Generation:0, CreationTimestamp:time.Date(2023, time.January, 9, 4, 50, 4, 0, time.Local), DeletionTimestamp:<nil>, DeletionGracePeriodSeconds:(*int64)(nil), Labels:map[string]string(nil), Annotations:map[string]string(nil), OwnerReferences:[]v1.OwnerReference(nil), Finalizers:[]string(nil), ManagedFields:[]v1.ManagedFieldsEntry{v1.ManagedFieldsEntry{Manager:"kube-scheduler", Operation:"Update", APIVersion:"events.k8s.io/v1", Time:time.Date(2023, time.January, 9, 4, 50, 4, 0, time.Local), FieldsType:"FieldsV1", FieldsV1:(*v1.FieldsV1)(0xc00227bd10), Subresource:""}}}, EventTime:time.Date(2023, time.January, 9, 4, 50, 4, 54542000, time.Local), Series:(*v1.EventSeries)(0xc002919ac0), ReportingController:"default-scheduler", ReportingInstance:"default-scheduler-ip-10-0-199-219", Action:"Scheduling", Reason:"FailedScheduling", Regarding:v1.ObjectReference{Kind:"Pod", Namespace:"openshift-oauth-apiserver", Name:"apiserver-545598cc79-stls7", UID:"0afa8bb3-8bee-42c1-a629-bce612df275c", APIVersion:"v1", ResourceVersion:"24284", FieldPath:""}, Related:(*v1.ObjectReference)(nil), Note:"0/7 nodes are available: 3 node(s) didn't match pod anti-affinity rules, 4 node(s) didn't match Pod's node affinity/selector. preemption: 0/7 nodes are available: 3 node(s) didn't match pod anti-affinity rules, 4 Preemption is not helpful for scheduling.", Type:"Warning", DeprecatedSource:v1.EventSource{Component:"", Host:""}, DeprecatedFirstTimestamp:time.Date(1, time.January, 1, 0, 0, 0, 0, time.UTC), DeprecatedLastTimestamp:time.Date(1, time.January, 1, 0, 0, 0, 0, time.UTC), DeprecatedCount:0}': 'Event "apiserver-545598cc79-stls7.17388abc90b73009" is invalid: series.count: Invalid value: "": should be at least 2' (will not retry!)
2023-01-09T05:00:39.198983574Z I0109 05:00:39.198927       1 schedule_one.go:826] "Unable to schedule pod; no fit; waiting" pod="openshift-authentication/oauth-openshift-7db4769fc7-xknq2" err="0/7 nodes are available: 3 node(s) didn't match pod anti-affinity rules, 4 node(s) didn't match Pod's node affinity/selector. preemption: 0/7 nodes are available: 3 node(s) didn't match pod anti-affinity rules, 4 Preemption is not helpful for scheduling."
2023-01-09T05:00:43.609649825Z I0109 05:00:43.609586       1 schedule_one.go:266] "Successfully bound pod to node" pod="openshift-authentication/oauth-openshift-7db4769fc7-xknq2" node="ip-10-0-160-211.us-east-2.compute.internal" evaluatedNodes=7 feasibleNodes=1
2023-01-09T05:00:45.414752642Z I0109 05:00:45.414713       1 schedule_one.go:826] "Unable to schedule pod; no fit; waiting" pod="openshift-authentication/oauth-openshift-7db4769fc7-hgm8d" err="0/7 nodes are available: 3 node(s) didn't match pod anti-affinity rules, 4 node(s) didn't match Pod's node affinity/selector. preemption: 0/7 nodes are available: 3 node(s) didn't match pod anti-affinity rules, 4 Preemption is not helpful for scheduling."
2023-01-09T05:01:11.854295664Z I0109 05:01:11.854251       1 schedule_one.go:266] "Successfully bound pod to node" pod="openshift-authentication/oauth-openshift-7db4769fc7-hgm8d" node="ip-10-0-145-4.us-east-2.compute.internal" evaluatedNodes=7 feasibleNodes=1
2023-01-09T05:02:39.257824847Z I0109 05:02:39.257772       1 schedule_one.go:266] "Successfully bound pod to node" pod="openshift-marketplace/certified-operators-85dkt" node="ip-10-0-199-219.us-east-2.compute.internal" evaluatedNodes=7 feasibleNodes=3
2023-01-09T05:03:22.737258513Z I0109 05:03:22.737078       1 schedule_one.go:266] "Successfully bound pod to node" pod="openshift-marketplace/community-operators-sk6zk" node="ip-10-0-145-4.us-east-2.compute.internal" evaluatedNodes=7 feasibleNodes=3
2023-01-09T05:06:27.926655199Z E0109 05:06:27.926533       1 event_broadcaster.go:253] Server rejected event '&v1.Event{TypeMeta:v1.TypeMeta{Kind:"", APIVersion:""}, ObjectMeta:v1.ObjectMeta{Name:"oauth-openshift-7db4769fc7-2f2q7.17388b4865d8e830", GenerateName:"", Namespace:"openshift-authentication", SelfLink:"", UID:"4e47b046-9232-4e87-a882-7d04838e695f", ResourceVersion:"30775", Generation:0, CreationTimestamp:time.Date(2023, time.January, 9, 5, 0, 4, 0, time.Local), DeletionTimestamp:<nil>, DeletionGracePeriodSeconds:(*int64)(nil), Labels:map[string]string(nil), Annotations:map[string]string(nil), OwnerReferences:[]v1.OwnerReference(nil), Finalizers:[]string(nil), ManagedFields:[]v1.ManagedFieldsEntry{v1.ManagedFieldsEntry{Manager:"kube-scheduler", Operation:"Update", APIVersion:"events.k8s.io/v1", Time:time.Date(2023, time.January, 9, 5, 0, 4, 0, time.Local), FieldsType:"FieldsV1", FieldsV1:(*v1.FieldsV1)(0xc000515cc8), Subresource:""}}}, EventTime:time.Date(2023, time.January, 9, 5, 0, 4, 630754000, time.Local), Series:(*v1.EventSeries)(0xc001bcc740), ReportingController:"default-scheduler", ReportingInstance:"default-scheduler-ip-10-0-199-219", Action:"Scheduling", Reason:"FailedScheduling", Regarding:v1.ObjectReference{Kind:"Pod", Namespace:"openshift-authentication", Name:"oauth-openshift-7db4769fc7-2f2q7", UID:"79f26195-985c-40c7-b734-544517c7ee58", APIVersion:"v1", ResourceVersion:"30635", FieldPath:""}, Related:(*v1.ObjectReference)(nil), Note:"0/7 nodes are available: 3 node(s) didn't match pod anti-affinity rules, 4 node(s) didn't match Pod's node affinity/selector. preemption: 0/7 nodes are available: 3 node(s) didn't match pod anti-affinity rules, 4 Preemption is not helpful for scheduling.", Type:"Warning", DeprecatedSource:v1.EventSource{Component:"", Host:""}, DeprecatedFirstTimestamp:time.Date(1, time.January, 1, 0, 0, 0, 0, time.UTC), DeprecatedLastTimestamp:time.Date(1, time.January, 1, 0, 0, 0, 0, time.UTC), DeprecatedCount:0}': 'Event "oauth-openshift-7db4769fc7-2f2q7.17388b4865d8e830" is invalid: series.count: Invalid value: "": should be at least 2' (will not retry!)
2023-01-09T05:07:35.826745209Z I0109 05:07:35.826687       1 schedule_one.go:266] "Successfully bound pod to node" pod="openshift-marketplace/redhat-marketplace-w2fqt" node="ip-10-0-199-219.us-east-2.compute.internal" evaluatedNodes=7 feasibleNodes=3
2023-01-09T05:07:35.827093733Z I0109 05:07:35.827068       1 schedule_one.go:266] "Successfully bound pod to node" pod="openshift-marketplace/redhat-operators-skvmx" node="ip-10-0-145-4.us-east-2.compute.internal" evaluatedNodes=7 feasibleNodes=3
2023-01-09T05:14:25.239173035Z I0109 05:14:25.239125       1 schedule_one.go:266] "Successfully bound pod to node" pod="openshift-marketplace/community-operators-xcc9v" node="ip-10-0-145-4.us-east-2.compute.internal" evaluatedNodes=7 feasibleNodes=3
2023-01-09T05:15:00.148326427Z I0109 05:15:00.148291       1 schedule_one.go:266] "Successfully bound pod to node" pod="openshift-operator-lifecycle-manager/collect-profiles-27887355-7mkjf" node="ip-10-0-144-137.us-east-2.compute.internal" evaluatedNodes=7 feasibleNodes=4
2023-01-09T05:18:02.199552117Z I0109 05:18:02.199509       1 schedule_one.go:266] "Successfully bound pod to node" pod="openshift-marketplace/redhat-operators-thm94" node="ip-10-0-145-4.us-east-2.compute.internal" evaluatedNodes=7 feasibleNodes=3
2023-01-09T05:18:14.794153674Z I0109 05:18:14.794106       1 schedule_one.go:266] "Successfully bound pod to node" pod="openshift-marketplace/redhat-marketplace-kztgd" node="ip-10-0-199-219.us-east-2.compute.internal" evaluatedNodes=7 feasibleNodes=3
2023-01-09T05:21:34.839513943Z I0109 05:21:34.839456       1 schedule_one.go:266] "Successfully bound pod to node" pod="openshift-marketplace/certified-operators-5h5fg" node="ip-10-0-199-219.us-east-2.compute.internal" evaluatedNodes=7 feasibleNodes=3
2023-01-09T05:24:55.475849541Z I0109 05:24:55.475798       1 schedule_one.go:266] "Successfully bound pod to node" pod="openshift-marketplace/community-operators-glgkn" node="ip-10-0-145-4.us-east-2.compute.internal" evaluatedNodes=7 feasibleNodes=3
2023-01-09T05:28:32.088013315Z I0109 05:28:32.087966       1 schedule_one.go:266] "Successfully bound pod to node" pod="openshift-marketplace/redhat-operators-2qt9z" node="ip-10-0-145-4.us-east-2.compute.internal" evaluatedNodes=7 feasibleNodes=3
2023-01-09T05:29:36.606384154Z I0109 05:29:36.605717       1 schedule_one.go:266] "Successfully bound pod to node" pod="openshift-marketplace/redhat-marketplace-xdj2x" node="ip-10-0-199-219.us-east-2.compute.internal" evaluatedNodes=7 feasibleNodes=3
2023-01-09T05:30:00.158714142Z I0109 05:30:00.158666       1 schedule_one.go:266] "Successfully bound pod to node" pod="openshift-operator-lifecycle-manager/collect-profiles-27887370-smwf8" node="ip-10-0-144-137.us-east-2.compute.internal" evaluatedNodes=7 feasibleNodes=3
2023-01-09T05:30:00.243094267Z I0109 05:30:00.243039       1 schedule_one.go:266] "Successfully bound pod to node" pod="openshift-monitoring/prometheus-adapter-b766b5595-j8bqb" node="ip-10-0-200-52.us-east-2.compute.internal" evaluatedNodes=7 feasibleNodes=2
2023-01-09T05:30:32.637583597Z I0109 05:30:32.637537       1 schedule_one.go:266] "Successfully bound pod to node" pod="openshift-console/downloads-8d695cd69-l7j6r" node="ip-10-0-199-219.us-east-2.compute.internal" evaluatedNodes=7 feasibleNodes=4
2023-01-09T05:30:32.645164475Z I0109 05:30:32.645121       1 schedule_one.go:266] "Successfully bound pod to node" pod="openshift-monitoring/prometheus-adapter-b766b5595-wd67t" node="ip-10-0-130-201.us-east-2.compute.internal" evaluatedNodes=7 feasibleNodes=1
2023-01-09T05:30:32.645573182Z I0109 05:30:32.645537       1 schedule_one.go:266] "Successfully bound pod to node" pod="openshift-monitoring/prometheus-operator-admission-webhook-7d4759d465-x6gk6" node="ip-10-0-144-137.us-east-2.compute.internal" evaluatedNodes=7 feasibleNodes=1
2023-01-09T05:30:32.657069871Z I0109 05:30:32.657030       1 schedule_one.go:266] "Successfully bound pod to node" pod="openshift-monitoring/thanos-querier-58b8748b48-hr8tn" node="ip-10-0-130-201.us-east-2.compute.internal" evaluatedNodes=7 feasibleNodes=1
2023-01-09T05:30:32.677733669Z I0109 05:30:32.677687       1 schedule_one.go:266] "Successfully bound pod to node" pod="openshift-network-diagnostics/network-check-source-746dd6c885-2b6km" node="ip-10-0-144-137.us-east-2.compute.internal" evaluatedNodes=7 feasibleNodes=2
2023-01-09T05:30:32.750397616Z I0109 05:30:32.748892       1 schedule_one.go:826] "Unable to schedule pod; no fit; waiting" pod="openshift-image-registry/image-registry-599d8489d7-97shl" err="0/7 nodes are available: 2 node(s) didn't match pod anti-affinity rules, 2 node(s) didn't match pod topology spread constraints, 2 node(s) had untolerated taint {node.kubernetes.io/unschedulable: }, 2 node(s) were unschedulable, 3 node(s) didn't match pod topology spread constraints (missing required label), 3 node(s) had untolerated taint {node-role.kubernetes.io/master: }. preemption: 0/7 nodes are available: 1 node(s) didn't match pod anti-affinity rules, 2 node(s) didn't match pod topology spread constraints, 5 Preemption is not helpful for scheduling."
2023-01-09T05:30:32.765826405Z I0109 05:30:32.765770       1 schedule_one.go:266] "Successfully bound pod to node" pod="openshift-ingress/router-default-595647774c-ppccq" node="ip-10-0-130-201.us-east-2.compute.internal" evaluatedNodes=7 feasibleNodes=1
2023-01-09T05:30:33.739391360Z I0109 05:30:33.739306       1 schedule_one.go:266] "Successfully bound pod to node" pod="openshift-marketplace/qe-app-registry-qzbbk" node="ip-10-0-144-137.us-east-2.compute.internal" evaluatedNodes=7 feasibleNodes=2
2023-01-09T05:30:34.151046536Z I0109 05:30:34.151003       1 schedule_one.go:826] "Unable to schedule pod; no fit; waiting" pod="openshift-image-registry/image-registry-599d8489d7-97shl" err="0/7 nodes are available: 2 node(s) didn't match pod anti-affinity rules, 2 node(s) didn't match pod topology spread constraints, 2 node(s) had untolerated taint {node.kubernetes.io/unschedulable: }, 2 node(s) were unschedulable, 3 node(s) didn't match pod topology spread constraints (missing required label), 3 node(s) had untolerated taint {node-role.kubernetes.io/master: }. preemption: 0/7 nodes are available: 1 node(s) didn't match pod anti-affinity rules, 2 node(s) didn't match pod topology spread constraints, 5 Preemption is not helpful for scheduling."
2023-01-09T05:30:35.304052774Z I0109 05:30:35.304001       1 schedule_one.go:266] "Successfully bound pod to node" pod="openshift-monitoring/prometheus-k8s-1" node="ip-10-0-144-137.us-east-2.compute.internal" evaluatedNodes=7 feasibleNodes=1
2023-01-09T05:30:35.362273543Z I0109 05:30:35.360968       1 schedule_one.go:266] "Successfully bound pod to node" pod="openshift-monitoring/alertmanager-main-1" node="ip-10-0-130-201.us-east-2.compute.internal" evaluatedNodes=7 feasibleNodes=1
2023-01-09T05:30:36.582558850Z I0109 05:30:36.582511       1 schedule_one.go:826] "Unable to schedule pod; no fit; waiting" pod="openshift-image-registry/image-registry-599d8489d7-97shl" err="0/7 nodes are available: 2 node(s) didn't match pod anti-affinity rules, 2 node(s) didn't match pod topology spread constraints, 2 node(s) had untolerated taint {node.kubernetes.io/unschedulable: }, 2 node(s) were unschedulable, 3 node(s) didn't match pod topology spread constraints (missing required label), 3 node(s) had untolerated taint {node-role.kubernetes.io/master: }. preemption: 0/7 nodes are available: 1 node(s) didn't match pod anti-affinity rules, 2 node(s) didn't match pod topology spread constraints, 5 Preemption is not helpful for scheduling."
2023-01-09T05:30:36.589216000Z E0109 05:30:36.589104       1 event_broadcaster.go:253] Server rejected event '&v1.Event{TypeMeta:v1.TypeMeta{Kind:"", APIVersion:""}, ObjectMeta:v1.ObjectMeta{Name:"image-registry-599d8489d7-97shl.17388cf25dc36fc1", GenerateName:"", Namespace:"openshift-image-registry", SelfLink:"", UID:"41110881-3a96-4982-a6ba-9b32f8ee7aa0", ResourceVersion:"42199", Generation:0, CreationTimestamp:time.Date(2023, time.January, 9, 5, 30, 34, 0, time.Local), DeletionTimestamp:<nil>, DeletionGracePeriodSeconds:(*int64)(nil), Labels:map[string]string(nil), Annotations:map[string]string(nil), OwnerReferences:[]v1.OwnerReference(nil), Finalizers:[]string(nil), ManagedFields:[]v1.ManagedFieldsEntry{v1.ManagedFieldsEntry{Manager:"kube-scheduler", Operation:"Update", APIVersion:"events.k8s.io/v1", Time:time.Date(2023, time.January, 9, 5, 30, 34, 0, time.Local), FieldsType:"FieldsV1", FieldsV1:(*v1.FieldsV1)(0xc000fb11e8), Subresource:""}}}, EventTime:time.Date(2023, time.January, 9, 5, 30, 34, 151198000, time.Local), Series:(*v1.EventSeries)(0xc0014e8d80), ReportingController:"default-scheduler", ReportingInstance:"default-scheduler-ip-10-0-199-219", Action:"Scheduling", Reason:"FailedScheduling", Regarding:v1.ObjectReference{Kind:"Pod", Namespace:"openshift-image-registry", Name:"image-registry-599d8489d7-97shl", UID:"fb236025-11c6-4cc0-a6c7-653f58091eaf", APIVersion:"v1", ResourceVersion:"42110", FieldPath:""}, Related:(*v1.ObjectReference)(nil), Note:"0/7 nodes are available: 2 node(s) didn't match pod anti-affinity rules, 2 node(s) didn't match pod topology spread constraints, 2 node(s) had untolerated taint {node.kubernetes.io/unschedulable: }, 2 node(s) were unschedulable, 3 node(s) didn't match pod topology spread constraints (missing required label), 3 node(s) had untolerated taint {node-role.kubernetes.io/master: }. preemption: 0/7 nodes are available: 1 node(s) didn't match pod anti-affinity rules, 2 node(s) didn't match pod topology spread constraints, 5 Preemption is not helpful for scheduling.", Type:"Warning", DeprecatedSource:v1.EventSource{Component:"", Host:""}, DeprecatedFirstTimestamp:time.Date(1, time.January, 1, 0, 0, 0, 0, time.UTC), DeprecatedLastTimestamp:time.Date(1, time.January, 1, 0, 0, 0, 0, time.UTC), DeprecatedCount:0}': 'Event "image-registry-599d8489d7-97shl.17388cf25dc36fc1" is invalid: series.count: Invalid value: "": should be at least 2' (will not retry!)
2023-01-09T05:30:42.432625576Z I0109 05:30:42.432567       1 schedule_one.go:826] "Unable to schedule pod; no fit; waiting" pod="openshift-image-registry/image-registry-599d8489d7-97shl" err="0/7 nodes are available: 2 node(s) didn't match pod anti-affinity rules, 2 node(s) didn't match pod topology spread constraints, 2 node(s) had untolerated taint {node.kubernetes.io/unschedulable: }, 2 node(s) were unschedulable, 3 node(s) didn't match pod topology spread constraints (missing required label), 3 node(s) had untolerated taint {node-role.kubernetes.io/master: }. preemption: 0/7 nodes are available: 1 node(s) didn't match pod anti-affinity rules, 2 node(s) didn't match pod topology spread constraints, 5 Preemption is not helpful for scheduling."
2023-01-09T05:30:50.595193641Z I0109 05:30:50.595113       1 schedule_one.go:826] "Unable to schedule pod; no fit; waiting" pod="openshift-image-registry/image-registry-599d8489d7-97shl" err="0/7 nodes are available: 2 node(s) didn't match pod anti-affinity rules, 2 node(s) didn't match pod topology spread constraints, 2 node(s) had untolerated taint {node.kubernetes.io/unschedulable: }, 2 node(s) were unschedulable, 3 node(s) didn't match pod topology spread constraints (missing required label), 3 node(s) had untolerated taint {node-role.kubernetes.io/master: }. preemption: 0/7 nodes are available: 1 node(s) didn't match pod anti-affinity rules, 2 node(s) didn't match pod topology spread constraints, 5 Preemption is not helpful for scheduling."
2023-01-09T05:30:59.594473851Z I0109 05:30:59.594429       1 schedule_one.go:266] "Successfully bound pod to node" pod="openshift-marketplace/ec1732e48b48e3715676decd393213ccbddebc2deb66b30e8723c3951etf9mn" node="ip-10-0-144-137.us-east-2.compute.internal" evaluatedNodes=7 feasibleNodes=2
2023-01-09T05:31:00.601211899Z I0109 05:31:00.601170       1 schedule_one.go:826] "Unable to schedule pod; no fit; waiting" pod="openshift-image-registry/image-registry-599d8489d7-97shl" err="0/7 nodes are available: 1 node(s) didn't match pod anti-affinity rules, 2 node(s) didn't match pod topology spread constraints, 2 node(s) had untolerated taint {node.kubernetes.io/unschedulable: }, 2 node(s) were unschedulable, 3 node(s) didn't match pod topology spread constraints (missing required label), 3 node(s) had untolerated taint {node-role.kubernetes.io/master: }. preemption: 0/7 nodes are available: 1 node(s) didn't match pod anti-affinity rules, 2 node(s) didn't match pod topology spread constraints, 5 Preemption is not helpful for scheduling."
2023-01-09T05:31:06.978937734Z I0109 05:31:06.978891       1 node_tree.go:79] "Removed node in listed group from NodeTree" node="ip-10-0-162-201.us-east-2.compute.internal" zone="us-east-2:\x00:us-east-2b"
2023-01-09T05:31:12.356869173Z I0109 05:31:12.356821       1 schedule_one.go:826] "Unable to schedule pod; no fit; waiting" pod="openshift-image-registry/image-registry-599d8489d7-97shl" err="0/6 nodes are available: 1 node(s) didn't match pod anti-affinity rules, 1 node(s) had untolerated taint {node.kubernetes.io/unschedulable: }, 1 node(s) were unschedulable, 2 node(s) didn't match pod topology spread constraints, 3 node(s) didn't match pod topology spread constraints (missing required label), 3 node(s) had untolerated taint {node-role.kubernetes.io/master: }. preemption: 0/6 nodes are available: 1 node(s) didn't match pod anti-affinity rules, 2 node(s) didn't match pod topology spread constraints, 4 Preemption is not helpful for scheduling."
2023-01-09T05:31:20.186840952Z I0109 05:31:20.186797       1 schedule_one.go:266] "Successfully bound pod to node" pod="openshift-logging/cluster-logging-operator-8656d566b7-hmvrw" node="ip-10-0-144-137.us-east-2.compute.internal" evaluatedNodes=6 feasibleNodes=2
2023-01-09T05:31:41.561960184Z I0109 05:31:41.561908       1 schedule_one.go:826] "Unable to schedule pod; no fit; waiting" pod="openshift-image-registry/image-registry-599d8489d7-97shl" err="0/6 nodes are available: 1 node(s) didn't match pod anti-affinity rules, 1 node(s) had untolerated taint {node.kubernetes.io/unschedulable: }, 1 node(s) were unschedulable, 2 node(s) didn't match pod topology spread constraints, 3 node(s) didn't match pod topology spread constraints (missing required label), 3 node(s) had untolerated taint {node-role.kubernetes.io/master: }. preemption: 0/6 nodes are available: 1 node(s) didn't match pod anti-affinity rules, 2 node(s) didn't match pod topology spread constraints, 4 Preemption is not helpful for scheduling."
2023-01-09T05:31:48.220714423Z I0109 05:31:48.220664       1 schedule_one.go:266] "Successfully bound pod to node" pod="openshift-marketplace/certified-operators-s6pgb" node="ip-10-0-199-219.us-east-2.compute.internal" evaluatedNodes=6 feasibleNodes=3
2023-01-09T05:32:01.461769962Z I0109 05:32:01.461725       1 schedule_one.go:826] "Unable to schedule pod; no fit; waiting" pod="openshift-image-registry/image-registry-599d8489d7-97shl" err="0/6 nodes are available: 1 node(s) didn't match pod anti-affinity rules, 1 node(s) had untolerated taint {node.kubernetes.io/unschedulable: }, 1 node(s) were unschedulable, 2 node(s) didn't match pod topology spread constraints, 3 node(s) didn't match pod topology spread constraints (missing required label), 3 node(s) had untolerated taint {node-role.kubernetes.io/master: }. preemption: 0/6 nodes are available: 1 node(s) didn't match pod anti-affinity rules, 2 node(s) didn't match pod topology spread constraints, 4 Preemption is not helpful for scheduling."
2023-01-09T05:32:01.467424222Z E0109 05:32:01.467300       1 event_broadcaster.go:253] Server rejected event '&v1.Event{TypeMeta:v1.TypeMeta{Kind:"", APIVersion:""}, ObjectMeta:v1.ObjectMeta{Name:"image-registry-599d8489d7-97shl.17388d020fc2bd6a", GenerateName:"", Namespace:"openshift-image-registry", SelfLink:"", UID:"44240403-5658-404e-85c6-be58bec75cc6", ResourceVersion:"43362", Generation:0, CreationTimestamp:time.Date(2023, time.January, 9, 5, 31, 41, 0, time.Local), DeletionTimestamp:<nil>, DeletionGracePeriodSeconds:(*int64)(nil), Labels:map[string]string(nil), Annotations:map[string]string(nil), OwnerReferences:[]v1.OwnerReference(nil), Finalizers:[]string(nil), ManagedFields:[]v1.ManagedFieldsEntry{v1.ManagedFieldsEntry{Manager:"kube-scheduler", Operation:"Update", APIVersion:"events.k8s.io/v1", Time:time.Date(2023, time.January, 9, 5, 31, 41, 0, time.Local), FieldsType:"FieldsV1", FieldsV1:(*v1.FieldsV1)(0xc00184c240), Subresource:""}}}, EventTime:time.Date(2023, time.January, 9, 5, 31, 41, 562007000, time.Local), Series:(*v1.EventSeries)(0xc00318c360), ReportingController:"default-scheduler", ReportingInstance:"default-scheduler-ip-10-0-199-219", Action:"Scheduling", Reason:"FailedScheduling", Regarding:v1.ObjectReference{Kind:"Pod", Namespace:"openshift-image-registry", Name:"image-registry-599d8489d7-97shl", UID:"fb236025-11c6-4cc0-a6c7-653f58091eaf", APIVersion:"v1", ResourceVersion:"43032", FieldPath:""}, Related:(*v1.ObjectReference)(nil), Note:"0/6 nodes are available: 1 node(s) didn't match pod anti-affinity rules, 1 node(s) had untolerated taint {node.kubernetes.io/unschedulable: }, 1 node(s) were unschedulable, 2 node(s) didn't match pod topology spread constraints, 3 node(s) didn't match pod topology spread constraints (missing required label), 3 node(s) had untolerated taint {node-role.kubernetes.io/master: }. preemption: 0/6 nodes are available: 1 node(s) didn't match pod anti-affinity rules, 2 node(s) didn't match pod topology spread constraints, 4 Preemption is not helpful for scheduling.", Type:"Warning", DeprecatedSource:v1.EventSource{Component:"", Host:""}, DeprecatedFirstTimestamp:time.Date(1, time.January, 1, 0, 0, 0, 0, time.UTC), DeprecatedLastTimestamp:time.Date(1, time.January, 1, 0, 0, 0, 0, time.UTC), DeprecatedCount:0}': 'Event "image-registry-599d8489d7-97shl.17388d020fc2bd6a" is invalid: series.count: Invalid value: "": should be at least 2' (will not retry!)
2023-01-09T05:32:05.838895924Z I0109 05:32:05.838850       1 schedule_one.go:266] "Successfully bound pod to node" pod="openshift-marketplace/524f407c363b467719a8a8960c0382b05288b3719be61d4258a21915e2p79gs" node="ip-10-0-144-137.us-east-2.compute.internal" evaluatedNodes=6 feasibleNodes=2
2023-01-09T05:32:11.647956163Z I0109 05:32:11.647912       1 schedule_one.go:826] "Unable to schedule pod; no fit; waiting" pod="openshift-image-registry/image-registry-599d8489d7-97shl" err="0/6 nodes are available: 1 node(s) didn't match pod anti-affinity rules, 1 node(s) had untolerated taint {node.kubernetes.io/unschedulable: }, 1 node(s) were unschedulable, 2 node(s) didn't match pod topology spread constraints, 3 node(s) didn't match pod topology spread constraints (missing required label), 3 node(s) had untolerated taint {node-role.kubernetes.io/master: }. preemption: 0/6 nodes are available: 1 node(s) didn't match pod anti-affinity rules, 2 node(s) didn't match pod topology spread constraints, 4 Preemption is not helpful for scheduling."
2023-01-09T05:32:20.490095559Z I0109 05:32:20.490033       1 schedule_one.go:266] "Successfully bound pod to node" pod="openshift-operators-redhat/loki-operator-controller-manager-565db69ff8-lkx27" node="ip-10-0-144-137.us-east-2.compute.internal" evaluatedNodes=6 feasibleNodes=2
2023-01-09T05:32:21.656728915Z I0109 05:32:21.656682       1 schedule_one.go:826] "Unable to schedule pod; no fit; waiting" pod="openshift-image-registry/image-registry-599d8489d7-97shl" err="0/6 nodes are available: 1 node(s) didn't match pod anti-affinity rules, 1 node(s) had untolerated taint {node.kubernetes.io/unschedulable: }, 1 node(s) were unschedulable, 2 node(s) didn't match pod topology spread constraints, 3 node(s) didn't match pod topology spread constraints (missing required label), 3 node(s) had untolerated taint {node-role.kubernetes.io/master: }. preemption: 0/6 nodes are available: 1 node(s) didn't match pod anti-affinity rules, 2 node(s) didn't match pod topology spread constraints, 4 Preemption is not helpful for scheduling."
2023-01-09T05:32:47.512468748Z I0109 05:32:47.512379       1 node_tree.go:79] "Removed node in listed group from NodeTree" node="ip-10-0-200-52.us-east-2.compute.internal" zone="us-east-2:\x00:us-east-2c"
2023-01-09T05:32:57.561474475Z I0109 05:32:57.560753       1 schedule_one.go:266] "Successfully bound pod to node" pod="openshift-image-registry/image-registry-599d8489d7-97shl" node="ip-10-0-144-137.us-east-2.compute.internal" evaluatedNodes=5 feasibleNodes=1
2023-01-09T05:32:59.163616682Z I0109 05:32:59.163561       1 node_tree.go:65] "Added node in listed group to NodeTree" node="ip-10-0-190-242.us-east-2.compute.internal" zone="us-east-2:\x00:us-east-2b"
2023-01-09T05:32:59.206109119Z I0109 05:32:59.206056       1 schedule_one.go:266] "Successfully bound pod to node" pod="openshift-multus/network-metrics-daemon-w2s9h" node="ip-10-0-190-242.us-east-2.compute.internal" evaluatedNodes=1 feasibleNodes=1
2023-01-09T05:32:59.239279269Z I0109 05:32:59.239212       1 schedule_one.go:266] "Successfully bound pod to node" pod="openshift-cluster-node-tuning-operator/tuned-dv5fj" node="ip-10-0-190-242.us-east-2.compute.internal" evaluatedNodes=1 feasibleNodes=1
2023-01-09T05:32:59.266326208Z I0109 05:32:59.266285       1 schedule_one.go:266] "Successfully bound pod to node" pod="openshift-machine-config-operator/machine-config-daemon-jr4wb" node="ip-10-0-190-242.us-east-2.compute.internal" evaluatedNodes=1 feasibleNodes=1
2023-01-09T05:32:59.274284814Z I0109 05:32:59.274218       1 schedule_one.go:266] "Successfully bound pod to node" pod="openshift-dns/node-resolver-97n7h" node="ip-10-0-190-242.us-east-2.compute.internal" evaluatedNodes=1 feasibleNodes=1
2023-01-09T05:32:59.305328333Z I0109 05:32:59.304645       1 schedule_one.go:266] "Successfully bound pod to node" pod="openshift-monitoring/node-exporter-r7swq" node="ip-10-0-190-242.us-east-2.compute.internal" evaluatedNodes=1 feasibleNodes=1
2023-01-09T05:32:59.310984793Z I0109 05:32:59.310937       1 schedule_one.go:266] "Successfully bound pod to node" pod="openshift-cluster-csi-drivers/aws-ebs-csi-driver-node-b8wsg" node="ip-10-0-190-242.us-east-2.compute.internal" evaluatedNodes=1 feasibleNodes=1
2023-01-09T05:32:59.357654383Z I0109 05:32:59.355686       1 schedule_one.go:266] "Successfully bound pod to node" pod="openshift-image-registry/node-ca-k2dtt" node="ip-10-0-190-242.us-east-2.compute.internal" evaluatedNodes=1 feasibleNodes=1
2023-01-09T05:32:59.367628831Z I0109 05:32:59.367586       1 schedule_one.go:266] "Successfully bound pod to node" pod="openshift-network-diagnostics/network-check-target-7zd9g" node="ip-10-0-190-242.us-east-2.compute.internal" evaluatedNodes=1 feasibleNodes=1
2023-01-09T05:32:59.394023170Z I0109 05:32:59.393976       1 schedule_one.go:266] "Successfully bound pod to node" pod="openshift-ovn-kubernetes/ovnkube-node-cmjkq" node="ip-10-0-190-242.us-east-2.compute.internal" evaluatedNodes=1 feasibleNodes=1
2023-01-09T05:32:59.416906197Z I0109 05:32:59.416861       1 schedule_one.go:266] "Successfully bound pod to node" pod="openshift-multus/multus-2bqp5" node="ip-10-0-190-242.us-east-2.compute.internal" evaluatedNodes=1 feasibleNodes=1
2023-01-09T05:32:59.420236805Z I0109 05:32:59.420020       1 schedule_one.go:266] "Successfully bound pod to node" pod="openshift-multus/multus-additional-cni-plugins-79g5j" node="ip-10-0-190-242.us-east-2.compute.internal" evaluatedNodes=1 feasibleNodes=1
2023-01-09T05:32:59.454038648Z I0109 05:32:59.453996       1 schedule_one.go:266] "Successfully bound pod to node" pod="openshift-machine-api/machine-api-termination-handler-nrzs5" node="ip-10-0-190-242.us-east-2.compute.internal" evaluatedNodes=1 feasibleNodes=1
2023-01-09T05:33:39.425488759Z I0109 05:33:39.425438       1 schedule_one.go:266] "Successfully bound pod to node" pod="openshift-dns/dns-default-482k5" node="ip-10-0-190-242.us-east-2.compute.internal" evaluatedNodes=1 feasibleNodes=1
2023-01-09T05:33:39.440465804Z I0109 05:33:39.440426       1 schedule_one.go:266] "Successfully bound pod to node" pod="openshift-ingress-canary/ingress-canary-zk8s2" node="ip-10-0-190-242.us-east-2.compute.internal" evaluatedNodes=1 feasibleNodes=1
2023-01-09T05:36:25.299874990Z I0109 05:36:25.299827       1 schedule_one.go:266] "Successfully bound pod to node" pod="openshift-marketplace/community-operators-7m5jl" node="ip-10-0-145-4.us-east-2.compute.internal" evaluatedNodes=6 feasibleNodes=3
2023-01-09T05:39:54.832816768Z I0109 05:39:54.832771       1 schedule_one.go:266] "Successfully bound pod to node" pod="openshift-marketplace/redhat-operators-n7m6b" node="ip-10-0-145-4.us-east-2.compute.internal" evaluatedNodes=6 feasibleNodes=3
2023-01-09T05:39:55.645229865Z I0109 05:39:55.645115       1 schedule_one.go:266] "Successfully bound pod to node" pod="openshift-marketplace/redhat-marketplace-lcv4z" node="ip-10-0-199-219.us-east-2.compute.internal" evaluatedNodes=6 feasibleNodes=3
2023-01-09T05:40:54.712636593Z I0109 05:40:54.712592       1 schedule_one.go:266] "Successfully bound pod to node" pod="openshift-marketplace/qe-app-registry-c9ltb" node="ip-10-0-144-137.us-east-2.compute.internal" evaluatedNodes=6 feasibleNodes=3
2023-01-09T05:43:06.411805300Z I0109 05:43:06.411755       1 schedule_one.go:266] "Successfully bound pod to node" pod="openshift-marketplace/certified-operators-gl8x7" node="ip-10-0-199-219.us-east-2.compute.internal" evaluatedNodes=6 feasibleNodes=3
2023-01-09T05:45:00.156886391Z I0109 05:45:00.156835       1 schedule_one.go:266] "Successfully bound pod to node" pod="openshift-operator-lifecycle-manager/collect-profiles-27887385-hl5pp" node="ip-10-0-144-137.us-east-2.compute.internal" evaluatedNodes=6 feasibleNodes=3
2023-01-09T05:46:39.355457499Z I0109 05:46:39.355377       1 schedule_one.go:266] "Successfully bound pod to node" pod="openshift-marketplace/community-operators-m5s2l" node="ip-10-0-145-4.us-east-2.compute.internal" evaluatedNodes=6 feasibleNodes=3
2023-01-09T05:49:55.828921332Z I0109 05:49:55.828861       1 schedule_one.go:266] "Successfully bound pod to node" pod="openshift-marketplace/redhat-marketplace-nnfql" node="ip-10-0-199-219.us-east-2.compute.internal" evaluatedNodes=6 feasibleNodes=3
2023-01-09T05:50:04.443435213Z I0109 05:50:04.443394       1 schedule_one.go:266] "Successfully bound pod to node" pod="openshift-marketplace/redhat-operators-m2b96" node="ip-10-0-145-4.us-east-2.compute.internal" evaluatedNodes=6 feasibleNodes=3
2023-01-09T05:51:16.952724126Z I0109 05:51:16.952652       1 schedule_one.go:266] "Successfully bound pod to node" pod="openshift-marketplace/qe-app-registry-j99jh" node="ip-10-0-144-137.us-east-2.compute.internal" evaluatedNodes=6 feasibleNodes=3
2023-01-09T05:53:24.779288088Z I0109 05:53:24.779242       1 schedule_one.go:266] "Successfully bound pod to node" pod="openshift-marketplace/certified-operators-v696b" node="ip-10-0-199-219.us-east-2.compute.internal" evaluatedNodes=6 feasibleNodes=3
2023-01-09T05:56:53.960991909Z I0109 05:56:53.960950       1 schedule_one.go:266] "Successfully bound pod to node" pod="openshift-marketplace/community-operators-p4md5" node="ip-10-0-145-4.us-east-2.compute.internal" evaluatedNodes=6 feasibleNodes=3
2023-01-09T06:00:00.184319197Z I0109 06:00:00.184276       1 schedule_one.go:266] "Successfully bound pod to node" pod="openshift-operator-lifecycle-manager/collect-profiles-27887400-rtnhq" node="ip-10-0-144-137.us-east-2.compute.internal" evaluatedNodes=6 feasibleNodes=3
2023-01-09T06:00:30.208620627Z I0109 06:00:30.208573       1 schedule_one.go:266] "Successfully bound pod to node" pod="openshift-marketplace/redhat-marketplace-jvr8f" node="ip-10-0-199-219.us-east-2.compute.internal" evaluatedNodes=6 feasibleNodes=3
2023-01-09T06:00:57.544555424Z I0109 06:00:57.544511       1 schedule_one.go:266] "Successfully bound pod to node" pod="openshift-marketplace/redhat-operators-xtcrx" node="ip-10-0-145-4.us-east-2.compute.internal" evaluatedNodes=6 feasibleNodes=3
2023-01-09T06:02:04.108055779Z I0109 06:02:04.107986       1 schedule_one.go:266] "Successfully bound pod to node" pod="openshift-marketplace/qe-app-registry-h86p6" node="ip-10-0-144-137.us-east-2.compute.internal" evaluatedNodes=6 feasibleNodes=3
2023-01-09T06:06:06.139496071Z I0109 06:06:06.139455       1 schedule_one.go:266] "Successfully bound pod to node" pod="openshift-marketplace/certified-operators-6v58x" node="ip-10-0-199-219.us-east-2.compute.internal" evaluatedNodes=6 feasibleNodes=3
2023-01-09T06:07:41.347520990Z I0109 06:07:41.347463       1 schedule_one.go:266] "Successfully bound pod to node" pod="openshift-marketplace/community-operators-vgls8" node="ip-10-0-145-4.us-east-2.compute.internal" evaluatedNodes=6 feasibleNodes=3
2023-01-09T06:10:59.094224426Z I0109 06:10:59.094175       1 schedule_one.go:266] "Successfully bound pod to node" pod="openshift-marketplace/redhat-marketplace-8ftxj" node="ip-10-0-199-219.us-east-2.compute.internal" evaluatedNodes=6 feasibleNodes=3
2023-01-09T06:11:11.007171920Z I0109 06:11:11.007129       1 schedule_one.go:266] "Successfully bound pod to node" pod="openshift-marketplace/redhat-operators-zzlhw" node="ip-10-0-145-4.us-east-2.compute.internal" evaluatedNodes=6 feasibleNodes=3
2023-01-09T06:11:57.457540394Z I0109 06:11:57.457480       1 schedule_one.go:266] "Successfully bound pod to node" pod="openshift-logging/logging-view-plugin-56cbd77f8b-f4hzq" node="ip-10-0-190-242.us-east-2.compute.internal" evaluatedNodes=6 feasibleNodes=3
2023-01-09T06:11:57.753402598Z I0109 06:11:57.753297       1 schedule_one.go:266] "Successfully bound pod to node" pod="openshift-logging/collector-cvxt9" node="ip-10-0-199-219.us-east-2.compute.internal" evaluatedNodes=1 feasibleNodes=1
2023-01-09T06:11:57.795804935Z I0109 06:11:57.795677       1 schedule_one.go:266] "Successfully bound pod to node" pod="openshift-logging/collector-5wwcz" node="ip-10-0-130-201.us-east-2.compute.internal" evaluatedNodes=1 feasibleNodes=1
2023-01-09T06:11:57.803935325Z I0109 06:11:57.800752       1 schedule_one.go:266] "Successfully bound pod to node" pod="openshift-logging/collector-cwngs" node="ip-10-0-190-242.us-east-2.compute.internal" evaluatedNodes=1 feasibleNodes=1
2023-01-09T06:11:57.831944188Z I0109 06:11:57.831898       1 schedule_one.go:266] "Successfully bound pod to node" pod="openshift-logging/collector-57c8b" node="ip-10-0-160-211.us-east-2.compute.internal" evaluatedNodes=1 feasibleNodes=1
2023-01-09T06:11:57.832585043Z I0109 06:11:57.832525       1 schedule_one.go:266] "Successfully bound pod to node" pod="openshift-logging/collector-chhjh" node="ip-10-0-144-137.us-east-2.compute.internal" evaluatedNodes=1 feasibleNodes=1
2023-01-09T06:11:57.849955857Z I0109 06:11:57.849914       1 schedule_one.go:266] "Successfully bound pod to node" pod="openshift-logging/collector-bq9ff" node="ip-10-0-145-4.us-east-2.compute.internal" evaluatedNodes=1 feasibleNodes=1
2023-01-09T06:12:07.255061602Z I0109 06:12:07.255003       1 schedule_one.go:266] "Successfully bound pod to node" pod="openshift-logging/collector-jdlk4" node="ip-10-0-144-137.us-east-2.compute.internal" evaluatedNodes=1 feasibleNodes=1
2023-01-09T06:12:09.810561162Z I0109 06:12:09.810510       1 schedule_one.go:266] "Successfully bound pod to node" pod="openshift-logging/collector-x4tn2" node="ip-10-0-130-201.us-east-2.compute.internal" evaluatedNodes=1 feasibleNodes=1
2023-01-09T06:12:10.084565848Z I0109 06:12:10.084518       1 schedule_one.go:266] "Successfully bound pod to node" pod="openshift-logging/collector-79swh" node="ip-10-0-145-4.us-east-2.compute.internal" evaluatedNodes=1 feasibleNodes=1
2023-01-09T06:12:10.127281587Z I0109 06:12:10.127235       1 schedule_one.go:266] "Successfully bound pod to node" pod="openshift-logging/collector-wrnk4" node="ip-10-0-199-219.us-east-2.compute.internal" evaluatedNodes=1 feasibleNodes=1
2023-01-09T06:12:11.256552025Z I0109 06:12:11.256509       1 schedule_one.go:266] "Successfully bound pod to node" pod="openshift-logging/collector-pvvls" node="ip-10-0-160-211.us-east-2.compute.internal" evaluatedNodes=1 feasibleNodes=1
2023-01-09T06:12:14.166811966Z I0109 06:12:14.166767       1 schedule_one.go:266] "Successfully bound pod to node" pod="openshift-logging/collector-bhqdl" node="ip-10-0-190-242.us-east-2.compute.internal" evaluatedNodes=1 feasibleNodes=1
2023-01-09T06:12:40.963530928Z I0109 06:12:40.963474       1 schedule_one.go:266] "Successfully bound pod to node" pod="openshift-logging/lokistack-sample-distributor-74bfbf6c7c-zgptk" node="ip-10-0-130-201.us-east-2.compute.internal" evaluatedNodes=6 feasibleNodes=3
2023-01-09T06:12:41.010367317Z I0109 06:12:41.007791       1 schedule_one.go:266] "Successfully bound pod to node" pod="openshift-logging/lokistack-sample-distributor-74bfbf6c7c-qh8t5" node="ip-10-0-190-242.us-east-2.compute.internal" evaluatedNodes=6 feasibleNodes=3
2023-01-09T06:12:41.063439002Z I0109 06:12:41.063372       1 schedule_one.go:266] "Successfully bound pod to node" pod="openshift-logging/lokistack-sample-querier-6c84499f88-b842q" node="ip-10-0-130-201.us-east-2.compute.internal" evaluatedNodes=6 feasibleNodes=3
2023-01-09T06:12:41.097613729Z I0109 06:12:41.097577       1 schedule_one.go:266] "Successfully bound pod to node" pod="openshift-logging/lokistack-sample-querier-6c84499f88-2sh8s" node="ip-10-0-144-137.us-east-2.compute.internal" evaluatedNodes=6 feasibleNodes=3
2023-01-09T06:12:41.175023353Z I0109 06:12:41.174951       1 schedule_one.go:266] "Successfully bound pod to node" pod="openshift-logging/lokistack-sample-query-frontend-7c78f4b446-h9n7d" node="ip-10-0-130-201.us-east-2.compute.internal" evaluatedNodes=6 feasibleNodes=3
2023-01-09T06:12:41.214325285Z I0109 06:12:41.214281       1 schedule_one.go:266] "Successfully bound pod to node" pod="openshift-logging/lokistack-sample-query-frontend-7c78f4b446-4fnpf" node="ip-10-0-190-242.us-east-2.compute.internal" evaluatedNodes=6 feasibleNodes=2
2023-01-09T06:12:41.508384920Z I0109 06:12:41.506190       1 schedule_one.go:266] "Successfully bound pod to node" pod="openshift-logging/lokistack-sample-gateway-6fcd77f58-9rmlf" node="ip-10-0-130-201.us-east-2.compute.internal" evaluatedNodes=6 feasibleNodes=3
2023-01-09T06:12:41.508384920Z I0109 06:12:41.507856       1 schedule_one.go:826] "Unable to schedule pod; no fit; waiting" pod="openshift-logging/lokistack-sample-ruler-1" err="0/6 nodes are available: 3 Insufficient cpu, 3 node(s) had untolerated taint {node-role.kubernetes.io/master: }. preemption: 0/6 nodes are available: 3 No preemption victims found for incoming pod, 3 Preemption is not helpful for scheduling."
2023-01-09T06:12:43.170061788Z I0109 06:12:43.170012       1 schedule_one.go:826] "Unable to schedule pod; no fit; waiting" pod="openshift-logging/lokistack-sample-ruler-1" err="0/6 nodes are available: 3 Insufficient cpu, 3 node(s) had untolerated taint {node-role.kubernetes.io/master: }. preemption: 0/6 nodes are available: 3 No preemption victims found for incoming pod, 3 Preemption is not helpful for scheduling."
2023-01-09T06:12:45.061278318Z I0109 06:12:45.061218       1 schedule_one.go:266] "Successfully bound pod to node" pod="openshift-logging/lokistack-sample-ingester-0" node="ip-10-0-144-137.us-east-2.compute.internal" evaluatedNodes=6 feasibleNodes=3
2023-01-09T06:12:45.152117303Z I0109 06:12:45.152066       1 schedule_one.go:266] "Successfully bound pod to node" pod="openshift-logging/lokistack-sample-compactor-0" node="ip-10-0-130-201.us-east-2.compute.internal" evaluatedNodes=6 feasibleNodes=3
2023-01-09T06:12:45.240128499Z I0109 06:12:45.240083       1 schedule_one.go:266] "Successfully bound pod to node" pod="openshift-logging/lokistack-sample-index-gateway-0" node="ip-10-0-144-137.us-east-2.compute.internal" evaluatedNodes=6 feasibleNodes=3
2023-01-09T06:12:45.474040803Z I0109 06:12:45.473972       1 schedule_one.go:266] "Successfully bound pod to node" pod="openshift-logging/lokistack-sample-ruler-0" node="ip-10-0-144-137.us-east-2.compute.internal" evaluatedNodes=6 feasibleNodes=1
2023-01-09T06:12:53.199148787Z I0109 06:12:53.199090       1 schedule_one.go:266] "Successfully bound pod to node" pod="openshift-marketplace/qe-app-registry-rx2v9" node="ip-10-0-144-137.us-east-2.compute.internal" evaluatedNodes=6 feasibleNodes=3
2023-01-09T06:13:07.079523743Z I0109 06:13:07.079463       1 schedule_one.go:826] "Unable to schedule pod; no fit; waiting" pod="openshift-logging/lokistack-sample-ruler-1" err="0/6 nodes are available: 3 Insufficient cpu, 3 node(s) had untolerated taint {node-role.kubernetes.io/master: }. preemption: 0/6 nodes are available: 3 No preemption victims found for incoming pod, 3 Preemption is not helpful for scheduling."
2023-01-09T06:13:07.084444083Z E0109 06:13:07.084346       1 event_broadcaster.go:253] Server rejected event '&v1.Event{TypeMeta:v1.TypeMeta{Kind:"", APIVersion:""}, ObjectMeta:v1.ObjectMeta{Name:"lokistack-sample-ruler-1.17388f3f33090e36", GenerateName:"", Namespace:"openshift-logging", SelfLink:"", UID:"405cab70-8734-481b-b9a9-f0fb3851a2ba", ResourceVersion:"60231", Generation:0, CreationTimestamp:time.Date(2023, time.January, 9, 6, 12, 43, 0, time.Local), DeletionTimestamp:<nil>, DeletionGracePeriodSeconds:(*int64)(nil), Labels:map[string]string(nil), Annotations:map[string]string(nil), OwnerReferences:[]v1.OwnerReference(nil), Finalizers:[]string(nil), ManagedFields:[]v1.ManagedFieldsEntry{v1.ManagedFieldsEntry{Manager:"kube-scheduler", Operation:"Update", APIVersion:"events.k8s.io/v1", Time:time.Date(2023, time.January, 9, 6, 12, 43, 0, time.Local), FieldsType:"FieldsV1", FieldsV1:(*v1.FieldsV1)(0xc0017e4708), Subresource:""}}}, EventTime:time.Date(2023, time.January, 9, 6, 12, 43, 170078000, time.Local), Series:(*v1.EventSeries)(0xc001379600), ReportingController:"default-scheduler", ReportingInstance:"default-scheduler-ip-10-0-199-219", Action:"Scheduling", Reason:"FailedScheduling", Regarding:v1.ObjectReference{Kind:"Pod", Namespace:"openshift-logging", Name:"lokistack-sample-ruler-1", UID:"6e246ac0-e4fb-4d34-ba51-f189984b1ca7", APIVersion:"v1", ResourceVersion:"60163", FieldPath:""}, Related:(*v1.ObjectReference)(nil), Note:"0/6 nodes are available: 3 Insufficient cpu, 3 node(s) had untolerated taint {node-role.kubernetes.io/master: }. preemption: 0/6 nodes are available: 3 No preemption victims found for incoming pod, 3 Preemption is not helpful for scheduling.", Type:"Warning", DeprecatedSource:v1.EventSource{Component:"", Host:""}, DeprecatedFirstTimestamp:time.Date(1, time.January, 1, 0, 0, 0, 0, time.UTC), DeprecatedLastTimestamp:time.Date(1, time.January, 1, 0, 0, 0, 0, time.UTC), DeprecatedCount:0}': 'Event "lokistack-sample-ruler-1.17388f3f33090e36" is invalid: series.count: Invalid value: "": should be at least 2' (will not retry!)
2023-01-09T06:13:15.039962223Z I0109 06:13:15.039909       1 schedule_one.go:266] "Successfully bound pod to node" pod="openshift-logging/lokistack-sample-index-gateway-1" node="ip-10-0-190-242.us-east-2.compute.internal" evaluatedNodes=6 feasibleNodes=3
2023-01-09T06:13:56.841371829Z I0109 06:13:56.841297       1 schedule_one.go:826] "Unable to schedule pod; no fit; waiting" pod="openshift-logging/lokistack-sample-ingester-1" err="0/6 nodes are available: 3 Insufficient cpu, 3 node(s) had untolerated taint {node-role.kubernetes.io/master: }. preemption: 0/6 nodes are available: 3 No preemption victims found for incoming pod, 3 Preemption is not helpful for scheduling."
2023-01-09T06:15:00.148963903Z I0109 06:15:00.148920       1 schedule_one.go:266] "Successfully bound pod to node" pod="openshift-operator-lifecycle-manager/collect-profiles-27887415-kkxvk" node="ip-10-0-144-137.us-east-2.compute.internal" evaluatedNodes=6 feasibleNodes=3
2023-01-09T06:15:05.367064216Z I0109 06:15:05.367022       1 schedule_one.go:826] "Unable to schedule pod; no fit; waiting" pod="openshift-logging/lokistack-sample-ruler-1" err="0/6 nodes are available: 3 Insufficient cpu, 3 node(s) had untolerated taint {node-role.kubernetes.io/master: }. preemption: 0/6 nodes are available: 3 No preemption victims found for incoming pod, 3 Preemption is not helpful for scheduling."
2023-01-09T06:15:05.367717750Z I0109 06:15:05.367672       1 schedule_one.go:826] "Unable to schedule pod; no fit; waiting" pod="openshift-logging/lokistack-sample-ingester-1" err="0/6 nodes are available: 3 Insufficient cpu, 3 node(s) had untolerated taint {node-role.kubernetes.io/master: }. preemption: 0/6 nodes are available: 3 No preemption victims found for incoming pod, 3 Preemption is not helpful for scheduling."
2023-01-09T06:18:04.966225330Z I0109 06:18:04.966180       1 schedule_one.go:266] "Successfully bound pod to node" pod="openshift-marketplace/community-operators-ft2b4" node="ip-10-0-145-4.us-east-2.compute.internal" evaluatedNodes=6 feasibleNodes=3
2023-01-09T06:18:27.817931176Z I0109 06:18:27.817882       1 schedule_one.go:826] "Unable to schedule pod; no fit; waiting" pod="openshift-logging/lokistack-sample-ruler-1" err="0/6 nodes are available: 3 Insufficient cpu, 3 node(s) had untolerated taint {node-role.kubernetes.io/master: }. preemption: 0/6 nodes are available: 3 No preemption victims found for incoming pod, 3 Preemption is not helpful for scheduling."
2023-01-09T06:18:27.818552011Z I0109 06:18:27.818511       1 schedule_one.go:826] "Unable to schedule pod; no fit; waiting" pod="openshift-logging/lokistack-sample-ingester-1" err="0/6 nodes are available: 3 Insufficient cpu, 3 node(s) had untolerated taint {node-role.kubernetes.io/master: }. preemption: 0/6 nodes are available: 3 No preemption victims found for incoming pod, 3 Preemption is not helpful for scheduling."
2023-01-09T06:18:27.823596805Z E0109 06:18:27.823498       1 event_broadcaster.go:253] Server rejected event '&v1.Event{TypeMeta:v1.TypeMeta{Kind:"", APIVersion:""}, ObjectMeta:v1.ObjectMeta{Name:"lokistack-sample-ingester-1.17388f604eacf97f", GenerateName:"", Namespace:"openshift-logging", SelfLink:"", UID:"a5d6ddcb-257b-4275-978b-b9a73443b829", ResourceVersion:"61645", Generation:0, CreationTimestamp:time.Date(2023, time.January, 9, 6, 15, 5, 0, time.Local), DeletionTimestamp:<nil>, DeletionGracePeriodSeconds:(*int64)(nil), Labels:map[string]string(nil), Annotations:map[string]string(nil), OwnerReferences:[]v1.OwnerReference(nil), Finalizers:[]string(nil), ManagedFields:[]v1.ManagedFieldsEntry{v1.ManagedFieldsEntry{Manager:"kube-scheduler", Operation:"Update", APIVersion:"events.k8s.io/v1", Time:time.Date(2023, time.January, 9, 6, 15, 5, 0, time.Local), FieldsType:"FieldsV1", FieldsV1:(*v1.FieldsV1)(0xc001f013f8), Subresource:""}}}, EventTime:time.Date(2023, time.January, 9, 6, 15, 5, 367728000, time.Local), Series:(*v1.EventSeries)(0xc001eeaac0), ReportingController:"default-scheduler", ReportingInstance:"default-scheduler-ip-10-0-199-219", Action:"Scheduling", Reason:"FailedScheduling", Regarding:v1.ObjectReference{Kind:"Pod", Namespace:"openshift-logging", Name:"lokistack-sample-ingester-1", UID:"cad4407e-3698-46c7-9373-c76a9a8915a5", APIVersion:"v1", ResourceVersion:"61182", FieldPath:""}, Related:(*v1.ObjectReference)(nil), Note:"0/6 nodes are available: 3 Insufficient cpu, 3 node(s) had untolerated taint {node-role.kubernetes.io/master: }. preemption: 0/6 nodes are available: 3 No preemption victims found for incoming pod, 3 Preemption is not helpful for scheduling.", Type:"Warning", DeprecatedSource:v1.EventSource{Component:"", Host:""}, DeprecatedFirstTimestamp:time.Date(1, time.January, 1, 0, 0, 0, 0, time.UTC), DeprecatedLastTimestamp:time.Date(1, time.January, 1, 0, 0, 0, 0, time.UTC), DeprecatedCount:0}': 'Event "lokistack-sample-ingester-1.17388f604eacf97f" is invalid: series.count: Invalid value: "": should be at least 2' (will not retry!)
2023-01-09T06:18:27.871842547Z E0109 06:18:27.871743       1 event_broadcaster.go:253] Server rejected event '&v1.Event{TypeMeta:v1.TypeMeta{Kind:"", APIVersion:""}, ObjectMeta:v1.ObjectMeta{Name:"lokistack-sample-ingester-1.17388f604eacf97f", GenerateName:"", Namespace:"openshift-logging", SelfLink:"", UID:"a5d6ddcb-257b-4275-978b-b9a73443b829", ResourceVersion:"61645", Generation:0, CreationTimestamp:time.Date(2023, time.January, 9, 6, 15, 5, 0, time.Local), DeletionTimestamp:<nil>, DeletionGracePeriodSeconds:(*int64)(nil), Labels:map[string]string(nil), Annotations:map[string]string(nil), OwnerReferences:[]v1.OwnerReference(nil), Finalizers:[]string(nil), ManagedFields:[]v1.ManagedFieldsEntry{v1.ManagedFieldsEntry{Manager:"kube-scheduler", Operation:"Update", APIVersion:"events.k8s.io/v1", Time:time.Date(2023, time.January, 9, 6, 15, 5, 0, time.Local), FieldsType:"FieldsV1", FieldsV1:(*v1.FieldsV1)(0xc001f013f8), Subresource:""}}}, EventTime:time.Date(2023, time.January, 9, 6, 15, 5, 367728000, time.Local), Series:(*v1.EventSeries)(0xc001eeaac0), ReportingController:"default-scheduler", ReportingInstance:"default-scheduler-ip-10-0-199-219", Action:"Scheduling", Reason:"FailedScheduling", Regarding:v1.ObjectReference{Kind:"Pod", Namespace:"openshift-logging", Name:"lokistack-sample-ingester-1", UID:"cad4407e-3698-46c7-9373-c76a9a8915a5", APIVersion:"v1", ResourceVersion:"61182", FieldPath:""}, Related:(*v1.ObjectReference)(nil), Note:"0/6 nodes are available: 3 Insufficient cpu, 3 node(s) had untolerated taint {node-role.kubernetes.io/master: }. preemption: 0/6 nodes are available: 3 No preemption victims found for incoming pod, 3 Preemption is not helpful for scheduling.", Type:"Warning", DeprecatedSource:v1.EventSource{Component:"", Host:""}, DeprecatedFirstTimestamp:time.Date(1, time.January, 1, 0, 0, 0, 0, time.UTC), DeprecatedLastTimestamp:time.Date(1, time.January, 1, 0, 0, 0, 0, time.UTC), DeprecatedCount:0}': 'Event "lokistack-sample-ingester-1.17388f604eacf97f" is invalid: series.count: Invalid value: "": should be at least 2' (will not retry!)
2023-01-09T06:20:43.717442525Z I0109 06:20:43.717364       1 schedule_one.go:266] "Successfully bound pod to node" pod="openshift-marketplace/certified-operators-p54kp" node="ip-10-0-199-219.us-east-2.compute.internal" evaluatedNodes=6 feasibleNodes=3
2023-01-09T06:20:57.653926038Z I0109 06:20:57.653876       1 schedule_one.go:826] "Unable to schedule pod; no fit; waiting" pod="openshift-logging/lokistack-sample-ruler-1" err="0/6 nodes are available: 3 Insufficient cpu, 3 node(s) had untolerated taint {node-role.kubernetes.io/master: }. preemption: 0/6 nodes are available: 3 No preemption victims found for incoming pod, 3 Preemption is not helpful for scheduling."
2023-01-09T06:20:57.654616622Z I0109 06:20:57.654565       1 schedule_one.go:826] "Unable to schedule pod; no fit; waiting" pod="openshift-logging/lokistack-sample-ingester-1" err="0/6 nodes are available: 3 Insufficient cpu, 3 node(s) had untolerated taint {node-role.kubernetes.io/master: }. preemption: 0/6 nodes are available: 3 No preemption victims found for incoming pod, 3 Preemption is not helpful for scheduling."
2023-01-09T06:21:21.089686125Z I0109 06:21:21.089602       1 schedule_one.go:266] "Successfully bound pod to node" pod="openshift-marketplace/redhat-marketplace-mktv6" node="ip-10-0-199-219.us-east-2.compute.internal" evaluatedNodes=6 feasibleNodes=3
2023-01-09T06:21:34.768408769Z I0109 06:21:34.767129       1 schedule_one.go:826] "Unable to schedule pod; no fit; waiting" pod="openshift-logging/lokistack-sample-ruler-1" err="0/6 nodes are available: 3 Insufficient cpu, 3 node(s) had untolerated taint {node-role.kubernetes.io/master: }. preemption: 0/6 nodes are available: 3 No preemption victims found for incoming pod, 3 Preemption is not helpful for scheduling."
2023-01-09T06:21:34.768408769Z I0109 06:21:34.768300       1 schedule_one.go:826] "Unable to schedule pod; no fit; waiting" pod="openshift-logging/lokistack-sample-ingester-1" err="0/6 nodes are available: 3 Insufficient cpu, 3 node(s) had untolerated taint {node-role.kubernetes.io/master: }. preemption: 0/6 nodes are available: 3 No preemption victims found for incoming pod, 3 Preemption is not helpful for scheduling."
2023-01-09T06:21:48.111217838Z I0109 06:21:48.111174       1 schedule_one.go:266] "Successfully bound pod to node" pod="logtesta0/centos-logtest-lpj2q" node="ip-10-0-190-242.us-east-2.compute.internal" evaluatedNodes=6 feasibleNodes=1
2023-01-09T06:21:50.786198228Z I0109 06:21:50.786150       1 schedule_one.go:266] "Successfully bound pod to node" pod="openshift-marketplace/redhat-operators-swck8" node="ip-10-0-145-4.us-east-2.compute.internal" evaluatedNodes=6 feasibleNodes=3
2023-01-09T06:22:23.480732346Z I0109 06:22:23.480681       1 schedule_one.go:826] "Unable to schedule pod; no fit; waiting" pod="openshift-logging/lokistack-sample-ruler-1" err="0/6 nodes are available: 3 Insufficient cpu, 3 node(s) had untolerated taint {node-role.kubernetes.io/master: }. preemption: 0/6 nodes are available: 3 No preemption victims found for incoming pod, 3 Preemption is not helpful for scheduling."
2023-01-09T06:22:23.481537259Z I0109 06:22:23.481502       1 schedule_one.go:826] "Unable to schedule pod; no fit; waiting" pod="openshift-logging/lokistack-sample-ingester-1" err="0/6 nodes are available: 3 Insufficient cpu, 3 node(s) had untolerated taint {node-role.kubernetes.io/master: }. preemption: 0/6 nodes are available: 3 No preemption victims found for incoming pod, 3 Preemption is not helpful for scheduling."
2023-01-09T06:22:55.694856562Z I0109 06:22:55.694809       1 schedule_one.go:266] "Successfully bound pod to node" pod="openshift-marketplace/qe-app-registry-j6qlv" node="ip-10-0-144-137.us-east-2.compute.internal" evaluatedNodes=6 feasibleNodes=3
2023-01-09T06:23:09.591384092Z I0109 06:23:09.591315       1 schedule_one.go:826] "Unable to schedule pod; no fit; waiting" pod="openshift-logging/lokistack-sample-ruler-1" err="0/6 nodes are available: 3 Insufficient cpu, 3 node(s) had untolerated taint {node-role.kubernetes.io/master: }. preemption: 0/6 nodes are available: 3 No preemption victims found for incoming pod, 3 Preemption is not helpful for scheduling."
2023-01-09T06:23:09.592640430Z I0109 06:23:09.592597       1 schedule_one.go:826] "Unable to schedule pod; no fit; waiting" pod="openshift-logging/lokistack-sample-ingester-1" err="0/6 nodes are available: 3 Insufficient cpu, 3 node(s) had untolerated taint {node-role.kubernetes.io/master: }. preemption: 0/6 nodes are available: 3 No preemption victims found for incoming pod, 3 Preemption is not helpful for scheduling."
2023-01-09T06:28:34.215502319Z I0109 06:28:34.215459       1 schedule_one.go:826] "Unable to schedule pod; no fit; waiting" pod="openshift-logging/lokistack-sample-ruler-1" err="0/6 nodes are available: 3 Insufficient cpu, 3 node(s) had untolerated taint {node-role.kubernetes.io/master: }. preemption: 0/6 nodes are available: 3 No preemption victims found for incoming pod, 3 Preemption is not helpful for scheduling."
2023-01-09T06:28:34.215990422Z I0109 06:28:34.215962       1 schedule_one.go:826] "Unable to schedule pod; no fit; waiting" pod="openshift-logging/lokistack-sample-ingester-1" err="0/6 nodes are available: 3 Insufficient cpu, 3 node(s) had untolerated taint {node-role.kubernetes.io/master: }. preemption: 0/6 nodes are available: 3 No preemption victims found for incoming pod, 3 Preemption is not helpful for scheduling."
2023-01-09T06:28:52.452503861Z I0109 06:28:52.452462       1 schedule_one.go:266] "Successfully bound pod to node" pod="openshift-marketplace/community-operators-xq9d6" node="ip-10-0-145-4.us-east-2.compute.internal" evaluatedNodes=6 feasibleNodes=3
2023-01-09T06:29:14.640240823Z I0109 06:29:14.640192       1 schedule_one.go:826] "Unable to schedule pod; no fit; waiting" pod="openshift-logging/lokistack-sample-ruler-1" err="0/6 nodes are available: 3 Insufficient cpu, 3 node(s) had untolerated taint {node-role.kubernetes.io/master: }. preemption: 0/6 nodes are available: 3 No preemption victims found for incoming pod, 3 Preemption is not helpful for scheduling."
2023-01-09T06:29:14.640955485Z I0109 06:29:14.640918       1 schedule_one.go:826] "Unable to schedule pod; no fit; waiting" pod="openshift-logging/lokistack-sample-ingester-1" err="0/6 nodes are available: 3 Insufficient cpu, 3 node(s) had untolerated taint {node-role.kubernetes.io/master: }. preemption: 0/6 nodes are available: 3 No preemption victims found for incoming pod, 3 Preemption is not helpful for scheduling."
2023-01-09T06:30:00.150216167Z I0109 06:30:00.150171       1 schedule_one.go:266] "Successfully bound pod to node" pod="openshift-operator-lifecycle-manager/collect-profiles-27887430-j7k84" node="ip-10-0-144-137.us-east-2.compute.internal" evaluatedNodes=6 feasibleNodes=3
2023-01-09T06:30:05.609703488Z I0109 06:30:05.609662       1 schedule_one.go:826] "Unable to schedule pod; no fit; waiting" pod="openshift-logging/lokistack-sample-ruler-1" err="0/6 nodes are available: 3 Insufficient cpu, 3 node(s) had untolerated taint {node-role.kubernetes.io/master: }. preemption: 0/6 nodes are available: 3 No preemption victims found for incoming pod, 3 Preemption is not helpful for scheduling."
2023-01-09T06:30:05.610303182Z I0109 06:30:05.610267       1 schedule_one.go:826] "Unable to schedule pod; no fit; waiting" pod="openshift-logging/lokistack-sample-ingester-1" err="0/6 nodes are available: 3 Insufficient cpu, 3 node(s) had untolerated taint {node-role.kubernetes.io/master: }. preemption: 0/6 nodes are available: 3 No preemption victims found for incoming pod, 3 Preemption is not helpful for scheduling."
2023-01-09T06:31:51.528765900Z I0109 06:31:51.528699       1 schedule_one.go:266] "Successfully bound pod to node" pod="openshift-marketplace/redhat-marketplace-l8mcn" node="ip-10-0-199-219.us-east-2.compute.internal" evaluatedNodes=6 feasibleNodes=3
2023-01-09T06:31:53.226806885Z I0109 06:31:53.226752       1 schedule_one.go:266] "Successfully bound pod to node" pod="openshift-marketplace/certified-operators-j4fbl" node="ip-10-0-199-219.us-east-2.compute.internal" evaluatedNodes=6 feasibleNodes=3
2023-01-09T06:32:05.597255503Z I0109 06:32:05.597209       1 schedule_one.go:826] "Unable to schedule pod; no fit; waiting" pod="openshift-logging/lokistack-sample-ruler-1" err="0/6 nodes are available: 3 Insufficient cpu, 3 node(s) had untolerated taint {node-role.kubernetes.io/master: }. preemption: 0/6 nodes are available: 3 No preemption victims found for incoming pod, 3 Preemption is not helpful for scheduling."
2023-01-09T06:32:05.598454143Z I0109 06:32:05.598413       1 schedule_one.go:826] "Unable to schedule pod; no fit; waiting" pod="openshift-logging/lokistack-sample-ingester-1" err="0/6 nodes are available: 3 Insufficient cpu, 3 node(s) had untolerated taint {node-role.kubernetes.io/master: }. preemption: 0/6 nodes are available: 3 No preemption victims found for incoming pod, 3 Preemption is not helpful for scheduling."
2023-01-09T06:32:15.859227852Z I0109 06:32:15.859182       1 schedule_one.go:826] "Unable to schedule pod; no fit; waiting" pod="openshift-logging/lokistack-sample-ruler-1" err="0/6 nodes are available: 3 Insufficient cpu, 3 node(s) had untolerated taint {node-role.kubernetes.io/master: }. preemption: 0/6 nodes are available: 3 No preemption victims found for incoming pod, 3 Preemption is not helpful for scheduling."
2023-01-09T06:32:15.859743391Z I0109 06:32:15.859709       1 schedule_one.go:826] "Unable to schedule pod; no fit; waiting" pod="openshift-logging/lokistack-sample-ingester-1" err="0/6 nodes are available: 3 Insufficient cpu, 3 node(s) had untolerated taint {node-role.kubernetes.io/master: }. preemption: 0/6 nodes are available: 3 No preemption victims found for incoming pod, 3 Preemption is not helpful for scheduling."
2023-01-09T06:33:29.103952241Z I0109 06:33:29.103892       1 schedule_one.go:266] "Successfully bound pod to node" pod="openshift-marketplace/redhat-operators-js5cw" node="ip-10-0-145-4.us-east-2.compute.internal" evaluatedNodes=6 feasibleNodes=3
2023-01-09T06:33:38.144368321Z I0109 06:33:38.144303       1 schedule_one.go:266] "Successfully bound pod to node" pod="openshift-marketplace/qe-app-registry-kxt2z" node="ip-10-0-144-137.us-east-2.compute.internal" evaluatedNodes=6 feasibleNodes=3
2023-01-09T06:33:52.147994034Z I0109 06:33:52.147940       1 schedule_one.go:826] "Unable to schedule pod; no fit; waiting" pod="openshift-logging/lokistack-sample-ruler-1" err="0/6 nodes are available: 3 Insufficient cpu, 3 node(s) had untolerated taint {node-role.kubernetes.io/master: }. preemption: 0/6 nodes are available: 3 No preemption victims found for incoming pod, 3 Preemption is not helpful for scheduling."
2023-01-09T06:33:52.148712136Z I0109 06:33:52.148669       1 schedule_one.go:826] "Unable to schedule pod; no fit; waiting" pod="openshift-logging/lokistack-sample-ingester-1" err="0/6 nodes are available: 3 Insufficient cpu, 3 node(s) had untolerated taint {node-role.kubernetes.io/master: }. preemption: 0/6 nodes are available: 3 No preemption victims found for incoming pod, 3 Preemption is not helpful for scheduling."
2023-01-09T06:34:02.446786645Z I0109 06:34:02.446736       1 schedule_one.go:826] "Unable to schedule pod; no fit; waiting" pod="openshift-logging/lokistack-sample-ruler-1" err="0/6 nodes are available: 3 Insufficient cpu, 3 node(s) had untolerated taint {node-role.kubernetes.io/master: }. preemption: 0/6 nodes are available: 3 No preemption victims found for incoming pod, 3 Preemption is not helpful for scheduling."
2023-01-09T06:34:02.447644135Z I0109 06:34:02.447606       1 schedule_one.go:826] "Unable to schedule pod; no fit; waiting" pod="openshift-logging/lokistack-sample-ingester-1" err="0/6 nodes are available: 3 Insufficient cpu, 3 node(s) had untolerated taint {node-role.kubernetes.io/master: }. preemption: 0/6 nodes are available: 3 No preemption victims found for incoming pod, 3 Preemption is not helpful for scheduling."
2023-01-09T06:39:04.227904286Z I0109 06:39:04.227862       1 schedule_one.go:826] "Unable to schedule pod; no fit; waiting" pod="openshift-logging/lokistack-sample-ruler-1" err="0/6 nodes are available: 3 Insufficient cpu, 3 node(s) had untolerated taint {node-role.kubernetes.io/master: }. preemption: 0/6 nodes are available: 3 No preemption victims found for incoming pod, 3 Preemption is not helpful for scheduling."
2023-01-09T06:39:04.228407423Z I0109 06:39:04.228379       1 schedule_one.go:826] "Unable to schedule pod; no fit; waiting" pod="openshift-logging/lokistack-sample-ingester-1" err="0/6 nodes are available: 3 Insufficient cpu, 3 node(s) had untolerated taint {node-role.kubernetes.io/master: }. preemption: 0/6 nodes are available: 3 No preemption victims found for incoming pod, 3 Preemption is not helpful for scheduling."
2023-01-09T06:39:16.595924390Z I0109 06:39:16.595883       1 schedule_one.go:266] "Successfully bound pod to node" pod="openshift-marketplace/community-operators-94ght" node="ip-10-0-145-4.us-east-2.compute.internal" evaluatedNodes=6 feasibleNodes=3
2023-01-09T06:39:39.434111712Z I0109 06:39:39.434064       1 schedule_one.go:826] "Unable to schedule pod; no fit; waiting" pod="openshift-logging/lokistack-sample-ruler-1" err="0/6 nodes are available: 3 Insufficient cpu, 3 node(s) had untolerated taint {node-role.kubernetes.io/master: }. preemption: 0/6 nodes are available: 3 No preemption victims found for incoming pod, 3 Preemption is not helpful for scheduling."
2023-01-09T06:39:39.434746257Z I0109 06:39:39.434708       1 schedule_one.go:826] "Unable to schedule pod; no fit; waiting" pod="openshift-logging/lokistack-sample-ingester-1" err="0/6 nodes are available: 3 Insufficient cpu, 3 node(s) had untolerated taint {node-role.kubernetes.io/master: }. preemption: 0/6 nodes are available: 3 No preemption victims found for incoming pod, 3 Preemption is not helpful for scheduling."
2023-01-09T06:42:26.361670207Z I0109 06:42:26.361606       1 schedule_one.go:266] "Successfully bound pod to node" pod="openshift-marketplace/redhat-marketplace-cmqjm" node="ip-10-0-199-219.us-east-2.compute.internal" evaluatedNodes=6 feasibleNodes=3
2023-01-09T06:42:26.364903229Z I0109 06:42:26.364859       1 schedule_one.go:266] "Successfully bound pod to node" pod="openshift-marketplace/certified-operators-m82jz" node="ip-10-0-199-219.us-east-2.compute.internal" evaluatedNodes=6 feasibleNodes=3
2023-01-09T06:42:40.435094816Z I0109 06:42:40.435056       1 schedule_one.go:826] "Unable to schedule pod; no fit; waiting" pod="openshift-logging/lokistack-sample-ruler-1" err="0/6 nodes are available: 3 Insufficient cpu, 3 node(s) had untolerated taint {node-role.kubernetes.io/master: }. preemption: 0/6 nodes are available: 3 No preemption victims found for incoming pod, 3 Preemption is not helpful for scheduling."
2023-01-09T06:42:40.435925548Z I0109 06:42:40.435881       1 schedule_one.go:826] "Unable to schedule pod; no fit; waiting" pod="openshift-logging/lokistack-sample-ingester-1" err="0/6 nodes are available: 3 Insufficient cpu, 3 node(s) had untolerated taint {node-role.kubernetes.io/master: }. preemption: 0/6 nodes are available: 3 No preemption victims found for incoming pod, 3 Preemption is not helpful for scheduling."
2023-01-09T06:42:51.274152602Z I0109 06:42:51.274102       1 schedule_one.go:826] "Unable to schedule pod; no fit; waiting" pod="openshift-logging/lokistack-sample-ruler-1" err="0/6 nodes are available: 3 Insufficient cpu, 3 node(s) had untolerated taint {node-role.kubernetes.io/master: }. preemption: 0/6 nodes are available: 3 No preemption victims found for incoming pod, 3 Preemption is not helpful for scheduling."
2023-01-09T06:42:51.274706979Z I0109 06:42:51.274673       1 schedule_one.go:826] "Unable to schedule pod; no fit; waiting" pod="openshift-logging/lokistack-sample-ingester-1" err="0/6 nodes are available: 3 Insufficient cpu, 3 node(s) had untolerated taint {node-role.kubernetes.io/master: }. preemption: 0/6 nodes are available: 3 No preemption victims found for incoming pod, 3 Preemption is not helpful for scheduling."
2023-01-09T06:44:40.703638468Z I0109 06:44:40.703598       1 schedule_one.go:266] "Successfully bound pod to node" pod="openshift-marketplace/redhat-operators-qnz9h" node="ip-10-0-145-4.us-east-2.compute.internal" evaluatedNodes=6 feasibleNodes=3
2023-01-09T06:44:42.571261428Z I0109 06:44:42.571205       1 schedule_one.go:266] "Successfully bound pod to node" pod="openshift-marketplace/qe-app-registry-w55v6" node="ip-10-0-144-137.us-east-2.compute.internal" evaluatedNodes=6 feasibleNodes=3
2023-01-09T06:44:56.785135736Z I0109 06:44:56.785088       1 schedule_one.go:826] "Unable to schedule pod; no fit; waiting" pod="openshift-logging/lokistack-sample-ruler-1" err="0/6 nodes are available: 3 Insufficient cpu, 3 node(s) had untolerated taint {node-role.kubernetes.io/master: }. preemption: 0/6 nodes are available: 3 No preemption victims found for incoming pod, 3 Preemption is not helpful for scheduling."
2023-01-09T06:44:56.786020209Z I0109 06:44:56.785991       1 schedule_one.go:826] "Unable to schedule pod; no fit; waiting" pod="openshift-logging/lokistack-sample-ingester-1" err="0/6 nodes are available: 3 Insufficient cpu, 3 node(s) had untolerated taint {node-role.kubernetes.io/master: }. preemption: 0/6 nodes are available: 3 No preemption victims found for incoming pod, 3 Preemption is not helpful for scheduling."
2023-01-09T06:45:00.143613599Z I0109 06:45:00.143577       1 schedule_one.go:266] "Successfully bound pod to node" pod="openshift-operator-lifecycle-manager/collect-profiles-27887445-b2psf" node="ip-10-0-144-137.us-east-2.compute.internal" evaluatedNodes=6 feasibleNodes=3
2023-01-09T06:45:07.361824261Z I0109 06:45:07.361779       1 schedule_one.go:826] "Unable to schedule pod; no fit; waiting" pod="openshift-logging/lokistack-sample-ruler-1" err="0/6 nodes are available: 3 Insufficient cpu, 3 node(s) had untolerated taint {node-role.kubernetes.io/master: }. preemption: 0/6 nodes are available: 3 No preemption victims found for incoming pod, 3 Preemption is not helpful for scheduling."
2023-01-09T06:45:07.362382130Z I0109 06:45:07.362349       1 schedule_one.go:826] "Unable to schedule pod; no fit; waiting" pod="openshift-logging/lokistack-sample-ingester-1" err="0/6 nodes are available: 3 Insufficient cpu, 3 node(s) had untolerated taint {node-role.kubernetes.io/master: }. preemption: 0/6 nodes are available: 3 No preemption victims found for incoming pod, 3 Preemption is not helpful for scheduling."
2023-01-09T06:45:17.366793566Z I0109 06:45:17.366746       1 schedule_one.go:826] "Unable to schedule pod; no fit; waiting" pod="openshift-logging/lokistack-sample-ruler-1" err="0/6 nodes are available: 3 Insufficient cpu, 3 node(s) had untolerated taint {node-role.kubernetes.io/master: }. preemption: 0/6 nodes are available: 3 No preemption victims found for incoming pod, 3 Preemption is not helpful for scheduling."
2023-01-09T06:45:17.367393273Z I0109 06:45:17.367359       1 schedule_one.go:826] "Unable to schedule pod; no fit; waiting" pod="openshift-logging/lokistack-sample-ingester-1" err="0/6 nodes are available: 3 Insufficient cpu, 3 node(s) had untolerated taint {node-role.kubernetes.io/master: }. preemption: 0/6 nodes are available: 3 No preemption victims found for incoming pod, 3 Preemption is not helpful for scheduling."
2023-01-09T06:49:50.395803423Z I0109 06:49:50.395710       1 schedule_one.go:266] "Successfully bound pod to node" pod="openshift-marketplace/community-operators-d84fg" node="ip-10-0-145-4.us-east-2.compute.internal" evaluatedNodes=6 feasibleNodes=3
2023-01-09T06:50:13.211043008Z I0109 06:50:13.210998       1 schedule_one.go:826] "Unable to schedule pod; no fit; waiting" pod="openshift-logging/lokistack-sample-ruler-1" err="0/6 nodes are available: 3 Insufficient cpu, 3 node(s) had untolerated taint {node-role.kubernetes.io/master: }. preemption: 0/6 nodes are available: 3 No preemption victims found for incoming pod, 3 Preemption is not helpful for scheduling."
2023-01-09T06:50:13.212186147Z I0109 06:50:13.212132       1 schedule_one.go:826] "Unable to schedule pod; no fit; waiting" pod="openshift-logging/lokistack-sample-ingester-1" err="0/6 nodes are available: 3 Insufficient cpu, 3 node(s) had untolerated taint {node-role.kubernetes.io/master: }. preemption: 0/6 nodes are available: 3 No preemption victims found for incoming pod, 3 Preemption is not helpful for scheduling."
2023-01-09T06:52:43.240429817Z I0109 06:52:43.240380       1 schedule_one.go:266] "Successfully bound pod to node" pod="openshift-marketplace/certified-operators-pdj6h" node="ip-10-0-199-219.us-east-2.compute.internal" evaluatedNodes=6 feasibleNodes=3
2023-01-09T06:52:57.214311460Z I0109 06:52:57.214269       1 schedule_one.go:826] "Unable to schedule pod; no fit; waiting" pod="openshift-logging/lokistack-sample-ruler-1" err="0/6 nodes are available: 3 Insufficient cpu, 3 node(s) had untolerated taint {node-role.kubernetes.io/master: }. preemption: 0/6 nodes are available: 3 No preemption victims found for incoming pod, 3 Preemption is not helpful for scheduling."
2023-01-09T06:52:57.214994116Z I0109 06:52:57.214964       1 schedule_one.go:826] "Unable to schedule pod; no fit; waiting" pod="openshift-logging/lokistack-sample-ingester-1" err="0/6 nodes are available: 3 Insufficient cpu, 3 node(s) had untolerated taint {node-role.kubernetes.io/master: }. preemption: 0/6 nodes are available: 3 No preemption victims found for incoming pod, 3 Preemption is not helpful for scheduling."
2023-01-09T06:53:45.880212463Z I0109 06:53:45.880153       1 schedule_one.go:266] "Successfully bound pod to node" pod="openshift-marketplace/redhat-marketplace-vv2lw" node="ip-10-0-199-219.us-east-2.compute.internal" evaluatedNodes=6 feasibleNodes=3
2023-01-09T06:53:59.408994651Z I0109 06:53:59.408949       1 schedule_one.go:826] "Unable to schedule pod; no fit; waiting" pod="openshift-logging/lokistack-sample-ruler-1" err="0/6 nodes are available: 3 Insufficient cpu, 3 node(s) had untolerated taint {node-role.kubernetes.io/master: }. preemption: 0/6 nodes are available: 3 No preemption victims found for incoming pod, 3 Preemption is not helpful for scheduling."
2023-01-09T06:53:59.409770254Z I0109 06:53:59.409736       1 schedule_one.go:826] "Unable to schedule pod; no fit; waiting" pod="openshift-logging/lokistack-sample-ingester-1" err="0/6 nodes are available: 3 Insufficient cpu, 3 node(s) had untolerated taint {node-role.kubernetes.io/master: }. preemption: 0/6 nodes are available: 3 No preemption victims found for incoming pod, 3 Preemption is not helpful for scheduling."
2023-01-09T06:55:39.096532809Z I0109 06:55:39.096451       1 schedule_one.go:266] "Successfully bound pod to node" pod="openshift-marketplace/qe-app-registry-ljxtk" node="ip-10-0-144-137.us-east-2.compute.internal" evaluatedNodes=6 feasibleNodes=3
2023-01-09T06:55:53.419449403Z I0109 06:55:53.419403       1 schedule_one.go:826] "Unable to schedule pod; no fit; waiting" pod="openshift-logging/lokistack-sample-ruler-1" err="0/6 nodes are available: 3 Insufficient cpu, 3 node(s) had untolerated taint {node-role.kubernetes.io/master: }. preemption: 0/6 nodes are available: 3 No preemption victims found for incoming pod, 3 Preemption is not helpful for scheduling."
2023-01-09T06:55:53.420462559Z I0109 06:55:53.420412       1 schedule_one.go:826] "Unable to schedule pod; no fit; waiting" pod="openshift-logging/lokistack-sample-ingester-1" err="0/6 nodes are available: 3 Insufficient cpu, 3 node(s) had untolerated taint {node-role.kubernetes.io/master: }. preemption: 0/6 nodes are available: 3 No preemption victims found for incoming pod, 3 Preemption is not helpful for scheduling."
2023-01-09T06:56:31.157045928Z I0109 06:56:31.156984       1 schedule_one.go:266] "Successfully bound pod to node" pod="openshift-marketplace/redhat-operators-25ng5" node="ip-10-0-145-4.us-east-2.compute.internal" evaluatedNodes=6 feasibleNodes=3
2023-01-09T06:57:04.342379661Z I0109 06:57:04.342315       1 schedule_one.go:826] "Unable to schedule pod; no fit; waiting" pod="openshift-logging/lokistack-sample-ruler-1" err="0/6 nodes are available: 3 Insufficient cpu, 3 node(s) had untolerated taint {node-role.kubernetes.io/master: }. preemption: 0/6 nodes are available: 3 No preemption victims found for incoming pod, 3 Preemption is not helpful for scheduling."
2023-01-09T06:57:04.342991226Z I0109 06:57:04.342955       1 schedule_one.go:826] "Unable to schedule pod; no fit; waiting" pod="openshift-logging/lokistack-sample-ingester-1" err="0/6 nodes are available: 3 Insufficient cpu, 3 node(s) had untolerated taint {node-role.kubernetes.io/master: }. preemption: 0/6 nodes are available: 3 No preemption victims found for incoming pod, 3 Preemption is not helpful for scheduling."
2023-01-09T07:00:00.185602102Z I0109 07:00:00.185558       1 schedule_one.go:266] "Successfully bound pod to node" pod="openshift-operator-lifecycle-manager/collect-profiles-27887460-rp9qq" node="ip-10-0-144-137.us-east-2.compute.internal" evaluatedNodes=6 feasibleNodes=3
2023-01-09T07:00:04.030460440Z I0109 07:00:04.030421       1 schedule_one.go:826] "Unable to schedule pod; no fit; waiting" pod="openshift-logging/lokistack-sample-ruler-1" err="0/6 nodes are available: 3 Insufficient cpu, 3 node(s) had untolerated taint {node-role.kubernetes.io/master: }. preemption: 0/6 nodes are available: 3 No preemption victims found for incoming pod, 3 Preemption is not helpful for scheduling."
2023-01-09T07:00:04.030990673Z I0109 07:00:04.030946       1 schedule_one.go:826] "Unable to schedule pod; no fit; waiting" pod="openshift-logging/lokistack-sample-ingester-1" err="0/6 nodes are available: 3 Insufficient cpu, 3 node(s) had untolerated taint {node-role.kubernetes.io/master: }. preemption: 0/6 nodes are available: 3 No preemption victims found for incoming pod, 3 Preemption is not helpful for scheduling."
2023-01-09T07:00:50.927715381Z I0109 07:00:50.927677       1 schedule_one.go:266] "Successfully bound pod to node" pod="openshift-marketplace/community-operators-tnd7g" node="ip-10-0-145-4.us-east-2.compute.internal" evaluatedNodes=6 feasibleNodes=3
2023-01-09T07:01:14.049512214Z I0109 07:01:14.049470       1 schedule_one.go:826] "Unable to schedule pod; no fit; waiting" pod="openshift-logging/lokistack-sample-ruler-1" err="0/6 nodes are available: 3 Insufficient cpu, 3 node(s) had untolerated taint {node-role.kubernetes.io/master: }. preemption: 0/6 nodes are available: 3 No preemption victims found for incoming pod, 3 Preemption is not helpful for scheduling."
2023-01-09T07:01:14.050128667Z I0109 07:01:14.050092       1 schedule_one.go:826] "Unable to schedule pod; no fit; waiting" pod="openshift-logging/lokistack-sample-ingester-1" err="0/6 nodes are available: 3 Insufficient cpu, 3 node(s) had untolerated taint {node-role.kubernetes.io/master: }. preemption: 0/6 nodes are available: 3 No preemption victims found for incoming pod, 3 Preemption is not helpful for scheduling."
2023-01-09T07:04:36.446569433Z I0109 07:04:36.446515       1 schedule_one.go:266] "Successfully bound pod to node" pod="openshift-marketplace/redhat-marketplace-f9k6v" node="ip-10-0-199-219.us-east-2.compute.internal" evaluatedNodes=6 feasibleNodes=3
2023-01-09T07:04:36.447320104Z I0109 07:04:36.447271       1 schedule_one.go:266] "Successfully bound pod to node" pod="openshift-marketplace/certified-operators-2n7jq" node="ip-10-0-199-219.us-east-2.compute.internal" evaluatedNodes=6 feasibleNodes=3
2023-01-09T07:04:50.299051746Z I0109 07:04:50.298997       1 schedule_one.go:826] "Unable to schedule pod; no fit; waiting" pod="openshift-logging/lokistack-sample-ruler-1" err="0/6 nodes are available: 3 Insufficient cpu, 3 node(s) had untolerated taint {node-role.kubernetes.io/master: }. preemption: 0/6 nodes are available: 3 No preemption victims found for incoming pod, 3 Preemption is not helpful for scheduling."
2023-01-09T07:04:50.300117065Z I0109 07:04:50.300062       1 schedule_one.go:826] "Unable to schedule pod; no fit; waiting" pod="openshift-logging/lokistack-sample-ingester-1" err="0/6 nodes are available: 3 Insufficient cpu, 3 node(s) had untolerated taint {node-role.kubernetes.io/master: }. preemption: 0/6 nodes are available: 3 No preemption victims found for incoming pod, 3 Preemption is not helpful for scheduling."
2023-01-09T07:05:01.051953332Z I0109 07:05:01.051910       1 schedule_one.go:826] "Unable to schedule pod; no fit; waiting" pod="openshift-logging/lokistack-sample-ruler-1" err="0/6 nodes are available: 3 Insufficient cpu, 3 node(s) had untolerated taint {node-role.kubernetes.io/master: }. preemption: 0/6 nodes are available: 3 No preemption victims found for incoming pod, 3 Preemption is not helpful for scheduling."
2023-01-09T07:05:01.052539356Z I0109 07:05:01.052505       1 schedule_one.go:826] "Unable to schedule pod; no fit; waiting" pod="openshift-logging/lokistack-sample-ingester-1" err="0/6 nodes are available: 3 Insufficient cpu, 3 node(s) had untolerated taint {node-role.kubernetes.io/master: }. preemption: 0/6 nodes are available: 3 No preemption victims found for incoming pod, 3 Preemption is not helpful for scheduling."
2023-01-09T07:05:56.565687591Z I0109 07:05:56.565639       1 schedule_one.go:266] "Successfully bound pod to node" pod="openshift-marketplace/qe-app-registry-2r6nv" node="ip-10-0-144-137.us-east-2.compute.internal" evaluatedNodes=6 feasibleNodes=3
2023-01-09T07:06:10.930066595Z I0109 07:06:10.929977       1 schedule_one.go:826] "Unable to schedule pod; no fit; waiting" pod="openshift-logging/lokistack-sample-ruler-1" err="0/6 nodes are available: 3 Insufficient cpu, 3 node(s) had untolerated taint {node-role.kubernetes.io/master: }. preemption: 0/6 nodes are available: 3 No preemption victims found for incoming pod, 3 Preemption is not helpful for scheduling."
2023-01-09T07:06:10.930745209Z I0109 07:06:10.930707       1 schedule_one.go:826] "Unable to schedule pod; no fit; waiting" pod="openshift-logging/lokistack-sample-ingester-1" err="0/6 nodes are available: 3 Insufficient cpu, 3 node(s) had untolerated taint {node-role.kubernetes.io/master: }. preemption: 0/6 nodes are available: 3 No preemption victims found for incoming pod, 3 Preemption is not helpful for scheduling."
2023-01-09T07:07:17.424733316Z I0109 07:07:17.424689       1 schedule_one.go:266] "Successfully bound pod to node" pod="openshift-marketplace/redhat-operators-4x9kn" node="ip-10-0-145-4.us-east-2.compute.internal" evaluatedNodes=6 feasibleNodes=3
2023-01-09T07:07:50.141135873Z I0109 07:07:50.141088       1 schedule_one.go:826] "Unable to schedule pod; no fit; waiting" pod="openshift-logging/lokistack-sample-ruler-1" err="0/6 nodes are available: 3 Insufficient cpu, 3 node(s) had untolerated taint {node-role.kubernetes.io/master: }. preemption: 0/6 nodes are available: 3 No preemption victims found for incoming pod, 3 Preemption is not helpful for scheduling."
2023-01-09T07:07:50.141747026Z I0109 07:07:50.141684       1 schedule_one.go:826] "Unable to schedule pod; no fit; waiting" pod="openshift-logging/lokistack-sample-ingester-1" err="0/6 nodes are available: 3 Insufficient cpu, 3 node(s) had untolerated taint {node-role.kubernetes.io/master: }. preemption: 0/6 nodes are available: 3 No preemption victims found for incoming pod, 3 Preemption is not helpful for scheduling."
2023-01-09T07:13:04.268786227Z I0109 07:13:04.268729       1 schedule_one.go:826] "Unable to schedule pod; no fit; waiting" pod="openshift-logging/lokistack-sample-ruler-1" err="0/6 nodes are available: 3 Insufficient cpu, 3 node(s) had untolerated taint {node-role.kubernetes.io/master: }. preemption: 0/6 nodes are available: 3 No preemption victims found for incoming pod, 3 Preemption is not helpful for scheduling."
2023-01-09T07:13:04.269970273Z I0109 07:13:04.269920       1 schedule_one.go:826] "Unable to schedule pod; no fit; waiting" pod="openshift-logging/lokistack-sample-ingester-1" err="0/6 nodes are available: 3 Insufficient cpu, 3 node(s) had untolerated taint {node-role.kubernetes.io/master: }. preemption: 0/6 nodes are available: 3 No preemption victims found for incoming pod, 3 Preemption is not helpful for scheduling."
2023-01-09T07:13:41.715564032Z I0109 07:13:41.715518       1 schedule_one.go:266] "Successfully bound pod to node" pod="openshift-marketplace/community-operators-frbmj" node="ip-10-0-145-4.us-east-2.compute.internal" evaluatedNodes=6 feasibleNodes=3
2023-01-09T07:14:04.204676525Z I0109 07:14:04.204628       1 schedule_one.go:826] "Unable to schedule pod; no fit; waiting" pod="openshift-logging/lokistack-sample-ruler-1" err="0/6 nodes are available: 3 Insufficient cpu, 3 node(s) had untolerated taint {node-role.kubernetes.io/master: }. preemption: 0/6 nodes are available: 3 No preemption victims found for incoming pod, 3 Preemption is not helpful for scheduling."
2023-01-09T07:14:04.205327485Z I0109 07:14:04.205291       1 schedule_one.go:826] "Unable to schedule pod; no fit; waiting" pod="openshift-logging/lokistack-sample-ingester-1" err="0/6 nodes are available: 3 Insufficient cpu, 3 node(s) had untolerated taint {node-role.kubernetes.io/master: }. preemption: 0/6 nodes are available: 3 No preemption victims found for incoming pod, 3 Preemption is not helpful for scheduling."
2023-01-09T07:14:37.752457159Z I0109 07:14:37.752406       1 schedule_one.go:266] "Successfully bound pod to node" pod="openshift-marketplace/certified-operators-mxcq9" node="ip-10-0-199-219.us-east-2.compute.internal" evaluatedNodes=6 feasibleNodes=3
2023-01-09T07:14:52.040785722Z I0109 07:14:52.040739       1 schedule_one.go:826] "Unable to schedule pod; no fit; waiting" pod="openshift-logging/lokistack-sample-ruler-1" err="0/6 nodes are available: 3 Insufficient cpu, 3 node(s) had untolerated taint {node-role.kubernetes.io/master: }. preemption: 0/6 nodes are available: 3 No preemption victims found for incoming pod, 3 Preemption is not helpful for scheduling."
2023-01-09T07:14:52.041730537Z I0109 07:14:52.041697       1 schedule_one.go:826] "Unable to schedule pod; no fit; waiting" pod="openshift-logging/lokistack-sample-ingester-1" err="0/6 nodes are available: 3 Insufficient cpu, 3 node(s) had untolerated taint {node-role.kubernetes.io/master: }. preemption: 0/6 nodes are available: 3 No preemption victims found for incoming pod, 3 Preemption is not helpful for scheduling."
2023-01-09T07:15:00.147378524Z I0109 07:15:00.147279       1 schedule_one.go:266] "Successfully bound pod to node" pod="openshift-operator-lifecycle-manager/collect-profiles-27887475-zxrcc" node="ip-10-0-144-137.us-east-2.compute.internal" evaluatedNodes=6 feasibleNodes=3
2023-01-09T07:15:06.036414314Z I0109 07:15:06.036369       1 schedule_one.go:826] "Unable to schedule pod; no fit; waiting" pod="openshift-logging/lokistack-sample-ruler-1" err="0/6 nodes are available: 3 Insufficient cpu, 3 node(s) had untolerated taint {node-role.kubernetes.io/master: }. preemption: 0/6 nodes are available: 3 No preemption victims found for incoming pod, 3 Preemption is not helpful for scheduling."
2023-01-09T07:15:06.036911960Z I0109 07:15:06.036874       1 schedule_one.go:826] "Unable to schedule pod; no fit; waiting" pod="openshift-logging/lokistack-sample-ingester-1" err="0/6 nodes are available: 3 Insufficient cpu, 3 node(s) had untolerated taint {node-role.kubernetes.io/master: }. preemption: 0/6 nodes are available: 3 No preemption victims found for incoming pod, 3 Preemption is not helpful for scheduling."
2023-01-09T07:15:49.211185614Z I0109 07:15:49.211125       1 schedule_one.go:266] "Successfully bound pod to node" pod="openshift-marketplace/redhat-marketplace-z7xrv" node="ip-10-0-199-219.us-east-2.compute.internal" evaluatedNodes=6 feasibleNodes=3
2023-01-09T07:16:03.256630798Z I0109 07:16:03.256577       1 schedule_one.go:826] "Unable to schedule pod; no fit; waiting" pod="openshift-logging/lokistack-sample-ruler-1" err="0/6 nodes are available: 3 Insufficient cpu, 3 node(s) had untolerated taint {node-role.kubernetes.io/master: }. preemption: 0/6 nodes are available: 3 No preemption victims found for incoming pod, 3 Preemption is not helpful for scheduling."
2023-01-09T07:16:03.257829409Z I0109 07:16:03.257792       1 schedule_one.go:826] "Unable to schedule pod; no fit; waiting" pod="openshift-logging/lokistack-sample-ingester-1" err="0/6 nodes are available: 3 Insufficient cpu, 3 node(s) had untolerated taint {node-role.kubernetes.io/master: }. preemption: 0/6 nodes are available: 3 No preemption victims found for incoming pod, 3 Preemption is not helpful for scheduling."
2023-01-09T07:16:12.349718329Z I0109 07:16:12.349671       1 schedule_one.go:266] "Successfully bound pod to node" pod="openshift-marketplace/qe-app-registry-c9qsw" node="ip-10-0-144-137.us-east-2.compute.internal" evaluatedNodes=6 feasibleNodes=3
2023-01-09T07:16:26.494090507Z I0109 07:16:26.494019       1 schedule_one.go:826] "Unable to schedule pod; no fit; waiting" pod="openshift-logging/lokistack-sample-ruler-1" err="0/6 nodes are available: 3 Insufficient cpu, 3 node(s) had untolerated taint {node-role.kubernetes.io/master: }. preemption: 0/6 nodes are available: 3 No preemption victims found for incoming pod, 3 Preemption is not helpful for scheduling."
2023-01-09T07:16:26.494733589Z I0109 07:16:26.494689       1 schedule_one.go:826] "Unable to schedule pod; no fit; waiting" pod="openshift-logging/lokistack-sample-ingester-1" err="0/6 nodes are available: 3 Insufficient cpu, 3 node(s) had untolerated taint {node-role.kubernetes.io/master: }. preemption: 0/6 nodes are available: 3 No preemption victims found for incoming pod, 3 Preemption is not helpful for scheduling."
2023-01-09T07:18:31.226348664Z I0109 07:18:31.226244       1 schedule_one.go:266] "Successfully bound pod to node" pod="openshift-marketplace/redhat-operators-vzwsz" node="ip-10-0-145-4.us-east-2.compute.internal" evaluatedNodes=6 feasibleNodes=3
2023-01-09T07:19:04.064122965Z I0109 07:19:04.063878       1 schedule_one.go:826] "Unable to schedule pod; no fit; waiting" pod="openshift-logging/lokistack-sample-ruler-1" err="0/6 nodes are available: 3 Insufficient cpu, 3 node(s) had untolerated taint {node-role.kubernetes.io/master: }. preemption: 0/6 nodes are available: 3 No preemption victims found for incoming pod, 3 Preemption is not helpful for scheduling."
2023-01-09T07:19:04.064677081Z I0109 07:19:04.064643       1 schedule_one.go:826] "Unable to schedule pod; no fit; waiting" pod="openshift-logging/lokistack-sample-ingester-1" err="0/6 nodes are available: 3 Insufficient cpu, 3 node(s) had untolerated taint {node-role.kubernetes.io/master: }. preemption: 0/6 nodes are available: 3 No preemption victims found for incoming pod, 3 Preemption is not helpful for scheduling."
2023-01-09T07:24:04.280841566Z I0109 07:24:04.280796       1 schedule_one.go:826] "Unable to schedule pod; no fit; waiting" pod="openshift-logging/lokistack-sample-ruler-1" err="0/6 nodes are available: 3 Insufficient cpu, 3 node(s) had untolerated taint {node-role.kubernetes.io/master: }. preemption: 0/6 nodes are available: 3 No preemption victims found for incoming pod, 3 Preemption is not helpful for scheduling."
2023-01-09T07:24:04.281320118Z I0109 07:24:04.281292       1 schedule_one.go:826] "Unable to schedule pod; no fit; waiting" pod="openshift-logging/lokistack-sample-ingester-1" err="0/6 nodes are available: 3 Insufficient cpu, 3 node(s) had untolerated taint {node-role.kubernetes.io/master: }. preemption: 0/6 nodes are available: 3 No preemption victims found for incoming pod, 3 Preemption is not helpful for scheduling."
2023-01-09T07:25:09.994317566Z I0109 07:25:09.994269       1 schedule_one.go:266] "Successfully bound pod to node" pod="openshift-marketplace/community-operators-bp4fn" node="ip-10-0-145-4.us-east-2.compute.internal" evaluatedNodes=6 feasibleNodes=3
2023-01-09T07:25:21.965327686Z I0109 07:25:21.965280       1 schedule_one.go:266] "Successfully bound pod to node" pod="openshift-marketplace/certified-operators-v8ljg" node="ip-10-0-199-219.us-east-2.compute.internal" evaluatedNodes=6 feasibleNodes=3
2023-01-09T07:25:33.173700242Z I0109 07:25:33.173656       1 schedule_one.go:826] "Unable to schedule pod; no fit; waiting" pod="openshift-logging/lokistack-sample-ruler-1" err="0/6 nodes are available: 3 Insufficient cpu, 3 node(s) had untolerated taint {node-role.kubernetes.io/master: }. preemption: 0/6 nodes are available: 3 No preemption victims found for incoming pod, 3 Preemption is not helpful for scheduling."
2023-01-09T07:25:33.174384438Z I0109 07:25:33.174242       1 schedule_one.go:826] "Unable to schedule pod; no fit; waiting" pod="openshift-logging/lokistack-sample-ingester-1" err="0/6 nodes are available: 3 Insufficient cpu, 3 node(s) had untolerated taint {node-role.kubernetes.io/master: }. preemption: 0/6 nodes are available: 3 No preemption victims found for incoming pod, 3 Preemption is not helpful for scheduling."
2023-01-09T07:25:43.802751624Z I0109 07:25:43.802708       1 schedule_one.go:826] "Unable to schedule pod; no fit; waiting" pod="openshift-logging/lokistack-sample-ruler-1" err="0/6 nodes are available: 3 Insufficient cpu, 3 node(s) had untolerated taint {node-role.kubernetes.io/master: }. preemption: 0/6 nodes are available: 3 No preemption victims found for incoming pod, 3 Preemption is not helpful for scheduling."
2023-01-09T07:25:43.803218551Z I0109 07:25:43.803194       1 schedule_one.go:826] "Unable to schedule pod; no fit; waiting" pod="openshift-logging/lokistack-sample-ingester-1" err="0/6 nodes are available: 3 Insufficient cpu, 3 node(s) had untolerated taint {node-role.kubernetes.io/master: }. preemption: 0/6 nodes are available: 3 No preemption victims found for incoming pod, 3 Preemption is not helpful for scheduling."
2023-01-09T07:26:05.973261890Z I0109 07:26:05.973177       1 schedule_one.go:266] "Successfully bound pod to node" pod="openshift-marketplace/redhat-marketplace-bnv8s" node="ip-10-0-199-219.us-east-2.compute.internal" evaluatedNodes=6 feasibleNodes=3
2023-01-09T07:26:20.057177424Z I0109 07:26:20.057133       1 schedule_one.go:826] "Unable to schedule pod; no fit; waiting" pod="openshift-logging/lokistack-sample-ruler-1" err="0/6 nodes are available: 3 Insufficient cpu, 3 node(s) had untolerated taint {node-role.kubernetes.io/master: }. preemption: 0/6 nodes are available: 3 No preemption victims found for incoming pod, 3 Preemption is not helpful for scheduling."
2023-01-09T07:26:20.057806274Z I0109 07:26:20.057767       1 schedule_one.go:826] "Unable to schedule pod; no fit; waiting" pod="openshift-logging/lokistack-sample-ingester-1" err="0/6 nodes are available: 3 Insufficient cpu, 3 node(s) had untolerated taint {node-role.kubernetes.io/master: }. preemption: 0/6 nodes are available: 3 No preemption victims found for incoming pod, 3 Preemption is not helpful for scheduling."
2023-01-09T07:26:56.003456936Z I0109 07:26:56.003393       1 schedule_one.go:266] "Successfully bound pod to node" pod="openshift-marketplace/qe-app-registry-w9pnz" node="ip-10-0-144-137.us-east-2.compute.internal" evaluatedNodes=6 feasibleNodes=3
2023-01-09T07:27:10.052231948Z I0109 07:27:10.052184       1 schedule_one.go:826] "Unable to schedule pod; no fit; waiting" pod="openshift-logging/lokistack-sample-ruler-1" err="0/6 nodes are available: 3 Insufficient cpu, 3 node(s) had untolerated taint {node-role.kubernetes.io/master: }. preemption: 0/6 nodes are available: 3 No preemption victims found for incoming pod, 3 Preemption is not helpful for scheduling."
2023-01-09T07:27:10.052889125Z I0109 07:27:10.052844       1 schedule_one.go:826] "Unable to schedule pod; no fit; waiting" pod="openshift-logging/lokistack-sample-ingester-1" err="0/6 nodes are available: 3 Insufficient cpu, 3 node(s) had untolerated taint {node-role.kubernetes.io/master: }. preemption: 0/6 nodes are available: 3 No preemption victims found for incoming pod, 3 Preemption is not helpful for scheduling."
2023-01-09T07:28:44.530676796Z I0109 07:28:44.530633       1 schedule_one.go:266] "Successfully bound pod to node" pod="openshift-marketplace/redhat-operators-n9wbs" node="ip-10-0-145-4.us-east-2.compute.internal" evaluatedNodes=6 feasibleNodes=3
2023-01-09T07:29:17.804711074Z I0109 07:29:17.804666       1 schedule_one.go:826] "Unable to schedule pod; no fit; waiting" pod="openshift-logging/lokistack-sample-ruler-1" err="0/6 nodes are available: 3 Insufficient cpu, 3 node(s) had untolerated taint {node-role.kubernetes.io/master: }. preemption: 0/6 nodes are available: 3 No preemption victims found for incoming pod, 3 Preemption is not helpful for scheduling."
2023-01-09T07:29:17.805310985Z I0109 07:29:17.805269       1 schedule_one.go:826] "Unable to schedule pod; no fit; waiting" pod="openshift-logging/lokistack-sample-ingester-1" err="0/6 nodes are available: 3 Insufficient cpu, 3 node(s) had untolerated taint {node-role.kubernetes.io/master: }. preemption: 0/6 nodes are available: 3 No preemption victims found for incoming pod, 3 Preemption is not helpful for scheduling."
2023-01-09T07:30:00.144221553Z I0109 07:30:00.144166       1 schedule_one.go:266] "Successfully bound pod to node" pod="openshift-operator-lifecycle-manager/collect-profiles-27887490-nzqwc" node="ip-10-0-144-137.us-east-2.compute.internal" evaluatedNodes=6 feasibleNodes=3
2023-01-09T07:30:05.472997602Z I0109 07:30:05.472949       1 schedule_one.go:826] "Unable to schedule pod; no fit; waiting" pod="openshift-logging/lokistack-sample-ruler-1" err="0/6 nodes are available: 3 Insufficient cpu, 3 node(s) had untolerated taint {node-role.kubernetes.io/master: }. preemption: 0/6 nodes are available: 3 No preemption victims found for incoming pod, 3 Preemption is not helpful for scheduling."
2023-01-09T07:30:05.473577701Z I0109 07:30:05.473548       1 schedule_one.go:826] "Unable to schedule pod; no fit; waiting" pod="openshift-logging/lokistack-sample-ingester-1" err="0/6 nodes are available: 3 Insufficient cpu, 3 node(s) had untolerated taint {node-role.kubernetes.io/master: }. preemption: 0/6 nodes are available: 3 No preemption victims found for incoming pod, 3 Preemption is not helpful for scheduling."
2023-01-09T07:35:34.297248512Z I0109 07:35:34.297207       1 schedule_one.go:826] "Unable to schedule pod; no fit; waiting" pod="openshift-logging/lokistack-sample-ruler-1" err="0/6 nodes are available: 3 Insufficient cpu, 3 node(s) had untolerated taint {node-role.kubernetes.io/master: }. preemption: 0/6 nodes are available: 3 No preemption victims found for incoming pod, 3 Preemption is not helpful for scheduling."
2023-01-09T07:35:34.297773479Z I0109 07:35:34.297737       1 schedule_one.go:826] "Unable to schedule pod; no fit; waiting" pod="openshift-logging/lokistack-sample-ingester-1" err="0/6 nodes are available: 3 Insufficient cpu, 3 node(s) had untolerated taint {node-role.kubernetes.io/master: }. preemption: 0/6 nodes are available: 3 No preemption victims found for incoming pod, 3 Preemption is not helpful for scheduling."
2023-01-09T07:36:04.140856825Z I0109 07:36:04.140806       1 schedule_one.go:266] "Successfully bound pod to node" pod="openshift-marketplace/community-operators-h2z8g" node="ip-10-0-145-4.us-east-2.compute.internal" evaluatedNodes=6 feasibleNodes=3
2023-01-09T07:36:17.087084540Z I0109 07:36:17.087025       1 schedule_one.go:266] "Successfully bound pod to node" pod="openshift-marketplace/certified-operators-rjgfp" node="ip-10-0-199-219.us-east-2.compute.internal" evaluatedNodes=6 feasibleNodes=3
2023-01-09T07:36:27.013282002Z I0109 07:36:27.013229       1 schedule_one.go:826] "Unable to schedule pod; no fit; waiting" pod="openshift-logging/lokistack-sample-ruler-1" err="0/6 nodes are available: 3 Insufficient cpu, 3 node(s) had untolerated taint {node-role.kubernetes.io/master: }. preemption: 0/6 nodes are available: 3 No preemption victims found for incoming pod, 3 Preemption is not helpful for scheduling."
2023-01-09T07:36:27.014283551Z I0109 07:36:27.014225       1 schedule_one.go:826] "Unable to schedule pod; no fit; waiting" pod="openshift-logging/lokistack-sample-ingester-1" err="0/6 nodes are available: 3 Insufficient cpu, 3 node(s) had untolerated taint {node-role.kubernetes.io/master: }. preemption: 0/6 nodes are available: 3 No preemption victims found for incoming pod, 3 Preemption is not helpful for scheduling."
2023-01-09T07:36:36.993204208Z I0109 07:36:36.993158       1 schedule_one.go:266] "Successfully bound pod to node" pod="openshift-marketplace/redhat-marketplace-hs6pr" node="ip-10-0-199-219.us-east-2.compute.internal" evaluatedNodes=6 feasibleNodes=3
2023-01-09T07:36:37.195252932Z I0109 07:36:37.195211       1 schedule_one.go:826] "Unable to schedule pod; no fit; waiting" pod="openshift-logging/lokistack-sample-ruler-1" err="0/6 nodes are available: 3 Insufficient cpu, 3 node(s) had untolerated taint {node-role.kubernetes.io/master: }. preemption: 0/6 nodes are available: 3 No preemption victims found for incoming pod, 3 Preemption is not helpful for scheduling."
2023-01-09T07:36:37.195856839Z I0109 07:36:37.195821       1 schedule_one.go:826] "Unable to schedule pod; no fit; waiting" pod="openshift-logging/lokistack-sample-ingester-1" err="0/6 nodes are available: 3 Insufficient cpu, 3 node(s) had untolerated taint {node-role.kubernetes.io/master: }. preemption: 0/6 nodes are available: 3 No preemption victims found for incoming pod, 3 Preemption is not helpful for scheduling."
2023-01-09T07:36:50.902941219Z I0109 07:36:50.902901       1 schedule_one.go:826] "Unable to schedule pod; no fit; waiting" pod="openshift-logging/lokistack-sample-ruler-1" err="0/6 nodes are available: 3 Insufficient cpu, 3 node(s) had untolerated taint {node-role.kubernetes.io/master: }. preemption: 0/6 nodes are available: 3 No preemption victims found for incoming pod, 3 Preemption is not helpful for scheduling."
2023-01-09T07:36:50.903859061Z I0109 07:36:50.903800       1 schedule_one.go:826] "Unable to schedule pod; no fit; waiting" pod="openshift-logging/lokistack-sample-ingester-1" err="0/6 nodes are available: 3 Insufficient cpu, 3 node(s) had untolerated taint {node-role.kubernetes.io/master: }. preemption: 0/6 nodes are available: 3 No preemption victims found for incoming pod, 3 Preemption is not helpful for scheduling."
2023-01-09T07:37:12.122205800Z I0109 07:37:12.122170       1 schedule_one.go:266] "Successfully bound pod to node" pod="openshift-marketplace/qe-app-registry-xzfb6" node="ip-10-0-144-137.us-east-2.compute.internal" evaluatedNodes=6 feasibleNodes=3
2023-01-09T07:37:25.552952490Z I0109 07:37:25.552907       1 schedule_one.go:826] "Unable to schedule pod; no fit; waiting" pod="openshift-logging/lokistack-sample-ruler-1" err="0/6 nodes are available: 3 Insufficient cpu, 3 node(s) had untolerated taint {node-role.kubernetes.io/master: }. preemption: 0/6 nodes are available: 3 No preemption victims found for incoming pod, 3 Preemption is not helpful for scheduling."
2023-01-09T07:37:25.553488801Z I0109 07:37:25.553450       1 schedule_one.go:826] "Unable to schedule pod; no fit; waiting" pod="openshift-logging/lokistack-sample-ingester-1" err="0/6 nodes are available: 3 Insufficient cpu, 3 node(s) had untolerated taint {node-role.kubernetes.io/master: }. preemption: 0/6 nodes are available: 3 No preemption victims found for incoming pod, 3 Preemption is not helpful for scheduling."
2023-01-09T07:40:38.688197479Z I0109 07:40:38.688079       1 schedule_one.go:266] "Successfully bound pod to node" pod="openshift-marketplace/redhat-operators-njmxw" node="ip-10-0-145-4.us-east-2.compute.internal" evaluatedNodes=6 feasibleNodes=3
2023-01-09T07:41:11.845655463Z I0109 07:41:11.845611       1 schedule_one.go:826] "Unable to schedule pod; no fit; waiting" pod="openshift-logging/lokistack-sample-ruler-1" err="0/6 nodes are available: 3 Insufficient cpu, 3 node(s) had untolerated taint {node-role.kubernetes.io/master: }. preemption: 0/6 nodes are available: 3 No preemption victims found for incoming pod, 3 Preemption is not helpful for scheduling."
2023-01-09T07:41:11.846271806Z I0109 07:41:11.846237       1 schedule_one.go:826] "Unable to schedule pod; no fit; waiting" pod="openshift-logging/lokistack-sample-ingester-1" err="0/6 nodes are available: 3 Insufficient cpu, 3 node(s) had untolerated taint {node-role.kubernetes.io/master: }. preemption: 0/6 nodes are available: 3 No preemption victims found for incoming pod, 3 Preemption is not helpful for scheduling."
2023-01-09T07:45:00.151001820Z I0109 07:45:00.150948       1 schedule_one.go:266] "Successfully bound pod to node" pod="openshift-operator-lifecycle-manager/collect-profiles-27887505-t7vns" node="ip-10-0-144-137.us-east-2.compute.internal" evaluatedNodes=6 feasibleNodes=3
2023-01-09T07:45:06.688738740Z I0109 07:45:06.688702       1 schedule_one.go:826] "Unable to schedule pod; no fit; waiting" pod="openshift-logging/lokistack-sample-ruler-1" err="0/6 nodes are available: 3 Insufficient cpu, 3 node(s) had untolerated taint {node-role.kubernetes.io/master: }. preemption: 0/6 nodes are available: 3 No preemption victims found for incoming pod, 3 Preemption is not helpful for scheduling."
2023-01-09T07:45:06.689307714Z I0109 07:45:06.689277       1 schedule_one.go:826] "Unable to schedule pod; no fit; waiting" pod="openshift-logging/lokistack-sample-ingester-1" err="0/6 nodes are available: 3 Insufficient cpu, 3 node(s) had untolerated taint {node-role.kubernetes.io/master: }. preemption: 0/6 nodes are available: 3 No preemption victims found for incoming pod, 3 Preemption is not helpful for scheduling."
2023-01-09T07:46:26.115827532Z I0109 07:46:26.115780       1 schedule_one.go:266] "Successfully bound pod to node" pod="openshift-marketplace/community-operators-zxspt" node="ip-10-0-145-4.us-east-2.compute.internal" evaluatedNodes=6 feasibleNodes=3
2023-01-09T07:46:41.188957596Z I0109 07:46:41.188910       1 schedule_one.go:266] "Successfully bound pod to node" pod="openshift-marketplace/certified-operators-td6km" node="ip-10-0-199-219.us-east-2.compute.internal" evaluatedNodes=6 feasibleNodes=3
2023-01-09T07:46:48.812801953Z I0109 07:46:48.812727       1 schedule_one.go:826] "Unable to schedule pod; no fit; waiting" pod="openshift-logging/lokistack-sample-ruler-1" err="0/6 nodes are available: 3 Insufficient cpu, 3 node(s) had untolerated taint {node-role.kubernetes.io/master: }. preemption: 0/6 nodes are available: 3 No preemption victims found for incoming pod, 3 Preemption is not helpful for scheduling."
2023-01-09T07:46:48.813363379Z I0109 07:46:48.813301       1 schedule_one.go:826] "Unable to schedule pod; no fit; waiting" pod="openshift-logging/lokistack-sample-ingester-1" err="0/6 nodes are available: 3 Insufficient cpu, 3 node(s) had untolerated taint {node-role.kubernetes.io/master: }. preemption: 0/6 nodes are available: 3 No preemption victims found for incoming pod, 3 Preemption is not helpful for scheduling."
2023-01-09T07:46:53.701032377Z I0109 07:46:53.700983       1 schedule_one.go:266] "Successfully bound pod to node" pod="openshift-marketplace/redhat-marketplace-5qjnk" node="ip-10-0-199-219.us-east-2.compute.internal" evaluatedNodes=6 feasibleNodes=3
2023-01-09T07:46:59.576189599Z I0109 07:46:59.576145       1 schedule_one.go:826] "Unable to schedule pod; no fit; waiting" pod="openshift-logging/lokistack-sample-ruler-1" err="0/6 nodes are available: 3 Insufficient cpu, 3 node(s) had untolerated taint {node-role.kubernetes.io/master: }. preemption: 0/6 nodes are available: 3 No preemption victims found for incoming pod, 3 Preemption is not helpful for scheduling."
2023-01-09T07:46:59.576665192Z I0109 07:46:59.576640       1 schedule_one.go:826] "Unable to schedule pod; no fit; waiting" pod="openshift-logging/lokistack-sample-ingester-1" err="0/6 nodes are available: 3 Insufficient cpu, 3 node(s) had untolerated taint {node-role.kubernetes.io/master: }. preemption: 0/6 nodes are available: 3 No preemption victims found for incoming pod, 3 Preemption is not helpful for scheduling."
2023-01-09T07:47:09.581280050Z I0109 07:47:09.581237       1 schedule_one.go:826] "Unable to schedule pod; no fit; waiting" pod="openshift-logging/lokistack-sample-ruler-1" err="0/6 nodes are available: 3 Insufficient cpu, 3 node(s) had untolerated taint {node-role.kubernetes.io/master: }. preemption: 0/6 nodes are available: 3 No preemption victims found for incoming pod, 3 Preemption is not helpful for scheduling."
2023-01-09T07:47:09.581787224Z I0109 07:47:09.581765       1 schedule_one.go:826] "Unable to schedule pod; no fit; waiting" pod="openshift-logging/lokistack-sample-ingester-1" err="0/6 nodes are available: 3 Insufficient cpu, 3 node(s) had untolerated taint {node-role.kubernetes.io/master: }. preemption: 0/6 nodes are available: 3 No preemption victims found for incoming pod, 3 Preemption is not helpful for scheduling."
2023-01-09T07:48:29.186677722Z I0109 07:48:29.186628       1 schedule_one.go:266] "Successfully bound pod to node" pod="openshift-marketplace/qe-app-registry-4r8bp" node="ip-10-0-144-137.us-east-2.compute.internal" evaluatedNodes=6 feasibleNodes=3
2023-01-09T07:48:43.219604375Z I0109 07:48:43.219541       1 schedule_one.go:826] "Unable to schedule pod; no fit; waiting" pod="openshift-logging/lokistack-sample-ruler-1" err="0/6 nodes are available: 3 Insufficient cpu, 3 node(s) had untolerated taint {node-role.kubernetes.io/master: }. preemption: 0/6 nodes are available: 3 No preemption victims found for incoming pod, 3 Preemption is not helpful for scheduling."
2023-01-09T07:48:43.220302638Z I0109 07:48:43.220269       1 schedule_one.go:826] "Unable to schedule pod; no fit; waiting" pod="openshift-logging/lokistack-sample-ingester-1" err="0/6 nodes are available: 3 Insufficient cpu, 3 node(s) had untolerated taint {node-role.kubernetes.io/master: }. preemption: 0/6 nodes are available: 3 No preemption victims found for incoming pod, 3 Preemption is not helpful for scheduling."
2023-01-09T07:51:04.446469934Z I0109 07:51:04.446419       1 schedule_one.go:266] "Successfully bound pod to node" pod="openshift-marketplace/redhat-operators-rwz69" node="ip-10-0-145-4.us-east-2.compute.internal" evaluatedNodes=6 feasibleNodes=3
2023-01-09T07:51:37.634783973Z I0109 07:51:37.634735       1 schedule_one.go:826] "Unable to schedule pod; no fit; waiting" pod="openshift-logging/lokistack-sample-ruler-1" err="0/6 nodes are available: 3 Insufficient cpu, 3 node(s) had untolerated taint {node-role.kubernetes.io/master: }. preemption: 0/6 nodes are available: 3 No preemption victims found for incoming pod, 3 Preemption is not helpful for scheduling."
2023-01-09T07:51:37.635413891Z I0109 07:51:37.635368       1 schedule_one.go:826] "Unable to schedule pod; no fit; waiting" pod="openshift-logging/lokistack-sample-ingester-1" err="0/6 nodes are available: 3 Insufficient cpu, 3 node(s) had untolerated taint {node-role.kubernetes.io/master: }. preemption: 0/6 nodes are available: 3 No preemption victims found for incoming pod, 3 Preemption is not helpful for scheduling."
2023-01-09T07:57:04.325305286Z I0109 07:57:04.325255       1 schedule_one.go:826] "Unable to schedule pod; no fit; waiting" pod="openshift-logging/lokistack-sample-ruler-1" err="0/6 nodes are available: 3 Insufficient cpu, 3 node(s) had untolerated taint {node-role.kubernetes.io/master: }. preemption: 0/6 nodes are available: 3 No preemption victims found for incoming pod, 3 Preemption is not helpful for scheduling."
2023-01-09T07:57:04.325832589Z I0109 07:57:04.325798       1 schedule_one.go:826] "Unable to schedule pod; no fit; waiting" pod="openshift-logging/lokistack-sample-ingester-1" err="0/6 nodes are available: 3 Insufficient cpu, 3 node(s) had untolerated taint {node-role.kubernetes.io/master: }. preemption: 0/6 nodes are available: 3 No preemption victims found for incoming pod, 3 Preemption is not helpful for scheduling."
2023-01-09T07:57:13.425686311Z I0109 07:57:13.425607       1 schedule_one.go:266] "Successfully bound pod to node" pod="openshift-marketplace/certified-operators-8q5gc" node="ip-10-0-199-219.us-east-2.compute.internal" evaluatedNodes=6 feasibleNodes=3
2023-01-09T07:57:20.467490812Z I0109 07:57:20.467444       1 schedule_one.go:266] "Successfully bound pod to node" pod="openshift-marketplace/community-operators-r6fx7" node="ip-10-0-145-4.us-east-2.compute.internal" evaluatedNodes=6 feasibleNodes=3
2023-01-09T07:57:27.612370526Z I0109 07:57:27.612293       1 schedule_one.go:826] "Unable to schedule pod; no fit; waiting" pod="openshift-logging/lokistack-sample-ruler-1" err="0/6 nodes are available: 3 Insufficient cpu, 3 node(s) had untolerated taint {node-role.kubernetes.io/master: }. preemption: 0/6 nodes are available: 3 No preemption victims found for incoming pod, 3 Preemption is not helpful for scheduling."
2023-01-09T07:57:27.613038908Z I0109 07:57:27.613001       1 schedule_one.go:826] "Unable to schedule pod; no fit; waiting" pod="openshift-logging/lokistack-sample-ingester-1" err="0/6 nodes are available: 3 Insufficient cpu, 3 node(s) had untolerated taint {node-role.kubernetes.io/master: }. preemption: 0/6 nodes are available: 3 No preemption victims found for incoming pod, 3 Preemption is not helpful for scheduling."
2023-01-09T07:57:29.413748693Z I0109 07:57:29.413696       1 schedule_one.go:266] "Successfully bound pod to node" pod="openshift-marketplace/redhat-marketplace-2sg6v" node="ip-10-0-199-219.us-east-2.compute.internal" evaluatedNodes=6 feasibleNodes=3
2023-01-09T07:57:43.677987959Z I0109 07:57:43.677930       1 schedule_one.go:826] "Unable to schedule pod; no fit; waiting" pod="openshift-logging/lokistack-sample-ruler-1" err="0/6 nodes are available: 3 Insufficient cpu, 3 node(s) had untolerated taint {node-role.kubernetes.io/master: }. preemption: 0/6 nodes are available: 3 No preemption victims found for incoming pod, 3 Preemption is not helpful for scheduling."
2023-01-09T07:57:43.679242448Z I0109 07:57:43.679207       1 schedule_one.go:826] "Unable to schedule pod; no fit; waiting" pod="openshift-logging/lokistack-sample-ingester-1" err="0/6 nodes are available: 3 Insufficient cpu, 3 node(s) had untolerated taint {node-role.kubernetes.io/master: }. preemption: 0/6 nodes are available: 3 No preemption victims found for incoming pod, 3 Preemption is not helpful for scheduling."
2023-01-09T07:57:53.982875949Z I0109 07:57:53.982832       1 schedule_one.go:826] "Unable to schedule pod; no fit; waiting" pod="openshift-logging/lokistack-sample-ruler-1" err="0/6 nodes are available: 3 Insufficient cpu, 3 node(s) had untolerated taint {node-role.kubernetes.io/master: }. preemption: 0/6 nodes are available: 3 No preemption victims found for incoming pod, 3 Preemption is not helpful for scheduling."
2023-01-09T07:57:53.983397398Z I0109 07:57:53.983367       1 schedule_one.go:826] "Unable to schedule pod; no fit; waiting" pod="openshift-logging/lokistack-sample-ingester-1" err="0/6 nodes are available: 3 Insufficient cpu, 3 node(s) had untolerated taint {node-role.kubernetes.io/master: }. preemption: 0/6 nodes are available: 3 No preemption victims found for incoming pod, 3 Preemption is not helpful for scheduling."
2023-01-09T07:58:53.398145195Z I0109 07:58:53.398090       1 schedule_one.go:266] "Successfully bound pod to node" pod="openshift-marketplace/qe-app-registry-298rk" node="ip-10-0-144-137.us-east-2.compute.internal" evaluatedNodes=6 feasibleNodes=3
2023-01-09T07:59:07.691654647Z I0109 07:59:07.691597       1 schedule_one.go:826] "Unable to schedule pod; no fit; waiting" pod="openshift-logging/lokistack-sample-ruler-1" err="0/6 nodes are available: 3 Insufficient cpu, 3 node(s) had untolerated taint {node-role.kubernetes.io/master: }. preemption: 0/6 nodes are available: 3 No preemption victims found for incoming pod, 3 Preemption is not helpful for scheduling."
2023-01-09T07:59:07.692253633Z I0109 07:59:07.692218       1 schedule_one.go:826] "Unable to schedule pod; no fit; waiting" pod="openshift-logging/lokistack-sample-ingester-1" err="0/6 nodes are available: 3 Insufficient cpu, 3 node(s) had untolerated taint {node-role.kubernetes.io/master: }. preemption: 0/6 nodes are available: 3 No preemption victims found for incoming pod, 3 Preemption is not helpful for scheduling."
2023-01-09T08:00:00.185911259Z I0109 08:00:00.185871       1 schedule_one.go:266] "Successfully bound pod to node" pod="openshift-operator-lifecycle-manager/collect-profiles-27887520-2krdl" node="ip-10-0-144-137.us-east-2.compute.internal" evaluatedNodes=6 feasibleNodes=3
2023-01-09T08:00:05.831568228Z I0109 08:00:05.831523       1 schedule_one.go:826] "Unable to schedule pod; no fit; waiting" pod="openshift-logging/lokistack-sample-ruler-1" err="0/6 nodes are available: 3 Insufficient cpu, 3 node(s) had untolerated taint {node-role.kubernetes.io/master: }. preemption: 0/6 nodes are available: 3 No preemption victims found for incoming pod, 3 Preemption is not helpful for scheduling."
2023-01-09T08:00:05.832865934Z I0109 08:00:05.832833       1 schedule_one.go:826] "Unable to schedule pod; no fit; waiting" pod="openshift-logging/lokistack-sample-ingester-1" err="0/6 nodes are available: 3 Insufficient cpu, 3 node(s) had untolerated taint {node-role.kubernetes.io/master: }. preemption: 0/6 nodes are available: 3 No preemption victims found for incoming pod, 3 Preemption is not helpful for scheduling."
2023-01-09T08:01:48.901060372Z I0109 08:01:48.901014       1 schedule_one.go:266] "Successfully bound pod to node" pod="openshift-marketplace/redhat-operators-gnd7q" node="ip-10-0-145-4.us-east-2.compute.internal" evaluatedNodes=6 feasibleNodes=3
2023-01-09T08:02:21.439637136Z I0109 08:02:21.439584       1 schedule_one.go:826] "Unable to schedule pod; no fit; waiting" pod="openshift-logging/lokistack-sample-ruler-1" err="0/6 nodes are available: 3 Insufficient cpu, 3 node(s) had untolerated taint {node-role.kubernetes.io/master: }. preemption: 0/6 nodes are available: 3 No preemption victims found for incoming pod, 3 Preemption is not helpful for scheduling."
2023-01-09T08:02:21.440439042Z I0109 08:02:21.440394       1 schedule_one.go:826] "Unable to schedule pod; no fit; waiting" pod="openshift-logging/lokistack-sample-ingester-1" err="0/6 nodes are available: 3 Insufficient cpu, 3 node(s) had untolerated taint {node-role.kubernetes.io/master: }. preemption: 0/6 nodes are available: 3 No preemption victims found for incoming pod, 3 Preemption is not helpful for scheduling."
2023-01-09T08:07:17.940976346Z I0109 08:07:17.940931       1 schedule_one.go:266] "Successfully bound pod to node" pod="openshift-marketplace/certified-operators-4mh6g" node="ip-10-0-199-219.us-east-2.compute.internal" evaluatedNodes=6 feasibleNodes=3
2023-01-09T08:07:32.376871701Z I0109 08:07:32.376822       1 schedule_one.go:826] "Unable to schedule pod; no fit; waiting" pod="openshift-logging/lokistack-sample-ruler-1" err="0/6 nodes are available: 3 Insufficient cpu, 3 node(s) had untolerated taint {node-role.kubernetes.io/master: }. preemption: 0/6 nodes are available: 3 No preemption victims found for incoming pod, 3 Preemption is not helpful for scheduling."
2023-01-09T08:07:32.377555404Z I0109 08:07:32.377521       1 schedule_one.go:826] "Unable to schedule pod; no fit; waiting" pod="openshift-logging/lokistack-sample-ingester-1" err="0/6 nodes are available: 3 Insufficient cpu, 3 node(s) had untolerated taint {node-role.kubernetes.io/master: }. preemption: 0/6 nodes are available: 3 No preemption victims found for incoming pod, 3 Preemption is not helpful for scheduling."
2023-01-09T08:07:42.381447404Z I0109 08:07:42.381396       1 schedule_one.go:266] "Successfully bound pod to node" pod="openshift-marketplace/redhat-marketplace-66nl6" node="ip-10-0-199-219.us-east-2.compute.internal" evaluatedNodes=6 feasibleNodes=3
2023-01-09T08:07:52.425408151Z I0109 08:07:52.425310       1 schedule_one.go:266] "Successfully bound pod to node" pod="openshift-marketplace/community-operators-qxmm9" node="ip-10-0-145-4.us-east-2.compute.internal" evaluatedNodes=6 feasibleNodes=3
2023-01-09T08:07:56.452949980Z I0109 08:07:56.452908       1 schedule_one.go:826] "Unable to schedule pod; no fit; waiting" pod="openshift-logging/lokistack-sample-ruler-1" err="0/6 nodes are available: 3 Insufficient cpu, 3 node(s) had untolerated taint {node-role.kubernetes.io/master: }. preemption: 0/6 nodes are available: 3 No preemption victims found for incoming pod, 3 Preemption is not helpful for scheduling."
2023-01-09T08:07:56.453763757Z I0109 08:07:56.453725       1 schedule_one.go:826] "Unable to schedule pod; no fit; waiting" pod="openshift-logging/lokistack-sample-ingester-1" err="0/6 nodes are available: 3 Insufficient cpu, 3 node(s) had untolerated taint {node-role.kubernetes.io/master: }. preemption: 0/6 nodes are available: 3 No preemption victims found for incoming pod, 3 Preemption is not helpful for scheduling."
2023-01-09T08:08:15.452275065Z I0109 08:08:15.452216       1 schedule_one.go:826] "Unable to schedule pod; no fit; waiting" pod="openshift-logging/lokistack-sample-ruler-1" err="0/6 nodes are available: 3 Insufficient cpu, 3 node(s) had untolerated taint {node-role.kubernetes.io/master: }. preemption: 0/6 nodes are available: 3 No preemption victims found for incoming pod, 3 Preemption is not helpful for scheduling."
2023-01-09T08:08:15.453146466Z I0109 08:08:15.453110       1 schedule_one.go:826] "Unable to schedule pod; no fit; waiting" pod="openshift-logging/lokistack-sample-ingester-1" err="0/6 nodes are available: 3 Insufficient cpu, 3 node(s) had untolerated taint {node-role.kubernetes.io/master: }. preemption: 0/6 nodes are available: 3 No preemption victims found for incoming pod, 3 Preemption is not helpful for scheduling."
2023-01-09T08:09:05.612040780Z I0109 08:09:05.612002       1 schedule_one.go:266] "Successfully bound pod to node" pod="openshift-marketplace/qe-app-registry-zqfth" node="ip-10-0-144-137.us-east-2.compute.internal" evaluatedNodes=6 feasibleNodes=3
2023-01-09T08:09:19.148919305Z I0109 08:09:19.148859       1 schedule_one.go:826] "Unable to schedule pod; no fit; waiting" pod="openshift-logging/lokistack-sample-ruler-1" err="0/6 nodes are available: 3 Insufficient cpu, 3 node(s) had untolerated taint {node-role.kubernetes.io/master: }. preemption: 0/6 nodes are available: 3 No preemption victims found for incoming pod, 3 Preemption is not helpful for scheduling."
2023-01-09T08:09:19.149645933Z I0109 08:09:19.149593       1 schedule_one.go:826] "Unable to schedule pod; no fit; waiting" pod="openshift-logging/lokistack-sample-ingester-1" err="0/6 nodes are available: 3 Insufficient cpu, 3 node(s) had untolerated taint {node-role.kubernetes.io/master: }. preemption: 0/6 nodes are available: 3 No preemption victims found for incoming pod, 3 Preemption is not helpful for scheduling."
2023-01-09T08:11:51.622256161Z I0109 08:11:51.622211       1 schedule_one.go:266] "Successfully bound pod to node" pod="openshift-marketplace/redhat-operators-sljjk" node="ip-10-0-145-4.us-east-2.compute.internal" evaluatedNodes=6 feasibleNodes=3
2023-01-09T08:12:24.138989088Z I0109 08:12:24.138942       1 schedule_one.go:826] "Unable to schedule pod; no fit; waiting" pod="openshift-logging/lokistack-sample-ruler-1" err="0/6 nodes are available: 3 Insufficient cpu, 3 node(s) had untolerated taint {node-role.kubernetes.io/master: }. preemption: 0/6 nodes are available: 3 No preemption victims found for incoming pod, 3 Preemption is not helpful for scheduling."
2023-01-09T08:12:24.139624120Z I0109 08:12:24.139590       1 schedule_one.go:826] "Unable to schedule pod; no fit; waiting" pod="openshift-logging/lokistack-sample-ingester-1" err="0/6 nodes are available: 3 Insufficient cpu, 3 node(s) had untolerated taint {node-role.kubernetes.io/master: }. preemption: 0/6 nodes are available: 3 No preemption victims found for incoming pod, 3 Preemption is not helpful for scheduling."
2023-01-09T08:15:00.158966498Z I0109 08:15:00.158930       1 schedule_one.go:266] "Successfully bound pod to node" pod="openshift-operator-lifecycle-manager/collect-profiles-27887535-dh5s7" node="ip-10-0-144-137.us-east-2.compute.internal" evaluatedNodes=6 feasibleNodes=3
2023-01-09T08:15:04.988278821Z I0109 08:15:04.988237       1 schedule_one.go:826] "Unable to schedule pod; no fit; waiting" pod="openshift-logging/lokistack-sample-ruler-1" err="0/6 nodes are available: 3 Insufficient cpu, 3 node(s) had untolerated taint {node-role.kubernetes.io/master: }. preemption: 0/6 nodes are available: 3 No preemption victims found for incoming pod, 3 Preemption is not helpful for scheduling."
2023-01-09T08:15:04.988801007Z I0109 08:15:04.988775       1 schedule_one.go:826] "Unable to schedule pod; no fit; waiting" pod="openshift-logging/lokistack-sample-ingester-1" err="0/6 nodes are available: 3 Insufficient cpu, 3 node(s) had untolerated taint {node-role.kubernetes.io/master: }. preemption: 0/6 nodes are available: 3 No preemption victims found for incoming pod, 3 Preemption is not helpful for scheduling."
2023-01-09T08:17:44.331056395Z I0109 08:17:44.330996       1 schedule_one.go:266] "Successfully bound pod to node" pod="openshift-marketplace/redhat-marketplace-lhs56" node="ip-10-0-199-219.us-east-2.compute.internal" evaluatedNodes=6 feasibleNodes=3
2023-01-09T08:17:44.339782854Z I0109 08:17:44.339735       1 schedule_one.go:266] "Successfully bound pod to node" pod="openshift-marketplace/certified-operators-ch2n7" node="ip-10-0-199-219.us-east-2.compute.internal" evaluatedNodes=6 feasibleNodes=3
2023-01-09T08:17:58.217083968Z I0109 08:17:58.217025       1 schedule_one.go:826] "Unable to schedule pod; no fit; waiting" pod="openshift-logging/lokistack-sample-ruler-1" err="0/6 nodes are available: 3 Insufficient cpu, 3 node(s) had untolerated taint {node-role.kubernetes.io/master: }. preemption: 0/6 nodes are available: 3 No preemption victims found for incoming pod, 3 Preemption is not helpful for scheduling."
2023-01-09T08:17:58.218252317Z I0109 08:17:58.218222       1 schedule_one.go:826] "Unable to schedule pod; no fit; waiting" pod="openshift-logging/lokistack-sample-ingester-1" err="0/6 nodes are available: 3 Insufficient cpu, 3 node(s) had untolerated taint {node-role.kubernetes.io/master: }. preemption: 0/6 nodes are available: 3 No preemption victims found for incoming pod, 3 Preemption is not helpful for scheduling."
2023-01-09T08:18:08.675031615Z I0109 08:18:08.674984       1 schedule_one.go:826] "Unable to schedule pod; no fit; waiting" pod="openshift-logging/lokistack-sample-ruler-1" err="0/6 nodes are available: 3 Insufficient cpu, 3 node(s) had untolerated taint {node-role.kubernetes.io/master: }. preemption: 0/6 nodes are available: 3 No preemption victims found for incoming pod, 3 Preemption is not helpful for scheduling."
2023-01-09T08:18:08.675570576Z I0109 08:18:08.675526       1 schedule_one.go:826] "Unable to schedule pod; no fit; waiting" pod="openshift-logging/lokistack-sample-ingester-1" err="0/6 nodes are available: 3 Insufficient cpu, 3 node(s) had untolerated taint {node-role.kubernetes.io/master: }. preemption: 0/6 nodes are available: 3 No preemption victims found for incoming pod, 3 Preemption is not helpful for scheduling."
2023-01-09T08:18:40.127877049Z I0109 08:18:40.127831       1 schedule_one.go:266] "Successfully bound pod to node" pod="openshift-marketplace/community-operators-428nv" node="ip-10-0-145-4.us-east-2.compute.internal" evaluatedNodes=6 feasibleNodes=3
2023-01-09T08:19:03.254607627Z I0109 08:19:03.254493       1 schedule_one.go:826] "Unable to schedule pod; no fit; waiting" pod="openshift-logging/lokistack-sample-ruler-1" err="0/6 nodes are available: 3 Insufficient cpu, 3 node(s) had untolerated taint {node-role.kubernetes.io/master: }. preemption: 0/6 nodes are available: 3 No preemption victims found for incoming pod, 3 Preemption is not helpful for scheduling."
2023-01-09T08:19:03.255756273Z I0109 08:19:03.255716       1 schedule_one.go:826] "Unable to schedule pod; no fit; waiting" pod="openshift-logging/lokistack-sample-ingester-1" err="0/6 nodes are available: 3 Insufficient cpu, 3 node(s) had untolerated taint {node-role.kubernetes.io/master: }. preemption: 0/6 nodes are available: 3 No preemption victims found for incoming pod, 3 Preemption is not helpful for scheduling."
2023-01-09T08:19:53.471384665Z I0109 08:19:53.471326       1 schedule_one.go:266] "Successfully bound pod to node" pod="openshift-marketplace/qe-app-registry-wsnwv" node="ip-10-0-144-137.us-east-2.compute.internal" evaluatedNodes=6 feasibleNodes=3
2023-01-09T08:20:07.830177496Z I0109 08:20:07.830127       1 schedule_one.go:826] "Unable to schedule pod; no fit; waiting" pod="openshift-logging/lokistack-sample-ruler-1" err="0/6 nodes are available: 3 Insufficient cpu, 3 node(s) had untolerated taint {node-role.kubernetes.io/master: }. preemption: 0/6 nodes are available: 3 No preemption victims found for incoming pod, 3 Preemption is not helpful for scheduling."
2023-01-09T08:20:07.831064433Z I0109 08:20:07.831032       1 schedule_one.go:826] "Unable to schedule pod; no fit; waiting" pod="openshift-logging/lokistack-sample-ingester-1" err="0/6 nodes are available: 3 Insufficient cpu, 3 node(s) had untolerated taint {node-role.kubernetes.io/master: }. preemption: 0/6 nodes are available: 3 No preemption victims found for incoming pod, 3 Preemption is not helpful for scheduling."
2023-01-09T08:22:51.845799912Z I0109 08:22:51.845739       1 schedule_one.go:266] "Successfully bound pod to node" pod="openshift-marketplace/redhat-operators-cxz9l" node="ip-10-0-145-4.us-east-2.compute.internal" evaluatedNodes=6 feasibleNodes=3
2023-01-09T08:23:25.012802353Z I0109 08:23:25.012734       1 schedule_one.go:826] "Unable to schedule pod; no fit; waiting" pod="openshift-logging/lokistack-sample-ruler-1" err="0/6 nodes are available: 3 Insufficient cpu, 3 node(s) had untolerated taint {node-role.kubernetes.io/master: }. preemption: 0/6 nodes are available: 3 No preemption victims found for incoming pod, 3 Preemption is not helpful for scheduling."
2023-01-09T08:23:25.013379035Z I0109 08:23:25.013345       1 schedule_one.go:826] "Unable to schedule pod; no fit; waiting" pod="openshift-logging/lokistack-sample-ingester-1" err="0/6 nodes are available: 3 Insufficient cpu, 3 node(s) had untolerated taint {node-role.kubernetes.io/master: }. preemption: 0/6 nodes are available: 3 No preemption victims found for incoming pod, 3 Preemption is not helpful for scheduling."
2023-01-09T08:27:56.824452468Z I0109 08:27:56.824392       1 schedule_one.go:266] "Successfully bound pod to node" pod="openshift-marketplace/certified-operators-phsxf" node="ip-10-0-199-219.us-east-2.compute.internal" evaluatedNodes=6 feasibleNodes=3
2023-01-09T08:28:11.021002663Z I0109 08:28:11.020955       1 schedule_one.go:826] "Unable to schedule pod; no fit; waiting" pod="openshift-logging/lokistack-sample-ruler-1" err="0/6 nodes are available: 3 Insufficient cpu, 3 node(s) had untolerated taint {node-role.kubernetes.io/master: }. preemption: 0/6 nodes are available: 3 No preemption victims found for incoming pod, 3 Preemption is not helpful for scheduling."
2023-01-09T08:28:11.021733926Z I0109 08:28:11.021697       1 schedule_one.go:826] "Unable to schedule pod; no fit; waiting" pod="openshift-logging/lokistack-sample-ingester-1" err="0/6 nodes are available: 3 Insufficient cpu, 3 node(s) had untolerated taint {node-role.kubernetes.io/master: }. preemption: 0/6 nodes are available: 3 No preemption victims found for incoming pod, 3 Preemption is not helpful for scheduling."
2023-01-09T08:28:40.342699808Z I0109 08:28:40.342638       1 schedule_one.go:266] "Successfully bound pod to node" pod="openshift-marketplace/community-operators-vkjrm" node="ip-10-0-145-4.us-east-2.compute.internal" evaluatedNodes=6 feasibleNodes=3
2023-01-09T08:29:03.982894929Z I0109 08:29:03.982850       1 schedule_one.go:826] "Unable to schedule pod; no fit; waiting" pod="openshift-logging/lokistack-sample-ruler-1" err="0/6 nodes are available: 3 Insufficient cpu, 3 node(s) had untolerated taint {node-role.kubernetes.io/master: }. preemption: 0/6 nodes are available: 3 No preemption victims found for incoming pod, 3 Preemption is not helpful for scheduling."
2023-01-09T08:29:03.983569774Z I0109 08:29:03.983515       1 schedule_one.go:826] "Unable to schedule pod; no fit; waiting" pod="openshift-logging/lokistack-sample-ingester-1" err="0/6 nodes are available: 3 Insufficient cpu, 3 node(s) had untolerated taint {node-role.kubernetes.io/master: }. preemption: 0/6 nodes are available: 3 No preemption victims found for incoming pod, 3 Preemption is not helpful for scheduling."
2023-01-09T08:30:00.145558459Z I0109 08:30:00.145522       1 schedule_one.go:266] "Successfully bound pod to node" pod="openshift-operator-lifecycle-manager/collect-profiles-27887550-7bn2w" node="ip-10-0-144-137.us-east-2.compute.internal" evaluatedNodes=6 feasibleNodes=3
2023-01-09T08:30:06.037491320Z I0109 08:30:06.037446       1 schedule_one.go:826] "Unable to schedule pod; no fit; waiting" pod="openshift-logging/lokistack-sample-ruler-1" err="0/6 nodes are available: 3 Insufficient cpu, 3 node(s) had untolerated taint {node-role.kubernetes.io/master: }. preemption: 0/6 nodes are available: 3 No preemption victims found for incoming pod, 3 Preemption is not helpful for scheduling."
2023-01-09T08:30:06.038047036Z I0109 08:30:06.038017       1 schedule_one.go:826] "Unable to schedule pod; no fit; waiting" pod="openshift-logging/lokistack-sample-ingester-1" err="0/6 nodes are available: 3 Insufficient cpu, 3 node(s) had untolerated taint {node-role.kubernetes.io/master: }. preemption: 0/6 nodes are available: 3 No preemption victims found for incoming pod, 3 Preemption is not helpful for scheduling."
2023-01-09T08:31:50.108018926Z I0109 08:31:50.107969       1 schedule_one.go:266] "Successfully bound pod to node" pod="openshift-marketplace/redhat-marketplace-7v8v2" node="ip-10-0-199-219.us-east-2.compute.internal" evaluatedNodes=6 feasibleNodes=3
2023-01-09T08:31:50.132057447Z I0109 08:31:50.131216       1 schedule_one.go:266] "Successfully bound pod to node" pod="openshift-marketplace/qe-app-registry-vpwft" node="ip-10-0-144-137.us-east-2.compute.internal" evaluatedNodes=6 feasibleNodes=3
2023-01-09T08:32:03.702279484Z I0109 08:32:03.702231       1 schedule_one.go:826] "Unable to schedule pod; no fit; waiting" pod="openshift-logging/lokistack-sample-ruler-1" err="0/6 nodes are available: 3 Insufficient cpu, 3 node(s) had untolerated taint {node-role.kubernetes.io/master: }. preemption: 0/6 nodes are available: 3 No preemption victims found for incoming pod, 3 Preemption is not helpful for scheduling."
2023-01-09T08:32:03.703693271Z I0109 08:32:03.703641       1 schedule_one.go:826] "Unable to schedule pod; no fit; waiting" pod="openshift-logging/lokistack-sample-ingester-1" err="0/6 nodes are available: 3 Insufficient cpu, 3 node(s) had untolerated taint {node-role.kubernetes.io/master: }. preemption: 0/6 nodes are available: 3 No preemption victims found for incoming pod, 3 Preemption is not helpful for scheduling."
2023-01-09T08:32:14.200627180Z I0109 08:32:14.200581       1 schedule_one.go:826] "Unable to schedule pod; no fit; waiting" pod="openshift-logging/lokistack-sample-ruler-1" err="0/6 nodes are available: 3 Insufficient cpu, 3 node(s) had untolerated taint {node-role.kubernetes.io/master: }. preemption: 0/6 nodes are available: 3 No preemption victims found for incoming pod, 3 Preemption is not helpful for scheduling."
2023-01-09T08:32:14.201125750Z I0109 08:32:14.201102       1 schedule_one.go:826] "Unable to schedule pod; no fit; waiting" pod="openshift-logging/lokistack-sample-ingester-1" err="0/6 nodes are available: 3 Insufficient cpu, 3 node(s) had untolerated taint {node-role.kubernetes.io/master: }. preemption: 0/6 nodes are available: 3 No preemption victims found for incoming pod, 3 Preemption is not helpful for scheduling."
2023-01-09T08:34:38.295311841Z I0109 08:34:38.295258       1 schedule_one.go:266] "Successfully bound pod to node" pod="openshift-marketplace/redhat-operators-fv4f2" node="ip-10-0-145-4.us-east-2.compute.internal" evaluatedNodes=6 feasibleNodes=3
2023-01-09T08:35:11.022937820Z I0109 08:35:11.022863       1 schedule_one.go:826] "Unable to schedule pod; no fit; waiting" pod="openshift-logging/lokistack-sample-ruler-1" err="0/6 nodes are available: 3 Insufficient cpu, 3 node(s) had untolerated taint {node-role.kubernetes.io/master: }. preemption: 0/6 nodes are available: 3 No preemption victims found for incoming pod, 3 Preemption is not helpful for scheduling."
2023-01-09T08:35:11.023939640Z I0109 08:35:11.023908       1 schedule_one.go:826] "Unable to schedule pod; no fit; waiting" pod="openshift-logging/lokistack-sample-ingester-1" err="0/6 nodes are available: 3 Insufficient cpu, 3 node(s) had untolerated taint {node-role.kubernetes.io/master: }. preemption: 0/6 nodes are available: 3 No preemption victims found for incoming pod, 3 Preemption is not helpful for scheduling."
2023-01-09T08:40:34.385117631Z I0109 08:40:34.385075       1 schedule_one.go:826] "Unable to schedule pod; no fit; waiting" pod="openshift-logging/lokistack-sample-ruler-1" err="0/6 nodes are available: 3 Insufficient cpu, 3 node(s) had untolerated taint {node-role.kubernetes.io/master: }. preemption: 0/6 nodes are available: 3 No preemption victims found for incoming pod, 3 Preemption is not helpful for scheduling."
2023-01-09T08:40:34.385651945Z I0109 08:40:34.385623       1 schedule_one.go:826] "Unable to schedule pod; no fit; waiting" pod="openshift-logging/lokistack-sample-ingester-1" err="0/6 nodes are available: 3 Insufficient cpu, 3 node(s) had untolerated taint {node-role.kubernetes.io/master: }. preemption: 0/6 nodes are available: 3 No preemption victims found for incoming pod, 3 Preemption is not helpful for scheduling."
2023-01-09T08:41:52.086679654Z I0109 08:41:52.086631       1 schedule_one.go:266] "Successfully bound pod to node" pod="openshift-marketplace/redhat-marketplace-p689q" node="ip-10-0-199-219.us-east-2.compute.internal" evaluatedNodes=6 feasibleNodes=3
2023-01-09T08:41:58.492133091Z I0109 08:41:58.492093       1 schedule_one.go:266] "Successfully bound pod to node" pod="openshift-marketplace/qe-app-registry-czzgh" node="ip-10-0-144-137.us-east-2.compute.internal" evaluatedNodes=6 feasibleNodes=3
2023-01-09T08:42:06.465726108Z I0109 08:42:06.465637       1 schedule_one.go:826] "Unable to schedule pod; no fit; waiting" pod="openshift-logging/lokistack-sample-ruler-1" err="0/6 nodes are available: 3 Insufficient cpu, 3 node(s) had untolerated taint {node-role.kubernetes.io/master: }. preemption: 0/6 nodes are available: 3 No preemption victims found for incoming pod, 3 Preemption is not helpful for scheduling."
2023-01-09T08:42:06.466965136Z I0109 08:42:06.466929       1 schedule_one.go:826] "Unable to schedule pod; no fit; waiting" pod="openshift-logging/lokistack-sample-ingester-1" err="0/6 nodes are available: 3 Insufficient cpu, 3 node(s) had untolerated taint {node-role.kubernetes.io/master: }. preemption: 0/6 nodes are available: 3 No preemption victims found for incoming pod, 3 Preemption is not helpful for scheduling."
2023-01-09T08:42:16.565898216Z I0109 08:42:16.565843       1 schedule_one.go:826] "Unable to schedule pod; no fit; waiting" pod="openshift-logging/lokistack-sample-ruler-1" err="0/6 nodes are available: 3 Insufficient cpu, 3 node(s) had untolerated taint {node-role.kubernetes.io/master: }. preemption: 0/6 nodes are available: 3 No preemption victims found for incoming pod, 3 Preemption is not helpful for scheduling."
2023-01-09T08:42:16.566770976Z I0109 08:42:16.566729       1 schedule_one.go:826] "Unable to schedule pod; no fit; waiting" pod="openshift-logging/lokistack-sample-ingester-1" err="0/6 nodes are available: 3 Insufficient cpu, 3 node(s) had untolerated taint {node-role.kubernetes.io/master: }. preemption: 0/6 nodes are available: 3 No preemption victims found for incoming pod, 3 Preemption is not helpful for scheduling."
2023-01-09T08:45:00.166568373Z I0109 08:45:00.166533       1 schedule_one.go:266] "Successfully bound pod to node" pod="openshift-operator-lifecycle-manager/collect-profiles-27887565-m2xxp" node="ip-10-0-144-137.us-east-2.compute.internal" evaluatedNodes=6 feasibleNodes=3
2023-01-09T08:45:04.238816132Z I0109 08:45:04.238763       1 schedule_one.go:266] "Successfully bound pod to node" pod="openshift-marketplace/redhat-operators-w2jfl" node="ip-10-0-145-4.us-east-2.compute.internal" evaluatedNodes=6 feasibleNodes=3
2023-01-09T08:45:07.338525407Z I0109 08:45:07.338485       1 schedule_one.go:826] "Unable to schedule pod; no fit; waiting" pod="openshift-logging/lokistack-sample-ruler-1" err="0/6 nodes are available: 3 Insufficient cpu, 3 node(s) had untolerated taint {node-role.kubernetes.io/master: }. preemption: 0/6 nodes are available: 3 No preemption victims found for incoming pod, 3 Preemption is not helpful for scheduling."
2023-01-09T08:45:07.339005112Z I0109 08:45:07.338978       1 schedule_one.go:826] "Unable to schedule pod; no fit; waiting" pod="openshift-logging/lokistack-sample-ingester-1" err="0/6 nodes are available: 3 Insufficient cpu, 3 node(s) had untolerated taint {node-role.kubernetes.io/master: }. preemption: 0/6 nodes are available: 3 No preemption victims found for incoming pod, 3 Preemption is not helpful for scheduling."
2023-01-09T08:45:36.802171488Z I0109 08:45:36.802125       1 schedule_one.go:826] "Unable to schedule pod; no fit; waiting" pod="openshift-logging/lokistack-sample-ruler-1" err="0/6 nodes are available: 3 Insufficient cpu, 3 node(s) had untolerated taint {node-role.kubernetes.io/master: }. preemption: 0/6 nodes are available: 3 No preemption victims found for incoming pod, 3 Preemption is not helpful for scheduling."
2023-01-09T08:45:36.802805009Z I0109 08:45:36.802768       1 schedule_one.go:826] "Unable to schedule pod; no fit; waiting" pod="openshift-logging/lokistack-sample-ingester-1" err="0/6 nodes are available: 3 Insufficient cpu, 3 node(s) had untolerated taint {node-role.kubernetes.io/master: }. preemption: 0/6 nodes are available: 3 No preemption victims found for incoming pod, 3 Preemption is not helpful for scheduling."
2023-01-09T08:46:59.507222602Z I0109 08:46:59.507163       1 schedule_one.go:266] "Successfully bound pod to node" pod="openshift-marketplace/community-operators-mwrml" node="ip-10-0-145-4.us-east-2.compute.internal" evaluatedNodes=6 feasibleNodes=3
2023-01-09T08:46:59.508439948Z I0109 08:46:59.508409       1 schedule_one.go:266] "Successfully bound pod to node" pod="openshift-marketplace/certified-operators-89zp5" node="ip-10-0-199-219.us-east-2.compute.internal" evaluatedNodes=6 feasibleNodes=3
2023-01-09T08:47:13.357792463Z I0109 08:47:13.357749       1 schedule_one.go:826] "Unable to schedule pod; no fit; waiting" pod="openshift-logging/lokistack-sample-ruler-1" err="0/6 nodes are available: 3 Insufficient cpu, 3 node(s) had untolerated taint {node-role.kubernetes.io/master: }. preemption: 0/6 nodes are available: 3 No preemption victims found for incoming pod, 3 Preemption is not helpful for scheduling."
2023-01-09T08:47:13.358508217Z I0109 08:47:13.358477       1 schedule_one.go:826] "Unable to schedule pod; no fit; waiting" pod="openshift-logging/lokistack-sample-ingester-1" err="0/6 nodes are available: 3 Insufficient cpu, 3 node(s) had untolerated taint {node-role.kubernetes.io/master: }. preemption: 0/6 nodes are available: 3 No preemption victims found for incoming pod, 3 Preemption is not helpful for scheduling."
2023-01-09T08:47:23.763206104Z I0109 08:47:23.763157       1 schedule_one.go:826] "Unable to schedule pod; no fit; waiting" pod="openshift-logging/lokistack-sample-ruler-1" err="0/6 nodes are available: 3 Insufficient cpu, 3 node(s) had untolerated taint {node-role.kubernetes.io/master: }. preemption: 0/6 nodes are available: 3 No preemption victims found for incoming pod, 3 Preemption is not helpful for scheduling."
2023-01-09T08:47:23.763738529Z I0109 08:47:23.763704       1 schedule_one.go:826] "Unable to schedule pod; no fit; waiting" pod="openshift-logging/lokistack-sample-ingester-1" err="0/6 nodes are available: 3 Insufficient cpu, 3 node(s) had untolerated taint {node-role.kubernetes.io/master: }. preemption: 0/6 nodes are available: 3 No preemption victims found for incoming pod, 3 Preemption is not helpful for scheduling."
2023-01-09T08:52:34.399068392Z I0109 08:52:34.399012       1 schedule_one.go:826] "Unable to schedule pod; no fit; waiting" pod="openshift-logging/lokistack-sample-ruler-1" err="0/6 nodes are available: 3 Insufficient cpu, 3 node(s) had untolerated taint {node-role.kubernetes.io/master: }. preemption: 0/6 nodes are available: 3 No preemption victims found for incoming pod, 3 Preemption is not helpful for scheduling."
2023-01-09T08:52:34.399625886Z I0109 08:52:34.399593       1 schedule_one.go:826] "Unable to schedule pod; no fit; waiting" pod="openshift-logging/lokistack-sample-ingester-1" err="0/6 nodes are available: 3 Insufficient cpu, 3 node(s) had untolerated taint {node-role.kubernetes.io/master: }. preemption: 0/6 nodes are available: 3 No preemption victims found for incoming pod, 3 Preemption is not helpful for scheduling."
2023-01-09T08:52:45.619631218Z I0109 08:52:45.619584       1 schedule_one.go:266] "Successfully bound pod to node" pod="openshift-marketplace/qe-app-registry-2c96w" node="ip-10-0-144-137.us-east-2.compute.internal" evaluatedNodes=6 feasibleNodes=3
2023-01-09T08:52:45.636292639Z I0109 08:52:45.636251       1 schedule_one.go:266] "Successfully bound pod to node" pod="openshift-marketplace/redhat-marketplace-ssn5s" node="ip-10-0-199-219.us-east-2.compute.internal" evaluatedNodes=6 feasibleNodes=3
2023-01-09T08:52:59.405968720Z I0109 08:52:59.405926       1 schedule_one.go:826] "Unable to schedule pod; no fit; waiting" pod="openshift-logging/lokistack-sample-ruler-1" err="0/6 nodes are available: 3 Insufficient cpu, 3 node(s) had untolerated taint {node-role.kubernetes.io/master: }. preemption: 0/6 nodes are available: 3 No preemption victims found for incoming pod, 3 Preemption is not helpful for scheduling."
2023-01-09T08:52:59.406541806Z I0109 08:52:59.406508       1 schedule_one.go:826] "Unable to schedule pod; no fit; waiting" pod="openshift-logging/lokistack-sample-ingester-1" err="0/6 nodes are available: 3 Insufficient cpu, 3 node(s) had untolerated taint {node-role.kubernetes.io/master: }. preemption: 0/6 nodes are available: 3 No preemption victims found for incoming pod, 3 Preemption is not helpful for scheduling."
2023-01-09T08:53:09.996005995Z I0109 08:53:09.995964       1 schedule_one.go:826] "Unable to schedule pod; no fit; waiting" pod="openshift-logging/lokistack-sample-ruler-1" err="0/6 nodes are available: 3 Insufficient cpu, 3 node(s) had untolerated taint {node-role.kubernetes.io/master: }. preemption: 0/6 nodes are available: 3 No preemption victims found for incoming pod, 3 Preemption is not helpful for scheduling."
2023-01-09T08:53:09.996588454Z I0109 08:53:09.996555       1 schedule_one.go:826] "Unable to schedule pod; no fit; waiting" pod="openshift-logging/lokistack-sample-ingester-1" err="0/6 nodes are available: 3 Insufficient cpu, 3 node(s) had untolerated taint {node-role.kubernetes.io/master: }. preemption: 0/6 nodes are available: 3 No preemption victims found for incoming pod, 3 Preemption is not helpful for scheduling."
2023-01-09T08:56:09.095716237Z I0109 08:56:09.095670       1 schedule_one.go:266] "Successfully bound pod to node" pod="openshift-marketplace/redhat-operators-r88vr" node="ip-10-0-145-4.us-east-2.compute.internal" evaluatedNodes=6 feasibleNodes=3
2023-01-09T08:56:41.653408341Z I0109 08:56:41.653362       1 schedule_one.go:826] "Unable to schedule pod; no fit; waiting" pod="openshift-logging/lokistack-sample-ruler-1" err="0/6 nodes are available: 3 Insufficient cpu, 3 node(s) had untolerated taint {node-role.kubernetes.io/master: }. preemption: 0/6 nodes are available: 3 No preemption victims found for incoming pod, 3 Preemption is not helpful for scheduling."
2023-01-09T08:56:41.654270840Z I0109 08:56:41.654228       1 schedule_one.go:826] "Unable to schedule pod; no fit; waiting" pod="openshift-logging/lokistack-sample-ingester-1" err="0/6 nodes are available: 3 Insufficient cpu, 3 node(s) had untolerated taint {node-role.kubernetes.io/master: }. preemption: 0/6 nodes are available: 3 No preemption victims found for incoming pod, 3 Preemption is not helpful for scheduling."
2023-01-09T08:57:06.368467392Z I0109 08:57:06.368413       1 schedule_one.go:266] "Successfully bound pod to node" pod="openshift-marketplace/community-operators-qpcj4" node="ip-10-0-145-4.us-east-2.compute.internal" evaluatedNodes=6 feasibleNodes=3
2023-01-09T08:57:29.784777192Z I0109 08:57:29.784723       1 schedule_one.go:826] "Unable to schedule pod; no fit; waiting" pod="openshift-logging/lokistack-sample-ruler-1" err="0/6 nodes are available: 3 Insufficient cpu, 3 node(s) had untolerated taint {node-role.kubernetes.io/master: }. preemption: 0/6 nodes are available: 3 No preemption victims found for incoming pod, 3 Preemption is not helpful for scheduling."
2023-01-09T08:57:29.785570367Z I0109 08:57:29.785523       1 schedule_one.go:826] "Unable to schedule pod; no fit; waiting" pod="openshift-logging/lokistack-sample-ingester-1" err="0/6 nodes are available: 3 Insufficient cpu, 3 node(s) had untolerated taint {node-role.kubernetes.io/master: }. preemption: 0/6 nodes are available: 3 No preemption victims found for incoming pod, 3 Preemption is not helpful for scheduling."
2023-01-09T09:00:00.191049225Z I0109 09:00:00.191010       1 schedule_one.go:266] "Successfully bound pod to node" pod="openshift-operator-lifecycle-manager/collect-profiles-27887580-hn8hl" node="ip-10-0-144-137.us-east-2.compute.internal" evaluatedNodes=6 feasibleNodes=3
2023-01-09T09:00:06.036369150Z I0109 09:00:06.036315       1 schedule_one.go:826] "Unable to schedule pod; no fit; waiting" pod="openshift-logging/lokistack-sample-ruler-1" err="0/6 nodes are available: 3 Insufficient cpu, 3 node(s) had untolerated taint {node-role.kubernetes.io/master: }. preemption: 0/6 nodes are available: 3 No preemption victims found for incoming pod, 3 Preemption is not helpful for scheduling."
2023-01-09T09:00:06.036961527Z I0109 09:00:06.036930       1 schedule_one.go:826] "Unable to schedule pod; no fit; waiting" pod="openshift-logging/lokistack-sample-ingester-1" err="0/6 nodes are available: 3 Insufficient cpu, 3 node(s) had untolerated taint {node-role.kubernetes.io/master: }. preemption: 0/6 nodes are available: 3 No preemption victims found for incoming pod, 3 Preemption is not helpful for scheduling."
2023-01-09T09:01:37.079219763Z I0109 09:01:37.074499       1 schedule_one.go:266] "Successfully bound pod to node" pod="openshift-marketplace/certified-operators-jxlwk" node="ip-10-0-199-219.us-east-2.compute.internal" evaluatedNodes=6 feasibleNodes=3
2023-01-09T09:01:50.980016478Z I0109 09:01:50.979974       1 schedule_one.go:826] "Unable to schedule pod; no fit; waiting" pod="openshift-logging/lokistack-sample-ruler-1" err="0/6 nodes are available: 3 Insufficient cpu, 3 node(s) had untolerated taint {node-role.kubernetes.io/master: }. preemption: 0/6 nodes are available: 3 No preemption victims found for incoming pod, 3 Preemption is not helpful for scheduling."
2023-01-09T09:01:50.980945359Z I0109 09:01:50.980908       1 schedule_one.go:826] "Unable to schedule pod; no fit; waiting" pod="openshift-logging/lokistack-sample-ingester-1" err="0/6 nodes are available: 3 Insufficient cpu, 3 node(s) had untolerated taint {node-role.kubernetes.io/master: }. preemption: 0/6 nodes are available: 3 No preemption victims found for incoming pod, 3 Preemption is not helpful for scheduling."
2023-01-09T09:03:05.466398183Z I0109 09:03:05.466329       1 schedule_one.go:266] "Successfully bound pod to node" pod="openshift-marketplace/qe-app-registry-nn76v" node="ip-10-0-144-137.us-east-2.compute.internal" evaluatedNodes=6 feasibleNodes=3
2023-01-09T09:03:05.470049731Z I0109 09:03:05.470010       1 schedule_one.go:266] "Successfully bound pod to node" pod="openshift-marketplace/redhat-marketplace-vqxzc" node="ip-10-0-199-219.us-east-2.compute.internal" evaluatedNodes=6 feasibleNodes=3
2023-01-09T09:03:18.940391530Z I0109 09:03:18.940304       1 schedule_one.go:826] "Unable to schedule pod; no fit; waiting" pod="openshift-logging/lokistack-sample-ruler-1" err="0/6 nodes are available: 3 Insufficient cpu, 3 node(s) had untolerated taint {node-role.kubernetes.io/master: }. preemption: 0/6 nodes are available: 3 No preemption victims found for incoming pod, 3 Preemption is not helpful for scheduling."
2023-01-09T09:03:18.941176935Z I0109 09:03:18.941139       1 schedule_one.go:826] "Unable to schedule pod; no fit; waiting" pod="openshift-logging/lokistack-sample-ingester-1" err="0/6 nodes are available: 3 Insufficient cpu, 3 node(s) had untolerated taint {node-role.kubernetes.io/master: }. preemption: 0/6 nodes are available: 3 No preemption victims found for incoming pod, 3 Preemption is not helpful for scheduling."
2023-01-09T09:03:29.377946227Z I0109 09:03:29.377899       1 schedule_one.go:826] "Unable to schedule pod; no fit; waiting" pod="openshift-logging/lokistack-sample-ruler-1" err="0/6 nodes are available: 3 Insufficient cpu, 3 node(s) had untolerated taint {node-role.kubernetes.io/master: }. preemption: 0/6 nodes are available: 3 No preemption victims found for incoming pod, 3 Preemption is not helpful for scheduling."
2023-01-09T09:03:29.378451603Z I0109 09:03:29.378425       1 schedule_one.go:826] "Unable to schedule pod; no fit; waiting" pod="openshift-logging/lokistack-sample-ingester-1" err="0/6 nodes are available: 3 Insufficient cpu, 3 node(s) had untolerated taint {node-role.kubernetes.io/master: }. preemption: 0/6 nodes are available: 3 No preemption victims found for incoming pod, 3 Preemption is not helpful for scheduling."
2023-01-09T09:07:03.758283812Z I0109 09:07:03.758226       1 schedule_one.go:266] "Successfully bound pod to node" pod="openshift-marketplace/redhat-operators-rvt6j" node="ip-10-0-145-4.us-east-2.compute.internal" evaluatedNodes=6 feasibleNodes=3
2023-01-09T09:07:36.468532348Z I0109 09:07:36.468476       1 schedule_one.go:826] "Unable to schedule pod; no fit; waiting" pod="openshift-logging/lokistack-sample-ruler-1" err="0/6 nodes are available: 3 Insufficient cpu, 3 node(s) had untolerated taint {node-role.kubernetes.io/master: }. preemption: 0/6 nodes are available: 3 No preemption victims found for incoming pod, 3 Preemption is not helpful for scheduling."
2023-01-09T09:07:36.469329821Z I0109 09:07:36.469307       1 schedule_one.go:826] "Unable to schedule pod; no fit; waiting" pod="openshift-logging/lokistack-sample-ingester-1" err="0/6 nodes are available: 3 Insufficient cpu, 3 node(s) had untolerated taint {node-role.kubernetes.io/master: }. preemption: 0/6 nodes are available: 3 No preemption victims found for incoming pod, 3 Preemption is not helpful for scheduling."
2023-01-09T09:08:14.456414826Z I0109 09:08:14.456358       1 schedule_one.go:266] "Successfully bound pod to node" pod="openshift-marketplace/community-operators-qrlkw" node="ip-10-0-145-4.us-east-2.compute.internal" evaluatedNodes=6 feasibleNodes=3
2023-01-09T09:08:37.652321571Z I0109 09:08:37.652280       1 schedule_one.go:826] "Unable to schedule pod; no fit; waiting" pod="openshift-logging/lokistack-sample-ruler-1" err="0/6 nodes are available: 3 Insufficient cpu, 3 node(s) had untolerated taint {node-role.kubernetes.io/master: }. preemption: 0/6 nodes are available: 3 No preemption victims found for incoming pod, 3 Preemption is not helpful for scheduling."
2023-01-09T09:08:37.653000434Z I0109 09:08:37.652972       1 schedule_one.go:826] "Unable to schedule pod; no fit; waiting" pod="openshift-logging/lokistack-sample-ingester-1" err="0/6 nodes are available: 3 Insufficient cpu, 3 node(s) had untolerated taint {node-role.kubernetes.io/master: }. preemption: 0/6 nodes are available: 3 No preemption victims found for incoming pod, 3 Preemption is not helpful for scheduling."
2023-01-09T09:11:52.768314118Z I0109 09:11:52.768257       1 schedule_one.go:266] "Successfully bound pod to node" pod="openshift-marketplace/certified-operators-w66ft" node="ip-10-0-199-219.us-east-2.compute.internal" evaluatedNodes=6 feasibleNodes=3
2023-01-09T09:12:06.740140764Z I0109 09:12:06.740088       1 schedule_one.go:826] "Unable to schedule pod; no fit; waiting" pod="openshift-logging/lokistack-sample-ruler-1" err="0/6 nodes are available: 3 Insufficient cpu, 3 node(s) had untolerated taint {node-role.kubernetes.io/master: }. preemption: 0/6 nodes are available: 3 No preemption victims found for incoming pod, 3 Preemption is not helpful for scheduling."
2023-01-09T09:12:06.741270453Z I0109 09:12:06.741234       1 schedule_one.go:826] "Unable to schedule pod; no fit; waiting" pod="openshift-logging/lokistack-sample-ingester-1" err="0/6 nodes are available: 3 Insufficient cpu, 3 node(s) had untolerated taint {node-role.kubernetes.io/master: }. preemption: 0/6 nodes are available: 3 No preemption victims found for incoming pod, 3 Preemption is not helpful for scheduling."
2023-01-09T09:13:22.086802823Z I0109 09:13:22.086753       1 schedule_one.go:266] "Successfully bound pod to node" pod="openshift-marketplace/redhat-marketplace-2ccbk" node="ip-10-0-199-219.us-east-2.compute.internal" evaluatedNodes=6 feasibleNodes=3
2023-01-09T09:13:35.992284282Z I0109 09:13:35.992243       1 schedule_one.go:826] "Unable to schedule pod; no fit; waiting" pod="openshift-logging/lokistack-sample-ruler-1" err="0/6 nodes are available: 3 Insufficient cpu, 3 node(s) had untolerated taint {node-role.kubernetes.io/master: }. preemption: 0/6 nodes are available: 3 No preemption victims found for incoming pod, 3 Preemption is not helpful for scheduling."
2023-01-09T09:13:35.993058699Z I0109 09:13:35.993014       1 schedule_one.go:826] "Unable to schedule pod; no fit; waiting" pod="openshift-logging/lokistack-sample-ingester-1" err="0/6 nodes are available: 3 Insufficient cpu, 3 node(s) had untolerated taint {node-role.kubernetes.io/master: }. preemption: 0/6 nodes are available: 3 No preemption victims found for incoming pod, 3 Preemption is not helpful for scheduling."
2023-01-09T09:14:34.381020196Z I0109 09:14:34.380964       1 schedule_one.go:266] "Successfully bound pod to node" pod="openshift-marketplace/qe-app-registry-h42bz" node="ip-10-0-144-137.us-east-2.compute.internal" evaluatedNodes=6 feasibleNodes=3
2023-01-09T09:14:48.619823672Z I0109 09:14:48.619772       1 schedule_one.go:826] "Unable to schedule pod; no fit; waiting" pod="openshift-logging/lokistack-sample-ruler-1" err="0/6 nodes are available: 3 Insufficient cpu, 3 node(s) had untolerated taint {node-role.kubernetes.io/master: }. preemption: 0/6 nodes are available: 3 No preemption victims found for incoming pod, 3 Preemption is not helpful for scheduling."
2023-01-09T09:14:48.620525245Z I0109 09:14:48.620489       1 schedule_one.go:826] "Unable to schedule pod; no fit; waiting" pod="openshift-logging/lokistack-sample-ingester-1" err="0/6 nodes are available: 3 Insufficient cpu, 3 node(s) had untolerated taint {node-role.kubernetes.io/master: }. preemption: 0/6 nodes are available: 3 No preemption victims found for incoming pod, 3 Preemption is not helpful for scheduling."
2023-01-09T09:15:00.148276995Z I0109 09:15:00.148225       1 schedule_one.go:266] "Successfully bound pod to node" pod="openshift-operator-lifecycle-manager/collect-profiles-27887595-2qqj7" node="ip-10-0-144-137.us-east-2.compute.internal" evaluatedNodes=6 feasibleNodes=3
2023-01-09T09:15:04.661385161Z I0109 09:15:04.661324       1 schedule_one.go:826] "Unable to schedule pod; no fit; waiting" pod="openshift-logging/lokistack-sample-ruler-1" err="0/6 nodes are available: 3 Insufficient cpu, 3 node(s) had untolerated taint {node-role.kubernetes.io/master: }. preemption: 0/6 nodes are available: 3 No preemption victims found for incoming pod, 3 Preemption is not helpful for scheduling."
2023-01-09T09:15:04.661992931Z I0109 09:15:04.661959       1 schedule_one.go:826] "Unable to schedule pod; no fit; waiting" pod="openshift-logging/lokistack-sample-ingester-1" err="0/6 nodes are available: 3 Insufficient cpu, 3 node(s) had untolerated taint {node-role.kubernetes.io/master: }. preemption: 0/6 nodes are available: 3 No preemption victims found for incoming pod, 3 Preemption is not helpful for scheduling."
2023-01-09T09:17:35.594281830Z I0109 09:17:35.594233       1 schedule_one.go:266] "Successfully bound pod to node" pod="openshift-marketplace/redhat-operators-48s86" node="ip-10-0-145-4.us-east-2.compute.internal" evaluatedNodes=6 feasibleNodes=3
2023-01-09T09:18:08.260239623Z I0109 09:18:08.260178       1 schedule_one.go:826] "Unable to schedule pod; no fit; waiting" pod="openshift-logging/lokistack-sample-ruler-1" err="0/6 nodes are available: 3 Insufficient cpu, 3 node(s) had untolerated taint {node-role.kubernetes.io/master: }. preemption: 0/6 nodes are available: 3 No preemption victims found for incoming pod, 3 Preemption is not helpful for scheduling."
2023-01-09T09:18:08.261281775Z I0109 09:18:08.261225       1 schedule_one.go:826] "Unable to schedule pod; no fit; waiting" pod="openshift-logging/lokistack-sample-ingester-1" err="0/6 nodes are available: 3 Insufficient cpu, 3 node(s) had untolerated taint {node-role.kubernetes.io/master: }. preemption: 0/6 nodes are available: 3 No preemption victims found for incoming pod, 3 Preemption is not helpful for scheduling."
2023-01-09T09:18:43.142300356Z I0109 09:18:43.142251       1 schedule_one.go:266] "Successfully bound pod to node" pod="openshift-marketplace/community-operators-b5dlg" node="ip-10-0-145-4.us-east-2.compute.internal" evaluatedNodes=6 feasibleNodes=3
2023-01-09T09:19:06.447872945Z I0109 09:19:06.447828       1 schedule_one.go:826] "Unable to schedule pod; no fit; waiting" pod="openshift-logging/lokistack-sample-ruler-1" err="0/6 nodes are available: 3 Insufficient cpu, 3 node(s) had untolerated taint {node-role.kubernetes.io/master: }. preemption: 0/6 nodes are available: 3 No preemption victims found for incoming pod, 3 Preemption is not helpful for scheduling."
2023-01-09T09:19:06.448409350Z I0109 09:19:06.448372       1 schedule_one.go:826] "Unable to schedule pod; no fit; waiting" pod="openshift-logging/lokistack-sample-ingester-1" err="0/6 nodes are available: 3 Insufficient cpu, 3 node(s) had untolerated taint {node-role.kubernetes.io/master: }. preemption: 0/6 nodes are available: 3 No preemption victims found for incoming pod, 3 Preemption is not helpful for scheduling."
2023-01-09T09:23:35.465303357Z I0109 09:23:35.465236       1 schedule_one.go:266] "Successfully bound pod to node" pod="openshift-marketplace/redhat-marketplace-ckn7n" node="ip-10-0-199-219.us-east-2.compute.internal" evaluatedNodes=6 feasibleNodes=3
2023-01-09T09:23:49.783203027Z I0109 09:23:49.783160       1 schedule_one.go:826] "Unable to schedule pod; no fit; waiting" pod="openshift-logging/lokistack-sample-ruler-1" err="0/6 nodes are available: 3 Insufficient cpu, 3 node(s) had untolerated taint {node-role.kubernetes.io/master: }. preemption: 0/6 nodes are available: 3 No preemption victims found for incoming pod, 3 Preemption is not helpful for scheduling."
2023-01-09T09:23:49.784249487Z I0109 09:23:49.784214       1 schedule_one.go:826] "Unable to schedule pod; no fit; waiting" pod="openshift-logging/lokistack-sample-ingester-1" err="0/6 nodes are available: 3 Insufficient cpu, 3 node(s) had untolerated taint {node-role.kubernetes.io/master: }. preemption: 0/6 nodes are available: 3 No preemption victims found for incoming pod, 3 Preemption is not helpful for scheduling."
2023-01-09T09:24:44.103378694Z I0109 09:24:44.103309       1 schedule_one.go:266] "Successfully bound pod to node" pod="openshift-marketplace/certified-operators-8h8fs" node="ip-10-0-199-219.us-east-2.compute.internal" evaluatedNodes=6 feasibleNodes=3
2023-01-09T09:24:44.115057533Z I0109 09:24:44.115012       1 schedule_one.go:266] "Successfully bound pod to node" pod="openshift-marketplace/qe-app-registry-r7k5k" node="ip-10-0-144-137.us-east-2.compute.internal" evaluatedNodes=6 feasibleNodes=3
2023-01-09T09:24:57.977251856Z I0109 09:24:57.977207       1 schedule_one.go:826] "Unable to schedule pod; no fit; waiting" pod="openshift-logging/lokistack-sample-ruler-1" err="0/6 nodes are available: 3 Insufficient cpu, 3 node(s) had untolerated taint {node-role.kubernetes.io/master: }. preemption: 0/6 nodes are available: 3 No preemption victims found for incoming pod, 3 Preemption is not helpful for scheduling."
2023-01-09T09:24:57.978478248Z I0109 09:24:57.978437       1 schedule_one.go:826] "Unable to schedule pod; no fit; waiting" pod="openshift-logging/lokistack-sample-ingester-1" err="0/6 nodes are available: 3 Insufficient cpu, 3 node(s) had untolerated taint {node-role.kubernetes.io/master: }. preemption: 0/6 nodes are available: 3 No preemption victims found for incoming pod, 3 Preemption is not helpful for scheduling."
2023-01-09T09:25:08.156225964Z I0109 09:25:08.156182       1 schedule_one.go:826] "Unable to schedule pod; no fit; waiting" pod="openshift-logging/lokistack-sample-ruler-1" err="0/6 nodes are available: 3 Insufficient cpu, 3 node(s) had untolerated taint {node-role.kubernetes.io/master: }. preemption: 0/6 nodes are available: 3 No preemption victims found for incoming pod, 3 Preemption is not helpful for scheduling."
2023-01-09T09:25:08.156732124Z I0109 09:25:08.156707       1 schedule_one.go:826] "Unable to schedule pod; no fit; waiting" pod="openshift-logging/lokistack-sample-ingester-1" err="0/6 nodes are available: 3 Insufficient cpu, 3 node(s) had untolerated taint {node-role.kubernetes.io/master: }. preemption: 0/6 nodes are available: 3 No preemption victims found for incoming pod, 3 Preemption is not helpful for scheduling."
2023-01-09T09:28:35.088260971Z I0109 09:28:35.088202       1 schedule_one.go:266] "Successfully bound pod to node" pod="openshift-marketplace/redhat-operators-6xx58" node="ip-10-0-145-4.us-east-2.compute.internal" evaluatedNodes=6 feasibleNodes=3
2023-01-09T09:29:08.180010599Z I0109 09:29:08.179966       1 schedule_one.go:826] "Unable to schedule pod; no fit; waiting" pod="openshift-logging/lokistack-sample-ruler-1" err="0/6 nodes are available: 3 Insufficient cpu, 3 node(s) had untolerated taint {node-role.kubernetes.io/master: }. preemption: 0/6 nodes are available: 3 No preemption victims found for incoming pod, 3 Preemption is not helpful for scheduling."
2023-01-09T09:29:08.180605178Z I0109 09:29:08.180565       1 schedule_one.go:826] "Unable to schedule pod; no fit; waiting" pod="openshift-logging/lokistack-sample-ingester-1" err="0/6 nodes are available: 3 Insufficient cpu, 3 node(s) had untolerated taint {node-role.kubernetes.io/master: }. preemption: 0/6 nodes are available: 3 No preemption victims found for incoming pod, 3 Preemption is not helpful for scheduling."
2023-01-09T09:30:00.147785571Z I0109 09:30:00.147744       1 schedule_one.go:266] "Successfully bound pod to node" pod="openshift-operator-lifecycle-manager/collect-profiles-27887610-z9vst" node="ip-10-0-144-137.us-east-2.compute.internal" evaluatedNodes=6 feasibleNodes=3
2023-01-09T09:30:04.838725685Z I0109 09:30:04.838686       1 schedule_one.go:826] "Unable to schedule pod; no fit; waiting" pod="openshift-logging/lokistack-sample-ruler-1" err="0/6 nodes are available: 3 Insufficient cpu, 3 node(s) had untolerated taint {node-role.kubernetes.io/master: }. preemption: 0/6 nodes are available: 3 No preemption victims found for incoming pod, 3 Preemption is not helpful for scheduling."
2023-01-09T09:30:04.839248379Z I0109 09:30:04.839202       1 schedule_one.go:826] "Unable to schedule pod; no fit; waiting" pod="openshift-logging/lokistack-sample-ingester-1" err="0/6 nodes are available: 3 Insufficient cpu, 3 node(s) had untolerated taint {node-role.kubernetes.io/master: }. preemption: 0/6 nodes are available: 3 No preemption victims found for incoming pod, 3 Preemption is not helpful for scheduling."
2023-01-09T09:30:52.229800374Z I0109 09:30:52.229743       1 schedule_one.go:266] "Successfully bound pod to node" pod="openshift-marketplace/community-operators-8ftds" node="ip-10-0-145-4.us-east-2.compute.internal" evaluatedNodes=6 feasibleNodes=3
2023-01-09T09:31:15.535385194Z I0109 09:31:15.535310       1 schedule_one.go:826] "Unable to schedule pod; no fit; waiting" pod="openshift-logging/lokistack-sample-ruler-1" err="0/6 nodes are available: 3 Insufficient cpu, 3 node(s) had untolerated taint {node-role.kubernetes.io/master: }. preemption: 0/6 nodes are available: 3 No preemption victims found for incoming pod, 3 Preemption is not helpful for scheduling."
2023-01-09T09:31:15.535968892Z I0109 09:31:15.535930       1 schedule_one.go:826] "Unable to schedule pod; no fit; waiting" pod="openshift-logging/lokistack-sample-ingester-1" err="0/6 nodes are available: 3 Insufficient cpu, 3 node(s) had untolerated taint {node-role.kubernetes.io/master: }. preemption: 0/6 nodes are available: 3 No preemption victims found for incoming pod, 3 Preemption is not helpful for scheduling."
2023-01-09T09:34:20.826577192Z I0109 09:34:20.826531       1 schedule_one.go:266] "Successfully bound pod to node" pod="openshift-marketplace/redhat-marketplace-zm9wv" node="ip-10-0-199-219.us-east-2.compute.internal" evaluatedNodes=6 feasibleNodes=3
2023-01-09T09:34:34.659772783Z I0109 09:34:34.659716       1 schedule_one.go:826] "Unable to schedule pod; no fit; waiting" pod="openshift-logging/lokistack-sample-ruler-1" err="0/6 nodes are available: 3 Insufficient cpu, 3 node(s) had untolerated taint {node-role.kubernetes.io/master: }. preemption: 0/6 nodes are available: 3 No preemption victims found for incoming pod, 3 Preemption is not helpful for scheduling."
2023-01-09T09:34:34.660806798Z I0109 09:34:34.660731       1 schedule_one.go:826] "Unable to schedule pod; no fit; waiting" pod="openshift-logging/lokistack-sample-ingester-1" err="0/6 nodes are available: 3 Insufficient cpu, 3 node(s) had untolerated taint {node-role.kubernetes.io/master: }. preemption: 0/6 nodes are available: 3 No preemption victims found for incoming pod, 3 Preemption is not helpful for scheduling."
2023-01-09T09:34:49.297893221Z I0109 09:34:49.297792       1 schedule_one.go:266] "Successfully bound pod to node" pod="openshift-marketplace/certified-operators-vfj7m" node="ip-10-0-199-219.us-east-2.compute.internal" evaluatedNodes=6 feasibleNodes=3
2023-01-09T09:35:03.763148041Z I0109 09:35:03.763089       1 schedule_one.go:826] "Unable to schedule pod; no fit; waiting" pod="openshift-logging/lokistack-sample-ruler-1" err="0/6 nodes are available: 3 Insufficient cpu, 3 node(s) had untolerated taint {node-role.kubernetes.io/master: }. preemption: 0/6 nodes are available: 3 No preemption victims found for incoming pod, 3 Preemption is not helpful for scheduling."
2023-01-09T09:35:03.763892717Z I0109 09:35:03.763859       1 schedule_one.go:826] "Unable to schedule pod; no fit; waiting" pod="openshift-logging/lokistack-sample-ingester-1" err="0/6 nodes are available: 3 Insufficient cpu, 3 node(s) had untolerated taint {node-role.kubernetes.io/master: }. preemption: 0/6 nodes are available: 3 No preemption victims found for incoming pod, 3 Preemption is not helpful for scheduling."
2023-01-09T09:35:47.016443726Z I0109 09:35:47.016403       1 schedule_one.go:266] "Successfully bound pod to node" pod="openshift-marketplace/qe-app-registry-66b9x" node="ip-10-0-144-137.us-east-2.compute.internal" evaluatedNodes=6 feasibleNodes=3
2023-01-09T09:36:00.686632582Z I0109 09:36:00.686578       1 schedule_one.go:826] "Unable to schedule pod; no fit; waiting" pod="openshift-logging/lokistack-sample-ruler-1" err="0/6 nodes are available: 3 Insufficient cpu, 3 node(s) had untolerated taint {node-role.kubernetes.io/master: }. preemption: 0/6 nodes are available: 3 No preemption victims found for incoming pod, 3 Preemption is not helpful for scheduling."
2023-01-09T09:36:00.687678445Z I0109 09:36:00.687644       1 schedule_one.go:826] "Unable to schedule pod; no fit; waiting" pod="openshift-logging/lokistack-sample-ingester-1" err="0/6 nodes are available: 3 Insufficient cpu, 3 node(s) had untolerated taint {node-role.kubernetes.io/master: }. preemption: 0/6 nodes are available: 3 No preemption victims found for incoming pod, 3 Preemption is not helpful for scheduling."
2023-01-09T09:39:05.806482565Z I0109 09:39:05.806420       1 schedule_one.go:266] "Successfully bound pod to node" pod="openshift-marketplace/redhat-operators-7fqcr" node="ip-10-0-145-4.us-east-2.compute.internal" evaluatedNodes=6 feasibleNodes=3
2023-01-09T09:39:38.969909219Z I0109 09:39:38.969862       1 schedule_one.go:826] "Unable to schedule pod; no fit; waiting" pod="openshift-logging/lokistack-sample-ruler-1" err="0/6 nodes are available: 3 Insufficient cpu, 3 node(s) had untolerated taint {node-role.kubernetes.io/master: }. preemption: 0/6 nodes are available: 3 No preemption victims found for incoming pod, 3 Preemption is not helpful for scheduling."
2023-01-09T09:39:38.970851691Z I0109 09:39:38.970812       1 schedule_one.go:826] "Unable to schedule pod; no fit; waiting" pod="openshift-logging/lokistack-sample-ingester-1" err="0/6 nodes are available: 3 Insufficient cpu, 3 node(s) had untolerated taint {node-role.kubernetes.io/master: }. preemption: 0/6 nodes are available: 3 No preemption victims found for incoming pod, 3 Preemption is not helpful for scheduling."
2023-01-09T09:42:06.959735867Z I0109 09:42:06.959683       1 schedule_one.go:266] "Successfully bound pod to node" pod="openshift-marketplace/community-operators-ts8z6" node="ip-10-0-145-4.us-east-2.compute.internal" evaluatedNodes=6 feasibleNodes=3
2023-01-09T09:42:29.448226068Z I0109 09:42:29.448179       1 schedule_one.go:826] "Unable to schedule pod; no fit; waiting" pod="openshift-logging/lokistack-sample-ruler-1" err="0/6 nodes are available: 3 Insufficient cpu, 3 node(s) had untolerated taint {node-role.kubernetes.io/master: }. preemption: 0/6 nodes are available: 3 No preemption victims found for incoming pod, 3 Preemption is not helpful for scheduling."
2023-01-09T09:42:29.448935705Z I0109 09:42:29.448882       1 schedule_one.go:826] "Unable to schedule pod; no fit; waiting" pod="openshift-logging/lokistack-sample-ingester-1" err="0/6 nodes are available: 3 Insufficient cpu, 3 node(s) had untolerated taint {node-role.kubernetes.io/master: }. preemption: 0/6 nodes are available: 3 No preemption victims found for incoming pod, 3 Preemption is not helpful for scheduling."
2023-01-09T09:44:58.258609560Z I0109 09:44:58.258563       1 schedule_one.go:266] "Successfully bound pod to node" pod="openshift-marketplace/certified-operators-nblzq" node="ip-10-0-199-219.us-east-2.compute.internal" evaluatedNodes=6 feasibleNodes=3
2023-01-09T09:45:00.202288794Z I0109 09:45:00.202238       1 schedule_one.go:266] "Successfully bound pod to node" pod="openshift-operator-lifecycle-manager/collect-profiles-27887625-hhdqk" node="ip-10-0-144-137.us-east-2.compute.internal" evaluatedNodes=6 feasibleNodes=3
2023-01-09T09:45:04.967953434Z I0109 09:45:04.967914       1 schedule_one.go:826] "Unable to schedule pod; no fit; waiting" pod="openshift-logging/lokistack-sample-ruler-1" err="0/6 nodes are available: 3 Insufficient cpu, 3 node(s) had untolerated taint {node-role.kubernetes.io/master: }. preemption: 0/6 nodes are available: 3 No preemption victims found for incoming pod, 3 Preemption is not helpful for scheduling."
2023-01-09T09:45:04.968518783Z I0109 09:45:04.968491       1 schedule_one.go:826] "Unable to schedule pod; no fit; waiting" pod="openshift-logging/lokistack-sample-ingester-1" err="0/6 nodes are available: 3 Insufficient cpu, 3 node(s) had untolerated taint {node-role.kubernetes.io/master: }. preemption: 0/6 nodes are available: 3 No preemption victims found for incoming pod, 3 Preemption is not helpful for scheduling."
2023-01-09T09:45:15.868512807Z I0109 09:45:15.868466       1 schedule_one.go:826] "Unable to schedule pod; no fit; waiting" pod="openshift-logging/lokistack-sample-ruler-1" err="0/6 nodes are available: 3 Insufficient cpu, 3 node(s) had untolerated taint {node-role.kubernetes.io/master: }. preemption: 0/6 nodes are available: 3 No preemption victims found for incoming pod, 3 Preemption is not helpful for scheduling."
2023-01-09T09:45:15.868985961Z I0109 09:45:15.868958       1 schedule_one.go:826] "Unable to schedule pod; no fit; waiting" pod="openshift-logging/lokistack-sample-ingester-1" err="0/6 nodes are available: 3 Insufficient cpu, 3 node(s) had untolerated taint {node-role.kubernetes.io/master: }. preemption: 0/6 nodes are available: 3 No preemption victims found for incoming pod, 3 Preemption is not helpful for scheduling."
2023-01-09T09:45:29.803452137Z I0109 09:45:29.803365       1 schedule_one.go:266] "Successfully bound pod to node" pod="openshift-marketplace/redhat-marketplace-g29z8" node="ip-10-0-199-219.us-east-2.compute.internal" evaluatedNodes=6 feasibleNodes=3
2023-01-09T09:45:43.674003712Z I0109 09:45:43.673959       1 schedule_one.go:826] "Unable to schedule pod; no fit; waiting" pod="openshift-logging/lokistack-sample-ruler-1" err="0/6 nodes are available: 3 Insufficient cpu, 3 node(s) had untolerated taint {node-role.kubernetes.io/master: }. preemption: 0/6 nodes are available: 3 No preemption victims found for incoming pod, 3 Preemption is not helpful for scheduling."
2023-01-09T09:45:43.674918686Z I0109 09:45:43.674884       1 schedule_one.go:826] "Unable to schedule pod; no fit; waiting" pod="openshift-logging/lokistack-sample-ingester-1" err="0/6 nodes are available: 3 Insufficient cpu, 3 node(s) had untolerated taint {node-role.kubernetes.io/master: }. preemption: 0/6 nodes are available: 3 No preemption victims found for incoming pod, 3 Preemption is not helpful for scheduling."
2023-01-09T09:49:40.500504206Z I0109 09:49:40.500455       1 schedule_one.go:266] "Successfully bound pod to node" pod="openshift-marketplace/redhat-operators-hjlw9" node="ip-10-0-145-4.us-east-2.compute.internal" evaluatedNodes=6 feasibleNodes=3
2023-01-09T09:49:58.506181566Z I0109 09:49:58.506143       1 schedule_one.go:266] "Successfully bound pod to node" pod="openshift-marketplace/qe-app-registry-bmfw8" node="ip-10-0-144-137.us-east-2.compute.internal" evaluatedNodes=6 feasibleNodes=3
2023-01-09T09:50:12.696008176Z I0109 09:50:12.695966       1 schedule_one.go:826] "Unable to schedule pod; no fit; waiting" pod="openshift-logging/lokistack-sample-ruler-1" err="0/6 nodes are available: 3 Insufficient cpu, 3 node(s) had untolerated taint {node-role.kubernetes.io/master: }. preemption: 0/6 nodes are available: 3 No preemption victims found for incoming pod, 3 Preemption is not helpful for scheduling."
2023-01-09T09:50:12.696755863Z I0109 09:50:12.696717       1 schedule_one.go:826] "Unable to schedule pod; no fit; waiting" pod="openshift-logging/lokistack-sample-ingester-1" err="0/6 nodes are available: 3 Insufficient cpu, 3 node(s) had untolerated taint {node-role.kubernetes.io/master: }. preemption: 0/6 nodes are available: 3 No preemption victims found for incoming pod, 3 Preemption is not helpful for scheduling."
2023-01-09T09:50:23.056563462Z I0109 09:50:23.056440       1 schedule_one.go:826] "Unable to schedule pod; no fit; waiting" pod="openshift-logging/lokistack-sample-ruler-1" err="0/6 nodes are available: 3 Insufficient cpu, 3 node(s) had untolerated taint {node-role.kubernetes.io/master: }. preemption: 0/6 nodes are available: 3 No preemption victims found for incoming pod, 3 Preemption is not helpful for scheduling."
2023-01-09T09:50:23.059487701Z I0109 09:50:23.059443       1 schedule_one.go:826] "Unable to schedule pod; no fit; waiting" pod="openshift-logging/lokistack-sample-ingester-1" err="0/6 nodes are available: 3 Insufficient cpu, 3 node(s) had untolerated taint {node-role.kubernetes.io/master: }. preemption: 0/6 nodes are available: 3 No preemption victims found for incoming pod, 3 Preemption is not helpful for scheduling."
2023-01-09T09:53:32.524203228Z I0109 09:53:32.524138       1 schedule_one.go:266] "Successfully bound pod to node" pod="openshift-marketplace/community-operators-6lp6r" node="ip-10-0-145-4.us-east-2.compute.internal" evaluatedNodes=6 feasibleNodes=3
2023-01-09T09:53:55.432125081Z I0109 09:53:55.432077       1 schedule_one.go:826] "Unable to schedule pod; no fit; waiting" pod="openshift-logging/lokistack-sample-ruler-1" err="0/6 nodes are available: 3 Insufficient cpu, 3 node(s) had untolerated taint {node-role.kubernetes.io/master: }. preemption: 0/6 nodes are available: 3 No preemption victims found for incoming pod, 3 Preemption is not helpful for scheduling."
2023-01-09T09:53:55.432774698Z I0109 09:53:55.432731       1 schedule_one.go:826] "Unable to schedule pod; no fit; waiting" pod="openshift-logging/lokistack-sample-ingester-1" err="0/6 nodes are available: 3 Insufficient cpu, 3 node(s) had untolerated taint {node-role.kubernetes.io/master: }. preemption: 0/6 nodes are available: 3 No preemption victims found for incoming pod, 3 Preemption is not helpful for scheduling."
2023-01-09T09:55:51.866324613Z I0109 09:55:51.866243       1 schedule_one.go:266] "Successfully bound pod to node" pod="openshift-marketplace/certified-operators-vwv9f" node="ip-10-0-199-219.us-east-2.compute.internal" evaluatedNodes=6 feasibleNodes=3
2023-01-09T09:55:58.905936740Z I0109 09:55:58.905885       1 schedule_one.go:266] "Successfully bound pod to node" pod="openshift-marketplace/redhat-marketplace-w45f9" node="ip-10-0-199-219.us-east-2.compute.internal" evaluatedNodes=6 feasibleNodes=3
2023-01-09T09:56:05.483008711Z I0109 09:56:05.482944       1 schedule_one.go:826] "Unable to schedule pod; no fit; waiting" pod="openshift-logging/lokistack-sample-ruler-1" err="0/6 nodes are available: 3 Insufficient cpu, 3 node(s) had untolerated taint {node-role.kubernetes.io/master: }. preemption: 0/6 nodes are available: 3 No preemption victims found for incoming pod, 3 Preemption is not helpful for scheduling."
2023-01-09T09:56:05.486225506Z I0109 09:56:05.486191       1 schedule_one.go:826] "Unable to schedule pod; no fit; waiting" pod="openshift-logging/lokistack-sample-ingester-1" err="0/6 nodes are available: 3 Insufficient cpu, 3 node(s) had untolerated taint {node-role.kubernetes.io/master: }. preemption: 0/6 nodes are available: 3 No preemption victims found for incoming pod, 3 Preemption is not helpful for scheduling."
2023-01-09T09:56:16.291815447Z I0109 09:56:16.291772       1 schedule_one.go:826] "Unable to schedule pod; no fit; waiting" pod="openshift-logging/lokistack-sample-ruler-1" err="0/6 nodes are available: 3 Insufficient cpu, 3 node(s) had untolerated taint {node-role.kubernetes.io/master: }. preemption: 0/6 nodes are available: 3 No preemption victims found for incoming pod, 3 Preemption is not helpful for scheduling."
2023-01-09T09:56:16.292377265Z I0109 09:56:16.292323       1 schedule_one.go:826] "Unable to schedule pod; no fit; waiting" pod="openshift-logging/lokistack-sample-ingester-1" err="0/6 nodes are available: 3 Insufficient cpu, 3 node(s) had untolerated taint {node-role.kubernetes.io/master: }. preemption: 0/6 nodes are available: 3 No preemption victims found for incoming pod, 3 Preemption is not helpful for scheduling."
2023-01-09T10:00:00.192628115Z I0109 10:00:00.192591       1 schedule_one.go:266] "Successfully bound pod to node" pod="openshift-operator-lifecycle-manager/collect-profiles-27887640-ln8h5" node="ip-10-0-144-137.us-east-2.compute.internal" evaluatedNodes=6 feasibleNodes=3
2023-01-09T10:00:06.038038263Z I0109 10:00:06.037965       1 schedule_one.go:826] "Unable to schedule pod; no fit; waiting" pod="openshift-logging/lokistack-sample-ruler-1" err="0/6 nodes are available: 3 Insufficient cpu, 3 node(s) had untolerated taint {node-role.kubernetes.io/master: }. preemption: 0/6 nodes are available: 3 No preemption victims found for incoming pod, 3 Preemption is not helpful for scheduling."
2023-01-09T10:00:06.038838512Z I0109 10:00:06.038802       1 schedule_one.go:826] "Unable to schedule pod; no fit; waiting" pod="openshift-logging/lokistack-sample-ingester-1" err="0/6 nodes are available: 3 Insufficient cpu, 3 node(s) had untolerated taint {node-role.kubernetes.io/master: }. preemption: 0/6 nodes are available: 3 No preemption victims found for incoming pod, 3 Preemption is not helpful for scheduling."
2023-01-09T10:00:07.400085350Z I0109 10:00:07.400034       1 schedule_one.go:266] "Successfully bound pod to node" pod="openshift-marketplace/qe-app-registry-846rg" node="ip-10-0-144-137.us-east-2.compute.internal" evaluatedNodes=6 feasibleNodes=3
2023-01-09T10:00:07.401930918Z I0109 10:00:07.401873       1 schedule_one.go:266] "Successfully bound pod to node" pod="openshift-marketplace/redhat-operators-jglps" node="ip-10-0-145-4.us-east-2.compute.internal" evaluatedNodes=6 feasibleNodes=3
2023-01-09T10:00:21.099046966Z I0109 10:00:21.098999       1 schedule_one.go:826] "Unable to schedule pod; no fit; waiting" pod="openshift-logging/lokistack-sample-ruler-1" err="0/6 nodes are available: 3 Insufficient cpu, 3 node(s) had untolerated taint {node-role.kubernetes.io/master: }. preemption: 0/6 nodes are available: 3 No preemption victims found for incoming pod, 3 Preemption is not helpful for scheduling."
2023-01-09T10:00:21.100032890Z I0109 10:00:21.099997       1 schedule_one.go:826] "Unable to schedule pod; no fit; waiting" pod="openshift-logging/lokistack-sample-ingester-1" err="0/6 nodes are available: 3 Insufficient cpu, 3 node(s) had untolerated taint {node-role.kubernetes.io/master: }. preemption: 0/6 nodes are available: 3 No preemption victims found for incoming pod, 3 Preemption is not helpful for scheduling."
2023-01-09T10:00:40.556092310Z I0109 10:00:40.556048       1 schedule_one.go:826] "Unable to schedule pod; no fit; waiting" pod="openshift-logging/lokistack-sample-ruler-1" err="0/6 nodes are available: 3 Insufficient cpu, 3 node(s) had untolerated taint {node-role.kubernetes.io/master: }. preemption: 0/6 nodes are available: 3 No preemption victims found for incoming pod, 3 Preemption is not helpful for scheduling."
2023-01-09T10:00:40.557156610Z I0109 10:00:40.557119       1 schedule_one.go:826] "Unable to schedule pod; no fit; waiting" pod="openshift-logging/lokistack-sample-ingester-1" err="0/6 nodes are available: 3 Insufficient cpu, 3 node(s) had untolerated taint {node-role.kubernetes.io/master: }. preemption: 0/6 nodes are available: 3 No preemption victims found for incoming pod, 3 Preemption is not helpful for scheduling."
2023-01-09T10:04:08.726644155Z I0109 10:04:08.726587       1 schedule_one.go:266] "Successfully bound pod to node" pod="openshift-marketplace/community-operators-k4mgb" node="ip-10-0-145-4.us-east-2.compute.internal" evaluatedNodes=6 feasibleNodes=3
2023-01-09T10:04:31.210658330Z I0109 10:04:31.210612       1 schedule_one.go:826] "Unable to schedule pod; no fit; waiting" pod="openshift-logging/lokistack-sample-ruler-1" err="0/6 nodes are available: 3 Insufficient cpu, 3 node(s) had untolerated taint {node-role.kubernetes.io/master: }. preemption: 0/6 nodes are available: 3 No preemption victims found for incoming pod, 3 Preemption is not helpful for scheduling."
2023-01-09T10:04:31.211366002Z I0109 10:04:31.211305       1 schedule_one.go:826] "Unable to schedule pod; no fit; waiting" pod="openshift-logging/lokistack-sample-ingester-1" err="0/6 nodes are available: 3 Insufficient cpu, 3 node(s) had untolerated taint {node-role.kubernetes.io/master: }. preemption: 0/6 nodes are available: 3 No preemption victims found for incoming pod, 3 Preemption is not helpful for scheduling."
2023-01-09T10:06:44.562976107Z I0109 10:06:44.562930       1 schedule_one.go:266] "Successfully bound pod to node" pod="openshift-marketplace/redhat-marketplace-bxfjj" node="ip-10-0-199-219.us-east-2.compute.internal" evaluatedNodes=6 feasibleNodes=3
2023-01-09T10:06:58.368582001Z I0109 10:06:58.368447       1 schedule_one.go:826] "Unable to schedule pod; no fit; waiting" pod="openshift-logging/lokistack-sample-ruler-1" err="0/6 nodes are available: 3 Insufficient cpu, 3 node(s) had untolerated taint {node-role.kubernetes.io/master: }. preemption: 0/6 nodes are available: 3 No preemption victims found for incoming pod, 3 Preemption is not helpful for scheduling."
2023-01-09T10:06:58.369479890Z I0109 10:06:58.369422       1 schedule_one.go:826] "Unable to schedule pod; no fit; waiting" pod="openshift-logging/lokistack-sample-ingester-1" err="0/6 nodes are available: 3 Insufficient cpu, 3 node(s) had untolerated taint {node-role.kubernetes.io/master: }. preemption: 0/6 nodes are available: 3 No preemption victims found for incoming pod, 3 Preemption is not helpful for scheduling."
2023-01-09T10:10:20.405729811Z I0109 10:10:20.405676       1 schedule_one.go:266] "Successfully bound pod to node" pod="openshift-marketplace/qe-app-registry-ncxld" node="ip-10-0-144-137.us-east-2.compute.internal" evaluatedNodes=6 feasibleNodes=3
2023-01-09T10:10:34.565055385Z I0109 10:10:34.565008       1 schedule_one.go:826] "Unable to schedule pod; no fit; waiting" pod="openshift-logging/lokistack-sample-ruler-1" err="0/6 nodes are available: 3 Insufficient cpu, 3 node(s) had untolerated taint {node-role.kubernetes.io/master: }. preemption: 0/6 nodes are available: 3 No preemption victims found for incoming pod, 3 Preemption is not helpful for scheduling."
2023-01-09T10:10:34.566427339Z I0109 10:10:34.566385       1 schedule_one.go:826] "Unable to schedule pod; no fit; waiting" pod="openshift-logging/lokistack-sample-ingester-1" err="0/6 nodes are available: 3 Insufficient cpu, 3 node(s) had untolerated taint {node-role.kubernetes.io/master: }. preemption: 0/6 nodes are available: 3 No preemption victims found for incoming pod, 3 Preemption is not helpful for scheduling."
2023-01-09T10:11:39.436088793Z I0109 10:11:39.436024       1 schedule_one.go:266] "Successfully bound pod to node" pod="openshift-marketplace/redhat-operators-jmtvg" node="ip-10-0-145-4.us-east-2.compute.internal" evaluatedNodes=6 feasibleNodes=3
2023-01-09T10:12:12.489189741Z I0109 10:12:12.489131       1 schedule_one.go:826] "Unable to schedule pod; no fit; waiting" pod="openshift-logging/lokistack-sample-ruler-1" err="0/6 nodes are available: 3 Insufficient cpu, 3 node(s) had untolerated taint {node-role.kubernetes.io/master: }. preemption: 0/6 nodes are available: 3 No preemption victims found for incoming pod, 3 Preemption is not helpful for scheduling."
2023-01-09T10:12:12.489777073Z I0109 10:12:12.489716       1 schedule_one.go:826] "Unable to schedule pod; no fit; waiting" pod="openshift-logging/lokistack-sample-ingester-1" err="0/6 nodes are available: 3 Insufficient cpu, 3 node(s) had untolerated taint {node-role.kubernetes.io/master: }. preemption: 0/6 nodes are available: 3 No preemption victims found for incoming pod, 3 Preemption is not helpful for scheduling."
2023-01-09T10:12:41.830845094Z I0109 10:12:41.830790       1 schedule_one.go:266] "Successfully bound pod to node" pod="openshift-marketplace/certified-operators-ntrp2" node="ip-10-0-199-219.us-east-2.compute.internal" evaluatedNodes=6 feasibleNodes=3
2023-01-09T10:12:55.443741346Z I0109 10:12:55.443685       1 schedule_one.go:826] "Unable to schedule pod; no fit; waiting" pod="openshift-logging/lokistack-sample-ruler-1" err="0/6 nodes are available: 3 Insufficient cpu, 3 node(s) had untolerated taint {node-role.kubernetes.io/master: }. preemption: 0/6 nodes are available: 3 No preemption victims found for incoming pod, 3 Preemption is not helpful for scheduling."
2023-01-09T10:12:55.444880528Z I0109 10:12:55.444844       1 schedule_one.go:826] "Unable to schedule pod; no fit; waiting" pod="openshift-logging/lokistack-sample-ingester-1" err="0/6 nodes are available: 3 Insufficient cpu, 3 node(s) had untolerated taint {node-role.kubernetes.io/master: }. preemption: 0/6 nodes are available: 3 No preemption victims found for incoming pod, 3 Preemption is not helpful for scheduling."
2023-01-09T10:14:44.976436612Z I0109 10:14:44.976395       1 schedule_one.go:266] "Successfully bound pod to node" pod="openshift-marketplace/community-operators-bw6cm" node="ip-10-0-145-4.us-east-2.compute.internal" evaluatedNodes=6 feasibleNodes=3
2023-01-09T10:15:00.148518659Z I0109 10:15:00.148475       1 schedule_one.go:266] "Successfully bound pod to node" pod="openshift-operator-lifecycle-manager/collect-profiles-27887655-hfqm6" node="ip-10-0-144-137.us-east-2.compute.internal" evaluatedNodes=6 feasibleNodes=3
2023-01-09T10:15:05.188038698Z I0109 10:15:05.187999       1 schedule_one.go:826] "Unable to schedule pod; no fit; waiting" pod="openshift-logging/lokistack-sample-ruler-1" err="0/6 nodes are available: 3 Insufficient cpu, 3 node(s) had untolerated taint {node-role.kubernetes.io/master: }. preemption: 0/6 nodes are available: 3 No preemption victims found for incoming pod, 3 Preemption is not helpful for scheduling."
2023-01-09T10:15:05.188555163Z I0109 10:15:05.188527       1 schedule_one.go:826] "Unable to schedule pod; no fit; waiting" pod="openshift-logging/lokistack-sample-ingester-1" err="0/6 nodes are available: 3 Insufficient cpu, 3 node(s) had untolerated taint {node-role.kubernetes.io/master: }. preemption: 0/6 nodes are available: 3 No preemption victims found for incoming pod, 3 Preemption is not helpful for scheduling."
2023-01-09T10:15:15.954743445Z I0109 10:15:15.954696       1 schedule_one.go:826] "Unable to schedule pod; no fit; waiting" pod="openshift-logging/lokistack-sample-ruler-1" err="0/6 nodes are available: 3 Insufficient cpu, 3 node(s) had untolerated taint {node-role.kubernetes.io/master: }. preemption: 0/6 nodes are available: 3 No preemption victims found for incoming pod, 3 Preemption is not helpful for scheduling."
2023-01-09T10:15:15.955198279Z I0109 10:15:15.955172       1 schedule_one.go:826] "Unable to schedule pod; no fit; waiting" pod="openshift-logging/lokistack-sample-ingester-1" err="0/6 nodes are available: 3 Insufficient cpu, 3 node(s) had untolerated taint {node-role.kubernetes.io/master: }. preemption: 0/6 nodes are available: 3 No preemption victims found for incoming pod, 3 Preemption is not helpful for scheduling."
2023-01-09T10:17:22.419787803Z I0109 10:17:22.419722       1 schedule_one.go:266] "Successfully bound pod to node" pod="openshift-marketplace/redhat-marketplace-pklcb" node="ip-10-0-199-219.us-east-2.compute.internal" evaluatedNodes=6 feasibleNodes=3
2023-01-09T10:17:36.292311830Z I0109 10:17:36.292258       1 schedule_one.go:826] "Unable to schedule pod; no fit; waiting" pod="openshift-logging/lokistack-sample-ruler-1" err="0/6 nodes are available: 3 Insufficient cpu, 3 node(s) had untolerated taint {node-role.kubernetes.io/master: }. preemption: 0/6 nodes are available: 3 No preemption victims found for incoming pod, 3 Preemption is not helpful for scheduling."
2023-01-09T10:17:36.293021504Z I0109 10:17:36.292975       1 schedule_one.go:826] "Unable to schedule pod; no fit; waiting" pod="openshift-logging/lokistack-sample-ingester-1" err="0/6 nodes are available: 3 Insufficient cpu, 3 node(s) had untolerated taint {node-role.kubernetes.io/master: }. preemption: 0/6 nodes are available: 3 No preemption victims found for incoming pod, 3 Preemption is not helpful for scheduling."
2023-01-09T10:21:13.870286446Z I0109 10:21:13.870242       1 schedule_one.go:266] "Successfully bound pod to node" pod="openshift-marketplace/qe-app-registry-c4qtp" node="ip-10-0-144-137.us-east-2.compute.internal" evaluatedNodes=6 feasibleNodes=3
2023-01-09T10:21:28.108653719Z I0109 10:21:28.108609       1 schedule_one.go:826] "Unable to schedule pod; no fit; waiting" pod="openshift-logging/lokistack-sample-ruler-1" err="0/6 nodes are available: 3 Insufficient cpu, 3 node(s) had untolerated taint {node-role.kubernetes.io/master: }. preemption: 0/6 nodes are available: 3 No preemption victims found for incoming pod, 3 Preemption is not helpful for scheduling."
2023-01-09T10:21:28.109226270Z I0109 10:21:28.109194       1 schedule_one.go:826] "Unable to schedule pod; no fit; waiting" pod="openshift-logging/lokistack-sample-ingester-1" err="0/6 nodes are available: 3 Insufficient cpu, 3 node(s) had untolerated taint {node-role.kubernetes.io/master: }. preemption: 0/6 nodes are available: 3 No preemption victims found for incoming pod, 3 Preemption is not helpful for scheduling."
2023-01-09T10:22:09.807951443Z I0109 10:22:09.807905       1 schedule_one.go:266] "Successfully bound pod to node" pod="openshift-marketplace/redhat-operators-jm6hd" node="ip-10-0-145-4.us-east-2.compute.internal" evaluatedNodes=6 feasibleNodes=3
2023-01-09T10:22:42.321788889Z I0109 10:22:42.321741       1 schedule_one.go:826] "Unable to schedule pod; no fit; waiting" pod="openshift-logging/lokistack-sample-ruler-1" err="0/6 nodes are available: 3 Insufficient cpu, 3 node(s) had untolerated taint {node-role.kubernetes.io/master: }. preemption: 0/6 nodes are available: 3 No preemption victims found for incoming pod, 3 Preemption is not helpful for scheduling."
2023-01-09T10:22:42.322710788Z I0109 10:22:42.322671       1 schedule_one.go:826] "Unable to schedule pod; no fit; waiting" pod="openshift-logging/lokistack-sample-ingester-1" err="0/6 nodes are available: 3 Insufficient cpu, 3 node(s) had untolerated taint {node-role.kubernetes.io/master: }. preemption: 0/6 nodes are available: 3 No preemption victims found for incoming pod, 3 Preemption is not helpful for scheduling."
2023-01-09T10:23:00.844572428Z I0109 10:23:00.843324       1 schedule_one.go:266] "Successfully bound pod to node" pod="openshift-marketplace/certified-operators-t2x7l" node="ip-10-0-199-219.us-east-2.compute.internal" evaluatedNodes=6 feasibleNodes=3
2023-01-09T10:23:14.306953581Z I0109 10:23:14.306885       1 schedule_one.go:826] "Unable to schedule pod; no fit; waiting" pod="openshift-logging/lokistack-sample-ruler-1" err="0/6 nodes are available: 3 Insufficient cpu, 3 node(s) had untolerated taint {node-role.kubernetes.io/master: }. preemption: 0/6 nodes are available: 3 No preemption victims found for incoming pod, 3 Preemption is not helpful for scheduling."
2023-01-09T10:23:14.308284056Z I0109 10:23:14.307992       1 schedule_one.go:826] "Unable to schedule pod; no fit; waiting" pod="openshift-logging/lokistack-sample-ingester-1" err="0/6 nodes are available: 3 Insufficient cpu, 3 node(s) had untolerated taint {node-role.kubernetes.io/master: }. preemption: 0/6 nodes are available: 3 No preemption victims found for incoming pod, 3 Preemption is not helpful for scheduling."
2023-01-09T10:25:35.508360027Z I0109 10:25:35.508293       1 schedule_one.go:266] "Successfully bound pod to node" pod="openshift-marketplace/community-operators-mrtwn" node="ip-10-0-145-4.us-east-2.compute.internal" evaluatedNodes=6 feasibleNodes=3
2023-01-09T10:25:58.898377626Z I0109 10:25:58.898314       1 schedule_one.go:826] "Unable to schedule pod; no fit; waiting" pod="openshift-logging/lokistack-sample-ruler-1" err="0/6 nodes are available: 3 Insufficient cpu, 3 node(s) had untolerated taint {node-role.kubernetes.io/master: }. preemption: 0/6 nodes are available: 3 No preemption victims found for incoming pod, 3 Preemption is not helpful for scheduling."
2023-01-09T10:25:58.899158447Z I0109 10:25:58.899121       1 schedule_one.go:826] "Unable to schedule pod; no fit; waiting" pod="openshift-logging/lokistack-sample-ingester-1" err="0/6 nodes are available: 3 Insufficient cpu, 3 node(s) had untolerated taint {node-role.kubernetes.io/master: }. preemption: 0/6 nodes are available: 3 No preemption victims found for incoming pod, 3 Preemption is not helpful for scheduling."
2023-01-09T10:28:41.082412745Z I0109 10:28:41.082362       1 schedule_one.go:266] "Successfully bound pod to node" pod="openshift-marketplace/redhat-marketplace-2fgq4" node="ip-10-0-199-219.us-east-2.compute.internal" evaluatedNodes=6 feasibleNodes=3
2023-01-09T10:28:55.286154706Z I0109 10:28:55.286103       1 schedule_one.go:826] "Unable to schedule pod; no fit; waiting" pod="openshift-logging/lokistack-sample-ruler-1" err="0/6 nodes are available: 3 Insufficient cpu, 3 node(s) had untolerated taint {node-role.kubernetes.io/master: }. preemption: 0/6 nodes are available: 3 No preemption victims found for incoming pod, 3 Preemption is not helpful for scheduling."
2023-01-09T10:28:55.287444429Z I0109 10:28:55.287404       1 schedule_one.go:826] "Unable to schedule pod; no fit; waiting" pod="openshift-logging/lokistack-sample-ingester-1" err="0/6 nodes are available: 3 Insufficient cpu, 3 node(s) had untolerated taint {node-role.kubernetes.io/master: }. preemption: 0/6 nodes are available: 3 No preemption victims found for incoming pod, 3 Preemption is not helpful for scheduling."
2023-01-09T10:30:00.163382505Z I0109 10:30:00.152805       1 schedule_one.go:266] "Successfully bound pod to node" pod="openshift-operator-lifecycle-manager/collect-profiles-27887670-856wh" node="ip-10-0-144-137.us-east-2.compute.internal" evaluatedNodes=6 feasibleNodes=3
2023-01-09T10:30:05.378471458Z I0109 10:30:05.378431       1 schedule_one.go:826] "Unable to schedule pod; no fit; waiting" pod="openshift-logging/lokistack-sample-ruler-1" err="0/6 nodes are available: 3 Insufficient cpu, 3 node(s) had untolerated taint {node-role.kubernetes.io/master: }. preemption: 0/6 nodes are available: 3 No preemption victims found for incoming pod, 3 Preemption is not helpful for scheduling."
2023-01-09T10:30:05.378970316Z I0109 10:30:05.378945       1 schedule_one.go:826] "Unable to schedule pod; no fit; waiting" pod="openshift-logging/lokistack-sample-ingester-1" err="0/6 nodes are available: 3 Insufficient cpu, 3 node(s) had untolerated taint {node-role.kubernetes.io/master: }. preemption: 0/6 nodes are available: 3 No preemption victims found for incoming pod, 3 Preemption is not helpful for scheduling."
2023-01-09T10:31:29.722828107Z I0109 10:31:29.722784       1 schedule_one.go:266] "Successfully bound pod to node" pod="openshift-marketplace/qe-app-registry-rcn79" node="ip-10-0-144-137.us-east-2.compute.internal" evaluatedNodes=6 feasibleNodes=3
2023-01-09T10:31:43.608559157Z I0109 10:31:43.608518       1 schedule_one.go:826] "Unable to schedule pod; no fit; waiting" pod="openshift-logging/lokistack-sample-ruler-1" err="0/6 nodes are available: 3 Insufficient cpu, 3 node(s) had untolerated taint {node-role.kubernetes.io/master: }. preemption: 0/6 nodes are available: 3 No preemption victims found for incoming pod, 3 Preemption is not helpful for scheduling."
2023-01-09T10:31:43.609071245Z I0109 10:31:43.609038       1 schedule_one.go:826] "Unable to schedule pod; no fit; waiting" pod="openshift-logging/lokistack-sample-ingester-1" err="0/6 nodes are available: 3 Insufficient cpu, 3 node(s) had untolerated taint {node-role.kubernetes.io/master: }. preemption: 0/6 nodes are available: 3 No preemption victims found for incoming pod, 3 Preemption is not helpful for scheduling."
2023-01-09T10:33:01.965971106Z I0109 10:33:01.965921       1 schedule_one.go:266] "Successfully bound pod to node" pod="openshift-marketplace/redhat-operators-bllfd" node="ip-10-0-145-4.us-east-2.compute.internal" evaluatedNodes=6 feasibleNodes=3
2023-01-09T10:33:35.189409714Z I0109 10:33:35.189329       1 schedule_one.go:826] "Unable to schedule pod; no fit; waiting" pod="openshift-logging/lokistack-sample-ruler-1" err="0/6 nodes are available: 3 Insufficient cpu, 3 node(s) had untolerated taint {node-role.kubernetes.io/master: }. preemption: 0/6 nodes are available: 3 No preemption victims found for incoming pod, 3 Preemption is not helpful for scheduling."
2023-01-09T10:33:35.190006299Z I0109 10:33:35.189973       1 schedule_one.go:826] "Unable to schedule pod; no fit; waiting" pod="openshift-logging/lokistack-sample-ingester-1" err="0/6 nodes are available: 3 Insufficient cpu, 3 node(s) had untolerated taint {node-role.kubernetes.io/master: }. preemption: 0/6 nodes are available: 3 No preemption victims found for incoming pod, 3 Preemption is not helpful for scheduling."
2023-01-09T10:36:40.416110665Z I0109 10:36:40.416044       1 schedule_one.go:266] "Successfully bound pod to node" pod="openshift-marketplace/community-operators-tv7xp" node="ip-10-0-145-4.us-east-2.compute.internal" evaluatedNodes=6 feasibleNodes=3
2023-01-09T10:36:51.528176021Z I0109 10:36:51.527290       1 schedule_one.go:266] "Successfully bound pod to node" pod="openshift-marketplace/certified-operators-c97bh" node="ip-10-0-199-219.us-east-2.compute.internal" evaluatedNodes=6 feasibleNodes=3
2023-01-09T10:37:03.780801815Z I0109 10:37:03.780750       1 schedule_one.go:826] "Unable to schedule pod; no fit; waiting" pod="openshift-logging/lokistack-sample-ruler-1" err="0/6 nodes are available: 3 Insufficient cpu, 3 node(s) had untolerated taint {node-role.kubernetes.io/master: }. preemption: 0/6 nodes are available: 3 No preemption victims found for incoming pod, 3 Preemption is not helpful for scheduling."
2023-01-09T10:37:03.781749222Z I0109 10:37:03.781718       1 schedule_one.go:826] "Unable to schedule pod; no fit; waiting" pod="openshift-logging/lokistack-sample-ingester-1" err="0/6 nodes are available: 3 Insufficient cpu, 3 node(s) had untolerated taint {node-role.kubernetes.io/master: }. preemption: 0/6 nodes are available: 3 No preemption victims found for incoming pod, 3 Preemption is not helpful for scheduling."
2023-01-09T10:37:14.729094731Z I0109 10:37:14.729049       1 schedule_one.go:826] "Unable to schedule pod; no fit; waiting" pod="openshift-logging/lokistack-sample-ruler-1" err="0/6 nodes are available: 3 Insufficient cpu, 3 node(s) had untolerated taint {node-role.kubernetes.io/master: }. preemption: 0/6 nodes are available: 3 No preemption victims found for incoming pod, 3 Preemption is not helpful for scheduling."
2023-01-09T10:37:14.729644793Z I0109 10:37:14.729613       1 schedule_one.go:826] "Unable to schedule pod; no fit; waiting" pod="openshift-logging/lokistack-sample-ingester-1" err="0/6 nodes are available: 3 Insufficient cpu, 3 node(s) had untolerated taint {node-role.kubernetes.io/master: }. preemption: 0/6 nodes are available: 3 No preemption victims found for incoming pod, 3 Preemption is not helpful for scheduling."
2023-01-09T10:39:15.143771735Z I0109 10:39:15.143696       1 schedule_one.go:266] "Successfully bound pod to node" pod="openshift-marketplace/redhat-marketplace-5wcjp" node="ip-10-0-199-219.us-east-2.compute.internal" evaluatedNodes=6 feasibleNodes=3
2023-01-09T10:39:29.201812055Z I0109 10:39:29.201769       1 schedule_one.go:826] "Unable to schedule pod; no fit; waiting" pod="openshift-logging/lokistack-sample-ruler-1" err="0/6 nodes are available: 3 Insufficient cpu, 3 node(s) had untolerated taint {node-role.kubernetes.io/master: }. preemption: 0/6 nodes are available: 3 No preemption victims found for incoming pod, 3 Preemption is not helpful for scheduling."
2023-01-09T10:39:29.202877837Z I0109 10:39:29.202838       1 schedule_one.go:826] "Unable to schedule pod; no fit; waiting" pod="openshift-logging/lokistack-sample-ingester-1" err="0/6 nodes are available: 3 Insufficient cpu, 3 node(s) had untolerated taint {node-role.kubernetes.io/master: }. preemption: 0/6 nodes are available: 3 No preemption victims found for incoming pod, 3 Preemption is not helpful for scheduling."
2023-01-09T10:42:29.288545005Z I0109 10:42:29.288500       1 schedule_one.go:266] "Successfully bound pod to node" pod="openshift-marketplace/qe-app-registry-6dkpp" node="ip-10-0-144-137.us-east-2.compute.internal" evaluatedNodes=6 feasibleNodes=3
2023-01-09T10:42:43.235623649Z I0109 10:42:43.235575       1 schedule_one.go:826] "Unable to schedule pod; no fit; waiting" pod="openshift-logging/lokistack-sample-ruler-1" err="0/6 nodes are available: 3 Insufficient cpu, 3 node(s) had untolerated taint {node-role.kubernetes.io/master: }. preemption: 0/6 nodes are available: 3 No preemption victims found for incoming pod, 3 Preemption is not helpful for scheduling."
2023-01-09T10:42:43.236243609Z I0109 10:42:43.236207       1 schedule_one.go:826] "Unable to schedule pod; no fit; waiting" pod="openshift-logging/lokistack-sample-ingester-1" err="0/6 nodes are available: 3 Insufficient cpu, 3 node(s) had untolerated taint {node-role.kubernetes.io/master: }. preemption: 0/6 nodes are available: 3 No preemption victims found for incoming pod, 3 Preemption is not helpful for scheduling."
2023-01-09T10:43:48.823326395Z I0109 10:43:48.823261       1 schedule_one.go:266] "Successfully bound pod to node" pod="openshift-marketplace/redhat-operators-52mfx" node="ip-10-0-145-4.us-east-2.compute.internal" evaluatedNodes=6 feasibleNodes=3
2023-01-09T10:44:22.026841856Z I0109 10:44:22.026782       1 schedule_one.go:826] "Unable to schedule pod; no fit; waiting" pod="openshift-logging/lokistack-sample-ruler-1" err="0/6 nodes are available: 3 Insufficient cpu, 3 node(s) had untolerated taint {node-role.kubernetes.io/master: }. preemption: 0/6 nodes are available: 3 No preemption victims found for incoming pod, 3 Preemption is not helpful for scheduling."
2023-01-09T10:44:22.027581853Z I0109 10:44:22.027529       1 schedule_one.go:826] "Unable to schedule pod; no fit; waiting" pod="openshift-logging/lokistack-sample-ingester-1" err="0/6 nodes are available: 3 Insufficient cpu, 3 node(s) had untolerated taint {node-role.kubernetes.io/master: }. preemption: 0/6 nodes are available: 3 No preemption victims found for incoming pod, 3 Preemption is not helpful for scheduling."
2023-01-09T10:45:00.144903600Z I0109 10:45:00.144864       1 schedule_one.go:266] "Successfully bound pod to node" pod="openshift-operator-lifecycle-manager/collect-profiles-27887685-wgz9k" node="ip-10-0-144-137.us-east-2.compute.internal" evaluatedNodes=6 feasibleNodes=3
2023-01-09T10:45:04.564759790Z I0109 10:45:04.564721       1 schedule_one.go:826] "Unable to schedule pod; no fit; waiting" pod="openshift-logging/lokistack-sample-ruler-1" err="0/6 nodes are available: 3 Insufficient cpu, 3 node(s) had untolerated taint {node-role.kubernetes.io/master: }. preemption: 0/6 nodes are available: 3 No preemption victims found for incoming pod, 3 Preemption is not helpful for scheduling."
2023-01-09T10:45:04.565269042Z I0109 10:45:04.565241       1 schedule_one.go:826] "Unable to schedule pod; no fit; waiting" pod="openshift-logging/lokistack-sample-ingester-1" err="0/6 nodes are available: 3 Insufficient cpu, 3 node(s) had untolerated taint {node-role.kubernetes.io/master: }. preemption: 0/6 nodes are available: 3 No preemption victims found for incoming pod, 3 Preemption is not helpful for scheduling."
2023-01-09T10:47:15.947664412Z I0109 10:47:15.947624       1 schedule_one.go:266] "Successfully bound pod to node" pod="openshift-marketplace/community-operators-xzc8v" node="ip-10-0-145-4.us-east-2.compute.internal" evaluatedNodes=6 feasibleNodes=3
2023-01-09T10:47:38.594232553Z I0109 10:47:38.594175       1 schedule_one.go:826] "Unable to schedule pod; no fit; waiting" pod="openshift-logging/lokistack-sample-ruler-1" err="0/6 nodes are available: 3 Insufficient cpu, 3 node(s) had untolerated taint {node-role.kubernetes.io/master: }. preemption: 0/6 nodes are available: 3 No preemption victims found for incoming pod, 3 Preemption is not helpful for scheduling."
2023-01-09T10:47:38.595269957Z I0109 10:47:38.595241       1 schedule_one.go:826] "Unable to schedule pod; no fit; waiting" pod="openshift-logging/lokistack-sample-ingester-1" err="0/6 nodes are available: 3 Insufficient cpu, 3 node(s) had untolerated taint {node-role.kubernetes.io/master: }. preemption: 0/6 nodes are available: 3 No preemption victims found for incoming pod, 3 Preemption is not helpful for scheduling."
2023-01-09T10:47:42.159853301Z I0109 10:47:42.159805       1 schedule_one.go:266] "Successfully bound pod to node" pod="openshift-marketplace/certified-operators-4zwkg" node="ip-10-0-199-219.us-east-2.compute.internal" evaluatedNodes=6 feasibleNodes=3
2023-01-09T10:47:55.681944573Z I0109 10:47:55.681896       1 schedule_one.go:826] "Unable to schedule pod; no fit; waiting" pod="openshift-logging/lokistack-sample-ruler-1" err="0/6 nodes are available: 3 Insufficient cpu, 3 node(s) had untolerated taint {node-role.kubernetes.io/master: }. preemption: 0/6 nodes are available: 3 No preemption victims found for incoming pod, 3 Preemption is not helpful for scheduling."
2023-01-09T10:47:55.683435241Z I0109 10:47:55.683405       1 schedule_one.go:826] "Unable to schedule pod; no fit; waiting" pod="openshift-logging/lokistack-sample-ingester-1" err="0/6 nodes are available: 3 Insufficient cpu, 3 node(s) had untolerated taint {node-role.kubernetes.io/master: }. preemption: 0/6 nodes are available: 3 No preemption victims found for incoming pod, 3 Preemption is not helpful for scheduling."
2023-01-09T10:49:43.363482462Z I0109 10:49:43.363435       1 schedule_one.go:266] "Successfully bound pod to node" pod="openshift-marketplace/redhat-marketplace-9cv2w" node="ip-10-0-199-219.us-east-2.compute.internal" evaluatedNodes=6 feasibleNodes=3
2023-01-09T10:49:57.034250083Z I0109 10:49:57.034200       1 schedule_one.go:826] "Unable to schedule pod; no fit; waiting" pod="openshift-logging/lokistack-sample-ruler-1" err="0/6 nodes are available: 3 Insufficient cpu, 3 node(s) had untolerated taint {node-role.kubernetes.io/master: }. preemption: 0/6 nodes are available: 3 No preemption victims found for incoming pod, 3 Preemption is not helpful for scheduling."
2023-01-09T10:49:57.035239920Z I0109 10:49:57.035206       1 schedule_one.go:826] "Unable to schedule pod; no fit; waiting" pod="openshift-logging/lokistack-sample-ingester-1" err="0/6 nodes are available: 3 Insufficient cpu, 3 node(s) had untolerated taint {node-role.kubernetes.io/master: }. preemption: 0/6 nodes are available: 3 No preemption victims found for incoming pod, 3 Preemption is not helpful for scheduling."
2023-01-09T10:52:29.220967935Z I0109 10:52:29.220925       1 schedule_one.go:266] "Successfully bound pod to node" pod="openshift-marketplace/qe-app-registry-wbnbm" node="ip-10-0-144-137.us-east-2.compute.internal" evaluatedNodes=6 feasibleNodes=3
2023-01-09T10:52:42.701329140Z I0109 10:52:42.701275       1 schedule_one.go:826] "Unable to schedule pod; no fit; waiting" pod="openshift-logging/lokistack-sample-ruler-1" err="0/6 nodes are available: 3 Insufficient cpu, 3 node(s) had untolerated taint {node-role.kubernetes.io/master: }. preemption: 0/6 nodes are available: 3 No preemption victims found for incoming pod, 3 Preemption is not helpful for scheduling."
2023-01-09T10:52:42.702097649Z I0109 10:52:42.702064       1 schedule_one.go:826] "Unable to schedule pod; no fit; waiting" pod="openshift-logging/lokistack-sample-ingester-1" err="0/6 nodes are available: 3 Insufficient cpu, 3 node(s) had untolerated taint {node-role.kubernetes.io/master: }. preemption: 0/6 nodes are available: 3 No preemption victims found for incoming pod, 3 Preemption is not helpful for scheduling."
2023-01-09T10:54:54.498927874Z I0109 10:54:54.498874       1 schedule_one.go:266] "Successfully bound pod to node" pod="openshift-marketplace/redhat-operators-w4j7g" node="ip-10-0-145-4.us-east-2.compute.internal" evaluatedNodes=6 feasibleNodes=3
2023-01-09T10:55:27.926923348Z I0109 10:55:27.926866       1 schedule_one.go:826] "Unable to schedule pod; no fit; waiting" pod="openshift-logging/lokistack-sample-ruler-1" err="0/6 nodes are available: 3 Insufficient cpu, 3 node(s) had untolerated taint {node-role.kubernetes.io/master: }. preemption: 0/6 nodes are available: 3 No preemption victims found for incoming pod, 3 Preemption is not helpful for scheduling."
2023-01-09T10:55:27.927574256Z I0109 10:55:27.927533       1 schedule_one.go:826] "Unable to schedule pod; no fit; waiting" pod="openshift-logging/lokistack-sample-ingester-1" err="0/6 nodes are available: 3 Insufficient cpu, 3 node(s) had untolerated taint {node-role.kubernetes.io/master: }. preemption: 0/6 nodes are available: 3 No preemption victims found for incoming pod, 3 Preemption is not helpful for scheduling."
2023-01-09T10:58:07.863019167Z I0109 10:58:07.862963       1 schedule_one.go:266] "Successfully bound pod to node" pod="openshift-marketplace/community-operators-bpltq" node="ip-10-0-145-4.us-east-2.compute.internal" evaluatedNodes=6 feasibleNodes=3
2023-01-09T10:58:27.985434492Z I0109 10:58:27.985379       1 schedule_one.go:266] "Successfully bound pod to node" pod="openshift-marketplace/certified-operators-b2jn8" node="ip-10-0-199-219.us-east-2.compute.internal" evaluatedNodes=6 feasibleNodes=3
2023-01-09T10:58:30.448467950Z I0109 10:58:30.448424       1 schedule_one.go:826] "Unable to schedule pod; no fit; waiting" pod="openshift-logging/lokistack-sample-ruler-1" err="0/6 nodes are available: 3 Insufficient cpu, 3 node(s) had untolerated taint {node-role.kubernetes.io/master: }. preemption: 0/6 nodes are available: 3 No preemption victims found for incoming pod, 3 Preemption is not helpful for scheduling."
2023-01-09T10:58:30.449266048Z I0109 10:58:30.449232       1 schedule_one.go:826] "Unable to schedule pod; no fit; waiting" pod="openshift-logging/lokistack-sample-ingester-1" err="0/6 nodes are available: 3 Insufficient cpu, 3 node(s) had untolerated taint {node-role.kubernetes.io/master: }. preemption: 0/6 nodes are available: 3 No preemption victims found for incoming pod, 3 Preemption is not helpful for scheduling."
2023-01-09T10:58:41.584833939Z I0109 10:58:41.584773       1 schedule_one.go:826] "Unable to schedule pod; no fit; waiting" pod="openshift-logging/lokistack-sample-ruler-1" err="0/6 nodes are available: 3 Insufficient cpu, 3 node(s) had untolerated taint {node-role.kubernetes.io/master: }. preemption: 0/6 nodes are available: 3 No preemption victims found for incoming pod, 3 Preemption is not helpful for scheduling."
2023-01-09T10:58:41.585747249Z I0109 10:58:41.585701       1 schedule_one.go:826] "Unable to schedule pod; no fit; waiting" pod="openshift-logging/lokistack-sample-ingester-1" err="0/6 nodes are available: 3 Insufficient cpu, 3 node(s) had untolerated taint {node-role.kubernetes.io/master: }. preemption: 0/6 nodes are available: 3 No preemption victims found for incoming pod, 3 Preemption is not helpful for scheduling."
2023-01-09T11:00:00.186322312Z I0109 11:00:00.186270       1 schedule_one.go:266] "Successfully bound pod to node" pod="openshift-operator-lifecycle-manager/collect-profiles-27887700-zhrmw" node="ip-10-0-144-137.us-east-2.compute.internal" evaluatedNodes=6 feasibleNodes=3
2023-01-09T11:00:07.773578297Z I0109 11:00:07.773538       1 schedule_one.go:826] "Unable to schedule pod; no fit; waiting" pod="openshift-logging/lokistack-sample-ruler-1" err="0/6 nodes are available: 3 Insufficient cpu, 3 node(s) had untolerated taint {node-role.kubernetes.io/master: }. preemption: 0/6 nodes are available: 3 No preemption victims found for incoming pod, 3 Preemption is not helpful for scheduling."
2023-01-09T11:00:07.774098885Z I0109 11:00:07.774066       1 schedule_one.go:826] "Unable to schedule pod; no fit; waiting" pod="openshift-logging/lokistack-sample-ingester-1" err="0/6 nodes are available: 3 Insufficient cpu, 3 node(s) had untolerated taint {node-role.kubernetes.io/master: }. preemption: 0/6 nodes are available: 3 No preemption victims found for incoming pod, 3 Preemption is not helpful for scheduling."
2023-01-09T11:00:39.575930277Z I0109 11:00:39.575880       1 schedule_one.go:266] "Successfully bound pod to node" pod="openshift-marketplace/redhat-marketplace-d9hrm" node="ip-10-0-199-219.us-east-2.compute.internal" evaluatedNodes=6 feasibleNodes=3
2023-01-09T11:00:54.130582414Z I0109 11:00:54.124171       1 schedule_one.go:826] "Unable to schedule pod; no fit; waiting" pod="openshift-logging/lokistack-sample-ruler-1" err="0/6 nodes are available: 3 Insufficient cpu, 3 node(s) had untolerated taint {node-role.kubernetes.io/master: }. preemption: 0/6 nodes are available: 3 No preemption victims found for incoming pod, 3 Preemption is not helpful for scheduling."
2023-01-09T11:00:54.130582414Z I0109 11:00:54.125723       1 schedule_one.go:826] "Unable to schedule pod; no fit; waiting" pod="openshift-logging/lokistack-sample-ingester-1" err="0/6 nodes are available: 3 Insufficient cpu, 3 node(s) had untolerated taint {node-role.kubernetes.io/master: }. preemption: 0/6 nodes are available: 3 No preemption victims found for incoming pod, 3 Preemption is not helpful for scheduling."
2023-01-09T11:02:45.526698665Z I0109 11:02:45.526641       1 schedule_one.go:266] "Successfully bound pod to node" pod="openshift-marketplace/qe-app-registry-b9chw" node="ip-10-0-144-137.us-east-2.compute.internal" evaluatedNodes=6 feasibleNodes=3
2023-01-09T11:03:00.179965233Z I0109 11:03:00.179921       1 schedule_one.go:826] "Unable to schedule pod; no fit; waiting" pod="openshift-logging/lokistack-sample-ruler-1" err="0/6 nodes are available: 3 Insufficient cpu, 3 node(s) had untolerated taint {node-role.kubernetes.io/master: }. preemption: 0/6 nodes are available: 3 No preemption victims found for incoming pod, 3 Preemption is not helpful for scheduling."
2023-01-09T11:03:00.180688991Z I0109 11:03:00.180654       1 schedule_one.go:826] "Unable to schedule pod; no fit; waiting" pod="openshift-logging/lokistack-sample-ingester-1" err="0/6 nodes are available: 3 Insufficient cpu, 3 node(s) had untolerated taint {node-role.kubernetes.io/master: }. preemption: 0/6 nodes are available: 3 No preemption victims found for incoming pod, 3 Preemption is not helpful for scheduling."
2023-01-09T11:05:22.956770853Z I0109 11:05:22.956693       1 schedule_one.go:266] "Successfully bound pod to node" pod="openshift-marketplace/redhat-operators-wsxcj" node="ip-10-0-145-4.us-east-2.compute.internal" evaluatedNodes=6 feasibleNodes=3
2023-01-09T11:05:55.759186828Z I0109 11:05:55.759141       1 schedule_one.go:826] "Unable to schedule pod; no fit; waiting" pod="openshift-logging/lokistack-sample-ruler-1" err="0/6 nodes are available: 3 Insufficient cpu, 3 node(s) had untolerated taint {node-role.kubernetes.io/master: }. preemption: 0/6 nodes are available: 3 No preemption victims found for incoming pod, 3 Preemption is not helpful for scheduling."
2023-01-09T11:05:55.759863585Z I0109 11:05:55.759831       1 schedule_one.go:826] "Unable to schedule pod; no fit; waiting" pod="openshift-logging/lokistack-sample-ingester-1" err="0/6 nodes are available: 3 Insufficient cpu, 3 node(s) had untolerated taint {node-role.kubernetes.io/master: }. preemption: 0/6 nodes are available: 3 No preemption victims found for incoming pod, 3 Preemption is not helpful for scheduling."
2023-01-09T11:08:58.114966883Z I0109 11:08:58.114896       1 schedule_one.go:266] "Successfully bound pod to node" pod="openshift-marketplace/community-operators-knrlb" node="ip-10-0-145-4.us-east-2.compute.internal" evaluatedNodes=6 feasibleNodes=3
2023-01-09T11:09:21.343398363Z I0109 11:09:21.343302       1 schedule_one.go:826] "Unable to schedule pod; no fit; waiting" pod="openshift-logging/lokistack-sample-ruler-1" err="0/6 nodes are available: 3 Insufficient cpu, 3 node(s) had untolerated taint {node-role.kubernetes.io/master: }. preemption: 0/6 nodes are available: 3 No preemption victims found for incoming pod, 3 Preemption is not helpful for scheduling."
2023-01-09T11:09:21.344451819Z I0109 11:09:21.344401       1 schedule_one.go:826] "Unable to schedule pod; no fit; waiting" pod="openshift-logging/lokistack-sample-ingester-1" err="0/6 nodes are available: 3 Insufficient cpu, 3 node(s) had untolerated taint {node-role.kubernetes.io/master: }. preemption: 0/6 nodes are available: 3 No preemption victims found for incoming pod, 3 Preemption is not helpful for scheduling."
2023-01-09T11:09:31.702699374Z I0109 11:09:31.702654       1 schedule_one.go:266] "Successfully bound pod to node" pod="openshift-marketplace/certified-operators-d6ggn" node="ip-10-0-199-219.us-east-2.compute.internal" evaluatedNodes=6 feasibleNodes=3
2023-01-09T11:09:45.554428787Z I0109 11:09:45.554386       1 schedule_one.go:826] "Unable to schedule pod; no fit; waiting" pod="openshift-logging/lokistack-sample-ruler-1" err="0/6 nodes are available: 3 Insufficient cpu, 3 node(s) had untolerated taint {node-role.kubernetes.io/master: }. preemption: 0/6 nodes are available: 3 No preemption victims found for incoming pod, 3 Preemption is not helpful for scheduling."
2023-01-09T11:09:45.555172599Z I0109 11:09:45.555087       1 schedule_one.go:826] "Unable to schedule pod; no fit; waiting" pod="openshift-logging/lokistack-sample-ingester-1" err="0/6 nodes are available: 3 Insufficient cpu, 3 node(s) had untolerated taint {node-role.kubernetes.io/master: }. preemption: 0/6 nodes are available: 3 No preemption victims found for incoming pod, 3 Preemption is not helpful for scheduling."
2023-01-09T11:11:19.083512044Z I0109 11:11:19.083467       1 schedule_one.go:266] "Successfully bound pod to node" pod="openshift-marketplace/redhat-marketplace-j4t5l" node="ip-10-0-199-219.us-east-2.compute.internal" evaluatedNodes=6 feasibleNodes=3
2023-01-09T11:11:32.877582168Z I0109 11:11:32.877535       1 schedule_one.go:826] "Unable to schedule pod; no fit; waiting" pod="openshift-logging/lokistack-sample-ruler-1" err="0/6 nodes are available: 3 Insufficient cpu, 3 node(s) had untolerated taint {node-role.kubernetes.io/master: }. preemption: 0/6 nodes are available: 3 No preemption victims found for incoming pod, 3 Preemption is not helpful for scheduling."
2023-01-09T11:11:32.878811210Z I0109 11:11:32.878775       1 schedule_one.go:826] "Unable to schedule pod; no fit; waiting" pod="openshift-logging/lokistack-sample-ingester-1" err="0/6 nodes are available: 3 Insufficient cpu, 3 node(s) had untolerated taint {node-role.kubernetes.io/master: }. preemption: 0/6 nodes are available: 3 No preemption victims found for incoming pod, 3 Preemption is not helpful for scheduling."
2023-01-09T11:13:14.394053443Z I0109 11:13:14.393993       1 schedule_one.go:266] "Successfully bound pod to node" pod="openshift-marketplace/qe-app-registry-rkh6b" node="ip-10-0-144-137.us-east-2.compute.internal" evaluatedNodes=6 feasibleNodes=3
2023-01-09T11:13:28.688797308Z I0109 11:13:28.688751       1 schedule_one.go:826] "Unable to schedule pod; no fit; waiting" pod="openshift-logging/lokistack-sample-ruler-1" err="0/6 nodes are available: 3 Insufficient cpu, 3 node(s) had untolerated taint {node-role.kubernetes.io/master: }. preemption: 0/6 nodes are available: 3 No preemption victims found for incoming pod, 3 Preemption is not helpful for scheduling."
2023-01-09T11:13:28.689583641Z I0109 11:13:28.689547       1 schedule_one.go:826] "Unable to schedule pod; no fit; waiting" pod="openshift-logging/lokistack-sample-ingester-1" err="0/6 nodes are available: 3 Insufficient cpu, 3 node(s) had untolerated taint {node-role.kubernetes.io/master: }. preemption: 0/6 nodes are available: 3 No preemption victims found for incoming pod, 3 Preemption is not helpful for scheduling."
2023-01-09T11:15:00.158713604Z I0109 11:15:00.158670       1 schedule_one.go:266] "Successfully bound pod to node" pod="openshift-operator-lifecycle-manager/collect-profiles-27887715-4rcdd" node="ip-10-0-144-137.us-east-2.compute.internal" evaluatedNodes=6 feasibleNodes=3
2023-01-09T11:15:05.919461738Z I0109 11:15:05.919413       1 schedule_one.go:826] "Unable to schedule pod; no fit; waiting" pod="openshift-logging/lokistack-sample-ruler-1" err="0/6 nodes are available: 3 Insufficient cpu, 3 node(s) had untolerated taint {node-role.kubernetes.io/master: }. preemption: 0/6 nodes are available: 3 No preemption victims found for incoming pod, 3 Preemption is not helpful for scheduling."
2023-01-09T11:15:05.919983467Z I0109 11:15:05.919950       1 schedule_one.go:826] "Unable to schedule pod; no fit; waiting" pod="openshift-logging/lokistack-sample-ingester-1" err="0/6 nodes are available: 3 Insufficient cpu, 3 node(s) had untolerated taint {node-role.kubernetes.io/master: }. preemption: 0/6 nodes are available: 3 No preemption victims found for incoming pod, 3 Preemption is not helpful for scheduling."
2023-01-09T11:16:04.763142296Z I0109 11:16:04.763101       1 schedule_one.go:266] "Successfully bound pod to node" pod="openshift-marketplace/redhat-operators-qdcfh" node="ip-10-0-145-4.us-east-2.compute.internal" evaluatedNodes=6 feasibleNodes=3
2023-01-09T11:16:37.579166449Z I0109 11:16:37.579121       1 schedule_one.go:826] "Unable to schedule pod; no fit; waiting" pod="openshift-logging/lokistack-sample-ruler-1" err="0/6 nodes are available: 3 Insufficient cpu, 3 node(s) had untolerated taint {node-role.kubernetes.io/master: }. preemption: 0/6 nodes are available: 3 No preemption victims found for incoming pod, 3 Preemption is not helpful for scheduling."
2023-01-09T11:16:37.580042199Z I0109 11:16:37.580004       1 schedule_one.go:826] "Unable to schedule pod; no fit; waiting" pod="openshift-logging/lokistack-sample-ingester-1" err="0/6 nodes are available: 3 Insufficient cpu, 3 node(s) had untolerated taint {node-role.kubernetes.io/master: }. preemption: 0/6 nodes are available: 3 No preemption victims found for incoming pod, 3 Preemption is not helpful for scheduling."
2023-01-09T11:19:49.639641619Z I0109 11:19:49.639561       1 schedule_one.go:266] "Successfully bound pod to node" pod="openshift-marketplace/community-operators-2jlhm" node="ip-10-0-145-4.us-east-2.compute.internal" evaluatedNodes=6 feasibleNodes=3
2023-01-09T11:20:12.178150116Z I0109 11:20:12.178102       1 schedule_one.go:826] "Unable to schedule pod; no fit; waiting" pod="openshift-logging/lokistack-sample-ruler-1" err="0/6 nodes are available: 3 Insufficient cpu, 3 node(s) had untolerated taint {node-role.kubernetes.io/master: }. preemption: 0/6 nodes are available: 3 No preemption victims found for incoming pod, 3 Preemption is not helpful for scheduling."
2023-01-09T11:20:12.178821234Z I0109 11:20:12.178782       1 schedule_one.go:826] "Unable to schedule pod; no fit; waiting" pod="openshift-logging/lokistack-sample-ingester-1" err="0/6 nodes are available: 3 Insufficient cpu, 3 node(s) had untolerated taint {node-role.kubernetes.io/master: }. preemption: 0/6 nodes are available: 3 No preemption victims found for incoming pod, 3 Preemption is not helpful for scheduling."
2023-01-09T11:22:17.120162930Z I0109 11:22:17.120115       1 schedule_one.go:266] "Successfully bound pod to node" pod="openshift-marketplace/redhat-marketplace-qmsng" node="ip-10-0-199-219.us-east-2.compute.internal" evaluatedNodes=6 feasibleNodes=3
2023-01-09T11:22:30.801537739Z I0109 11:22:30.801466       1 schedule_one.go:826] "Unable to schedule pod; no fit; waiting" pod="openshift-logging/lokistack-sample-ruler-1" err="0/6 nodes are available: 3 Insufficient cpu, 3 node(s) had untolerated taint {node-role.kubernetes.io/master: }. preemption: 0/6 nodes are available: 3 No preemption victims found for incoming pod, 3 Preemption is not helpful for scheduling."
2023-01-09T11:22:30.802430298Z I0109 11:22:30.802373       1 schedule_one.go:826] "Unable to schedule pod; no fit; waiting" pod="openshift-logging/lokistack-sample-ingester-1" err="0/6 nodes are available: 3 Insufficient cpu, 3 node(s) had untolerated taint {node-role.kubernetes.io/master: }. preemption: 0/6 nodes are available: 3 No preemption victims found for incoming pod, 3 Preemption is not helpful for scheduling."
2023-01-09T11:23:44.567972950Z I0109 11:23:44.567919       1 schedule_one.go:266] "Successfully bound pod to node" pod="openshift-marketplace/certified-operators-nxjvj" node="ip-10-0-199-219.us-east-2.compute.internal" evaluatedNodes=6 feasibleNodes=3
2023-01-09T11:23:44.615757545Z I0109 11:23:44.615711       1 schedule_one.go:266] "Successfully bound pod to node" pod="openshift-marketplace/qe-app-registry-2k7xg" node="ip-10-0-144-137.us-east-2.compute.internal" evaluatedNodes=6 feasibleNodes=3
2023-01-09T11:23:58.068158858Z I0109 11:23:58.067965       1 schedule_one.go:826] "Unable to schedule pod; no fit; waiting" pod="openshift-logging/lokistack-sample-ruler-1" err="0/6 nodes are available: 3 Insufficient cpu, 3 node(s) had untolerated taint {node-role.kubernetes.io/master: }. preemption: 0/6 nodes are available: 3 No preemption victims found for incoming pod, 3 Preemption is not helpful for scheduling."
2023-01-09T11:23:58.069201001Z I0109 11:23:58.069153       1 schedule_one.go:826] "Unable to schedule pod; no fit; waiting" pod="openshift-logging/lokistack-sample-ingester-1" err="0/6 nodes are available: 3 Insufficient cpu, 3 node(s) had untolerated taint {node-role.kubernetes.io/master: }. preemption: 0/6 nodes are available: 3 No preemption victims found for incoming pod, 3 Preemption is not helpful for scheduling."
2023-01-09T11:24:08.473417613Z I0109 11:24:08.473364       1 schedule_one.go:826] "Unable to schedule pod; no fit; waiting" pod="openshift-logging/lokistack-sample-ruler-1" err="0/6 nodes are available: 3 Insufficient cpu, 3 node(s) had untolerated taint {node-role.kubernetes.io/master: }. preemption: 0/6 nodes are available: 3 No preemption victims found for incoming pod, 3 Preemption is not helpful for scheduling."
2023-01-09T11:24:08.473874555Z I0109 11:24:08.473851       1 schedule_one.go:826] "Unable to schedule pod; no fit; waiting" pod="openshift-logging/lokistack-sample-ingester-1" err="0/6 nodes are available: 3 Insufficient cpu, 3 node(s) had untolerated taint {node-role.kubernetes.io/master: }. preemption: 0/6 nodes are available: 3 No preemption victims found for incoming pod, 3 Preemption is not helpful for scheduling."
2023-01-09T11:26:14.678011207Z I0109 11:26:14.677970       1 schedule_one.go:266] "Successfully bound pod to node" pod="openshift-marketplace/redhat-operators-4zmd7" node="ip-10-0-145-4.us-east-2.compute.internal" evaluatedNodes=6 feasibleNodes=3
2023-01-09T11:26:47.303996230Z I0109 11:26:47.303934       1 schedule_one.go:826] "Unable to schedule pod; no fit; waiting" pod="openshift-logging/lokistack-sample-ruler-1" err="0/6 nodes are available: 3 Insufficient cpu, 3 node(s) had untolerated taint {node-role.kubernetes.io/master: }. preemption: 0/6 nodes are available: 3 No preemption victims found for incoming pod, 3 Preemption is not helpful for scheduling."
2023-01-09T11:26:47.304599424Z I0109 11:26:47.304568       1 schedule_one.go:826] "Unable to schedule pod; no fit; waiting" pod="openshift-logging/lokistack-sample-ingester-1" err="0/6 nodes are available: 3 Insufficient cpu, 3 node(s) had untolerated taint {node-role.kubernetes.io/master: }. preemption: 0/6 nodes are available: 3 No preemption victims found for incoming pod, 3 Preemption is not helpful for scheduling."
2023-01-09T11:30:00.151965664Z I0109 11:30:00.151929       1 schedule_one.go:266] "Successfully bound pod to node" pod="openshift-operator-lifecycle-manager/collect-profiles-27887730-ljsxb" node="ip-10-0-144-137.us-east-2.compute.internal" evaluatedNodes=6 feasibleNodes=3
2023-01-09T11:30:05.067137661Z I0109 11:30:05.067098       1 schedule_one.go:826] "Unable to schedule pod; no fit; waiting" pod="openshift-logging/lokistack-sample-ruler-1" err="0/6 nodes are available: 3 Insufficient cpu, 3 node(s) had untolerated taint {node-role.kubernetes.io/master: }. preemption: 0/6 nodes are available: 3 No preemption victims found for incoming pod, 3 Preemption is not helpful for scheduling."
2023-01-09T11:30:05.067785159Z I0109 11:30:05.067740       1 schedule_one.go:826] "Unable to schedule pod; no fit; waiting" pod="openshift-logging/lokistack-sample-ingester-1" err="0/6 nodes are available: 3 Insufficient cpu, 3 node(s) had untolerated taint {node-role.kubernetes.io/master: }. preemption: 0/6 nodes are available: 3 No preemption victims found for incoming pod, 3 Preemption is not helpful for scheduling."
2023-01-09T11:30:18.677140588Z I0109 11:30:18.677081       1 schedule_one.go:266] "Successfully bound pod to node" pod="openshift-marketplace/community-operators-tvxkp" node="ip-10-0-145-4.us-east-2.compute.internal" evaluatedNodes=6 feasibleNodes=3
2023-01-09T11:30:42.000809772Z I0109 11:30:42.000761       1 schedule_one.go:826] "Unable to schedule pod; no fit; waiting" pod="openshift-logging/lokistack-sample-ruler-1" err="0/6 nodes are available: 3 Insufficient cpu, 3 node(s) had untolerated taint {node-role.kubernetes.io/master: }. preemption: 0/6 nodes are available: 3 No preemption victims found for incoming pod, 3 Preemption is not helpful for scheduling."
2023-01-09T11:30:42.001623898Z I0109 11:30:42.001571       1 schedule_one.go:826] "Unable to schedule pod; no fit; waiting" pod="openshift-logging/lokistack-sample-ingester-1" err="0/6 nodes are available: 3 Insufficient cpu, 3 node(s) had untolerated taint {node-role.kubernetes.io/master: }. preemption: 0/6 nodes are available: 3 No preemption victims found for incoming pod, 3 Preemption is not helpful for scheduling."
2023-01-09T11:32:38.047463316Z I0109 11:32:38.047419       1 schedule_one.go:266] "Successfully bound pod to node" pod="openshift-marketplace/redhat-marketplace-r7t4b" node="ip-10-0-199-219.us-east-2.compute.internal" evaluatedNodes=6 feasibleNodes=3
2023-01-09T11:32:51.645053752Z I0109 11:32:51.645004       1 schedule_one.go:826] "Unable to schedule pod; no fit; waiting" pod="openshift-logging/lokistack-sample-ruler-1" err="0/6 nodes are available: 3 Insufficient cpu, 3 node(s) had untolerated taint {node-role.kubernetes.io/master: }. preemption: 0/6 nodes are available: 3 No preemption victims found for incoming pod, 3 Preemption is not helpful for scheduling."
2023-01-09T11:32:51.646175312Z I0109 11:32:51.646134       1 schedule_one.go:826] "Unable to schedule pod; no fit; waiting" pod="openshift-logging/lokistack-sample-ingester-1" err="0/6 nodes are available: 3 Insufficient cpu, 3 node(s) had untolerated taint {node-role.kubernetes.io/master: }. preemption: 0/6 nodes are available: 3 No preemption victims found for incoming pod, 3 Preemption is not helpful for scheduling."
2023-01-09T11:34:57.943529414Z I0109 11:34:57.943480       1 schedule_one.go:266] "Successfully bound pod to node" pod="openshift-marketplace/qe-app-registry-gmpq2" node="ip-10-0-144-137.us-east-2.compute.internal" evaluatedNodes=6 feasibleNodes=3
2023-01-09T11:35:05.067777454Z I0109 11:35:05.067700       1 schedule_one.go:266] "Successfully bound pod to node" pod="openshift-marketplace/certified-operators-5sg6t" node="ip-10-0-199-219.us-east-2.compute.internal" evaluatedNodes=6 feasibleNodes=3
2023-01-09T11:35:11.793319703Z I0109 11:35:11.793276       1 schedule_one.go:826] "Unable to schedule pod; no fit; waiting" pod="openshift-logging/lokistack-sample-ruler-1" err="0/6 nodes are available: 3 Insufficient cpu, 3 node(s) had untolerated taint {node-role.kubernetes.io/master: }. preemption: 0/6 nodes are available: 3 No preemption victims found for incoming pod, 3 Preemption is not helpful for scheduling."
2023-01-09T11:35:11.793998849Z I0109 11:35:11.793965       1 schedule_one.go:826] "Unable to schedule pod; no fit; waiting" pod="openshift-logging/lokistack-sample-ingester-1" err="0/6 nodes are available: 3 Insufficient cpu, 3 node(s) had untolerated taint {node-role.kubernetes.io/master: }. preemption: 0/6 nodes are available: 3 No preemption victims found for incoming pod, 3 Preemption is not helpful for scheduling."
2023-01-09T11:35:21.871315784Z I0109 11:35:21.871271       1 schedule_one.go:826] "Unable to schedule pod; no fit; waiting" pod="openshift-logging/lokistack-sample-ruler-1" err="0/6 nodes are available: 3 Insufficient cpu, 3 node(s) had untolerated taint {node-role.kubernetes.io/master: }. preemption: 0/6 nodes are available: 3 No preemption victims found for incoming pod, 3 Preemption is not helpful for scheduling."
2023-01-09T11:35:21.871860476Z I0109 11:35:21.871831       1 schedule_one.go:826] "Unable to schedule pod; no fit; waiting" pod="openshift-logging/lokistack-sample-ingester-1" err="0/6 nodes are available: 3 Insufficient cpu, 3 node(s) had untolerated taint {node-role.kubernetes.io/master: }. preemption: 0/6 nodes are available: 3 No preemption victims found for incoming pod, 3 Preemption is not helpful for scheduling."
2023-01-09T11:37:39.689320095Z I0109 11:37:39.689272       1 schedule_one.go:266] "Successfully bound pod to node" pod="openshift-marketplace/redhat-operators-s82wg" node="ip-10-0-145-4.us-east-2.compute.internal" evaluatedNodes=6 feasibleNodes=3
2023-01-09T11:38:12.277751721Z I0109 11:38:12.277702       1 schedule_one.go:826] "Unable to schedule pod; no fit; waiting" pod="openshift-logging/lokistack-sample-ruler-1" err="0/6 nodes are available: 3 Insufficient cpu, 3 node(s) had untolerated taint {node-role.kubernetes.io/master: }. preemption: 0/6 nodes are available: 3 No preemption victims found for incoming pod, 3 Preemption is not helpful for scheduling."
2023-01-09T11:38:12.278663851Z I0109 11:38:12.278624       1 schedule_one.go:826] "Unable to schedule pod; no fit; waiting" pod="openshift-logging/lokistack-sample-ingester-1" err="0/6 nodes are available: 3 Insufficient cpu, 3 node(s) had untolerated taint {node-role.kubernetes.io/master: }. preemption: 0/6 nodes are available: 3 No preemption victims found for incoming pod, 3 Preemption is not helpful for scheduling."
2023-01-09T11:42:30.436434731Z I0109 11:42:30.436379       1 schedule_one.go:266] "Successfully bound pod to node" pod="openshift-marketplace/community-operators-qldq9" node="ip-10-0-145-4.us-east-2.compute.internal" evaluatedNodes=6 feasibleNodes=3
2023-01-09T11:42:53.059572706Z I0109 11:42:53.059528       1 schedule_one.go:826] "Unable to schedule pod; no fit; waiting" pod="openshift-logging/lokistack-sample-ruler-1" err="0/6 nodes are available: 3 Insufficient cpu, 3 node(s) had untolerated taint {node-role.kubernetes.io/master: }. preemption: 0/6 nodes are available: 3 No preemption victims found for incoming pod, 3 Preemption is not helpful for scheduling."
2023-01-09T11:42:53.060191178Z I0109 11:42:53.060157       1 schedule_one.go:826] "Unable to schedule pod; no fit; waiting" pod="openshift-logging/lokistack-sample-ingester-1" err="0/6 nodes are available: 3 Insufficient cpu, 3 node(s) had untolerated taint {node-role.kubernetes.io/master: }. preemption: 0/6 nodes are available: 3 No preemption victims found for incoming pod, 3 Preemption is not helpful for scheduling."
2023-01-09T11:43:35.132995432Z I0109 11:43:35.132948       1 schedule_one.go:266] "Successfully bound pod to node" pod="openshift-marketplace/redhat-marketplace-6d726" node="ip-10-0-199-219.us-east-2.compute.internal" evaluatedNodes=6 feasibleNodes=3
2023-01-09T11:43:48.692396909Z I0109 11:43:48.692350       1 schedule_one.go:826] "Unable to schedule pod; no fit; waiting" pod="openshift-logging/lokistack-sample-ruler-1" err="0/6 nodes are available: 3 Insufficient cpu, 3 node(s) had untolerated taint {node-role.kubernetes.io/master: }. preemption: 0/6 nodes are available: 3 No preemption victims found for incoming pod, 3 Preemption is not helpful for scheduling."
2023-01-09T11:43:48.693566674Z I0109 11:43:48.693536       1 schedule_one.go:826] "Unable to schedule pod; no fit; waiting" pod="openshift-logging/lokistack-sample-ingester-1" err="0/6 nodes are available: 3 Insufficient cpu, 3 node(s) had untolerated taint {node-role.kubernetes.io/master: }. preemption: 0/6 nodes are available: 3 No preemption victims found for incoming pod, 3 Preemption is not helpful for scheduling."
2023-01-09T11:45:00.150619715Z I0109 11:45:00.150560       1 schedule_one.go:266] "Successfully bound pod to node" pod="openshift-operator-lifecycle-manager/collect-profiles-27887745-g8bdk" node="ip-10-0-144-137.us-east-2.compute.internal" evaluatedNodes=6 feasibleNodes=3
2023-01-09T11:45:05.213095711Z I0109 11:45:05.213052       1 schedule_one.go:826] "Unable to schedule pod; no fit; waiting" pod="openshift-logging/lokistack-sample-ruler-1" err="0/6 nodes are available: 3 Insufficient cpu, 3 node(s) had untolerated taint {node-role.kubernetes.io/master: }. preemption: 0/6 nodes are available: 3 No preemption victims found for incoming pod, 3 Preemption is not helpful for scheduling."
2023-01-09T11:45:05.213713077Z I0109 11:45:05.213681       1 schedule_one.go:826] "Unable to schedule pod; no fit; waiting" pod="openshift-logging/lokistack-sample-ingester-1" err="0/6 nodes are available: 3 Insufficient cpu, 3 node(s) had untolerated taint {node-role.kubernetes.io/master: }. preemption: 0/6 nodes are available: 3 No preemption victims found for incoming pod, 3 Preemption is not helpful for scheduling."
2023-01-09T11:45:29.698150561Z I0109 11:45:29.698084       1 schedule_one.go:266] "Successfully bound pod to node" pod="openshift-marketplace/qe-app-registry-lvbfs" node="ip-10-0-144-137.us-east-2.compute.internal" evaluatedNodes=6 feasibleNodes=3
2023-01-09T11:45:44.310196060Z I0109 11:45:44.310137       1 schedule_one.go:826] "Unable to schedule pod; no fit; waiting" pod="openshift-logging/lokistack-sample-ruler-1" err="0/6 nodes are available: 3 Insufficient cpu, 3 node(s) had untolerated taint {node-role.kubernetes.io/master: }. preemption: 0/6 nodes are available: 3 No preemption victims found for incoming pod, 3 Preemption is not helpful for scheduling."
2023-01-09T11:45:44.310827025Z I0109 11:45:44.310797       1 schedule_one.go:826] "Unable to schedule pod; no fit; waiting" pod="openshift-logging/lokistack-sample-ingester-1" err="0/6 nodes are available: 3 Insufficient cpu, 3 node(s) had untolerated taint {node-role.kubernetes.io/master: }. preemption: 0/6 nodes are available: 3 No preemption victims found for incoming pod, 3 Preemption is not helpful for scheduling."
2023-01-09T11:48:29.541327707Z I0109 11:48:29.541269       1 schedule_one.go:266] "Successfully bound pod to node" pod="openshift-marketplace/redhat-operators-jnpgv" node="ip-10-0-145-4.us-east-2.compute.internal" evaluatedNodes=6 feasibleNodes=3
2023-01-09T11:48:37.286141603Z I0109 11:48:37.286096       1 schedule_one.go:266] "Successfully bound pod to node" pod="openshift-marketplace/certified-operators-29knl" node="ip-10-0-199-219.us-east-2.compute.internal" evaluatedNodes=6 feasibleNodes=3
2023-01-09T11:48:51.585240943Z I0109 11:48:51.585195       1 schedule_one.go:826] "Unable to schedule pod; no fit; waiting" pod="openshift-logging/lokistack-sample-ruler-1" err="0/6 nodes are available: 3 Insufficient cpu, 3 node(s) had untolerated taint {node-role.kubernetes.io/master: }. preemption: 0/6 nodes are available: 3 No preemption victims found for incoming pod, 3 Preemption is not helpful for scheduling."
2023-01-09T11:48:51.586800087Z I0109 11:48:51.586768       1 schedule_one.go:826] "Unable to schedule pod; no fit; waiting" pod="openshift-logging/lokistack-sample-ingester-1" err="0/6 nodes are available: 3 Insufficient cpu, 3 node(s) had untolerated taint {node-role.kubernetes.io/master: }. preemption: 0/6 nodes are available: 3 No preemption victims found for incoming pod, 3 Preemption is not helpful for scheduling."
2023-01-09T11:49:02.097353071Z I0109 11:49:02.097290       1 schedule_one.go:826] "Unable to schedule pod; no fit; waiting" pod="openshift-logging/lokistack-sample-ruler-1" err="0/6 nodes are available: 3 Insufficient cpu, 3 node(s) had untolerated taint {node-role.kubernetes.io/master: }. preemption: 0/6 nodes are available: 3 No preemption victims found for incoming pod, 3 Preemption is not helpful for scheduling."
2023-01-09T11:49:02.097983853Z I0109 11:49:02.097950       1 schedule_one.go:826] "Unable to schedule pod; no fit; waiting" pod="openshift-logging/lokistack-sample-ingester-1" err="0/6 nodes are available: 3 Insufficient cpu, 3 node(s) had untolerated taint {node-role.kubernetes.io/master: }. preemption: 0/6 nodes are available: 3 No preemption victims found for incoming pod, 3 Preemption is not helpful for scheduling."
2023-01-09T11:52:49.170003612Z I0109 11:52:49.169957       1 schedule_one.go:266] "Successfully bound pod to node" pod="openshift-marketplace/community-operators-gjzxm" node="ip-10-0-145-4.us-east-2.compute.internal" evaluatedNodes=6 feasibleNodes=3
2023-01-09T11:53:11.806084762Z I0109 11:53:11.806035       1 schedule_one.go:826] "Unable to schedule pod; no fit; waiting" pod="openshift-logging/lokistack-sample-ruler-1" err="0/6 nodes are available: 3 Insufficient cpu, 3 node(s) had untolerated taint {node-role.kubernetes.io/master: }. preemption: 0/6 nodes are available: 3 No preemption victims found for incoming pod, 3 Preemption is not helpful for scheduling."
2023-01-09T11:53:11.806804405Z I0109 11:53:11.806754       1 schedule_one.go:826] "Unable to schedule pod; no fit; waiting" pod="openshift-logging/lokistack-sample-ingester-1" err="0/6 nodes are available: 3 Insufficient cpu, 3 node(s) had untolerated taint {node-role.kubernetes.io/master: }. preemption: 0/6 nodes are available: 3 No preemption victims found for incoming pod, 3 Preemption is not helpful for scheduling."
2023-01-09T11:54:39.507936508Z I0109 11:54:39.507899       1 schedule_one.go:266] "Successfully bound pod to node" pod="openshift-marketplace/redhat-marketplace-4bstk" node="ip-10-0-199-219.us-east-2.compute.internal" evaluatedNodes=6 feasibleNodes=3
2023-01-09T11:54:53.655935137Z I0109 11:54:53.655891       1 schedule_one.go:826] "Unable to schedule pod; no fit; waiting" pod="openshift-logging/lokistack-sample-ruler-1" err="0/6 nodes are available: 3 Insufficient cpu, 3 node(s) had untolerated taint {node-role.kubernetes.io/master: }. preemption: 0/6 nodes are available: 3 No preemption victims found for incoming pod, 3 Preemption is not helpful for scheduling."
2023-01-09T11:54:53.656783866Z I0109 11:54:53.656750       1 schedule_one.go:826] "Unable to schedule pod; no fit; waiting" pod="openshift-logging/lokistack-sample-ingester-1" err="0/6 nodes are available: 3 Insufficient cpu, 3 node(s) had untolerated taint {node-role.kubernetes.io/master: }. preemption: 0/6 nodes are available: 3 No preemption victims found for incoming pod, 3 Preemption is not helpful for scheduling."
2023-01-09T11:56:17.686130330Z I0109 11:56:17.686088       1 schedule_one.go:266] "Successfully bound pod to node" pod="openshift-marketplace/qe-app-registry-fqvnc" node="ip-10-0-144-137.us-east-2.compute.internal" evaluatedNodes=6 feasibleNodes=3
2023-01-09T11:56:31.912553429Z I0109 11:56:31.912505       1 schedule_one.go:826] "Unable to schedule pod; no fit; waiting" pod="openshift-logging/lokistack-sample-ruler-1" err="0/6 nodes are available: 3 Insufficient cpu, 3 node(s) had untolerated taint {node-role.kubernetes.io/master: }. preemption: 0/6 nodes are available: 3 No preemption victims found for incoming pod, 3 Preemption is not helpful for scheduling."
2023-01-09T11:56:31.913254009Z I0109 11:56:31.913214       1 schedule_one.go:826] "Unable to schedule pod; no fit; waiting" pod="openshift-logging/lokistack-sample-ingester-1" err="0/6 nodes are available: 3 Insufficient cpu, 3 node(s) had untolerated taint {node-role.kubernetes.io/master: }. preemption: 0/6 nodes are available: 3 No preemption victims found for incoming pod, 3 Preemption is not helpful for scheduling."
2023-01-09T11:58:48.066905609Z I0109 11:58:48.066858       1 schedule_one.go:266] "Successfully bound pod to node" pod="openshift-marketplace/certified-operators-qmqz6" node="ip-10-0-199-219.us-east-2.compute.internal" evaluatedNodes=6 feasibleNodes=3
2023-01-09T11:58:55.452363746Z I0109 11:58:55.452300       1 schedule_one.go:266] "Successfully bound pod to node" pod="openshift-marketplace/redhat-operators-4k6gt" node="ip-10-0-145-4.us-east-2.compute.internal" evaluatedNodes=6 feasibleNodes=3
2023-01-09T11:59:02.401246735Z I0109 11:59:02.401205       1 schedule_one.go:826] "Unable to schedule pod; no fit; waiting" pod="openshift-logging/lokistack-sample-ruler-1" err="0/6 nodes are available: 3 Insufficient cpu, 3 node(s) had untolerated taint {node-role.kubernetes.io/master: }. preemption: 0/6 nodes are available: 3 No preemption victims found for incoming pod, 3 Preemption is not helpful for scheduling."
2023-01-09T11:59:02.402062217Z I0109 11:59:02.402022       1 schedule_one.go:826] "Unable to schedule pod; no fit; waiting" pod="openshift-logging/lokistack-sample-ingester-1" err="0/6 nodes are available: 3 Insufficient cpu, 3 node(s) had untolerated taint {node-role.kubernetes.io/master: }. preemption: 0/6 nodes are available: 3 No preemption victims found for incoming pod, 3 Preemption is not helpful for scheduling."
2023-01-09T11:59:28.850227717Z I0109 11:59:28.850179       1 schedule_one.go:826] "Unable to schedule pod; no fit; waiting" pod="openshift-logging/lokistack-sample-ruler-1" err="0/6 nodes are available: 3 Insufficient cpu, 3 node(s) had untolerated taint {node-role.kubernetes.io/master: }. preemption: 0/6 nodes are available: 3 No preemption victims found for incoming pod, 3 Preemption is not helpful for scheduling."
2023-01-09T11:59:28.851179724Z I0109 11:59:28.851150       1 schedule_one.go:826] "Unable to schedule pod; no fit; waiting" pod="openshift-logging/lokistack-sample-ingester-1" err="0/6 nodes are available: 3 Insufficient cpu, 3 node(s) had untolerated taint {node-role.kubernetes.io/master: }. preemption: 0/6 nodes are available: 3 No preemption victims found for incoming pod, 3 Preemption is not helpful for scheduling."
2023-01-09T12:00:00.183865256Z I0109 12:00:00.183830       1 schedule_one.go:266] "Successfully bound pod to node" pod="openshift-operator-lifecycle-manager/collect-profiles-27887760-qfbr4" node="ip-10-0-144-137.us-east-2.compute.internal" evaluatedNodes=6 feasibleNodes=3
2023-01-09T12:00:06.036190463Z I0109 12:00:06.036141       1 schedule_one.go:826] "Unable to schedule pod; no fit; waiting" pod="openshift-logging/lokistack-sample-ruler-1" err="0/6 nodes are available: 3 Insufficient cpu, 3 node(s) had untolerated taint {node-role.kubernetes.io/master: }. preemption: 0/6 nodes are available: 3 No preemption victims found for incoming pod, 3 Preemption is not helpful for scheduling."
2023-01-09T12:00:06.038858817Z I0109 12:00:06.038825       1 schedule_one.go:826] "Unable to schedule pod; no fit; waiting" pod="openshift-logging/lokistack-sample-ingester-1" err="0/6 nodes are available: 3 Insufficient cpu, 3 node(s) had untolerated taint {node-role.kubernetes.io/master: }. preemption: 0/6 nodes are available: 3 No preemption victims found for incoming pod, 3 Preemption is not helpful for scheduling."
2023-01-09T12:03:24.915132866Z I0109 12:03:24.915063       1 schedule_one.go:266] "Successfully bound pod to node" pod="openshift-marketplace/community-operators-zwmvp" node="ip-10-0-145-4.us-east-2.compute.internal" evaluatedNodes=6 feasibleNodes=3
2023-01-09T12:03:47.584696959Z I0109 12:03:47.584648       1 schedule_one.go:826] "Unable to schedule pod; no fit; waiting" pod="openshift-logging/lokistack-sample-ruler-1" err="0/6 nodes are available: 3 Insufficient cpu, 3 node(s) had untolerated taint {node-role.kubernetes.io/master: }. preemption: 0/6 nodes are available: 3 No preemption victims found for incoming pod, 3 Preemption is not helpful for scheduling."
2023-01-09T12:03:47.587826551Z I0109 12:03:47.587786       1 schedule_one.go:826] "Unable to schedule pod; no fit; waiting" pod="openshift-logging/lokistack-sample-ingester-1" err="0/6 nodes are available: 3 Insufficient cpu, 3 node(s) had untolerated taint {node-role.kubernetes.io/master: }. preemption: 0/6 nodes are available: 3 No preemption victims found for incoming pod, 3 Preemption is not helpful for scheduling."
2023-01-09T12:05:39.154078639Z I0109 12:05:39.154029       1 schedule_one.go:266] "Successfully bound pod to node" pod="openshift-marketplace/redhat-marketplace-c7tb9" node="ip-10-0-199-219.us-east-2.compute.internal" evaluatedNodes=6 feasibleNodes=3
2023-01-09T12:05:52.608787607Z I0109 12:05:52.608748       1 schedule_one.go:826] "Unable to schedule pod; no fit; waiting" pod="openshift-logging/lokistack-sample-ruler-1" err="0/6 nodes are available: 3 Insufficient cpu, 3 node(s) had untolerated taint {node-role.kubernetes.io/master: }. preemption: 0/6 nodes are available: 3 No preemption victims found for incoming pod, 3 Preemption is not helpful for scheduling."
2023-01-09T12:05:52.609873680Z I0109 12:05:52.609824       1 schedule_one.go:826] "Unable to schedule pod; no fit; waiting" pod="openshift-logging/lokistack-sample-ingester-1" err="0/6 nodes are available: 3 Insufficient cpu, 3 node(s) had untolerated taint {node-role.kubernetes.io/master: }. preemption: 0/6 nodes are available: 3 No preemption victims found for incoming pod, 3 Preemption is not helpful for scheduling."
2023-01-09T12:06:28.845117965Z I0109 12:06:28.845077       1 schedule_one.go:266] "Successfully bound pod to node" pod="openshift-marketplace/qe-app-registry-5ld78" node="ip-10-0-144-137.us-east-2.compute.internal" evaluatedNodes=6 feasibleNodes=3
2023-01-09T12:06:42.429419763Z I0109 12:06:42.429320       1 schedule_one.go:826] "Unable to schedule pod; no fit; waiting" pod="openshift-logging/lokistack-sample-ruler-1" err="0/6 nodes are available: 3 Insufficient cpu, 3 node(s) had untolerated taint {node-role.kubernetes.io/master: }. preemption: 0/6 nodes are available: 3 No preemption victims found for incoming pod, 3 Preemption is not helpful for scheduling."
2023-01-09T12:06:42.430017436Z I0109 12:06:42.429980       1 schedule_one.go:826] "Unable to schedule pod; no fit; waiting" pod="openshift-logging/lokistack-sample-ingester-1" err="0/6 nodes are available: 3 Insufficient cpu, 3 node(s) had untolerated taint {node-role.kubernetes.io/master: }. preemption: 0/6 nodes are available: 3 No preemption victims found for incoming pod, 3 Preemption is not helpful for scheduling."
2023-01-09T12:10:19.008011486Z I0109 12:10:19.007966       1 schedule_one.go:266] "Successfully bound pod to node" pod="openshift-marketplace/redhat-operators-h8v2x" node="ip-10-0-145-4.us-east-2.compute.internal" evaluatedNodes=6 feasibleNodes=3
2023-01-09T12:10:37.601998999Z I0109 12:10:37.601950       1 schedule_one.go:266] "Successfully bound pod to node" pod="openshift-marketplace/certified-operators-dh8bg" node="ip-10-0-199-219.us-east-2.compute.internal" evaluatedNodes=6 feasibleNodes=3
2023-01-09T12:10:51.487627546Z I0109 12:10:51.487577       1 schedule_one.go:826] "Unable to schedule pod; no fit; waiting" pod="openshift-logging/lokistack-sample-ruler-1" err="0/6 nodes are available: 3 Insufficient cpu, 3 node(s) had untolerated taint {node-role.kubernetes.io/master: }. preemption: 0/6 nodes are available: 3 No preemption victims found for incoming pod, 3 Preemption is not helpful for scheduling."
2023-01-09T12:10:51.488652172Z I0109 12:10:51.488614       1 schedule_one.go:826] "Unable to schedule pod; no fit; waiting" pod="openshift-logging/lokistack-sample-ingester-1" err="0/6 nodes are available: 3 Insufficient cpu, 3 node(s) had untolerated taint {node-role.kubernetes.io/master: }. preemption: 0/6 nodes are available: 3 No preemption victims found for incoming pod, 3 Preemption is not helpful for scheduling."
2023-01-09T12:11:02.176224279Z I0109 12:11:02.176172       1 schedule_one.go:826] "Unable to schedule pod; no fit; waiting" pod="openshift-logging/lokistack-sample-ruler-1" err="0/6 nodes are available: 3 Insufficient cpu, 3 node(s) had untolerated taint {node-role.kubernetes.io/master: }. preemption: 0/6 nodes are available: 3 No preemption victims found for incoming pod, 3 Preemption is not helpful for scheduling."
2023-01-09T12:11:02.176722464Z I0109 12:11:02.176689       1 schedule_one.go:826] "Unable to schedule pod; no fit; waiting" pod="openshift-logging/lokistack-sample-ingester-1" err="0/6 nodes are available: 3 Insufficient cpu, 3 node(s) had untolerated taint {node-role.kubernetes.io/master: }. preemption: 0/6 nodes are available: 3 No preemption victims found for incoming pod, 3 Preemption is not helpful for scheduling."
2023-01-09T12:13:47.295361299Z I0109 12:13:47.295289       1 schedule_one.go:266] "Successfully bound pod to node" pod="openshift-marketplace/community-operators-994kf" node="ip-10-0-145-4.us-east-2.compute.internal" evaluatedNodes=6 feasibleNodes=3
2023-01-09T12:14:10.371901051Z I0109 12:14:10.371858       1 schedule_one.go:826] "Unable to schedule pod; no fit; waiting" pod="openshift-logging/lokistack-sample-ruler-1" err="0/6 nodes are available: 3 Insufficient cpu, 3 node(s) had untolerated taint {node-role.kubernetes.io/master: }. preemption: 0/6 nodes are available: 3 No preemption victims found for incoming pod, 3 Preemption is not helpful for scheduling."
2023-01-09T12:14:10.372762713Z I0109 12:14:10.372732       1 schedule_one.go:826] "Unable to schedule pod; no fit; waiting" pod="openshift-logging/lokistack-sample-ingester-1" err="0/6 nodes are available: 3 Insufficient cpu, 3 node(s) had untolerated taint {node-role.kubernetes.io/master: }. preemption: 0/6 nodes are available: 3 No preemption victims found for incoming pod, 3 Preemption is not helpful for scheduling."
2023-01-09T12:15:00.173573195Z I0109 12:15:00.173361       1 schedule_one.go:266] "Successfully bound pod to node" pod="openshift-operator-lifecycle-manager/collect-profiles-27887775-c7sc9" node="ip-10-0-144-137.us-east-2.compute.internal" evaluatedNodes=6 feasibleNodes=3
2023-01-09T12:15:05.650798296Z I0109 12:15:05.650740       1 schedule_one.go:826] "Unable to schedule pod; no fit; waiting" pod="openshift-logging/lokistack-sample-ruler-1" err="0/6 nodes are available: 3 Insufficient cpu, 3 node(s) had untolerated taint {node-role.kubernetes.io/master: }. preemption: 0/6 nodes are available: 3 No preemption victims found for incoming pod, 3 Preemption is not helpful for scheduling."
2023-01-09T12:15:05.651309603Z I0109 12:15:05.651281       1 schedule_one.go:826] "Unable to schedule pod; no fit; waiting" pod="openshift-logging/lokistack-sample-ingester-1" err="0/6 nodes are available: 3 Insufficient cpu, 3 node(s) had untolerated taint {node-role.kubernetes.io/master: }. preemption: 0/6 nodes are available: 3 No preemption victims found for incoming pod, 3 Preemption is not helpful for scheduling."
2023-01-09T12:16:59.695249517Z I0109 12:16:59.695191       1 schedule_one.go:266] "Successfully bound pod to node" pod="openshift-marketplace/qe-app-registry-f9rtm" node="ip-10-0-144-137.us-east-2.compute.internal" evaluatedNodes=6 feasibleNodes=3
2023-01-09T12:17:00.077246641Z I0109 12:17:00.077194       1 schedule_one.go:266] "Successfully bound pod to node" pod="openshift-marketplace/redhat-marketplace-sgx8j" node="ip-10-0-199-219.us-east-2.compute.internal" evaluatedNodes=6 feasibleNodes=3
2023-01-09T12:17:13.569851147Z I0109 12:17:13.569795       1 schedule_one.go:826] "Unable to schedule pod; no fit; waiting" pod="openshift-logging/lokistack-sample-ruler-1" err="0/6 nodes are available: 3 Insufficient cpu, 3 node(s) had untolerated taint {node-role.kubernetes.io/master: }. preemption: 0/6 nodes are available: 3 No preemption victims found for incoming pod, 3 Preemption is not helpful for scheduling."
2023-01-09T12:17:13.570931258Z I0109 12:17:13.570900       1 schedule_one.go:826] "Unable to schedule pod; no fit; waiting" pod="openshift-logging/lokistack-sample-ingester-1" err="0/6 nodes are available: 3 Insufficient cpu, 3 node(s) had untolerated taint {node-role.kubernetes.io/master: }. preemption: 0/6 nodes are available: 3 No preemption victims found for incoming pod, 3 Preemption is not helpful for scheduling."
2023-01-09T12:17:24.415812669Z I0109 12:17:24.415768       1 schedule_one.go:826] "Unable to schedule pod; no fit; waiting" pod="openshift-logging/lokistack-sample-ruler-1" err="0/6 nodes are available: 3 Insufficient cpu, 3 node(s) had untolerated taint {node-role.kubernetes.io/master: }. preemption: 0/6 nodes are available: 3 No preemption victims found for incoming pod, 3 Preemption is not helpful for scheduling."
2023-01-09T12:17:24.416387607Z I0109 12:17:24.416353       1 schedule_one.go:826] "Unable to schedule pod; no fit; waiting" pod="openshift-logging/lokistack-sample-ingester-1" err="0/6 nodes are available: 3 Insufficient cpu, 3 node(s) had untolerated taint {node-role.kubernetes.io/master: }. preemption: 0/6 nodes are available: 3 No preemption victims found for incoming pod, 3 Preemption is not helpful for scheduling."
2023-01-09T12:20:35.775358013Z I0109 12:20:35.775261       1 schedule_one.go:266] "Successfully bound pod to node" pod="openshift-marketplace/redhat-operators-t4qjb" node="ip-10-0-145-4.us-east-2.compute.internal" evaluatedNodes=6 feasibleNodes=3
2023-01-09T12:21:08.555524992Z I0109 12:21:08.555479       1 schedule_one.go:826] "Unable to schedule pod; no fit; waiting" pod="openshift-logging/lokistack-sample-ruler-1" err="0/6 nodes are available: 3 Insufficient cpu, 3 node(s) had untolerated taint {node-role.kubernetes.io/master: }. preemption: 0/6 nodes are available: 3 No preemption victims found for incoming pod, 3 Preemption is not helpful for scheduling."
2023-01-09T12:21:08.556054680Z I0109 12:21:08.556022       1 schedule_one.go:826] "Unable to schedule pod; no fit; waiting" pod="openshift-logging/lokistack-sample-ingester-1" err="0/6 nodes are available: 3 Insufficient cpu, 3 node(s) had untolerated taint {node-role.kubernetes.io/master: }. preemption: 0/6 nodes are available: 3 No preemption victims found for incoming pod, 3 Preemption is not helpful for scheduling."
2023-01-09T12:21:46.901014881Z I0109 12:21:46.900960       1 schedule_one.go:266] "Successfully bound pod to node" pod="openshift-marketplace/certified-operators-mvkzc" node="ip-10-0-199-219.us-east-2.compute.internal" evaluatedNodes=6 feasibleNodes=3
2023-01-09T12:22:00.410892788Z I0109 12:22:00.410842       1 schedule_one.go:826] "Unable to schedule pod; no fit; waiting" pod="openshift-logging/lokistack-sample-ruler-1" err="0/6 nodes are available: 3 Insufficient cpu, 3 node(s) had untolerated taint {node-role.kubernetes.io/master: }. preemption: 0/6 nodes are available: 3 No preemption victims found for incoming pod, 3 Preemption is not helpful for scheduling."
2023-01-09T12:22:00.411626722Z I0109 12:22:00.411585       1 schedule_one.go:826] "Unable to schedule pod; no fit; waiting" pod="openshift-logging/lokistack-sample-ingester-1" err="0/6 nodes are available: 3 Insufficient cpu, 3 node(s) had untolerated taint {node-role.kubernetes.io/master: }. preemption: 0/6 nodes are available: 3 No preemption victims found for incoming pod, 3 Preemption is not helpful for scheduling."
2023-01-09T12:24:16.283217676Z I0109 12:24:16.283175       1 schedule_one.go:266] "Successfully bound pod to node" pod="openshift-marketplace/community-operators-pxhvl" node="ip-10-0-145-4.us-east-2.compute.internal" evaluatedNodes=6 feasibleNodes=3
2023-01-09T12:24:39.160147417Z I0109 12:24:39.160099       1 schedule_one.go:826] "Unable to schedule pod; no fit; waiting" pod="openshift-logging/lokistack-sample-ruler-1" err="0/6 nodes are available: 3 Insufficient cpu, 3 node(s) had untolerated taint {node-role.kubernetes.io/master: }. preemption: 0/6 nodes are available: 3 No preemption victims found for incoming pod, 3 Preemption is not helpful for scheduling."
2023-01-09T12:24:39.160812129Z I0109 12:24:39.160779       1 schedule_one.go:826] "Unable to schedule pod; no fit; waiting" pod="openshift-logging/lokistack-sample-ingester-1" err="0/6 nodes are available: 3 Insufficient cpu, 3 node(s) had untolerated taint {node-role.kubernetes.io/master: }. preemption: 0/6 nodes are available: 3 No preemption victims found for incoming pod, 3 Preemption is not helpful for scheduling."
2023-01-09T12:27:38.955012193Z I0109 12:27:38.954965       1 schedule_one.go:266] "Successfully bound pod to node" pod="openshift-marketplace/redhat-marketplace-tqqrw" node="ip-10-0-199-219.us-east-2.compute.internal" evaluatedNodes=6 feasibleNodes=3
2023-01-09T12:27:52.443295009Z I0109 12:27:52.443234       1 schedule_one.go:826] "Unable to schedule pod; no fit; waiting" pod="openshift-logging/lokistack-sample-ruler-1" err="0/6 nodes are available: 3 Insufficient cpu, 3 node(s) had untolerated taint {node-role.kubernetes.io/master: }. preemption: 0/6 nodes are available: 3 No preemption victims found for incoming pod, 3 Preemption is not helpful for scheduling."
2023-01-09T12:27:52.444261882Z I0109 12:27:52.444225       1 schedule_one.go:826] "Unable to schedule pod; no fit; waiting" pod="openshift-logging/lokistack-sample-ingester-1" err="0/6 nodes are available: 3 Insufficient cpu, 3 node(s) had untolerated taint {node-role.kubernetes.io/master: }. preemption: 0/6 nodes are available: 3 No preemption victims found for incoming pod, 3 Preemption is not helpful for scheduling."
2023-01-09T12:28:14.275748477Z I0109 12:28:14.275703       1 schedule_one.go:266] "Successfully bound pod to node" pod="openshift-marketplace/qe-app-registry-prwdg" node="ip-10-0-144-137.us-east-2.compute.internal" evaluatedNodes=6 feasibleNodes=3
2023-01-09T12:28:28.619414127Z I0109 12:28:28.619356       1 schedule_one.go:826] "Unable to schedule pod; no fit; waiting" pod="openshift-logging/lokistack-sample-ruler-1" err="0/6 nodes are available: 3 Insufficient cpu, 3 node(s) had untolerated taint {node-role.kubernetes.io/master: }. preemption: 0/6 nodes are available: 3 No preemption victims found for incoming pod, 3 Preemption is not helpful for scheduling."
2023-01-09T12:28:28.620586085Z I0109 12:28:28.620534       1 schedule_one.go:826] "Unable to schedule pod; no fit; waiting" pod="openshift-logging/lokistack-sample-ingester-1" err="0/6 nodes are available: 3 Insufficient cpu, 3 node(s) had untolerated taint {node-role.kubernetes.io/master: }. preemption: 0/6 nodes are available: 3 No preemption victims found for incoming pod, 3 Preemption is not helpful for scheduling."
2023-01-09T12:30:00.158924479Z I0109 12:30:00.158888       1 schedule_one.go:266] "Successfully bound pod to node" pod="openshift-operator-lifecycle-manager/collect-profiles-27887790-vhtw6" node="ip-10-0-144-137.us-east-2.compute.internal" evaluatedNodes=6 feasibleNodes=3
2023-01-09T12:30:06.847591486Z I0109 12:30:06.847543       1 schedule_one.go:826] "Unable to schedule pod; no fit; waiting" pod="openshift-logging/lokistack-sample-ruler-1" err="0/6 nodes are available: 3 Insufficient cpu, 3 node(s) had untolerated taint {node-role.kubernetes.io/master: }. preemption: 0/6 nodes are available: 3 No preemption victims found for incoming pod, 3 Preemption is not helpful for scheduling."
2023-01-09T12:30:06.848197264Z I0109 12:30:06.848156       1 schedule_one.go:826] "Unable to schedule pod; no fit; waiting" pod="openshift-logging/lokistack-sample-ingester-1" err="0/6 nodes are available: 3 Insufficient cpu, 3 node(s) had untolerated taint {node-role.kubernetes.io/master: }. preemption: 0/6 nodes are available: 3 No preemption victims found for incoming pod, 3 Preemption is not helpful for scheduling."
2023-01-09T12:30:37.247181027Z I0109 12:30:37.247143       1 schedule_one.go:266] "Successfully bound pod to node" pod="openshift-marketplace/redhat-operators-gw2k8" node="ip-10-0-145-4.us-east-2.compute.internal" evaluatedNodes=6 feasibleNodes=3
2023-01-09T12:31:10.273435607Z I0109 12:31:10.273387       1 schedule_one.go:826] "Unable to schedule pod; no fit; waiting" pod="openshift-logging/lokistack-sample-ruler-1" err="0/6 nodes are available: 3 Insufficient cpu, 3 node(s) had untolerated taint {node-role.kubernetes.io/master: }. preemption: 0/6 nodes are available: 3 No preemption victims found for incoming pod, 3 Preemption is not helpful for scheduling."
2023-01-09T12:31:10.274007926Z I0109 12:31:10.273969       1 schedule_one.go:826] "Unable to schedule pod; no fit; waiting" pod="openshift-logging/lokistack-sample-ingester-1" err="0/6 nodes are available: 3 Insufficient cpu, 3 node(s) had untolerated taint {node-role.kubernetes.io/master: }. preemption: 0/6 nodes are available: 3 No preemption victims found for incoming pod, 3 Preemption is not helpful for scheduling."
2023-01-09T12:32:08.824557637Z I0109 12:32:08.824512       1 schedule_one.go:266] "Successfully bound pod to node" pod="openshift-marketplace/certified-operators-qfhks" node="ip-10-0-199-219.us-east-2.compute.internal" evaluatedNodes=6 feasibleNodes=3
2023-01-09T12:32:23.241946593Z I0109 12:32:23.241905       1 schedule_one.go:826] "Unable to schedule pod; no fit; waiting" pod="openshift-logging/lokistack-sample-ruler-1" err="0/6 nodes are available: 3 Insufficient cpu, 3 node(s) had untolerated taint {node-role.kubernetes.io/master: }. preemption: 0/6 nodes are available: 3 No preemption victims found for incoming pod, 3 Preemption is not helpful for scheduling."
2023-01-09T12:32:23.242865674Z I0109 12:32:23.242831       1 schedule_one.go:826] "Unable to schedule pod; no fit; waiting" pod="openshift-logging/lokistack-sample-ingester-1" err="0/6 nodes are available: 3 Insufficient cpu, 3 node(s) had untolerated taint {node-role.kubernetes.io/master: }. preemption: 0/6 nodes are available: 3 No preemption victims found for incoming pod, 3 Preemption is not helpful for scheduling."
2023-01-09T12:35:02.135655696Z I0109 12:35:02.135612       1 schedule_one.go:266] "Successfully bound pod to node" pod="openshift-marketplace/community-operators-rpp2z" node="ip-10-0-145-4.us-east-2.compute.internal" evaluatedNodes=6 feasibleNodes=3
2023-01-09T12:35:25.028014048Z I0109 12:35:25.027950       1 schedule_one.go:826] "Unable to schedule pod; no fit; waiting" pod="openshift-logging/lokistack-sample-ruler-1" err="0/6 nodes are available: 3 Insufficient cpu, 3 node(s) had untolerated taint {node-role.kubernetes.io/master: }. preemption: 0/6 nodes are available: 3 No preemption victims found for incoming pod, 3 Preemption is not helpful for scheduling."
2023-01-09T12:35:25.029091417Z I0109 12:35:25.029056       1 schedule_one.go:826] "Unable to schedule pod; no fit; waiting" pod="openshift-logging/lokistack-sample-ingester-1" err="0/6 nodes are available: 3 Insufficient cpu, 3 node(s) had untolerated taint {node-role.kubernetes.io/master: }. preemption: 0/6 nodes are available: 3 No preemption victims found for incoming pod, 3 Preemption is not helpful for scheduling."
2023-01-09T12:38:20.776275301Z I0109 12:38:20.776211       1 schedule_one.go:266] "Successfully bound pod to node" pod="openshift-marketplace/redhat-marketplace-79qwg" node="ip-10-0-199-219.us-east-2.compute.internal" evaluatedNodes=6 feasibleNodes=3
2023-01-09T12:38:34.356566748Z I0109 12:38:34.356520       1 schedule_one.go:826] "Unable to schedule pod; no fit; waiting" pod="openshift-logging/lokistack-sample-ruler-1" err="0/6 nodes are available: 3 Insufficient cpu, 3 node(s) had untolerated taint {node-role.kubernetes.io/master: }. preemption: 0/6 nodes are available: 3 No preemption victims found for incoming pod, 3 Preemption is not helpful for scheduling."
2023-01-09T12:38:34.357890097Z I0109 12:38:34.357843       1 schedule_one.go:826] "Unable to schedule pod; no fit; waiting" pod="openshift-logging/lokistack-sample-ingester-1" err="0/6 nodes are available: 3 Insufficient cpu, 3 node(s) had untolerated taint {node-role.kubernetes.io/master: }. preemption: 0/6 nodes are available: 3 No preemption victims found for incoming pod, 3 Preemption is not helpful for scheduling."
2023-01-09T12:40:27.786012159Z I0109 12:40:27.785897       1 schedule_one.go:266] "Successfully bound pod to node" pod="openshift-marketplace/qe-app-registry-vp7ns" node="ip-10-0-144-137.us-east-2.compute.internal" evaluatedNodes=6 feasibleNodes=3
2023-01-09T12:40:41.370747538Z I0109 12:40:41.370704       1 schedule_one.go:826] "Unable to schedule pod; no fit; waiting" pod="openshift-logging/lokistack-sample-ruler-1" err="0/6 nodes are available: 3 Insufficient cpu, 3 node(s) had untolerated taint {node-role.kubernetes.io/master: }. preemption: 0/6 nodes are available: 3 No preemption victims found for incoming pod, 3 Preemption is not helpful for scheduling."
2023-01-09T12:40:41.371370983Z I0109 12:40:41.371320       1 schedule_one.go:826] "Unable to schedule pod; no fit; waiting" pod="openshift-logging/lokistack-sample-ingester-1" err="0/6 nodes are available: 3 Insufficient cpu, 3 node(s) had untolerated taint {node-role.kubernetes.io/master: }. preemption: 0/6 nodes are available: 3 No preemption victims found for incoming pod, 3 Preemption is not helpful for scheduling."
2023-01-09T12:40:56.671415708Z I0109 12:40:56.671379       1 schedule_one.go:266] "Successfully bound pod to node" pod="openshift-marketplace/redhat-operators-9fkqr" node="ip-10-0-145-4.us-east-2.compute.internal" evaluatedNodes=6 feasibleNodes=3
2023-01-09T12:41:30.053429102Z I0109 12:41:30.053383       1 schedule_one.go:826] "Unable to schedule pod; no fit; waiting" pod="openshift-logging/lokistack-sample-ruler-1" err="0/6 nodes are available: 3 Insufficient cpu, 3 node(s) had untolerated taint {node-role.kubernetes.io/master: }. preemption: 0/6 nodes are available: 3 No preemption victims found for incoming pod, 3 Preemption is not helpful for scheduling."
2023-01-09T12:41:30.053987446Z I0109 12:41:30.053952       1 schedule_one.go:826] "Unable to schedule pod; no fit; waiting" pod="openshift-logging/lokistack-sample-ingester-1" err="0/6 nodes are available: 3 Insufficient cpu, 3 node(s) had untolerated taint {node-role.kubernetes.io/master: }. preemption: 0/6 nodes are available: 3 No preemption victims found for incoming pod, 3 Preemption is not helpful for scheduling."
2023-01-09T12:43:09.333225015Z I0109 12:43:09.333177       1 schedule_one.go:266] "Successfully bound pod to node" pod="openshift-marketplace/certified-operators-pwrtr" node="ip-10-0-199-219.us-east-2.compute.internal" evaluatedNodes=6 feasibleNodes=3
2023-01-09T12:43:23.203370099Z I0109 12:43:23.203308       1 schedule_one.go:826] "Unable to schedule pod; no fit; waiting" pod="openshift-logging/lokistack-sample-ruler-1" err="0/6 nodes are available: 3 Insufficient cpu, 3 node(s) had untolerated taint {node-role.kubernetes.io/master: }. preemption: 0/6 nodes are available: 3 No preemption victims found for incoming pod, 3 Preemption is not helpful for scheduling."
2023-01-09T12:43:23.204525034Z I0109 12:43:23.204475       1 schedule_one.go:826] "Unable to schedule pod; no fit; waiting" pod="openshift-logging/lokistack-sample-ingester-1" err="0/6 nodes are available: 3 Insufficient cpu, 3 node(s) had untolerated taint {node-role.kubernetes.io/master: }. preemption: 0/6 nodes are available: 3 No preemption victims found for incoming pod, 3 Preemption is not helpful for scheduling."
2023-01-09T12:45:00.151041854Z I0109 12:45:00.151006       1 schedule_one.go:266] "Successfully bound pod to node" pod="openshift-operator-lifecycle-manager/collect-profiles-27887805-pnnl8" node="ip-10-0-144-137.us-east-2.compute.internal" evaluatedNodes=6 feasibleNodes=3
2023-01-09T12:45:04.009379897Z I0109 12:45:04.009312       1 schedule_one.go:826] "Unable to schedule pod; no fit; waiting" pod="openshift-logging/lokistack-sample-ruler-1" err="0/6 nodes are available: 3 Insufficient cpu, 3 node(s) had untolerated taint {node-role.kubernetes.io/master: }. preemption: 0/6 nodes are available: 3 No preemption victims found for incoming pod, 3 Preemption is not helpful for scheduling."
2023-01-09T12:45:04.009897479Z I0109 12:45:04.009868       1 schedule_one.go:826] "Unable to schedule pod; no fit; waiting" pod="openshift-logging/lokistack-sample-ingester-1" err="0/6 nodes are available: 3 Insufficient cpu, 3 node(s) had untolerated taint {node-role.kubernetes.io/master: }. preemption: 0/6 nodes are available: 3 No preemption victims found for incoming pod, 3 Preemption is not helpful for scheduling."
2023-01-09T12:48:55.986785770Z I0109 12:48:55.986733       1 schedule_one.go:266] "Successfully bound pod to node" pod="openshift-marketplace/redhat-marketplace-kv96f" node="ip-10-0-199-219.us-east-2.compute.internal" evaluatedNodes=6 feasibleNodes=3
2023-01-09T12:49:10.191971755Z I0109 12:49:10.191922       1 schedule_one.go:826] "Unable to schedule pod; no fit; waiting" pod="openshift-logging/lokistack-sample-ruler-1" err="0/6 nodes are available: 3 Insufficient cpu, 3 node(s) had untolerated taint {node-role.kubernetes.io/master: }. preemption: 0/6 nodes are available: 3 No preemption victims found for incoming pod, 3 Preemption is not helpful for scheduling."
2023-01-09T12:49:10.193281621Z I0109 12:49:10.193234       1 schedule_one.go:826] "Unable to schedule pod; no fit; waiting" pod="openshift-logging/lokistack-sample-ingester-1" err="0/6 nodes are available: 3 Insufficient cpu, 3 node(s) had untolerated taint {node-role.kubernetes.io/master: }. preemption: 0/6 nodes are available: 3 No preemption victims found for incoming pod, 3 Preemption is not helpful for scheduling."
2023-01-09T12:52:26.621117500Z I0109 12:52:26.621075       1 schedule_one.go:266] "Successfully bound pod to node" pod="openshift-marketplace/redhat-operators-tbl8s" node="ip-10-0-145-4.us-east-2.compute.internal" evaluatedNodes=6 feasibleNodes=3
2023-01-09T12:52:34.247248121Z I0109 12:52:34.247207       1 schedule_one.go:266] "Successfully bound pod to node" pod="openshift-marketplace/community-operators-gvczh" node="ip-10-0-145-4.us-east-2.compute.internal" evaluatedNodes=6 feasibleNodes=3
2023-01-09T12:52:34.296901064Z I0109 12:52:34.296847       1 schedule_one.go:266] "Successfully bound pod to node" pod="openshift-marketplace/qe-app-registry-48f8v" node="ip-10-0-144-137.us-east-2.compute.internal" evaluatedNodes=6 feasibleNodes=3
2023-01-09T12:52:48.128151527Z I0109 12:52:48.128107       1 schedule_one.go:826] "Unable to schedule pod; no fit; waiting" pod="openshift-logging/lokistack-sample-ruler-1" err="0/6 nodes are available: 3 Insufficient cpu, 3 node(s) had untolerated taint {node-role.kubernetes.io/master: }. preemption: 0/6 nodes are available: 3 No preemption victims found for incoming pod, 3 Preemption is not helpful for scheduling."
2023-01-09T12:52:48.128712807Z I0109 12:52:48.128678       1 schedule_one.go:826] "Unable to schedule pod; no fit; waiting" pod="openshift-logging/lokistack-sample-ingester-1" err="0/6 nodes are available: 3 Insufficient cpu, 3 node(s) had untolerated taint {node-role.kubernetes.io/master: }. preemption: 0/6 nodes are available: 3 No preemption victims found for incoming pod, 3 Preemption is not helpful for scheduling."
2023-01-09T12:53:00.032874945Z I0109 12:53:00.032818       1 schedule_one.go:826] "Unable to schedule pod; no fit; waiting" pod="openshift-logging/lokistack-sample-ruler-1" err="0/6 nodes are available: 3 Insufficient cpu, 3 node(s) had untolerated taint {node-role.kubernetes.io/master: }. preemption: 0/6 nodes are available: 3 No preemption victims found for incoming pod, 3 Preemption is not helpful for scheduling."
2023-01-09T12:53:00.033580564Z I0109 12:53:00.033547       1 schedule_one.go:826] "Unable to schedule pod; no fit; waiting" pod="openshift-logging/lokistack-sample-ingester-1" err="0/6 nodes are available: 3 Insufficient cpu, 3 node(s) had untolerated taint {node-role.kubernetes.io/master: }. preemption: 0/6 nodes are available: 3 No preemption victims found for incoming pod, 3 Preemption is not helpful for scheduling."
2023-01-09T12:53:10.684551881Z I0109 12:53:10.684499       1 schedule_one.go:826] "Unable to schedule pod; no fit; waiting" pod="openshift-logging/lokistack-sample-ruler-1" err="0/6 nodes are available: 3 Insufficient cpu, 3 node(s) had untolerated taint {node-role.kubernetes.io/master: }. preemption: 0/6 nodes are available: 3 No preemption victims found for incoming pod, 3 Preemption is not helpful for scheduling."
2023-01-09T12:53:10.685076012Z I0109 12:53:10.685046       1 schedule_one.go:826] "Unable to schedule pod; no fit; waiting" pod="openshift-logging/lokistack-sample-ingester-1" err="0/6 nodes are available: 3 Insufficient cpu, 3 node(s) had untolerated taint {node-role.kubernetes.io/master: }. preemption: 0/6 nodes are available: 3 No preemption victims found for incoming pod, 3 Preemption is not helpful for scheduling."
2023-01-09T12:53:20.477360947Z I0109 12:53:20.477290       1 schedule_one.go:266] "Successfully bound pod to node" pod="openshift-marketplace/certified-operators-wk6pg" node="ip-10-0-199-219.us-east-2.compute.internal" evaluatedNodes=6 feasibleNodes=3
2023-01-09T12:53:34.003294723Z I0109 12:53:34.003251       1 schedule_one.go:826] "Unable to schedule pod; no fit; waiting" pod="openshift-logging/lokistack-sample-ruler-1" err="0/6 nodes are available: 3 Insufficient cpu, 3 node(s) had untolerated taint {node-role.kubernetes.io/master: }. preemption: 0/6 nodes are available: 3 No preemption victims found for incoming pod, 3 Preemption is not helpful for scheduling."
2023-01-09T12:53:34.004594566Z I0109 12:53:34.004561       1 schedule_one.go:826] "Unable to schedule pod; no fit; waiting" pod="openshift-logging/lokistack-sample-ingester-1" err="0/6 nodes are available: 3 Insufficient cpu, 3 node(s) had untolerated taint {node-role.kubernetes.io/master: }. preemption: 0/6 nodes are available: 3 No preemption victims found for incoming pod, 3 Preemption is not helpful for scheduling."
2023-01-09T12:58:34.714773632Z I0109 12:58:34.714705       1 schedule_one.go:826] "Unable to schedule pod; no fit; waiting" pod="openshift-logging/lokistack-sample-ruler-1" err="0/6 nodes are available: 3 Insufficient cpu, 3 node(s) had untolerated taint {node-role.kubernetes.io/master: }. preemption: 0/6 nodes are available: 3 No preemption victims found for incoming pod, 3 Preemption is not helpful for scheduling."
2023-01-09T12:58:34.726690137Z I0109 12:58:34.716018       1 schedule_one.go:826] "Unable to schedule pod; no fit; waiting" pod="openshift-logging/lokistack-sample-ingester-1" err="0/6 nodes are available: 3 Insufficient cpu, 3 node(s) had untolerated taint {node-role.kubernetes.io/master: }. preemption: 0/6 nodes are available: 3 No preemption victims found for incoming pod, 3 Preemption is not helpful for scheduling."
2023-01-09T12:59:00.767663802Z I0109 12:59:00.767614       1 schedule_one.go:266] "Successfully bound pod to node" pod="openshift-marketplace/redhat-marketplace-wlrns" node="ip-10-0-199-219.us-east-2.compute.internal" evaluatedNodes=6 feasibleNodes=3
2023-01-09T12:59:15.007126209Z I0109 12:59:15.007079       1 schedule_one.go:826] "Unable to schedule pod; no fit; waiting" pod="openshift-logging/lokistack-sample-ruler-1" err="0/6 nodes are available: 3 Insufficient cpu, 3 node(s) had untolerated taint {node-role.kubernetes.io/master: }. preemption: 0/6 nodes are available: 3 No preemption victims found for incoming pod, 3 Preemption is not helpful for scheduling."
2023-01-09T12:59:15.007935081Z I0109 12:59:15.007898       1 schedule_one.go:826] "Unable to schedule pod; no fit; waiting" pod="openshift-logging/lokistack-sample-ingester-1" err="0/6 nodes are available: 3 Insufficient cpu, 3 node(s) had untolerated taint {node-role.kubernetes.io/master: }. preemption: 0/6 nodes are available: 3 No preemption victims found for incoming pod, 3 Preemption is not helpful for scheduling."
2023-01-09T13:00:00.179258888Z I0109 13:00:00.179217       1 schedule_one.go:266] "Successfully bound pod to node" pod="openshift-operator-lifecycle-manager/collect-profiles-27887820-s6nft" node="ip-10-0-144-137.us-east-2.compute.internal" evaluatedNodes=6 feasibleNodes=3
2023-01-09T13:00:05.167601931Z I0109 13:00:05.167554       1 schedule_one.go:826] "Unable to schedule pod; no fit; waiting" pod="openshift-logging/lokistack-sample-ruler-1" err="0/6 nodes are available: 3 Insufficient cpu, 3 node(s) had untolerated taint {node-role.kubernetes.io/master: }. preemption: 0/6 nodes are available: 3 No preemption victims found for incoming pod, 3 Preemption is not helpful for scheduling."
2023-01-09T13:00:05.168146987Z I0109 13:00:05.168116       1 schedule_one.go:826] "Unable to schedule pod; no fit; waiting" pod="openshift-logging/lokistack-sample-ingester-1" err="0/6 nodes are available: 3 Insufficient cpu, 3 node(s) had untolerated taint {node-role.kubernetes.io/master: }. preemption: 0/6 nodes are available: 3 No preemption victims found for incoming pod, 3 Preemption is not helpful for scheduling."
2023-01-09T13:02:28.119372829Z I0109 13:02:28.119286       1 schedule_one.go:266] "Successfully bound pod to node" pod="openshift-marketplace/redhat-operators-qt8nc" node="ip-10-0-145-4.us-east-2.compute.internal" evaluatedNodes=6 feasibleNodes=3
2023-01-09T13:03:26.392848777Z I0109 13:03:26.392803       1 schedule_one.go:266] "Successfully bound pod to node" pod="openshift-marketplace/community-operators-vqkn8" node="ip-10-0-145-4.us-east-2.compute.internal" evaluatedNodes=6 feasibleNodes=3
2023-01-09T13:03:30.803147340Z I0109 13:03:30.803095       1 schedule_one.go:826] "Unable to schedule pod; no fit; waiting" pod="openshift-logging/lokistack-sample-ruler-1" err="0/6 nodes are available: 3 Insufficient cpu, 3 node(s) had untolerated taint {node-role.kubernetes.io/master: }. preemption: 0/6 nodes are available: 3 No preemption victims found for incoming pod, 3 Preemption is not helpful for scheduling."
2023-01-09T13:03:30.804161777Z I0109 13:03:30.804116       1 schedule_one.go:826] "Unable to schedule pod; no fit; waiting" pod="openshift-logging/lokistack-sample-ingester-1" err="0/6 nodes are available: 3 Insufficient cpu, 3 node(s) had untolerated taint {node-role.kubernetes.io/master: }. preemption: 0/6 nodes are available: 3 No preemption victims found for incoming pod, 3 Preemption is not helpful for scheduling."
2023-01-09T13:03:48.853898657Z I0109 13:03:48.853847       1 schedule_one.go:826] "Unable to schedule pod; no fit; waiting" pod="openshift-logging/lokistack-sample-ruler-1" err="0/6 nodes are available: 3 Insufficient cpu, 3 node(s) had untolerated taint {node-role.kubernetes.io/master: }. preemption: 0/6 nodes are available: 3 No preemption victims found for incoming pod, 3 Preemption is not helpful for scheduling."
2023-01-09T13:03:48.854713399Z I0109 13:03:48.854678       1 schedule_one.go:826] "Unable to schedule pod; no fit; waiting" pod="openshift-logging/lokistack-sample-ingester-1" err="0/6 nodes are available: 3 Insufficient cpu, 3 node(s) had untolerated taint {node-role.kubernetes.io/master: }. preemption: 0/6 nodes are available: 3 No preemption victims found for incoming pod, 3 Preemption is not helpful for scheduling."
2023-01-09T13:03:55.327579153Z I0109 13:03:55.327523       1 schedule_one.go:266] "Successfully bound pod to node" pod="openshift-marketplace/qe-app-registry-kkx89" node="ip-10-0-144-137.us-east-2.compute.internal" evaluatedNodes=6 feasibleNodes=3
2023-01-09T13:04:08.769115657Z I0109 13:04:08.769039       1 schedule_one.go:826] "Unable to schedule pod; no fit; waiting" pod="openshift-logging/lokistack-sample-ruler-1" err="0/6 nodes are available: 3 Insufficient cpu, 3 node(s) had untolerated taint {node-role.kubernetes.io/master: }. preemption: 0/6 nodes are available: 3 No preemption victims found for incoming pod, 3 Preemption is not helpful for scheduling."
2023-01-09T13:04:08.770913579Z I0109 13:04:08.770888       1 schedule_one.go:826] "Unable to schedule pod; no fit; waiting" pod="openshift-logging/lokistack-sample-ingester-1" err="0/6 nodes are available: 3 Insufficient cpu, 3 node(s) had untolerated taint {node-role.kubernetes.io/master: }. preemption: 0/6 nodes are available: 3 No preemption victims found for incoming pod, 3 Preemption is not helpful for scheduling."
2023-01-09T13:04:11.327071218Z I0109 13:04:11.327015       1 schedule_one.go:266] "Successfully bound pod to node" pod="openshift-marketplace/certified-operators-jsb6d" node="ip-10-0-199-219.us-east-2.compute.internal" evaluatedNodes=6 feasibleNodes=3
2023-01-09T13:04:24.918297978Z I0109 13:04:24.918251       1 schedule_one.go:826] "Unable to schedule pod; no fit; waiting" pod="openshift-logging/lokistack-sample-ruler-1" err="0/6 nodes are available: 3 Insufficient cpu, 3 node(s) had untolerated taint {node-role.kubernetes.io/master: }. preemption: 0/6 nodes are available: 3 No preemption victims found for incoming pod, 3 Preemption is not helpful for scheduling."
2023-01-09T13:04:24.919666266Z I0109 13:04:24.919632       1 schedule_one.go:826] "Unable to schedule pod; no fit; waiting" pod="openshift-logging/lokistack-sample-ingester-1" err="0/6 nodes are available: 3 Insufficient cpu, 3 node(s) had untolerated taint {node-role.kubernetes.io/master: }. preemption: 0/6 nodes are available: 3 No preemption victims found for incoming pod, 3 Preemption is not helpful for scheduling."
2023-01-09T13:09:34.725600710Z I0109 13:09:34.725557       1 schedule_one.go:826] "Unable to schedule pod; no fit; waiting" pod="openshift-logging/lokistack-sample-ruler-1" err="0/6 nodes are available: 3 Insufficient cpu, 3 node(s) had untolerated taint {node-role.kubernetes.io/master: }. preemption: 0/6 nodes are available: 3 No preemption victims found for incoming pod, 3 Preemption is not helpful for scheduling."
2023-01-09T13:09:34.726059308Z I0109 13:09:34.726033       1 schedule_one.go:826] "Unable to schedule pod; no fit; waiting" pod="openshift-logging/lokistack-sample-ingester-1" err="0/6 nodes are available: 3 Insufficient cpu, 3 node(s) had untolerated taint {node-role.kubernetes.io/master: }. preemption: 0/6 nodes are available: 3 No preemption victims found for incoming pod, 3 Preemption is not helpful for scheduling."
2023-01-09T13:09:41.690129926Z I0109 13:09:41.690053       1 schedule_one.go:266] "Successfully bound pod to node" pod="openshift-marketplace/redhat-marketplace-gh6s8" node="ip-10-0-199-219.us-east-2.compute.internal" evaluatedNodes=6 feasibleNodes=3
2023-01-09T13:09:55.887177937Z I0109 13:09:55.887119       1 schedule_one.go:826] "Unable to schedule pod; no fit; waiting" pod="openshift-logging/lokistack-sample-ruler-1" err="0/6 nodes are available: 3 Insufficient cpu, 3 node(s) had untolerated taint {node-role.kubernetes.io/master: }. preemption: 0/6 nodes are available: 3 No preemption victims found for incoming pod, 3 Preemption is not helpful for scheduling."
2023-01-09T13:09:55.888118928Z I0109 13:09:55.888079       1 schedule_one.go:826] "Unable to schedule pod; no fit; waiting" pod="openshift-logging/lokistack-sample-ingester-1" err="0/6 nodes are available: 3 Insufficient cpu, 3 node(s) had untolerated taint {node-role.kubernetes.io/master: }. preemption: 0/6 nodes are available: 3 No preemption victims found for incoming pod, 3 Preemption is not helpful for scheduling."
2023-01-09T13:13:08.321562581Z I0109 13:13:08.321520       1 schedule_one.go:266] "Successfully bound pod to node" pod="openshift-marketplace/redhat-operators-c8gph" node="ip-10-0-145-4.us-east-2.compute.internal" evaluatedNodes=6 feasibleNodes=3
2023-01-09T13:13:41.553155819Z I0109 13:13:41.553098       1 schedule_one.go:826] "Unable to schedule pod; no fit; waiting" pod="openshift-logging/lokistack-sample-ruler-1" err="0/6 nodes are available: 3 Insufficient cpu, 3 node(s) had untolerated taint {node-role.kubernetes.io/master: }. preemption: 0/6 nodes are available: 3 No preemption victims found for incoming pod, 3 Preemption is not helpful for scheduling."
2023-01-09T13:13:41.553931624Z I0109 13:13:41.553895       1 schedule_one.go:826] "Unable to schedule pod; no fit; waiting" pod="openshift-logging/lokistack-sample-ingester-1" err="0/6 nodes are available: 3 Insufficient cpu, 3 node(s) had untolerated taint {node-role.kubernetes.io/master: }. preemption: 0/6 nodes are available: 3 No preemption victims found for incoming pod, 3 Preemption is not helpful for scheduling."
2023-01-09T13:14:58.737470140Z I0109 13:14:58.737403       1 schedule_one.go:266] "Successfully bound pod to node" pod="openshift-marketplace/certified-operators-ztm92" node="ip-10-0-199-219.us-east-2.compute.internal" evaluatedNodes=6 feasibleNodes=3
2023-01-09T13:15:00.151514747Z I0109 13:15:00.151443       1 schedule_one.go:266] "Successfully bound pod to node" pod="openshift-operator-lifecycle-manager/collect-profiles-27887835-7lvl5" node="ip-10-0-144-137.us-east-2.compute.internal" evaluatedNodes=6 feasibleNodes=3
2023-01-09T13:15:08.435812540Z I0109 13:15:08.435770       1 schedule_one.go:826] "Unable to schedule pod; no fit; waiting" pod="openshift-logging/lokistack-sample-ruler-1" err="0/6 nodes are available: 3 Insufficient cpu, 3 node(s) had untolerated taint {node-role.kubernetes.io/master: }. preemption: 0/6 nodes are available: 3 No preemption victims found for incoming pod, 3 Preemption is not helpful for scheduling."
2023-01-09T13:15:08.436385685Z I0109 13:15:08.436322       1 schedule_one.go:826] "Unable to schedule pod; no fit; waiting" pod="openshift-logging/lokistack-sample-ingester-1" err="0/6 nodes are available: 3 Insufficient cpu, 3 node(s) had untolerated taint {node-role.kubernetes.io/master: }. preemption: 0/6 nodes are available: 3 No preemption victims found for incoming pod, 3 Preemption is not helpful for scheduling."
2023-01-09T13:15:18.507869985Z I0109 13:15:18.507823       1 schedule_one.go:826] "Unable to schedule pod; no fit; waiting" pod="openshift-logging/lokistack-sample-ruler-1" err="0/6 nodes are available: 3 Insufficient cpu, 3 node(s) had untolerated taint {node-role.kubernetes.io/master: }. preemption: 0/6 nodes are available: 3 No preemption victims found for incoming pod, 3 Preemption is not helpful for scheduling."
2023-01-09T13:15:18.509115562Z I0109 13:15:18.509077       1 schedule_one.go:826] "Unable to schedule pod; no fit; waiting" pod="openshift-logging/lokistack-sample-ingester-1" err="0/6 nodes are available: 3 Insufficient cpu, 3 node(s) had untolerated taint {node-role.kubernetes.io/master: }. preemption: 0/6 nodes are available: 3 No preemption victims found for incoming pod, 3 Preemption is not helpful for scheduling."
2023-01-09T13:20:34.752238590Z I0109 13:20:34.752195       1 schedule_one.go:826] "Unable to schedule pod; no fit; waiting" pod="openshift-logging/lokistack-sample-ruler-1" err="0/6 nodes are available: 3 Insufficient cpu, 3 node(s) had untolerated taint {node-role.kubernetes.io/master: }. preemption: 0/6 nodes are available: 3 No preemption victims found for incoming pod, 3 Preemption is not helpful for scheduling."
2023-01-09T13:20:34.752753834Z I0109 13:20:34.752717       1 schedule_one.go:826] "Unable to schedule pod; no fit; waiting" pod="openshift-logging/lokistack-sample-ingester-1" err="0/6 nodes are available: 3 Insufficient cpu, 3 node(s) had untolerated taint {node-role.kubernetes.io/master: }. preemption: 0/6 nodes are available: 3 No preemption victims found for incoming pod, 3 Preemption is not helpful for scheduling."
2023-01-09T13:23:34.228120761Z I0109 13:23:34.228076       1 schedule_one.go:266] "Successfully bound pod to node" pod="openshift-marketplace/community-operators-s4km7" node="ip-10-0-145-4.us-east-2.compute.internal" evaluatedNodes=6 feasibleNodes=3
2023-01-09T13:23:57.261183854Z I0109 13:23:57.260550       1 schedule_one.go:826] "Unable to schedule pod; no fit; waiting" pod="openshift-logging/lokistack-sample-ruler-1" err="0/6 nodes are available: 3 Insufficient cpu, 3 node(s) had untolerated taint {node-role.kubernetes.io/master: }. preemption: 0/6 nodes are available: 3 No preemption victims found for incoming pod, 3 Preemption is not helpful for scheduling."
2023-01-09T13:23:57.262443258Z I0109 13:23:57.262402       1 schedule_one.go:826] "Unable to schedule pod; no fit; waiting" pod="openshift-logging/lokistack-sample-ingester-1" err="0/6 nodes are available: 3 Insufficient cpu, 3 node(s) had untolerated taint {node-role.kubernetes.io/master: }. preemption: 0/6 nodes are available: 3 No preemption victims found for incoming pod, 3 Preemption is not helpful for scheduling."
2023-01-09T13:23:58.374206334Z I0109 13:23:58.374163       1 schedule_one.go:266] "Successfully bound pod to node" pod="openshift-marketplace/qe-app-registry-sf9tj" node="ip-10-0-144-137.us-east-2.compute.internal" evaluatedNodes=6 feasibleNodes=3
2023-01-09T13:24:12.735449388Z I0109 13:24:12.735404       1 schedule_one.go:826] "Unable to schedule pod; no fit; waiting" pod="openshift-logging/lokistack-sample-ruler-1" err="0/6 nodes are available: 3 Insufficient cpu, 3 node(s) had untolerated taint {node-role.kubernetes.io/master: }. preemption: 0/6 nodes are available: 3 No preemption victims found for incoming pod, 3 Preemption is not helpful for scheduling."
2023-01-09T13:24:12.736163664Z I0109 13:24:12.736130       1 schedule_one.go:826] "Unable to schedule pod; no fit; waiting" pod="openshift-logging/lokistack-sample-ingester-1" err="0/6 nodes are available: 3 Insufficient cpu, 3 node(s) had untolerated taint {node-role.kubernetes.io/master: }. preemption: 0/6 nodes are available: 3 No preemption victims found for incoming pod, 3 Preemption is not helpful for scheduling."
2023-01-09T13:24:21.831045030Z I0109 13:24:21.830999       1 schedule_one.go:266] "Successfully bound pod to node" pod="openshift-marketplace/redhat-operators-pwmsw" node="ip-10-0-145-4.us-east-2.compute.internal" evaluatedNodes=6 feasibleNodes=3
2023-01-09T13:24:32.739122995Z I0109 13:24:32.739073       1 schedule_one.go:266] "Successfully bound pod to node" pod="openshift-marketplace/redhat-marketplace-pllfn" node="ip-10-0-199-219.us-east-2.compute.internal" evaluatedNodes=6 feasibleNodes=3
2023-01-09T13:24:46.564787144Z I0109 13:24:46.564743       1 schedule_one.go:826] "Unable to schedule pod; no fit; waiting" pod="openshift-logging/lokistack-sample-ruler-1" err="0/6 nodes are available: 3 Insufficient cpu, 3 node(s) had untolerated taint {node-role.kubernetes.io/master: }. preemption: 0/6 nodes are available: 3 No preemption victims found for incoming pod, 3 Preemption is not helpful for scheduling."
2023-01-09T13:24:46.565752269Z I0109 13:24:46.565703       1 schedule_one.go:826] "Unable to schedule pod; no fit; waiting" pod="openshift-logging/lokistack-sample-ingester-1" err="0/6 nodes are available: 3 Insufficient cpu, 3 node(s) had untolerated taint {node-role.kubernetes.io/master: }. preemption: 0/6 nodes are available: 3 No preemption victims found for incoming pod, 3 Preemption is not helpful for scheduling."
2023-01-09T13:24:56.849375067Z I0109 13:24:56.849302       1 schedule_one.go:826] "Unable to schedule pod; no fit; waiting" pod="openshift-logging/lokistack-sample-ruler-1" err="0/6 nodes are available: 3 Insufficient cpu, 3 node(s) had untolerated taint {node-role.kubernetes.io/master: }. preemption: 0/6 nodes are available: 3 No preemption victims found for incoming pod, 3 Preemption is not helpful for scheduling."
2023-01-09T13:24:56.849869992Z I0109 13:24:56.849843       1 schedule_one.go:826] "Unable to schedule pod; no fit; waiting" pod="openshift-logging/lokistack-sample-ingester-1" err="0/6 nodes are available: 3 Insufficient cpu, 3 node(s) had untolerated taint {node-role.kubernetes.io/master: }. preemption: 0/6 nodes are available: 3 No preemption victims found for incoming pod, 3 Preemption is not helpful for scheduling."
2023-01-09T13:28:46.003188712Z I0109 13:28:46.003146       1 schedule_one.go:266] "Successfully bound pod to node" pod="openshift-marketplace/certified-operators-nqn2c" node="ip-10-0-199-219.us-east-2.compute.internal" evaluatedNodes=6 feasibleNodes=3
2023-01-09T13:29:00.298389273Z I0109 13:29:00.298347       1 schedule_one.go:826] "Unable to schedule pod; no fit; waiting" pod="openshift-logging/lokistack-sample-ruler-1" err="0/6 nodes are available: 3 Insufficient cpu, 3 node(s) had untolerated taint {node-role.kubernetes.io/master: }. preemption: 0/6 nodes are available: 3 No preemption victims found for incoming pod, 3 Preemption is not helpful for scheduling."
2023-01-09T13:29:00.298962072Z I0109 13:29:00.298927       1 schedule_one.go:826] "Unable to schedule pod; no fit; waiting" pod="openshift-logging/lokistack-sample-ingester-1" err="0/6 nodes are available: 3 Insufficient cpu, 3 node(s) had untolerated taint {node-role.kubernetes.io/master: }. preemption: 0/6 nodes are available: 3 No preemption victims found for incoming pod, 3 Preemption is not helpful for scheduling."
2023-01-09T13:30:00.148359840Z I0109 13:30:00.148304       1 schedule_one.go:266] "Successfully bound pod to node" pod="openshift-operator-lifecycle-manager/collect-profiles-27887850-5bvlv" node="ip-10-0-144-137.us-east-2.compute.internal" evaluatedNodes=6 feasibleNodes=3
2023-01-09T13:30:04.576719097Z I0109 13:30:04.576679       1 schedule_one.go:826] "Unable to schedule pod; no fit; waiting" pod="openshift-logging/lokistack-sample-ruler-1" err="0/6 nodes are available: 3 Insufficient cpu, 3 node(s) had untolerated taint {node-role.kubernetes.io/master: }. preemption: 0/6 nodes are available: 3 No preemption victims found for incoming pod, 3 Preemption is not helpful for scheduling."
2023-01-09T13:30:04.577199161Z I0109 13:30:04.577173       1 schedule_one.go:826] "Unable to schedule pod; no fit; waiting" pod="openshift-logging/lokistack-sample-ingester-1" err="0/6 nodes are available: 3 Insufficient cpu, 3 node(s) had untolerated taint {node-role.kubernetes.io/master: }. preemption: 0/6 nodes are available: 3 No preemption victims found for incoming pod, 3 Preemption is not helpful for scheduling."
2023-01-09T13:34:11.210288762Z I0109 13:34:11.210225       1 schedule_one.go:266] "Successfully bound pod to node" pod="openshift-marketplace/qe-app-registry-j767k" node="ip-10-0-144-137.us-east-2.compute.internal" evaluatedNodes=6 feasibleNodes=3
2023-01-09T13:34:25.278968915Z I0109 13:34:25.278925       1 schedule_one.go:826] "Unable to schedule pod; no fit; waiting" pod="openshift-logging/lokistack-sample-ruler-1" err="0/6 nodes are available: 3 Insufficient cpu, 3 node(s) had untolerated taint {node-role.kubernetes.io/master: }. preemption: 0/6 nodes are available: 3 No preemption victims found for incoming pod, 3 Preemption is not helpful for scheduling."
2023-01-09T13:34:25.279577292Z I0109 13:34:25.279540       1 schedule_one.go:826] "Unable to schedule pod; no fit; waiting" pod="openshift-logging/lokistack-sample-ingester-1" err="0/6 nodes are available: 3 Insufficient cpu, 3 node(s) had untolerated taint {node-role.kubernetes.io/master: }. preemption: 0/6 nodes are available: 3 No preemption victims found for incoming pod, 3 Preemption is not helpful for scheduling."
2023-01-09T13:35:48.150431175Z I0109 13:35:48.150373       1 schedule_one.go:266] "Successfully bound pod to node" pod="openshift-marketplace/redhat-operators-5cwfl" node="ip-10-0-145-4.us-east-2.compute.internal" evaluatedNodes=6 feasibleNodes=3
2023-01-09T13:35:59.890155987Z I0109 13:35:59.890109       1 schedule_one.go:266] "Successfully bound pod to node" pod="openshift-marketplace/redhat-marketplace-m4rqj" node="ip-10-0-199-219.us-east-2.compute.internal" evaluatedNodes=6 feasibleNodes=3
2023-01-09T13:36:13.576256645Z I0109 13:36:13.576211       1 schedule_one.go:826] "Unable to schedule pod; no fit; waiting" pod="openshift-logging/lokistack-sample-ruler-1" err="0/6 nodes are available: 3 Insufficient cpu, 3 node(s) had untolerated taint {node-role.kubernetes.io/master: }. preemption: 0/6 nodes are available: 3 No preemption victims found for incoming pod, 3 Preemption is not helpful for scheduling."
2023-01-09T13:36:13.577111872Z I0109 13:36:13.577072       1 schedule_one.go:826] "Unable to schedule pod; no fit; waiting" pod="openshift-logging/lokistack-sample-ingester-1" err="0/6 nodes are available: 3 Insufficient cpu, 3 node(s) had untolerated taint {node-role.kubernetes.io/master: }. preemption: 0/6 nodes are available: 3 No preemption victims found for incoming pod, 3 Preemption is not helpful for scheduling."
2023-01-09T13:36:24.254289969Z I0109 13:36:24.254246       1 schedule_one.go:826] "Unable to schedule pod; no fit; waiting" pod="openshift-logging/lokistack-sample-ruler-1" err="0/6 nodes are available: 3 Insufficient cpu, 3 node(s) had untolerated taint {node-role.kubernetes.io/master: }. preemption: 0/6 nodes are available: 3 No preemption victims found for incoming pod, 3 Preemption is not helpful for scheduling."
2023-01-09T13:36:24.254864481Z I0109 13:36:24.254823       1 schedule_one.go:826] "Unable to schedule pod; no fit; waiting" pod="openshift-logging/lokistack-sample-ingester-1" err="0/6 nodes are available: 3 Insufficient cpu, 3 node(s) had untolerated taint {node-role.kubernetes.io/master: }. preemption: 0/6 nodes are available: 3 No preemption victims found for incoming pod, 3 Preemption is not helpful for scheduling."
2023-01-09T13:39:27.837172638Z I0109 13:39:27.837117       1 schedule_one.go:266] "Successfully bound pod to node" pod="openshift-marketplace/certified-operators-b4fb9" node="ip-10-0-199-219.us-east-2.compute.internal" evaluatedNodes=6 feasibleNodes=3
2023-01-09T13:39:31.049610851Z I0109 13:39:31.049562       1 schedule_one.go:266] "Successfully bound pod to node" pod="openshift-marketplace/community-operators-sjgk6" node="ip-10-0-145-4.us-east-2.compute.internal" evaluatedNodes=6 feasibleNodes=3
2023-01-09T13:39:42.181534606Z I0109 13:39:42.181469       1 schedule_one.go:826] "Unable to schedule pod; no fit; waiting" pod="openshift-logging/lokistack-sample-ruler-1" err="0/6 nodes are available: 3 Insufficient cpu, 3 node(s) had untolerated taint {node-role.kubernetes.io/master: }. preemption: 0/6 nodes are available: 3 No preemption victims found for incoming pod, 3 Preemption is not helpful for scheduling."
2023-01-09T13:39:42.182285615Z I0109 13:39:42.182244       1 schedule_one.go:826] "Unable to schedule pod; no fit; waiting" pod="openshift-logging/lokistack-sample-ingester-1" err="0/6 nodes are available: 3 Insufficient cpu, 3 node(s) had untolerated taint {node-role.kubernetes.io/master: }. preemption: 0/6 nodes are available: 3 No preemption victims found for incoming pod, 3 Preemption is not helpful for scheduling."
2023-01-09T13:39:53.957036455Z I0109 13:39:53.956977       1 schedule_one.go:826] "Unable to schedule pod; no fit; waiting" pod="openshift-logging/lokistack-sample-ruler-1" err="0/6 nodes are available: 3 Insufficient cpu, 3 node(s) had untolerated taint {node-role.kubernetes.io/master: }. preemption: 0/6 nodes are available: 3 No preemption victims found for incoming pod, 3 Preemption is not helpful for scheduling."
2023-01-09T13:39:53.957891815Z I0109 13:39:53.957854       1 schedule_one.go:826] "Unable to schedule pod; no fit; waiting" pod="openshift-logging/lokistack-sample-ingester-1" err="0/6 nodes are available: 3 Insufficient cpu, 3 node(s) had untolerated taint {node-role.kubernetes.io/master: }. preemption: 0/6 nodes are available: 3 No preemption victims found for incoming pod, 3 Preemption is not helpful for scheduling."
2023-01-09T13:44:23.675016422Z I0109 13:44:23.674952       1 schedule_one.go:266] "Successfully bound pod to node" pod="openshift-marketplace/qe-app-registry-cwvvd" node="ip-10-0-144-137.us-east-2.compute.internal" evaluatedNodes=6 feasibleNodes=3
2023-01-09T13:44:37.769125848Z I0109 13:44:37.769012       1 schedule_one.go:826] "Unable to schedule pod; no fit; waiting" pod="openshift-logging/lokistack-sample-ruler-1" err="0/6 nodes are available: 3 Insufficient cpu, 3 node(s) had untolerated taint {node-role.kubernetes.io/master: }. preemption: 0/6 nodes are available: 3 No preemption victims found for incoming pod, 3 Preemption is not helpful for scheduling."
2023-01-09T13:44:37.770084810Z I0109 13:44:37.770049       1 schedule_one.go:826] "Unable to schedule pod; no fit; waiting" pod="openshift-logging/lokistack-sample-ingester-1" err="0/6 nodes are available: 3 Insufficient cpu, 3 node(s) had untolerated taint {node-role.kubernetes.io/master: }. preemption: 0/6 nodes are available: 3 No preemption victims found for incoming pod, 3 Preemption is not helpful for scheduling."
2023-01-09T13:45:00.141852872Z I0109 13:45:00.141794       1 schedule_one.go:266] "Successfully bound pod to node" pod="openshift-operator-lifecycle-manager/collect-profiles-27887865-gplj9" node="ip-10-0-144-137.us-east-2.compute.internal" evaluatedNodes=6 feasibleNodes=3
2023-01-09T13:45:04.830162281Z I0109 13:45:04.830115       1 schedule_one.go:826] "Unable to schedule pod; no fit; waiting" pod="openshift-logging/lokistack-sample-ruler-1" err="0/6 nodes are available: 3 Insufficient cpu, 3 node(s) had untolerated taint {node-role.kubernetes.io/master: }. preemption: 0/6 nodes are available: 3 No preemption victims found for incoming pod, 3 Preemption is not helpful for scheduling."
2023-01-09T13:45:04.830769514Z I0109 13:45:04.830740       1 schedule_one.go:826] "Unable to schedule pod; no fit; waiting" pod="openshift-logging/lokistack-sample-ingester-1" err="0/6 nodes are available: 3 Insufficient cpu, 3 node(s) had untolerated taint {node-role.kubernetes.io/master: }. preemption: 0/6 nodes are available: 3 No preemption victims found for incoming pod, 3 Preemption is not helpful for scheduling."
2023-01-09T13:46:23.866768714Z I0109 13:46:23.866722       1 schedule_one.go:266] "Successfully bound pod to node" pod="openshift-marketplace/redhat-marketplace-zmz4c" node="ip-10-0-199-219.us-east-2.compute.internal" evaluatedNodes=6 feasibleNodes=3
2023-01-09T13:46:37.437501292Z I0109 13:46:37.437458       1 schedule_one.go:826] "Unable to schedule pod; no fit; waiting" pod="openshift-logging/lokistack-sample-ruler-1" err="0/6 nodes are available: 3 Insufficient cpu, 3 node(s) had untolerated taint {node-role.kubernetes.io/master: }. preemption: 0/6 nodes are available: 3 No preemption victims found for incoming pod, 3 Preemption is not helpful for scheduling."
2023-01-09T13:46:37.438603872Z I0109 13:46:37.438573       1 schedule_one.go:826] "Unable to schedule pod; no fit; waiting" pod="openshift-logging/lokistack-sample-ingester-1" err="0/6 nodes are available: 3 Insufficient cpu, 3 node(s) had untolerated taint {node-role.kubernetes.io/master: }. preemption: 0/6 nodes are available: 3 No preemption victims found for incoming pod, 3 Preemption is not helpful for scheduling."
2023-01-09T13:46:55.261259502Z I0109 13:46:55.261219       1 schedule_one.go:266] "Successfully bound pod to node" pod="openshift-marketplace/redhat-operators-g6pbk" node="ip-10-0-145-4.us-east-2.compute.internal" evaluatedNodes=6 feasibleNodes=3
2023-01-09T13:47:28.290565479Z I0109 13:47:28.290511       1 schedule_one.go:826] "Unable to schedule pod; no fit; waiting" pod="openshift-logging/lokistack-sample-ruler-1" err="0/6 nodes are available: 3 Insufficient cpu, 3 node(s) had untolerated taint {node-role.kubernetes.io/master: }. preemption: 0/6 nodes are available: 3 No preemption victims found for incoming pod, 3 Preemption is not helpful for scheduling."
2023-01-09T13:47:28.291232861Z I0109 13:47:28.291201       1 schedule_one.go:826] "Unable to schedule pod; no fit; waiting" pod="openshift-logging/lokistack-sample-ingester-1" err="0/6 nodes are available: 3 Insufficient cpu, 3 node(s) had untolerated taint {node-role.kubernetes.io/master: }. preemption: 0/6 nodes are available: 3 No preemption victims found for incoming pod, 3 Preemption is not helpful for scheduling."
2023-01-09T13:50:12.309872470Z I0109 13:50:12.309825       1 schedule_one.go:266] "Successfully bound pod to node" pod="openshift-marketplace/certified-operators-pwgpn" node="ip-10-0-199-219.us-east-2.compute.internal" evaluatedNodes=6 feasibleNodes=3
2023-01-09T13:50:21.292719917Z I0109 13:50:21.292678       1 schedule_one.go:266] "Successfully bound pod to node" pod="openshift-marketplace/community-operators-427xd" node="ip-10-0-145-4.us-east-2.compute.internal" evaluatedNodes=6 feasibleNodes=3
2023-01-09T13:50:26.123245446Z I0109 13:50:26.123207       1 schedule_one.go:826] "Unable to schedule pod; no fit; waiting" pod="openshift-logging/lokistack-sample-ruler-1" err="0/6 nodes are available: 3 Insufficient cpu, 3 node(s) had untolerated taint {node-role.kubernetes.io/master: }. preemption: 0/6 nodes are available: 3 No preemption victims found for incoming pod, 3 Preemption is not helpful for scheduling."
2023-01-09T13:50:26.124094369Z I0109 13:50:26.124058       1 schedule_one.go:826] "Unable to schedule pod; no fit; waiting" pod="openshift-logging/lokistack-sample-ingester-1" err="0/6 nodes are available: 3 Insufficient cpu, 3 node(s) had untolerated taint {node-role.kubernetes.io/master: }. preemption: 0/6 nodes are available: 3 No preemption victims found for incoming pod, 3 Preemption is not helpful for scheduling."
2023-01-09T13:50:43.851584364Z I0109 13:50:43.851537       1 schedule_one.go:826] "Unable to schedule pod; no fit; waiting" pod="openshift-logging/lokistack-sample-ruler-1" err="0/6 nodes are available: 3 Insufficient cpu, 3 node(s) had untolerated taint {node-role.kubernetes.io/master: }. preemption: 0/6 nodes are available: 3 No preemption victims found for incoming pod, 3 Preemption is not helpful for scheduling."
2023-01-09T13:50:43.852407006Z I0109 13:50:43.852373       1 schedule_one.go:826] "Unable to schedule pod; no fit; waiting" pod="openshift-logging/lokistack-sample-ingester-1" err="0/6 nodes are available: 3 Insufficient cpu, 3 node(s) had untolerated taint {node-role.kubernetes.io/master: }. preemption: 0/6 nodes are available: 3 No preemption victims found for incoming pod, 3 Preemption is not helpful for scheduling."
2023-01-09T13:56:04.801369470Z I0109 13:56:04.801308       1 schedule_one.go:826] "Unable to schedule pod; no fit; waiting" pod="openshift-logging/lokistack-sample-ruler-1" err="0/6 nodes are available: 3 Insufficient cpu, 3 node(s) had untolerated taint {node-role.kubernetes.io/master: }. preemption: 0/6 nodes are available: 3 No preemption victims found for incoming pod, 3 Preemption is not helpful for scheduling."
2023-01-09T13:56:04.801844431Z I0109 13:56:04.801816       1 schedule_one.go:826] "Unable to schedule pod; no fit; waiting" pod="openshift-logging/lokistack-sample-ingester-1" err="0/6 nodes are available: 3 Insufficient cpu, 3 node(s) had untolerated taint {node-role.kubernetes.io/master: }. preemption: 0/6 nodes are available: 3 No preemption victims found for incoming pod, 3 Preemption is not helpful for scheduling."
2023-01-09T13:56:31.226483063Z I0109 13:56:31.226437       1 schedule_one.go:266] "Successfully bound pod to node" pod="openshift-marketplace/qe-app-registry-dlnng" node="ip-10-0-144-137.us-east-2.compute.internal" evaluatedNodes=6 feasibleNodes=3
2023-01-09T13:56:31.232731702Z I0109 13:56:31.232646       1 schedule_one.go:266] "Successfully bound pod to node" pod="openshift-marketplace/redhat-marketplace-vxwtd" node="ip-10-0-199-219.us-east-2.compute.internal" evaluatedNodes=6 feasibleNodes=3
2023-01-09T13:56:45.218632434Z I0109 13:56:45.218566       1 schedule_one.go:826] "Unable to schedule pod; no fit; waiting" pod="openshift-logging/lokistack-sample-ruler-1" err="0/6 nodes are available: 3 Insufficient cpu, 3 node(s) had untolerated taint {node-role.kubernetes.io/master: }. preemption: 0/6 nodes are available: 3 No preemption victims found for incoming pod, 3 Preemption is not helpful for scheduling."
2023-01-09T13:56:45.219370542Z I0109 13:56:45.219299       1 schedule_one.go:826] "Unable to schedule pod; no fit; waiting" pod="openshift-logging/lokistack-sample-ingester-1" err="0/6 nodes are available: 3 Insufficient cpu, 3 node(s) had untolerated taint {node-role.kubernetes.io/master: }. preemption: 0/6 nodes are available: 3 No preemption victims found for incoming pod, 3 Preemption is not helpful for scheduling."
2023-01-09T13:56:55.978885817Z I0109 13:56:55.978843       1 schedule_one.go:826] "Unable to schedule pod; no fit; waiting" pod="openshift-logging/lokistack-sample-ruler-1" err="0/6 nodes are available: 3 Insufficient cpu, 3 node(s) had untolerated taint {node-role.kubernetes.io/master: }. preemption: 0/6 nodes are available: 3 No preemption victims found for incoming pod, 3 Preemption is not helpful for scheduling."
2023-01-09T13:56:55.979427047Z I0109 13:56:55.979392       1 schedule_one.go:826] "Unable to schedule pod; no fit; waiting" pod="openshift-logging/lokistack-sample-ingester-1" err="0/6 nodes are available: 3 Insufficient cpu, 3 node(s) had untolerated taint {node-role.kubernetes.io/master: }. preemption: 0/6 nodes are available: 3 No preemption victims found for incoming pod, 3 Preemption is not helpful for scheduling."
2023-01-09T13:58:47.817808880Z I0109 13:58:47.817750       1 schedule_one.go:266] "Successfully bound pod to node" pod="openshift-marketplace/redhat-operators-64fmp" node="ip-10-0-145-4.us-east-2.compute.internal" evaluatedNodes=6 feasibleNodes=3
